Workbook

Sheet About
A1: BPEaCP BAU Population Employment and Compensation Projections | B1: Nebraska | C1: 44838 | I1: Alabama | J1: AL
B2: =LOOKUP(B1,I1:J50,J1:J50) -> NE | I2: Alaska | J2: AK
A3: Sources: | B3: Population Projection | I3: Arizona | J3: AZ
B4: U.S. Census Bureau | I4: Arkansas | J4: AR
B5: 2017 | I5: California | J5: CA
B6: 2017 National Population Projections Datasets | I6: Colorado | J6: CO
B7: https://www.census.gov/data/datasets/2017/demo/popproj/2017-popproj.html | I7: Connecticut | J7: CT
B8: Table 1 | I8: Delaware | J8: DE
B9: Note that years 2014 and 2015 filled in using the 2014 version of this publication, as the 2017 version only provides data back through 2016. | I9: Florida | J9: FL
B10: State Populations | I10: Georgia | J10: GA
B11: Demographics Research Group | I11: Hawaii | J11: HI
B12: 43435 | I12: Idaho | J12: ID
B13: Projections for the 50 States and D.C. | I13: Illinois | J13: IL
B14: https://demographics.coopercenter.org/national-population-projections | I14: Indiana | J14: IN
I15: Iowa | J15: IA
B16: Employment-to-Population Ratio | I16: Kansas | J16: KS
B17: St. Louis Federal Reserve Bank | I17: Kentucky | J17: KY
B18: 2020 | I18: Louisiana | J18: LA
B19: Employment-Population Ratio | I19: Maine | J19: ME
B20: https://fred.stlouisfed.org/series/EMRATIO | I20: Maryland | J20: MD
I21: Massachusetts | J21: MA
B22: Total Employee Compensation (from IO tables, historical year) | I22: Michigan | J22: MI
B23: OECD | I23: Minnesota | J23: MN
B24: 2018 | I24: Mississippi | J24: MS
B25: Input-Output Tables 2018 Edition (ISIC Rev. 4) | I25: Missouri | J25: MO
B26: https://stats.oecd.org/Index.aspx?DataSetCode=IOTS# | I26: Montana | J26: MT
B27: Variable: VAL | I27: Nebraska | J27: NE
I28: Nevada | J28: NV
B29: Annual Change in Compensation per EE Hour Worked | I29: New Hampshire | J29: NH
B30: U.S. Bureau of Labor Statistics | I30: New Jersey | J30: NJ
B31: 2020 | I31: New Mexico | J31: NM
B32: Employer Costs for Employee Compensation | I32: New York | J32: NY
B33: https://www.bls.gov/data/ | I33: North Carolina | J33: NC
B34: Use data finder to create table for all civilian workers nationally | I34: North Dakota | J34: ND
I35: Ohio | J35: OH
A36: Notes | I36: Oklahoma | J36: OK
I37: Oregon | J37: OR
A38: Population | I38: Pennsylvania | J38: PA
A39: Population projections are available directly from the U.S. Census department. | I39: Rhode Island | J39: RI
I40: South Carolina | J40: SC
...

Sheet State Populations
A1: Observed and Total Population for the U.S. and the States, 2010-2040
A2: Updated on Dec 2018 by the Weldon Cooper Center for Public Service, Demographics Research Group, www.demographics.coopercenter.org
A3: FIPS | B3: Geography Name | C3: Total Population
C4: 2010 | D4: 2020 | E4: 2030 | F4: 2040
B5: United States | C5: 308745538 | D5: 332527548 | E5: 357975719 | F5: 379392779
A6: 1 | B6: Alabama | C6: 4779736 | D6: 4911278 | E6: 5029833 | F6: 5056796
A7: 2 | B7: Alaska | C7: 710231 | D7: 751328 | E7: 792188 | F7: 819954
A8: 4 | B8: Arizona | C8: 6392017 | D8: 7268694 | E8: 8238407 | F8: 9166279
A9: 5 | B9: Arkansas | C9: 2915918 | D9: 3038491 | E9: 3155798 | F9: 3217535
A10: 6 | B10: California | C10: 37253956 | D10: 40438640 | E10: 43751116 | F10: 46467001
A11: 8 | B11: Colorado | C11: 5029196 | D11: 5843359 | E11: 6766983 | F11: 7692907
A12: 9 | B12: Connecticut | C12: 3574097 | D12: 3593542 | E12: 3601202 | F12: 3542707
A13: 10 | B13: Delaware | C13: 897934 | D13: 987393 | E13: 1082192 | F13: 1164344
A14: 11 | B14: District of Columbia | C14: 601723 | D14: 732552 | E14: 888891 | F14: 1058820
A15: 12 | B15: Florida | C15: 18801310 | D15: 21877257 | E15: 25372664 | F15: 28886983
A16: 13 | B16: Georgia | C16: 9687653 | D16: 10725351 | E16: 11835126 | F16: 12820271
A17: 15 | B17: Hawaii | C17: 1360301 | D17: 1453902 | E17: 1548831 | F17: 1619703
... A56: 56 | B56: Wyoming | C56: 563626 | D56: 585380 | E56: 605972 | F56: 615787
A57: Subgroups may not sum to total due to rounding

Sheet Census Pop Projection
A1: SEX | B1: ORIGIN | C1: RACE | D1: YEAR | E1: TOTAL_POP | F1: State Population (Estimated) | G1: POP_0 | H1: POP_1 | I1: POP_2 | J1: POP_3 | K1: POP_4 | L1: POP_5 | M1: POP_6 | N1: POP_7 | O1: POP_8 | P1: POP_9 | Q1: POP_10 | R1: POP_11 | S1: POP_12 | T1: POP_13 | U1: POP_14 | V1: POP_15 | W1: POP_16 | X1: POP_17 | Y1: POP_18 | Z1: POP_19 | AA1: POP_20 | AB1: POP_21 | AC1: POP_22 | AD1: POP_23 | AE1: POP_24 | AF1: POP_25 | AG1: POP_26 | AH1: POP_27 | AI1: POP_28 | AJ1: POP_29 | AK1: POP_30 | AL1: POP_31 | AM1: POP_32 | AN1: POP_33 | AO1: POP_34 | AP1: POP_35 | AQ1: POP_36 | AR1: POP_37 | AS1: POP_38 | AT1: POP_39 | AU1: POP_40 | AV1: POP_41 | AW1: POP_42 | AX1: POP_43 | AY1: POP_44 | AZ1: POP_45 | BA1: POP_46 | BB1: POP_47 | BC1: POP_48 | BD1: POP_49 | BE1: POP_50 | BF1: POP_51 | BG1: POP_52 | BH1: POP_53 | BI1: POP_54 | BJ1: POP_55 | BK1: POP_56 | BL1: POP_57 | BM1: POP_58 | BN1: POP_59 | BO1: POP_60 | BP1: POP_61 | BQ1: POP_62 | BR1: POP_63 | BS1: POP_64 | BT1: POP_65 | BU1: POP_66 | BV1: POP_67 | BW1: POP_68 | BX1: POP_69 | BY1: POP_70 | BZ1: POP_71 | CA1: POP_72 | CB1: POP_73 | CC1: POP_74 | CD1: POP_75 | CE1: POP_76 | CF1: POP_77 | CG1: POP_78 | CH1: POP_79 | CI1: POP_80 | CJ1: POP_81 | CK1: POP_82 | CL1: POP_83 | CM1: POP_84 | CN1: POP_85 | CO1: POP_86 | CP1: POP_87 | CQ1: POP_88 | CR1: POP_89 | CS1: POP_90 | CT1: POP_91 | CU1: POP_92 | CV1: POP_93 | CW1: POP_94 | CX1: POP_95 | CY1: POP_96 | CZ1: POP_97 | DA1: POP_98 | DB1: POP_99 | DC1: POP_100
A2: 0 | B2: 0 | C2: 0 | D2: 2014 | E2: 318748017 | F2: =SUMIFS('State Populations'!C6:C56,'State Populations'!B6:B56,About!B1) -> 1826341 | G2: 3971847 | H2: 3957864 | I2: 3972081 | J2: 4003272 | K2: 4001929 | L2: 4002977 | M2: 4132455 | N2: 4152653 | O2: 4118628 | P2: 4105776 | Q2: 4113824 | R2: 4083474 | S2: 4066054 | T2: 4166320 | U2: 4229659 | V2: 4162124 | W2: 4166629 | X2: 4183163 | Y2: 4222436 | Z2: 4322037 | AA2: 4416453 | AB2: 4487463 | AC2: 4610463 | AD2: 4696846 | AE2: 4692440 | AF2: 4510702 | AG2: 4408412 | AH2: 4334890 | AI2: 4354323 | AJ2: 4389704 | AK2: 4252230 | AL2: 4318575 | AM2: 4318366 | AN2: 4272544 | AO2: 4358493 | AP2: 4090127 | AQ2: 4010218 | AR2: 3970081 | AS2: 3854355 | AT2: 3974444 | AU2: 3851401 | AV2: 3911379 | AW2: 4089495 | AX2: 4326021 | AY2: 4381655 | AZ2: 4154848 | BA2: 4069099 | BB2: 4074304 | BC2: 4151453 | BD2: 4402094 | BE2: 4485065 | BF2: 4482625 | BG2: 4475720 | BH2: 4532166 | BI2: 4571112 | BJ2: 4419271 | BK2: 4394194 | BL2: 4346785 | BM2: 4191782 | BN2: 4155788 | BO2: 3986465 | BP2: 3835472 | BQ2: 3687663 | BR2: 3573492 | BS2: 3487116 | BT2: 3386367 | BU2: 3353662 | BV2: 3491158 | BW2: 2570754 | BX2: 2532956 | BY2: 2468980 | BZ2: 2524389 | CA2: 2195492 | CB2: 2001582 | CC2: 1889215 | CD2: 1773421 | CE2: 1693253 | CF2: 1556002 | CG2: 1480267 | CH2: 1413154 | CI2: 1263394 | CJ2: 1215284 | CK2: 1153333 | CL2: 1090418 | CM2: 1036315 | CN2: 925381 | CO2: 856136 | CP2: 771029 | CQ2: 676079 | CR2: 600259 | CS2: 513331 | CT2: 427331 | CU2: 355279 | CV2: 286604 | CW2: 219260 | CX2: 157054 | CY2: 121336 | CZ2: 84101 | DA2: 60314 | DB2: 41987 | DC2: 70344
A3: 0 | B3: 0 | C3: 0 | D3: 2015 | E3: 321368864 | F3: =ROUND(F2*(E3/E2),0) -> 1841358 | G3: 4000831 | H3: 3988161 | I3: 3974109 | J3: 3986357 | K3: 4015656 | L3: 4013264 | M3: 4013790 | N3: 4142998 | O3: 4163270 | P3: 4129322 | Q3: 4116403 | R3: 4124332 | S3: 4093774 | T3: 4076731 | U3: 4178338 | V3: 4244458 | W3: 4181583 | X3: 4191978 | Y3: 4214789 | Z3: 4259365 | AA3: 4362335 | AB3: 4458636 | AC3: 4529888 | AD3: 4652042 | AE3: 4737222 | AF3: 4730816 | AG3: 4547569 | AH3: 4443015 | AI3: 4367581 | AJ3: 4384373 | AK3: 4416896 | AL3: 4276717 | AM3: 4339486 | AN3: 4336956 | AO3: 4289091 | AP3: 4372984 | AQ3: 4103961 | AR3: 4022709 | AS3: 3981690 | AT3: 3865068 | AU3: 3983251 | AV3: 3858627 | AW3: 3916268 | AX3: 4092606 | AY3: 4327261 | AZ3: 4381254 | BA3: 4153768 | BB3: 4066359 | BC3: 4070170 | BD3: 4145136 | BE3: 4392871 | BF3: 4473620 | BG3: 4469245 | BH3: 4460772 | BI3: 4515002 | BJ3: 4551557 | BK3: 4398728 | BL3: 4371736 | BM3: 4322549 | BN3: 4166575 | BO3: 4128691 | BP3: 3958655 | BQ3: 3806448 | BR3: 3657448 | BS3: 3541478 | BT3: 3452626 | BU3: 3349536 | BV3: 3313296 | BW3: 3444612 | BX3: 2534265 | BY3: 2493204 | BZ3: 2426285 | CA3: 2475932 | CB3: 2149257 | CC3: 1955068 | CD3: 1840533 | CE3: 1722783 | CF3: 1639501 | CG3: 1501182 | CH3: 1422273 | CI3: 1351639 | CJ3: 1202361 | CK3: 1149985 | CL3: 1084276 | CM3: 1017451 | CN3: 958787 | CO3: 848198 | CP3: 776788 | CQ3: 691754 | CR3: 599204 | CS3: 524832 | CT3: 442185 | CU3: 362183 | CV3: 295845 | CW3: 234146 | CX3: 175609 | CY3: 123059 | CZ3: 92909 | DA3: 62843 | DB3: 43941 | DC3: 71897
A4: 0 | B4: 0 | C4: 0 | D4: 2016 | E4: 323127513 | F4: =ROUND(F3*(E4/E3),0) -> 1851435 | G4: 3970145 | H4: 3995008 | I4: 3992154 | J4: 3982074 | K4: 3987656 | L4: 4032515 | M4: 4029655 | N4: 4029991 | O4: 4159114 | P4: 4178524 | Q4: 4144019 | R4: 4131222 | S4: 4139558 | T4: 4109703 | U4: 4093731 | V4: 4196991 | W4: 4265224 | X4: 4205001 | Y4: 4219303 | Z4: 4243480 | AA4: 4286221 | AB4: 4386854 | AC4: 4480904 | AD4: 4552952 | AE4: 4674097 | AF4: 4758352 | AG4: 4747254 | AH4: 4559206 | AI4: 4451507 | AJ4: 4374565 | AK4: 4392155 | AL4: 4423807 | AM4: 4283076 | AN4: 4345786 | AO4: 4341535 | AP4: 4293125 | AQ4: 4375562 | AR4: 4103498 | AS4: 4022119 | AT4: 3979601 | AU4: 3862150 | AV4: 3979596 | AW4: 3854553 | AX4: 3912307 | AY4: 4087645 | AZ4: 4319616 | BA4: 4371961 | BB4: 4142964 | BC4: 4055074 | BD4: 4058008 | BE4: 4131293 | BF4: 4375892 | BG4: 4452636 | BH4: 4445605 | BI4: 4433630 | BJ4: 4484565 | BK4: 4518758 | BL4: 4362807 | BM4: 4332953 | BN4: 4281025 | BO4: 4123968 | BP4: 4083962 | BQ4: 3911429 | BR4: 3757382 | BS4: 3606295 | BT4: 3490890 | BU4: 3403647 | BV4: 3295266 | BW4: 3251936 | BX4: 3378344 | BY4: 2487211 | BZ4: 2445650 | CA4: 2371252 | CB4: 2413647 | CC4: 2092487 | CD4: 1900211 | CE4: 1784266 | CF4: 1664566 | CG4: 1578915 | CH4: 1439937 | CI4: 1358260 | CJ4: 1284298 | CK4: 1135109 | CL4: 1079082 | CM4: 1008890 | CN4: 938333 | CO4: 876190 | CP4: 766479 | CQ4: 693882 | CR4: 610338 | CS4: 520906 | CT4: 449986 | CU4: 372625 | CV4: 300000 | CW4: 239313 | CX4: 186408 | CY4: 135797 | CZ4: 94311 | DA4: 68972 | DB4: 44895 | DC4: 81896
A5: 0 | B5: 0 | C5: 0 | D5: 2017 | E5: 325511184 | F5: =ROUND(F4*(E5/E4),0) -> 1865093 | G5: 4054035 | H5: 3982964 | I5: 4008116 | J5: 4003478 | K5: 3992207 | L5: 3997392 | M5: 4042440 | N5: 4040047 | O5: 4041063 | P5: 4170685 | Q5: 4190108 | R5: 4155219 | S5: 4142074 | T5: 4150730 | U5: 4121794 | V5: 4108277 | W5: 4215342 | X5: 4288196 | Y5: 4233261 | Z5: 4251108 | AA5: 4277774 | AB5: 4321626 | AC5: 4422467 | AD5: 4516236 | AE5: 4587291 | AF5: 4707566 | AG5: 4790058 | AH5: 4777149 | AI5: 4587850 | AJ5: 4477889 | AK5: 4398868 | AL5: 4413258 | AM5: 4442014 | AN5: 4298767 | AO5: 4359491 | AP5: 4353713 | AQ5: 4303531 | AR5: 4383641 | AS5: 4111179 | AT5: 4028537 | AU5: 3984541 | AV5: 3865650 | AW5: 3981593 | AX5: 3855725 | AY5: 3912585 | AZ5: 4086265 | BA5: 4315712 | BB5: 4365407 | BC5: 4134928 | BD5: 4045056 | BE5: 4046013 | BF5: 4116949 | BG5: 4358883 | BH5: 4433952 | BI5: 4425934 | BJ5: 4412773 | BK5: 4461817 | BL5: 4493975 | BM5: 4337169 | BN5: 4305372 | BO5: 4251447 | BP5: 4092912 | BQ5: 4050176 | BR5: 3876056 | BS5: 3720444 | BT5: 3567687 | BU5: 3449965 | BV5: 3359750 | BW5: 3249376 | BX5: 3202397 | BY5: 3322076 | BZ5: 2442787 | CA5: 2397598 | CB5: 2319958 | CC5: 2355941 | CD5: 2037902 | CE5: 1845534 | CF5: 1727722 | CG5: 1606350 | CH5: 1517812 | CI5: 1378128 | CJ5: 1293376 | CK5: 1215828 | CL5: 1067366 | CM5: 1006951 | CN5: 933492 | CO5: 860398 | CP5: 795555 | CQ5: 688525 | CR5: 616024 | CS5: 534781 | CT5: 449945 | CU5: 382669 | CV5: 311525 | CW5: 246219 | CX5: 192531 | CY5: 146801 | CZ5: 104540 | DA5: 70840 | DB5: 50486 | DC5: 83574
A6: 0 | B6: 0 | C6: 0 | D6: 2018 | E6: 327891911 | F6: =ROUND(F5*(E6/E5),0) -> 1878734 | G6: 4075563 | H6: 4068172 | I6: 3995888 | J6: 4019345 | K6: 4013649 | L6: 4001995 | M6: 4007421 | N6: 4052927 | O6: 4051175 | P6: 4052752 | Q6: 4182356 | R6: 4201452 | S6: 4166128 | T6: 4153355 | U6: 4163009 | V6: 4136524 | W6: 4127018 | X6: 4238674 | Y6: 4316526 | Z6: 4265709 | AA6: 4285871 | AB6: 4313525 | AC6: 4357896 | AD6: 4458227 | AE6: 4551400 | AF6: 4621327 | AG6: 4739992 | AH6: 4820454 | AI6: 4805708 | AJ6: 4614495 | AK6: 4502236 | AL6: 4420352 | AM6: 4431928 | AN6: 4457882 | AO6: 4312997 | AP6: 4371920 | AQ6: 4364340 | AR6: 4312313 | AS6: 4390538 | AT6: 4117661 | AU6: 4033632 | AV6: 3988017 | AW6: 3868194 | AX6: 3982657 | AY6: 3856316 | AZ6: 3911959 | BA6: 4083352 | BB6: 4309706 | BC6: 4356542 | BD6: 4124836 | BE6: 4033282 | BF6: 4032485 | BG6: 4101693 | BH6: 4341119 | BI6: 4414648 | BJ6: 4405551 | BK6: 4391051 | BL6: 4438175 | BM6: 4467892 | BN6: 4310232 | BO6: 4276279 | BP6: 4219953 | BQ6: 4059664 | BR6: 4013995 | BS6: 3838330 | BT6: 3681103 | BU6: 3526404 | BV6: 3406382 | BW6: 3313266 | BX6: 3200623 | BY6: 3149795 | BZ6: 3262161 | CA6: 2395309 | CB6: 2346213 | CC6: 2265372 | CD6: 2294638 | CE6: 1979846 | CF6: 1787596 | CG6: 1667825 | CH6: 1544687 | CI6: 1453127 | CJ6: 1312814 | CK6: 1224880 | CL6: 1143790 | CM6: 996514 | CN6: 932170 | CO6: 856482 | CP6: 781737 | CQ6: 715160 | CR6: 611713 | CS6: 540235 | CT6: 462335 | CU6: 382993 | CV6: 320285 | CW6: 256011 | CX6: 198354 | CY6: 151848 | CZ6: 113165 | DA6: 78659 | DB6: 51938 | DC6: 86221
A7: 0 | B7: 0 | C7: 0 | D7: 2019 | E7: 330268840 | F7: =ROUND(F6*(E7/E6),0) -> 1892353 | G7: 4095614 | H7: 4089881 | I7: 4082231 | J7: 4006967 | K7: 4029427 | L7: 4023461 | M7: 4012057 | N7: 4017972 | O7: 4064123 | P7: 4062890 | Q7: 4064631 | R7: 4193833 | S7: 4212469 | T7: 4177496 | U7: 4165769 | V7: 4177960 | W7: 4155502 | X7: 4150810 | Y7: 4267452 | Z7: 4349076 | AA7: 4301156 | AB7: 4322123 | AC7: 4350162 | AD7: 4394289 | AE7: 4493828 | AF7: 4586190 | AG7: 4654316 | AH7: 4771037 | AI7: 4849468 | AJ7: 4832291 | AK7: 4639056 | AL7: 4523767 | AM7: 4439360 | AN7: 4448246 | AO7: 4472242 | AP7: 4325927 | AQ7: 4382807 | AR7: 4373352 | AS7: 4319887 | AT7: 4396212 | AU7: 4122808 | AV7: 4037231 | AW7: 3990513 | AX7: 3869809 | AY7: 3983126 | AZ7: 3856029 | BA7: 3909826 | BB7: 4078377 | BC7: 4301376 | BD7: 4345510 | BE7: 4112985 | BF7: 4019996 | BG7: 4018048 | BH7: 4085765 | BI7: 4322783 | BJ7: 4394677 | BK7: 4384337 | BL7: 4368454 | BM7: 4413272 | BN7: 4440486 | BO7: 4281761 | BP7: 4245285 | BQ7: 4186210 | BR7: 4023983 | BS7: 3975371 | BT7: 3798127 | BU7: 3639026 | BV7: 3482418 | BW7: 3360142 | BX7: 3263891 | BY7: 3148763 | BZ7: 3093739 | CA7: 3198266 | CB7: 2344536 | CC7: 2291473 | CD7: 2207291 | CE7: 2229517 | CF7: 1918247 | CG7: 1726158 | CH7: 1604385 | CI7: 1479385 | CJ7: 1384715 | CK7: 1243788 | CL7: 1152809 | CM7: 1068395 | CN7: 923012 | CO7: 855747 | CP7: 778704 | CQ7: 703240 | CR7: 635873 | CS7: 536880 | CT7: 467488 | CU7: 393919 | CV7: 320884 | CW7: 263533 | CX7: 206526 | CY7: 156654 | CZ7: 117240 | DA7: 85265 | DB7: 57778 | DC7: 87671
A8: 0 | B8: 0 | C8: 0 | D8: 2020 | E8: 332639102 | F8: =ROUND(F7*(E8/E7),0) -> 1905934 | G8: 4113164 | H8: 4110117 | I8: 4104058 | J8: 4094281 | K8: 4016919 | L8: 4039164 | M8: 4033531 | N8: 4022626 | O8: 4029209 | P8: 4075879 | Q8: 4074733 | R8: 4076315 | S8: 4205008 | T8: 4223909 | U8: 4190013 | V8: 4180890 | W8: 4197186 | X8: 4179617 | Y8: 4180135 | Z8: 4300527 | AA8: 4384632 | AB8: 4338146 | AC8: 4359234 | AD8: 4386967 | AE8: 4430497 | AF8: 4529025 | AG8: 4619893 | AH8: 4685941 | AI8: 4800614 | AJ8: 4876514 | AK8: 4856771 | AL8: 4660832 | AM8: 4542808 | AN8: 4455998 | AO8: 4463007 | AP8: 4485228 | AQ8: 4337294 | AR8: 4392096 | AS8: 4381171 | AT8: 4326220 | AU8: 4400565 | AV8: 4126454 | AW8: 4039827 | AX8: 3992089 | AY8: 3870851 | AZ8: 3982690 | BA8: 3854262 | BB8: 3905661 | BC8: 4071128 | BD8: 4290890 | BE8: 4332660 | BF8: 4099623 | BG8: 4005824 | BH8: 4002980 | BI8: 4069319 | BJ8: 4303838 | BK8: 4373935 | BL8: 4362272 | BM8: 4344637 | BN8: 4387070 | BO8: 4411539 | BP8: 4251390 | BQ8: 4212048 | BR8: 4149974 | BS8: 3985841 | BT8: 3934139 | BU8: 3755158 | BV8: 3594166 | BW8: 3435726 | BX8: 3310982 | BY8: 3211395 | BZ8: 3093441 | CA8: 3033884 | CB8: 3130130 | CC8: 2290416 | CD8: 2233196 | CE8: 2145506 | CF8: 2160437 | CG8: 1852886 | CH8: 1661013 | CI8: 1537134 | CJ8: 1410262 | CK8: 1312397 | CL8: 1171078 | CM8: 1077340 | CN8: 990131 | CO8: 847852 | CP8: 778518 | CQ8: 701025 | CR8: 625755 | CS8: 558560 | CT8: 464985 | CU8: 398712 | CV8: 330389 | CW8: 264318 | CX8: 212880 | CY8: 163348 | CZ8: 121128 | DA8: 88491 | DB8: 62724 | DC8: 92064
A9: 0 | B9: 0 | C9: 0 | D9: 2021 | E9: 334998398 | F9: =ROUND(F8*(E9/E8),0) -> 1919452 | G9: 4127525 | H9: 4127842 | I9: 4124416 | J9: 4116205 | K9: 4105035 | L9: 4026556 | M9: 4049172 | N9: 4044099 | O9: 4033860 | P9: 4040982 | Q9: 4087777 | R9: 4086372 | S9: 4087676 | T9: 4216581 | U9: 4236505 | V9: 4205270 | W9: 4200326 | X9: 4221634 | Y9: 4209336 | Z9: 4213861 | AA9: 4336645 | AB9: 4421766 | AC9: 4375952 | AD9: 4396486 | AE9: 4423591 | AF9: 4466248 | AG9: 4563143 | AH9: 4652142 | AI9: 4716116 | AJ9: 4828163 | AK9: 4901434 | AL9: 4878458 | AM9: 4680107 | AN9: 4559497 | AO9: 4471082 | AP9: 4476392 | AQ9: 4496649 | AR9: 4347057 | AS9: 4400186 | AT9: 4387763 | AU9: 4331231 | AV9: 4403495 | AW9: 4129067 | AX9: 4041520 | AY9: 3993077 | AZ9: 3871017 | BA9: 3980747 | BB9: 3850472 | BC9: 3899258 | BD9: 4061770 | BE9: 4278602 | BF9: 4318286 | BG9: 4085369 | BH9: 3991050 | BI9: 3987451 | BJ9: 4052319 | BK9: 4284151 | BL9: 4352403 | BM9: 4339037 | BN9: 4319573 | BO9: 4359325 | BP9: 4380641 | BQ9: 4218754 | BR9: 4176281 | BS9: 4111173 | BT9: 3945080 | BU9: 3890017 | BV9: 3709353 | BW9: 3546511 | BX9: 3386045 | BY9: 3258649 | BZ9: 3155415 | CA9: 3034348 | CB9: 2969998 | CC9: 3057634 | CD9: 2232771 | CE9: 2171178 | CF9: 2079886 | CG9: 2087150 | CH9: 1783547 | CI9: 1591883 | CJ9: 1465872 | CK9: 1337153 | CL9: 1236193 | CM9: 1094889 | CN9: 998939 | CO9: 910054 | CP9: 771847 | CQ9: 701346 | CR9: 624288 | CS9: 550142 | CT9: 484225 | CU9: 396958 | CV9: 334771 | CW9: 272457 | CX9: 213764 | CY9: 168612 | CZ9: 126502 | DA9: 91564 | DB9: 65221 | DC9: 98160
A10: 0 | B10: 0 | C10: 0 | D10: 2022 | E10: 337341954 | F10: =ROUND(F9*(E10/E9),0) -> 1932880 | G10: 4139039 | H10: 4142382 | I10: 4142254 | J10: 4136660 | K10: 4127020 | L10: 4115321 | M10: 4036489 | N10: 4059689 | O10: 4055322 | P10: 4045609 | Q10: 4052883 | R10: 4099479 | S10: 4097721 | T10: 4099405 | U10: 4229339 | V10: 4251870 | W10: 4224895 | X10: 4225046 | Y10: 4251751 | Z10: 4243518 | AA10: 4250687 | AB10: 4374374 | AC10: 4459740 | AD10: 4413867 | AE10: 4433548 | AF10: 4459696 | AG10: 4500899 | AH10: 4595831 | AI10: 4682865 | AJ10: 4744241 | AK10: 4853502 | AL10: 4923497 | AM10: 4897614 | AN10: 4697027 | AO10: 4574642 | AP10: 4484789 | AQ10: 4488229 | AR10: 4506489 | AS10: 4355605 | AT10: 4407052 | AU10: 4393007 | AV10: 4334803 | AW10: 4405446 | AX10: 4130784 | AY10: 4042621 | AZ10: 3993170 | BA10: 3869712 | BB10: 3976745 | BC10: 3844444 | BD10: 3890778 | BE10: 4050655 | BF10: 4264820 | BG10: 4303009 | BH10: 4070530 | BI10: 3975842 | BJ10: 3971415 | BK10: 4034644 | BL10: 4263691 | BM10: 4329741 | BN10: 4314560 | BO10: 4292988 | BP10: 4329627 | BQ10: 4347377 | BR10: 4183553 | BS10: 4137923 | BT10: 4069658 | BU10: 3901421 | BV10: 3842987 | BW10: 3660676 | BX10: 3495790 | BY10: 3333103 | BZ10: 3202742 | CA10: 3095605 | CB10: 2971226 | CC10: 2901984 | CD10: 2980548 | CE10: 2171394 | CF10: 2105272 | CG10: 2010177 | CH10: 2009409 | CI10: 1709864 | CJ10: 1518571 | CK10: 1390458 | CL10: 1260063 | CM10: 1156314 | CN10: 1015712 | CO10: 918670 | CP10: 829014 | CQ10: 695831 | CR10: 625049 | CS10: 549331 | CT10: 477362 | CU10: 413808 | CV10: 333649 | CW10: 276396 | CX10: 220621 | CY10: 169538 | CZ10: 130778 | DA10: 95792 | DB10: 67596 | DC10: 103774
A11: 0 | B11: 0 | C11: 0 | D11: 2023 | E11: 339665118 | F11: =ROUND(F10*(E11/E10),0) -> 1946191 | G11: 4147758 | H11: 4154076 | I11: 4156909 | J11: 4154588 | K11: 4147538 | L11: 4137347 | M11: 4125778 | N11: 4046953 | O11: 4070870 | P11: 4067066 | Q11: 4057473 | R11: 4064559 | S11: 4110900 | T11: 4109449 | U11: 4112330 | V11: 4244861 | W11: 4271643 | X11: 4249886 | Y11: 4255496 | Z11: 4286407 | AA11: 4280796 | AB11: 4289176 | AC11: 4412927 | AD11: 4497857 | AE11: 4451532 | AF11: 4470058 | AG11: 4494674 | AH11: 4534059 | AI11: 4627012 | AJ11: 4711511 | AK11: 4770116 | AL11: 4875956 | AM11: 4942955 | AN11: 4914448 | AO11: 4712336 | AP11: 4588430 | AQ11: 4496972 | AR11: 4498515 | AS11: 4515109 | AT11: 4362938 | AU11: 4412597 | AV11: 4396784 | AW11: 4337365 | AX11: 4406569 | AY11: 4131905 | AZ11: 4042832 | BA11: 3991794 | BB11: 3866390 | BC11: 3970470 | BD11: 3836358 | BE11: 3880595 | BF11: 4038110 | BG11: 4250164 | BH11: 4287166 | BI11: 4055269 | BJ11: 3960176 | BK11: 3954766 | BL11: 4016261 | BM11: 4242150 | BN11: 4305875 | BO11: 4288580 | BP11: 4264484 | BQ11: 4297589 | BR11: 4311445 | BS11: 4145741 | BT11: 4096797 | BU11: 4025170 | BV11: 3854829 | BW11: 3792992 | BX11: 3608853 | BY11: 3441741 | BZ11: 3276541 | CA11: 3142936 | CB11: 3031719 | CC11: 2903967 | CD11: 2829608 | CE11: 2898630 | CF11: 2106139 | CG11: 2035239 | CH11: 1936117 | CI11: 1926807 | CJ11: 1631626 | CK11: 1440986 | CL11: 1310877 | CM11: 1179191 | CN11: 1073249 | CO11: 934614 | CP11: 837385 | CQ11: 747906 | CR11: 620615 | CS11: 550460 | CT11: 477110 | CU11: 408345 | CV11: 348195 | CW11: 275781 | CX11: 224099 | CY11: 175204 | CZ11: 131682 | DA11: 99192 | DB11: 70843 | DC11: 108974
A12: 0 | B12: 0 | C12: 0 | D12: 2024 | E12: 341963408 | F12: =ROUND(F11*(E12/E11),0) -> 1959360 | G12: 4154108 | H12: 4162971 | I12: 4168717 | J12: 4169332 | K12: 4165525 | L12: 4157904 | M12: 4147828 | N12: 4136675 | O12: 4058091 | P12: 4082553 | Q12: 4078894 | R12: 4069125 | S12: 4075946 | T12: 4122675 | U12: 4122411 | V12: 4128065 | W12: 4264799 | X12: 4296850 | Y12: 4280674 | Z12: 4290546 | AA12: 4324168 | AB12: 4319777 | AC12: 4328450 | AD12: 4451637 | AE12: 4535742 | AF12: 4488571 | AG12: 4505436 | AH12: 4528144 | AI12: 4565616 | AJ12: 4656110 | AK12: 4737870 | AL12: 4793097 | AM12: 4895790 | AN12: 4960104 | AO12: 4929680 | AP12: 4726249 | AQ12: 4600701 | AR12: 4507616 | AS12: 4507583 | AT12: 4522497 | AU12: 4368961 | AV12: 4416690 | AW12: 4399491 | AX12: 4339085 | AY12: 4407111 | AZ12: 4132111 | BA12: 4041569 | BB12: 3988376 | BC12: 3860835 | BD12: 3962111 | BE12: 3826613 | BF12: 3869048 | BG12: 4024750 | BH12: 4234977 | BI12: 4270925 | BJ12: 4039586 | BK12: 3943936 | BL12: 3937451 | BM12: 3996895 | BN12: 4219436 | BO12: 4280520 | BP12: 4260687 | BQ12: 4233662 | BR12: 4262903 | BS12: 4272812 | BT12: 4105154 | BU12: 4052671 | BV12: 3977712 | BW12: 3805296 | BX12: 3739770 | BY12: 3553602 | BZ12: 3383956 | CA12: 3215994 | CB12: 3078960 | CC12: 2963648 | CD12: 2832386 | CE12: 2752640 | CF12: 2811624 | CG12: 2036777 | CH12: 1960846 | CI12: 1857308 | CJ12: 1839087 | CK12: 1548770 | CL12: 1359088 | CM12: 1227344 | CN12: 1095024 | CO12: 988125 | CP12: 852450 | CQ12: 755964 | CR12: 667574 | CS12: 547019 | CT12: 478523 | CU12: 408546 | CV12: 343970 | CW12: 288149 | CX12: 223875 | CY12: 178209 | CZ12: 136274 | DA12: 100030 | DB12: 73482 | DC12: 114493
A13: 0 | B13: 0 | C13: 0 | D13: 2025 | E13: 344234377 | F13: =ROUND(F12*(E13/E12),0) -> 1972372 | G13: 4158795 | H13: 4169495 | I13: 4177722 | J13: 4181225 | K13: 4180328 | L13: 4175929 | M13: 4168415 | N13: 4158746 | O13: 4148184 | P13: 4069757 | Q13: 4094343 | R13: 4090541 | S13: 4080558 | T13: 4087738 | U13: 4135695 | V13: 4138216 | W13: 4148262 | X13: 4290235 | Y13: 4327918 | Z13: 4316130 | AA13: 4328721 | AB13: 4363627 | AC13: 4359531 | AD13: 4367839 | AE13: 4490127 | AF13: 4573003 | AG13: 4524491 | AH13: 4539331 | AI13: 4560049 | AJ13: 4595102 | AK13: 4682890 | AL13: 4761327 | AM13: 4813443 | AN13: 4913329 | AO13: 4975685 | AP13: 4943534 | AQ13: 4738710 | AR13: 4611463 | AS13: 4517058 | AT13: 4515429 | AU13: 4528559 | AV13: 4373560 | AW13: 4419693 | AX13: 4401339 | AY13: 4340209 | AZ13: 4406731 | BA13: 4130832 | BB13: 4038272 | BC13: 3982695 | BD13: 3853247 | BE13: 3952083 | BF13: 3815584 | BG13: 3856754 | BH13: 4010950 | BI13: 4219456 | BJ13: 4254301 | BK13: 4023338 | BL13: 3927059 | BM13: 3919194 | BN13: 3976467 | BO13: 4195280 | BP13: 4253262 | BQ13: 4230464 | BR13: 4200229 | BS13: 4225565 | BT13: 4231331 | BU13: 4061595 | BV13: 4005573 | BW13: 3927257 | BX13: 3752598 | BY13: 3683044 | BZ13: 3494529 | CA13: 3322098 | CB13: 3151232 | CC13: 3010697 | CD13: 2891244 | CE13: 2756258 | CF13: 2670909 | CG13: 2719250 | CH13: 1963082 | CI13: 1881659 | CJ13: 1773539 | CK13: 1746214 | CL13: 1461274 | CM13: 1273103 | CN13: 1140365 | CO13: 1008736 | CP13: 901822 | CQ13: 770102 | CR13: 675259 | CS13: 588914 | CT13: 475977 | CU13: 410170 | CV13: 344518 | CW13: 284978 | CX13: 234217 | CY13: 178269 | CZ13: 138820 | DA13: 103674 | DB13: 74220 | DC13: 119806
A14: 0 | B14: 0 | C14: 0 | D14: 2026 | E14: 346481182 | F14: =ROUND(F13*(E14/E13),0) -> 1985246 | G14: 4162506 | H14: 4174374 | I14: 4184383 | J14: 4190355 | K14: 4192326 | L14: 4190821 | M14: 4186520 | N14: 4179415 | O14: 4170335 | P14: 4160211 | Q14: 4081719 | R14: 4106132 | S14: 4102104 | T14: 4092488 | U14: 4100908 | V14: 4151654 | W14: 4158594 | X14: 4174066 | Y14: 4321655 | Z14: 4363774 | AA14: 4354821 | AB14: 4368722 | AC14: 4403902 | AD14: 4399453 | AE14: 4407024 | AF14: 4528013 | AG14: 4609267 | AH14: 4558937 | AI14: 4571769 | AJ14: 4590021 | AK14: 4622421 | AL14: 4706898 | AM14: 4782212 | AN14: 4831592 | AO14: 4929379 | AP14: 4989948 | AQ14: 4956030 | AR14: 4749765 | AS14: 4621154 | AT14: 4525374 | AU14: 4522008 | AV14: 4533243 | AW14: 4377134 | AX14: 4421893 | AY14: 4402609 | AZ14: 4340430 | BA14: 4404872 | BB14: 4127554 | BC14: 4032742 | BD14: 3974994 | BE14: 3844059 | BF14: 3940776 | BG14: 3803882 | BH14: 3844112 | BI14: 3996923 | BJ14: 4203626 | BK14: 4237206 | BL14: 4006488 | BM14: 3909309 | BN14: 3899915 | BO14: 3954724 | BP14: 4169311 | BQ14: 4223757 | BR14: 4197680 | BS14: 4164204 | BT14: 4185501 | BU14: 4186915 | BV14: 4015120 | BW14: 3955548 | BX14: 3873632 | BY14: 3696537 | BZ14: 3622529 | CA14: 3431406 | CB14: 3256022 | CC14: 3082242 | CD14: 2938091 | CE14: 2814389 | CF14: 2675423 | CG14: 2584234 | CH14: 2621255 | CI14: 1884602 | CJ14: 1797507 | CK14: 1684804 | CL14: 1648172 | CM14: 1369388 | CN14: 1183547 | CO14: 1051161 | CP14: 921204 | CQ14: 815258 | CR14: 688421 | CS14: 596178 | CT14: 512913 | CU14: 408405 | CV14: 346269 | CW14: 285776 | CX14: 231933 | CY14: 186762 | CZ14: 139061 | DA14: 105777 | DB14: 77053 | DC14: 123654
... A48: 0 | B48: 0 | C48: 0 | D48: 2060 | E48: 404483055 | F48: =ROUND(F47*(E48/E47),0) -> 2317581 | G48: 4407785 | H48: 4420827 | I48: 4431709 | J48: 4439404 | K48: 4444469 | L48: 4447891 | M48: 4450448 | N48: 4452526 | O48: 4454427 | P48: 4456018 | Q48: 4456892 | R48: 4457123 | S48: 4457023 | T48: 4457530 | U48: 4459930 | V48: 4466253 | W48: 4478539 | X48: 4498105 | Y48: 4525241 | Z48: 4558494 | AA48: 4595867 | AB48: 4635497 | AC48: 4676205 | AD48: 4717434 | AE48: 4758640 | AF48: 4799584 | AG48: 4839891 | AH48: 4879022 | AI48: 4916572 | AJ48: 4951752 | AK48: 4983783 | AL48: 5011706 | AM48: 5035276 | AN48: 5054557 | AO48: 5070118 | AP48: 5082636 | AQ48: 5092131 | AR48: 5097958 | AS48: 5099747 | AT48: 5097041 | AU48: 5089666 | AV48: 5077153 | AW48: 5060454 | AX48: 5041022 | AY48: 4949707 | AZ48: 4963457 | BA48: 4947331 | BB48: 4922419 | BC48: 4911243 | BD48: 4935731 | BE48: 4911220 | BF48: 4888254 | BG48: 4986460 | BH48: 4977910 | BI48: 4917069 | BJ48: 4876452 | BK48: 4855621 | BL48: 4796575 | BM48: 4749136 | BN48: 4808914 | BO48: 4831065 | BP48: 4730282 | BQ48: 4688219 | BR48: 4650606 | BS48: 4625110 | BT48: 4645987 | BU48: 4656414 | BV48: 4641681 | BW48: 4667364 | BX48: 4657078 | BY48: 4560519 | BZ48: 4313908 | CA48: 4133422 | CB48: 3978746 | CC48: 3897238 | CD48: 3823025 | CE48: 3612657 | CF48: 3555296 | CG48: 3441926 | CH48: 3292095 | CI48: 3222151 | CJ48: 2913713 | CK48: 2728825 | CL48: 2564025 | CM48: 2350742 | CN48: 2263978 | CO48: 2045250 | CP48: 1916142 | CQ48: 1830039 | CR48: 1752135 | CS48: 1590984 | CT48: 1343535 | CU48: 1154297 | CV48: 1000730 | CW48: 867121 | CX48: 768737 | CY48: 644664 | CZ48: 520204 | DA48: 410644 | DB48: 321274 | DC48: 589382

Sheet Emp Pop Ratio
A1: FRED Graph Observations
A2: Federal Reserve Economic Data
A3: Link: https://fred.stlouisfed.org
A4: Help: https://fred.stlouisfed.org/help-faq
A5: Economic Research Division
A6: Federal Reserve Bank of St. Louis
A8: EMRATIO | B8: Employment-Population Ratio, Percent, Monthly, Seasonally Adjusted
A10: Frequency: Monthly
A11: observation_date | B11: EMRATIO
A12: 17533 | B12: 56.6
A13: 17564 | B13: 56.7
A14: 17593 | B14: 56.1
A15: 17624 | B15: 56.7
A16: 17654 | B16: 56.2
A17: 17685 | B17: 57
A18: 17715 | B18: 57.1
A19: 17746 | B19: 56.6
A20: 17777 | B20: 56.6
A21: 17807 | B21: 56.5
A22: 17838 | B22: 56.5
A23: 17868 | B23: 56.8
... A881: 43983 | B881: 54.6

Sheet Avg Emp-Pop Ratio
A1: Average Employment-to-Population Ratio
A2: from date | B2: 40179
A3: to date | B3: 43830
A5: is: | B5: =AVERAGEIFS('Emp Pop Ratio'!B:B,'Emp Pop Ratio'!A:A,">="&'Avg Emp-Pop Ratio'!B2,'Emp Pop Ratio'!A:A,"<="&'Avg Emp-Pop Ratio'!B3)/100 -> 0.59340833

Sheet OECD VAL
A1: =DotStatQuery(B1) -> #NAME? | B1: Sorry, the query is too large to fit into the Excel cell. You will not be able to update your table with the .Stat Populator.
A2: Dataset: Input-Output Tables 2018 edition
A3: Variable | C3: VAL: Value added
A4: Country | C4: USA: United States
A5: Time | C5: 2015
A6: Unit | C6: US Dollar, Millions
A7: To: (sector in column) | C7: D01T03: Agriculture, forestry and fishing | D7: D05T06: Mining and extraction of energy producing products | E7: D07T08: Mining and quarrying of non-energy producing products | F7: D09: Mining support service activities | G7: D10T12: Food products, beverages and tobacco | H7: D13T15: Textiles, wearing apparel, leather and related products | I7: D16: Wood and products of wood and cork | J7: D17T18: Paper products and printing | K7: D19: Coke and refined petroleum products | L7: D20T21: Chemicals and pharmaceutical products | M7: D22: Rubber and plastic products | N7: D23: Other non-metallic mineral products | O7: D24: Basic metals | P7: D25: Fabricated metal products | Q7: D26: Computer, electronic and optical products | R7: D27: Electrical equipment | S7: D28: Machinery and equipment, nec | T7: D29: Motor vehicles, trailers and semi-trailers | U7: D30: Other transport equipment | V7: D31T33: Other manufacturing; repair and installation of machinery and equipment | W7: D35T39: Electricity, gas, water supply, sewerage, waste and remediation services | X7: D41T43: Construction | Y7: D45T47: Wholesale and retail trade; repair of motor vehicles | Z7: D49T53: Transportation and storage | AA7: D55T56: Accomodation and food services | AB7: D58T60: Publishing, audiovisual and broadcasting activities | AC7: D61: Telecommunications | AD7: D62T63: IT and other information services | AE7: D64T66: Financial and insurance activities | AF7: D68: Real estate activities | AG7: D69T82: Other business sector services | AH7: D84: Public admin. and defence; compulsory social security | AI7: D85: Education | AJ7: D86T88: Human health and social work | AK7: D90T96: Arts, entertainment, recreation and other service activities | AL7: D97T98: Private households with employed persons
A8: From: (sector in row)
A9: LABR: Compensation of employees | C9: 55762.914 | D9: 43448.685 | E9: 13619.199 | F9: 32724.689 | G9: 107945.85 | H9: 19871.939 | I9: 19701.956 | J9: 55695.152 | K9: 18474.415 | L9: 101057.93 | M9: 49588.167 | N9: 28867.79 | O9: 31522.32 | P9: 96161.3 | Q9: 138134.1 | R9: 34122.231 | S9: 90491.687 | T9: 68236.228 | U9: 79237.049 | V9: 73046.581 | W9: 102871.54 | X9: 457892.09 | Y9: 1128201 | Z9: 370328.18 | AA9: 340904.28 | AB9: 204032.85 | AC9: 85985.094 | AD9: 295720.28 | AE9: 750363.11 | AF9: 102329.8 | AG9: 1362903.4 | AH9: 1221115 | AI9: 865699.73 | AJ9: 1075470 | AK9: 319976.05 | AL9: 21351.7
A10: OTXS: Other taxes less subsidies on production | C10: 11926.959 | D10: 22236.446 | E10: 2311.311 | F10: 2083.967 | G10: 8024.6 | H10: 879.298 | I10: 685.696 | J10: 2510.323 | K10: 3395.362 | L10: 13100.214 | M10: 1731.286 | N10: 1464.045 | O10: 2420.814 | P10: 2833.919 | Q10: 7170.704 | R10: 1134.489 | S10: 3331.678 | T10: 2995.89 | U10: 2412.781 | V10: 2228.652 | W10: 40723.43 | X10: 8240.802 | Y10: 54949.026 | Z10: 14802.978 | AA10: 23748.665 | AB10: 8516.97 | AC10: 8862.189 | AD10: 3501.547 | AE10: 41900.949 | AF10: 238841.58 | AG10: 30684.765 | AH10: 11907.354 | AI10: 35650.364 | AJ10: 25367.348 | AK10: 13906.24 | AL10: 0
A11: GOPS: Gross operating surplus and mixed income | C11: 126190.23 | D11: 158772.67 | E11: 25249.19 | F11: 17093.544 | G11: 132476.85 | H11: 6881.463 | I11: 8716.348 | J11: 38432.625 | K11: 136601.02 | L11: 261826.25 | M11: 28535.547 | N11: 21073.465 | O11: 21699.766 | P11: 47785.78 | Q11: 133207.19 | R11: 21061.68 | S11: 53386.635 | T11: 89287.181 | U11: 52498.97 | V11: 37863.368 | W11: 162146.13 | X11: 273780.8 | Y11: 661673.91 | Z11: 192958.04 | AA11: 120207.05 | AB11: 222554.88 | AC11: 186381.42 | AD11: 74944.076 | AE11: 538286.24 | AF11: 1835216.9 | AG11: 643188.55 | AH11: 317682.31 | AI11: 66144.604 | AJ11: 183358.17 | AK11: 133749.91 | AL11: 0
A12: Data extracted on 03 Jun 2020 20:52 UTC (GMT) from OECD.Stat

Sheet BLS Comp per Hr Worked
A1: Employer Costs for Employee Compensation
A2: Original Data Value
A4: Series Id: | B4: CMU1010000000000D
A5: Series Title: | B5: All Civilian Total compensation for All occupations; Cost per hour worked
A6: Ownership: | B6: Civilian workers
A7: Component: | B7: Total compensation
A8: Occupation: | B8: All workers
A9: Industry: | B9: All workers
A10: Subcategory: | B10: All workers
A11: Area: | B11: United States (National)
A12: Data Type: | B12: Cost of compensation (Cost per hour worked)
A13: Years: | B13: 2004 to 2020
A15: Year | B15: Period | C15: Estimate Value | D15: Relative Standard Error
A16: 2004 | B16: Qtr1 | C16: 24.95
A17: 2004 | B17: Qtr2 | C17: 24.96
A18: 2004 | B18: Qtr3 | C18: 25.36
A19: 2004 | B19: Qtr4 | C19: 25.57
A20: 2005 | B20: Qtr1 | C20: 25.87
A21: 2005 | B21: Qtr2 | C21: 25.86
A22: 2005 | B22: Qtr3 | C22: 26.05
A23: 2005 | B23: Qtr4 | C23: 26.46
A24: 2006 | B24: Qtr1 | C24: 26.86
A25: 2006 | B25: Qtr2 | C25: 26.86
A26: 2006 | B26: Qtr3 | C26: 27.31
A27: 2006 | B27: Qtr4 | C27: 27.54
... A73: 2018 | B73: Qtr2 | C73: 36.22
A74: 2018 | B74: Qtr3 | C74: 36.63 | D74: 1.4
A75: 2018 | B75: Qtr4 | C75: 36.32 | D75: 1.3
A76: 2019 | B76: Qtr1 | C76: 36.77 | D76: 1.3
A77: 2019 | B77: Qtr2 | C77: 36.61 | D77: 1.3
A78: 2019 | B78: Qtr3 | C78: 37.03 | D78: 1.3
A79: 2019 | B79: Qtr4 | C79: 37.1 | D79: 1.2
A80: 2020 | B80: Qtr1 | C80: 37.73 | D80: 1.2

Sheet EE Comp Projection
A1: To calculate future total employee compensation, we begin by establishing a trend of
A2: cost change per hour worked. We then will scale the historical total EE compensation
A3: figure from the OECD by the number of employees, adjusting for the change in cost
A4: per hour worked.
A6: These figures refer to total employee compensation, not just wages and salaries.
A7: E.g. this includes employer-paid benefits, employer contribution to retirement plans, etc.
A9: Average Employee Compensation per Hour Worked
B10: 2004 | C10: 2005 | D10: 2006 | E10: 2007 | F10: 2008 | G10: 2009 | H10: 2010 | I10: 2011 | J10: 2012 | K10: 2013 | L10: 2014 | M10: 2015 | N10: 2016 | O10: 2017 | P10: 2018 | Q10: 2019
A11: nominal $/hr | B11: =AVERAGEIFS('BLS Comp per Hr Worked'!$C$16:$C$80,'BLS Comp per Hr Worked'!$A$16:$A$80,B10) -> 25.21 | C11: =AVERAGEIFS('BLS Comp per Hr Worked'!$C$16:$C$80,'BLS Comp per Hr Worked'!$A$16:$A$80,C10) -> 26.06 | D11: =AVERAGEIFS('BLS Comp per Hr Worked'!$C$16:$C$80,'BLS Comp per Hr Worked'!$A$16:$A$80,D10) -> 27.1425 | E11: =AVERAGEIFS('BLS Comp per Hr Worked'!$C$16:$C$80,'BLS Comp per Hr Worked'!$A$16:$A$80,E10) -> 27.9275 | F11: =AVERAGEIFS('BLS Comp per Hr Worked'!$C$16:$C$80,'BLS Comp per Hr Worked'!$A$16:$A$80,F10) -> 28.7475 | G11: =AVERAGEIFS('BLS Comp per Hr Worked'!$C$16:$C$80,'BLS Comp per Hr Worked'!$A$16:$A$80,G10) -> 29.3675 | H11: =AVERAGEIFS('BLS Comp per Hr Worked'!$C$16:$C$80,'BLS Comp per Hr Worked'!$A$16:$A$80,H10) -> 29.675 | I11: =AVERAGEIFS('BLS Comp per Hr Worked'!$C$16:$C$80,'BLS Comp per Hr Worked'!$A$16:$A$80,I10) -> 30.1525 | ... Q11: =AVERAGEIFS('BLS Comp per Hr Worked'!$C$16:$C$80,'BLS Comp per Hr Worked'!$A$16:$A$80,Q10) -> 36.8775
A12: 2012 $ / nominal $ (from CPI) | B12: 1.2154262 | C12: 1.1755965 | D12: 1.1388591 | E12: 1.1073203 | F12: 1.0663762 | G12: 1.0701837 | H12: 1.052913 | I12: 1.0206945 | J12: 1 | K12: 0.98556386 | L12: 0.96983137 | M12: 0.96868157 | N12: 0.95661377 | O12: 0.9366596 | P12: 0.91432736 | Q12: 0.89805482
A13: 2012 $/hr | B13: =B11*B12 -> 30.640893 | C13: =C11*C12 -> 30.636045 | D13: =D11*D12 -> 30.911484 | E13: =E11*E12 -> 30.924687 | F13: =F11*F12 -> 30.65565 | G13: =G11*G12 -> 31.42862 | H13: =H11*H12 -> 31.245194 | I13: =I11*I12 -> 30.776491 | ... Q13: =Q11*Q12 -> 33.118016
A14: Annual Perc Change | C14: =(C13-B13)/B13 -> -0.00015822036 | D14: =(D13-C13)/C13 -> 0.0089906706 | E14: =(E13-D13)/D13 -> 0.00042712489 | F14: =(F13-E13)/E13 -> -0.0086997304 | G14: =(G13-F13)/F13 -> 0.025214577 | H14: =(H13-G13)/G13 -> -0.0058362755 | I14: =(I13-H13)/H13 -> -0.015000796 | J14: =(J13-I13)/I13 -> -0.0016730593 | ... Q14: =(Q13-P13)/P13 -> -0.0041602669
A15: Avg Annual Perc Cng / Yr | B15: =AVERAGE(C14:Q14) -> 0.0052780119
A21: BEA 2017 Total Employee Compensation
A22: 53333583000 | B22: 2017 value, from downscaling script (BECbIC.py)
A25: Projected Future Employee Compensation (2012 USD)
B26: 2015 | C26: 2016 | D26: 2017 | E26: 2018 | F26: 2019 | G26: 2020 | H26: 2021 | I26: 2022 | J26: 2023 | K26: 2024 | L26: 2025 | M26: 2026 | N26: 2027 | O26: 2028 | P26: 2029 | Q26: 2030 | R26: 2031 | S26: 2032 | T26: 2033 | U26: 2034 | V26: 2035 | W26: 2036 | X26: 2037 | Y26: 2038 | Z26: 2039 | AA26: 2040 | AB26: 2041 | AC26: 2042 | AD26: 2043 | AE26: 2044 | AF26: 2045 | AG26: 2046 | AH26: 2047 | AI26: 2048 | AJ26: 2049 | AK26: 2050
A27: Perc Change in Number of EEs (vs. 2015) | D27: =VLOOKUP(D$26,'Census Pop Projection'!$D:$E,2,FALSE)/'Census Pop Projection'!$E$3-1 -> 0.012889612 | E27: =VLOOKUP(E$26,'Census Pop Projection'!$D:$E,2,FALSE)/'Census Pop Projection'!$E$3-1 -> 0.020297694 | F27: =VLOOKUP(F$26,'Census Pop Projection'!$D:$E,2,FALSE)/'Census Pop Projection'!$E$3-1 -> 0.027693959 | G27: =VLOOKUP(G$26,'Census Pop Projection'!$D:$E,2,FALSE)/'Census Pop Projection'!$E$3-1 -> 0.035069477 | H27: =VLOOKUP(H$26,'Census Pop Projection'!$D:$E,2,FALSE)/'Census Pop Projection'!$E$3-1 -> 0.042410873 | I27: =VLOOKUP(I$26,'Census Pop Projection'!$D:$E,2,FALSE)/'Census Pop Projection'!$E$3-1 -> 0.04970329 | J27: =VLOOKUP(J$26,'Census Pop Projection'!$D:$E,2,FALSE)/'Census Pop Projection'!$E$3-1 -> 0.056932255 | K27: =VLOOKUP(K$26,'Census Pop Projection'!$D:$E,2,FALSE)/'Census Pop Projection'!$E$3-1 -> 0.064083819 | ... AK27: =VLOOKUP(AK$26,'Census Pop Projection'!$D:$E,2,FALSE)/'Census Pop Projection'!$E$3-1 -> 0.21020498
A28: Perc Change in Compensation / EE (vs. 2015) | D28: =C28*(1+$B$15)+$B$15 -> 0.0052780119 | E28: =D28*(1+$B$15)+$B$15 -> 0.010583881 | F28: =E28*(1+$B$15)+$B$15 -> 0.015917755 | G28: =F28*(1+$B$15)+$B$15 -> 0.021279781 | H28: =G28*(1+$B$15)+$B$15 -> 0.026670108 | I28: =H28*(1+$B$15)+$B$15 -> 0.032088885 | J28: =I28*(1+$B$15)+$B$15 -> 0.037536262 | K28: =J28*(1+$B$15)+$B$15 -> 0.043012391 | ... AK28: =AJ28*(1+$B$15)+$B$15 -> 0.19599741
A29: Projected Compensation (2012 $) | D29: =A22 -> 53333583000 | E29: =$D29*(1+E27)*(1+E28) -> 5.4992066e+10 | F29: =$D29*(1+F27)*(1+F28) -> 5.5683063e+10 | G29: =$D29*(1+G27)*(1+G28) -> 5.6378692e+10 | H29: =$D29*(1+H27)*(1+H28) -> 5.7078245e+10 | I29: =$D29*(1+I27)*(1+I28) -> 5.7780916e+10 | J29: =$D29*(1+J27)*(1+J28) -> 5.8485903e+10 | K29: =$D29*(1+K27)*(1+K28) -> 5.9192416e+10 | L29: =$D29*(1+L27)*(1+L28) -> 5.9900004e+10 | ... AK29: =$D29*(1+AK27)*(1+AK28) -> 7.7195136e+10

Sheet masterdata_oct4
A1: Unnamed: 0 | B1: state | C1: Time | D1: NoSettings | E1: 2020 | F1: 2021 | G1: 2022 | H1: 2023 | I1: 2024 | J1: 2025 | K1: 2026 | L1: 2027 | M1: 2028 | N1: 2029 | O1: 2030 | P1: 2031 | Q1: 2032 | R1: 2033 | S1: 2034 | T1: 2035 | U1: 2036 | V1: 2037 | W1: 2038 | X1: 2039 | Y1: 2040 | Z1: 2041 | AA1: 2042 | AB1: 2043 | AC1: 2044 | AD1: 2045 | AE1: 2046 | AF1: 2047 | AG1: 2048 | AH1: 2049 | AI1: 2050 | AJ1: NY Current Policy | AK1: NJ Current Policy | AL1: IL Current Policy
A2: 9038 | B2: AL | C2: BAU Employment by ISIC Code by Year[ISIC 01T03] | D2: NoSettings | E2: 19053.5 | F2: 19368.2 | G2: 19646.5 | H2: 19886.4 | I2: 20085.9 | J2: 20243.4 | K2: 20357.7 | L2: 20427.7 | M2: 20498 | N2: 20568.6 | O2: 20639.4 | P2: 20710.5 | Q2: 20782 | R2: 20853.7 | S2: 20925.7 | T2: 20997.9 | U2: 21070.5 | V2: 21143.4 | W2: 21216.5 | X2: 21289.9 | Y2: 21363.7 | Z2: 21437.7 | AA2: 21512 | AB2: 21586.7 | AC2: 21661.6 | AD2: 21736.8 | AE2: 21812.3 | AF2: 21888.2 | AG2: 21964.3 | AH2: 22040.7 | AI2: 22117.5
A3: 9039 | B3: AL | C3: BAU Employment by ISIC Code by Year[ISIC 05] | D3: NoSettings | E3: 227.707 | F3: 225.556 | G3: 223.722 | H3: 222.196 | I3: 220.969 | J3: 220.036 | K3: 219.391 | L3: 219.031 | M3: 218.672 | N3: 218.314 | O3: 217.956 | P3: 217.599 | Q3: 217.243 | R3: 216.888 | S3: 216.533 | T3: 216.179 | U3: 215.825 | V3: 215.473 | W3: 215.121 | X3: 214.77 | Y3: 214.419 | Z3: 214.069 | AA3: 213.72 | AB3: 213.372 | AC3: 213.024 | AD3: 212.677 | AE3: 212.331 | AF3: 211.985 | AG3: 211.64 | AH3: 211.296 | AI3: 210.952
A4: 9040 | B4: AL | C4: BAU Employment by ISIC Code by Year[ISIC 06] | D4: NoSettings | E4: 162.805 | F4: 170.164 | G4: 177.459 | H4: 184.643 | I4: 191.668 | J4: 198.483 | K4: 205.039 | L4: 211.287 | M4: 217.746 | N4: 224.426 | O4: 231.333 | P4: 238.474 | Q4: 245.859 | R4: 253.494 | S4: 261.389 | T4: 269.553 | U4: 277.994 | V4: 286.722 | W4: 295.746 | X4: 305.078 | Y4: 314.727 | Z4: 324.704 | AA4: 335.02 | AB4: 345.687 | AC4: 356.716 | AD4: 368.121 | AE4: 379.913 | AF4: 392.106 | AG4: 404.714 | AH4: 417.751 | AI4: 431.231
A5: 9041 | B5: AL | C5: BAU Employment by ISIC Code by Year[ISIC 07T08] | D5: NoSettings | E5: 4772.55 | F5: 4726.11 | G5: 4694.38 | H5: 4676.95 | I5: 4673.58 | J5: 4684.19 | K5: 4708.83 | L5: 4747.73 | M5: 4787.02 | N5: 4826.71 | O5: 4866.79 | P5: 4907.28 | Q5: 4948.18 | R5: 4989.48 | S5: 5031.2 | T5: 5073.34 | U5: 5115.9 | V5: 5158.89 | W5: 5202.31 | X5: 5246.17 | Y5: 5290.47 | Z5: 5335.21 | AA5: 5380.4 | AB5: 5426.05 | AC5: 5472.16 | AD5: 5518.73 | AE5: 5565.76 | AF5: 5613.27 | AG5: 5661.26 | AH5: 5709.72 | AI5: 5758.68
A6: 9042 | B6: AL | C6: BAU Employment by ISIC Code by Year[ISIC 09] | D6: NoSettings | E6: 907.201 | F6: 909.69 | G6: 915.444 | H6: 924.524 | I6: 937.033 | J6: 953.117 | K6: 972.974 | L6: 996.849 | M6: 1021.42 | N6: 1046.7 | O6: 1072.71 | P6: 1099.48 | Q6: 1127.02 | R6: 1155.37 | S6: 1184.53 | T6: 1214.54 | U6: 1245.42 | V6: 1277.2 | W6: 1309.9 | X6: 1343.55 | Y6: 1378.17 | Z6: 1413.79 | AA6: 1450.45 | AB6: 1488.18 | AC6: 1526.99 | AD6: 1566.93 | AE6: 1608.04 | AF6: 1650.33 | AG6: 1693.85 | AH6: 1738.63 | AI6: 1784.71
A7: 9043 | B7: AL | C7: BAU Employment by ISIC Code by Year[ISIC 10T12] | D7: NoSettings | E7: 37095.6 | F7: 37367.1 | G7: 37621.5 | H7: 37858.5 | I7: 38077.5 | J7: 38278.2 | K7: 38460.3 | L7: 38623.2 | M7: 38787 | N7: 38951.7 | O7: 39117.1 | P7: 39283.4 | Q7: 39450.5 | R7: 39618.4 | S7: 39787.2 | T7: 39956.8 | U7: 40127.3 | V7: 40298.6 | W7: 40470.8 | X7: 40643.9 | Y7: 40817.8 | Z7: 40992.5 | AA7: 41168.2 | AB7: 41344.7 | AC7: 41522.1 | AD7: 41700.4 | AE7: 41879.6 | AF7: 42059.7 | AG7: 42240.7 | AH7: 42422.6 | AI7: 42605.4
A8: 9044 | B8: AL | C8: BAU Employment by ISIC Code by Year[ISIC 13T15] | D8: NoSettings | E8: 11575.9 | F8: 11528.5 | G8: 11484.5 | H8: 11443.7 | I8: 11406.1 | J8: 11371.6 | K8: 11340.3 | L8: 11312.2 | M8: 11284.1 | N8: 11256 | O8: 11228.1 | P8: 11200.2 | Q8: 11172.5 | R8: 11144.8 | S8: 11117.2 | T8: 11089.7 | U8: 11062.2 | V8: 11034.9 | W8: 11007.6 | X8: 10980.4 | Y8: 10953.3 | Z8: 10926.3 | AA8: 10899.3 | AB8: 10872.5 | AC8: 10845.7 | AD8: 10819 | AE8: 10792.3 | AF8: 10765.8 | AG8: 10739.3 | AH8: 10712.9 | AI8: 10686.6
A9: 9045 | B9: AL | C9: BAU Employment by ISIC Code by Year[ISIC 16] | D9: NoSettings | E9: 19502.6 | F9: 19827.6 | G9: 20083.9 | H9: 20268 | I9: 20377.2 | J9: 20409.7 | K9: 20364.6 | L9: 20242.4 | M9: 20121 | N9: 20000.4 | O9: 19880.7 | P9: 19761.9 | Q9: 19643.8 | R9: 19526.6 | S9: 19410.2 | T9: 19294.6 | U9: 19179.9 | V9: 19065.9 | W9: 18952.7 | X9: 18840.4 | Y9: 18728.8 | Z9: 18618 | AA9: 18507.9 | AB9: 18398.7 | AC9: 18290.2 | AD9: 18182.4 | AE9: 18075.5 | AF9: 17969.2 | AG9: 17863.7 | AH9: 17759 | AI9: 17655
A10: 9046 | B10: AL | C10: BAU Employment by ISIC Code by Year[ISIC 17T18] | D10: NoSettings | E10: 15073.7 | F10: 15063.5 | G10: 15038.3 | H10: 14998 | I10: 14942.8 | J10: 14873 | K10: 14788.6 | L10: 14690.1 | M10: 14592.4 | N10: 14495.4 | O10: 14399.2 | P10: 14303.8 | Q10: 14209.2 | R10: 14115.3 | S10: 14022.1 | T10: 13929.7 | U10: 13838.1 | V10: 13747.2 | W10: 13657 | X10: 13567.5 | Y10: 13478.7 | Z10: 13390.7 | AA10: 13303.3 | AB10: 13216.7 | AC10: 13130.7 | AD10: 13045.5 | AE10: 12960.9 | AF10: 12877 | AG10: 12793.7 | AH10: 12711.2 | AI10: 12629.3
A11: 9047 | B11: AL | C11: BAU Employment by ISIC Code by Year[ISIC 19] | D11: NoSettings | E11: 2447.51 | F11: 2461.32 | G11: 2474.63 | H11: 2487.43 | I11: 2499.71 | J11: 2511.46 | K11: 2522.68 | L11: 2533.34 | M11: 2544.05 | N11: 2554.82 | O11: 2565.64 | P11: 2576.51 | Q11: 2587.44 | R11: 2598.43 | S11: 2609.47 | T11: 2620.56 | U11: 2631.71 | V11: 2642.92 | W11: 2654.18 | X11: 2665.5 | Y11: 2676.87 | Z11: 2688.31 | AA11: 2699.79 | AB11: 2711.34 | AC11: 2722.95 | AD11: 2734.61 | AE11: 2746.33 | AF11: 2758.11 | AG11: 2769.94 | AH11: 2781.84 | AI11: 2793.8 | AJ11: NY Current Policy
A12: 9048 | B12: AL | C12: BAU Employment by ISIC Code by Year[ISIC 20] | D12: NoSettings | E12: 11211.5 | F12: 11405.6 | G12: 11585.3 | H12: 11749.5 | I12: 11897.4 | J12: 12028.1 | K12: 12140.8 | L12: 12235 | M12: 12330 | N12: 12425.9 | O12: 12522.6 | P12: 12620.2 | Q12: 12718.7 | R12: 12818 | S12: 12918.3 | T12: 13019.4 | U12: 13121.5 | V12: 13224.5 | W12: 13328.4 | X12: 13433.2 | Y12: 13539 | Z12: 13645.8 | AA12: 13753.5 | AB12: 13862.1 | AC12: 13971.8 | AD12: 14082.4 | AE12: 14194.1 | AF12: 14306.7 | AG12: 14420.4 | AH12: 14535 | AI12: 14650.7 | AJ12: NY Current Policy
A13: 9049 | B13: AL | C13: BAU Employment by ISIC Code by Year[ISIC 21] | D13: NoSettings | E13: 801.649 | F13: 801.077 | G13: 802.602 | H13: 806.232 | I13: 811.995 | J13: 819.938 | K13: 830.13 | L13: 842.661 | M13: 855.418 | N13: 868.405 | O13: 881.626 | P13: 895.084 | Q13: 908.785 | R13: 922.733 | S13: 936.931 | T13: 951.385 | U13: 966.099 | V13: 981.078 | W13: 996.327 | X13: 1011.85 | Y13: 1027.65 | Z13: 1043.74 | AA13: 1060.12 | AB13: 1076.79 | AC13: 1093.76 | AD13: 1111.04 | AE13: 1128.62 | AF13: 1146.53 | AG13: 1164.76 | AH13: 1183.31 | AI13: 1202.2 | AJ13: NY Current Policy
A14: 9050 | B14: AL | C14: BAU Employment by ISIC Code by Year[ISIC 22] | D14: NoSettings | E14: 19597.5 | F14: 19884.6 | G14: 20164.6 | H14: 20437 | I14: 20701.3 | J14: 20956.9 | K14: 21203.3 | L14: 21440.1 | M14: 21680 | N14: 21923 | O14: 22169.2 | P14: 22418.6 | Q14: 22671.2 | R14: 22927.1 | S14: 23186.3 | T14: 23448.9 | U14: 23714.9 | V14: 23984.4 | W14: 24257.3 | X14: 24533.8 | Y14: 24813.9 | Z14: 25097.7 | AA14: 25385.1 | AB14: 25676.3 | AC14: 25971.3 | AD14: 26270.1 | AE14: 26572.8 | AF14: 26879.4 | AG14: 27190 | AH14: 27504.6 | AI14: 27823.3 | AJ14: NY Current Policy
A15: 9051 | B15: AL | C15: BAU Employment by ISIC Code by Year[ISIC 231] | D15: NoSettings | E15: 1473.65 | F15: 1518.87 | G15: 1555.91 | H15: 1583.95 | I15: 1602.3 | J15: 1610.5 | K15: 1608.29 | L15: 1595.64 | M15: 1583.1 | N15: 1570.67 | O15: 1558.36 | P15: 1546.16 | Q15: 1534.06 | R15: 1522.08 | S15: 1510.2 | T15: 1498.43 | U15: 1486.77 | V15: 1475.21 | W15: 1463.76 | X15: 1452.41 | Y15: 1441.16 | Z15: 1430.01 | AA15: 1418.96 | AB15: 1408.01 | AC15: 1397.16 | AD15: 1386.41 | AE15: 1375.75 | AF15: 1365.19 | AG15: 1354.73 | AH15: 1344.36 | AI15: 1334.08 | AJ15: NY Current Policy
A16: 9052 | B16: AL | C16: BAU Employment by ISIC Code by Year[ISIC 239] | D16: NoSettings | E16: 6704.77 | F16: 6816 | G16: 6920.19 | H16: 7016.86 | I16: 7105.56 | J16: 7185.9 | K16: 7257.48 | L16: 7319.96 | M16: 7383.08 | N16: 7446.82 | O16: 7511.2 | P16: 7576.23 | Q16: 7641.9 | R16: 7708.23 | S16: 7775.23 | T16: 7842.89 | U16: 7911.23 | V16: 7980.26 | W16: 8049.97 | X16: 8120.39 | Y16: 8191.5 | Z16: 8263.33 | AA16: 8335.88 | AB16: 8409.15 | AC16: 8483.15 | AD16: 8557.9 | AE16: 8633.39 | AF16: 8709.64 | AG16: 8786.64 | AH16: 8864.42 | AI16: 8942.98 | AJ16: NY Current Policy
A17: 9053 | B17: AL | C17: BAU Employment by ISIC Code by Year[ISIC 241] | D17: NoSettings | E17: 12613.2 | F17: 12770.5 | G17: 12894.5 | H17: 12983.8 | I17: 13037.6 | J17: 13055 | K17: 13035.9 | L17: 12980.4 | M17: 12925.1 | N17: 12870.1 | O17: 12815.3 | P17: 12760.9 | Q17: 12706.7 | R17: 12652.8 | S17: 12599.1 | T17: 12545.7 | U17: 12492.6 | V17: 12439.8 | W17: 12387.2 | X17: 12334.8 | Y17: 12282.8 | Z17: 12231 | AA17: 12179.4 | AB17: 12128.2 | AC17: 12077.1 | AD17: 12026.4 | AE17: 11975.8 | AF17: 11925.6 | AG17: 11875.5 | AH17: 11825.8 | AI17: 11776.3 | AJ17: NY Current Policy
A18: 9054 | B18: AL | C18: BAU Employment by ISIC Code by Year[ISIC 242] | D18: NoSettings | E18: 6407.38 | F18: 6506.17 | G18: 6597.37 | H18: 6680.54 | I18: 6755.26 | J18: 6821.16 | K18: 6877.89 | L18: 6925.16 | M18: 6972.81 | N18: 7020.84 | O18: 7069.25 | P18: 7118.05 | Q18: 7167.24 | R18: 7216.83 | S18: 7266.81 | T18: 7317.19 | U18: 7367.98 | V18: 7419.17 | W18: 7470.77 | X18: 7522.79 | Y18: 7575.22 | Z18: 7628.07 | AA18: 7681.34 | AB18: 7735.04 | AC18: 7789.16 | AD18: 7843.72 | AE18: 7898.72 | AF18: 7954.16 | AG18: 8010.04 | AH18: 8066.37 | AI18: 8123.15 | AJ18: NY Current Policy
A19: 9055 | B19: AL | C19: BAU Employment by ISIC Code by Year[ISIC 25] | D19: NoSettings | E19: 30489.3 | F19: 31113.6 | G19: 31673 | H19: 32162.5 | I19: 32577.8 | J19: 32915.1 | K19: 33171 | L19: 33343.2 | M19: 33516.4 | N19: 33690.6 | O19: 33865.9 | P19: 34042.2 | Q19: 34219.6 | R19: 34398.1 | S19: 34577.6 | T19: 34758.2 | U19: 34939.9 | V19: 35122.7 | W19: 35306.6 | X19: 35491.6 | Y19: 35677.7 | Z19: 35864.9 | AA19: 36053.2 | AB19: 36242.7 | AC19: 36433.3 | AD19: 36625 | AE19: 36817.9 | AF19: 37011.9 | AG19: 37207.2 | AH19: 37403.5 | AI19: 37601.1 | AJ19: NY Current Policy
A20: 9056 | B20: AL | C20: BAU Employment by ISIC Code by Year[ISIC 26] | D20: NoSettings | E20: 9375.24 | F20: 9529.74 | G20: 9690.72 | H20: 9858.44 | I20: 10033.2 | J20: 10215.2 | K20: 10404.9 | L20: 10602.5 | M20: 10804.4 | N20: 11010.8 | O20: 11221.8 | P20: 11437.3 | Q20: 11657.6 | R20: 11882.8 | S20: 12112.9 | T20: 12348.1 | U20: 12588.5 | V20: 12834.1 | W20: 13085.1 | X20: 13341.7 | Y20: 13603.9 | Z20: 13871.9 | AA20: 14145.8 | AB20: 14425.7 | AC20: 14711.7 | AD20: 15004.1 | AE20: 15302.9 | AF20: 15608.2 | AG20: 15920.3 | AH20: 16239.2 | AI20: 16565.2 | AJ20: NY Current Policy
A21: 9057 | B21: AL | C21: BAU Employment by ISIC Code by Year[ISIC 27] | D21: NoSettings | E21: 6027.05 | F21: 6143.51 | G21: 6261.12 | H21: 6379.84 | I21: 6499.62 | J21: 6620.42 | K21: 6742.19 | L21: 6864.88 | M21: 6990.15 | N21: 7118.05 | O21: 7248.63 | P21: 7381.96 | Q21: 7518.09 | R21: 7657.08 | S21: 7798.98 | T21: 7943.87 | U21: 8091.79 | V21: 8242.83 | W21: 8397.03 | X21: 8554.48 | Y21: 8715.23 | Z21: 8879.36 | AA21: 9046.93 | AB21: 9218.02 | AC21: 9392.7 | AD21: 9571.06 | AE21: 9753.16 | AF21: 9939.08 | AG21: 10128.9 | AH21: 10322.7 | AI21: 10520.6 | AJ21: NY Current Policy
A22: 9058 | B22: AL | C22: BAU Employment by ISIC Code by Year[ISIC 28] | D22: NoSettings | E22: 11706.4 | F22: 11938.6 | G22: 12158.7 | H22: 12365.8 | I22: 12558.7 | J22: 12736.5 | K22: 12898.4 | L22: 13043.6 | M22: 13190.6 | N22: 13339.6 | O22: 13490.5 | P22: 13643.3 | Q22: 13798.1 | R22: 13955 | S22: 14113.9 | T22: 14274.8 | U22: 14437.9 | V22: 14603 | W22: 14770.3 | X22: 14939.8 | Y22: 15111.5 | Z22: 15285.4 | AA22: 15461.6 | AB22: 15640.1 | AC22: 15820.9 | AD22: 16004 | AE22: 16189.6 | AF22: 16377.5 | AG22: 16567.9 | AH22: 16760.7 | AI22: 16956.1 | AJ22: NY Current Policy
... A124: 9162 | B124: AL | C124: BAU Value Added by ISIC Code by Year[ISIC 90T96] | D124: NoSettings | E124: 791188000 | F124: 807161000 | G124: 823316000 | H124: 839648000 | I124: 856152000 | J124: 872821000 | K124: 889652000 | L124: 906637000 | M124: 923995000 | N124: 941735000 | O124: 959866000 | P124: 978395000 | Q124: 997333000 | R124: 1016690000 | S124: 1036470000 | T124: 1056680000 | U124: 1077340000 | V124: 1098450000 | W124: 1120030000 | X124: 1142090000 | Y124: 1164620000 | Z124: 1187660000 | AA124: 1211200000 | AB124: 1235260000 | AC124: 1259850000 | AD124: 1284980000 | AE124: 1310660000 | AF124: 1336900000 | AG124: 1363730000 | AH124: 1391140000 | AI124: 1419160000 | AJ124: NY Current Policy
A125: 9038 | B125: AR | C125: BAU Employment by ISIC Code by Year[ISIC 01T03] | D125: NoSettings | E125: 29044.5 | F125: 29524.3 | G125: 29948.6 | H125: 30314.2 | I125: 30618.3 | J125: 30858.4 | K125: 31032.6 | L125: 31139.3 | M125: 31246.5 | N125: 31354 | O125: 31462 | P125: 31570.5 | Q125: 31679.3 | R125: 31788.6 | S125: 31898.4 | T125: 32008.6 | U125: 32119.2 | V125: 32230.2 | W125: 32341.8 | X125: 32453.7 | Y125: 32566.1 | Z125: 32679 | AA125: 32792.3 | AB125: 32906 | AC125: 33020.2 | AD125: 33134.9 | AE125: 33250 | AF125: 33365.6 | AG125: 33481.6 | AH125: 33598.2 | AI125: 33715.1 | AK125: NJ Current Policy
A126: 9040 | B126: AR | C126: BAU Employment by ISIC Code by Year[ISIC 06] | D126: NoSettings | E126: 841.873 | F126: 879.927 | G126: 917.649 | H126: 954.797 | I126: 991.12 | J126: 1026.36 | K126: 1060.26 | L126: 1092.57 | M126: 1125.98 | N126: 1160.52 | O126: 1196.23 | P126: 1233.16 | Q126: 1271.34 | R126: 1310.83 | S126: 1351.65 | T126: 1393.87 | U126: 1437.51 | V126: 1482.65 | W126: 1529.32 | X126: 1577.57 | Y126: 1627.46 | Z126: 1679.05 | AA126: 1732.4 | AB126: 1787.56 | AC126: 1844.59 | AD126: 1903.57 | AE126: 1964.55 | AF126: 2027.6 | AG126: 2092.79 | AH126: 2160.2 | AI126: 2229.91 | AK126: NJ Current Policy
A127: 9041 | B127: AR | C127: BAU Employment by ISIC Code by Year[ISIC 07T08] | D127: NoSettings | E127: 1685.53 | F127: 1669.13 | G127: 1657.92 | H127: 1651.77 | I127: 1650.58 | J127: 1654.33 | K127: 1663.03 | L127: 1676.77 | M127: 1690.64 | N127: 1704.66 | O127: 1718.82 | P127: 1733.12 | Q127: 1747.56 | R127: 1762.15 | S127: 1776.88 | T127: 1791.76 | U127: 1806.79 | V127: 1821.98 | W127: 1837.31 | X127: 1852.8 | Y127: 1868.45 | Z127: 1884.25 | AA127: 1900.21 | AB127: 1916.33 | AC127: 1932.61 | AD127: 1949.06 | AE127: 1965.67 | AF127: 1982.45 | AG127: 1999.4 | AH127: 2016.52 | AI127: 2033.81 | AK127: NJ Current Policy
A128: 9042 | B128: AR | C128: BAU Employment by ISIC Code by Year[ISIC 09] | D128: NoSettings | E128: 1306.53 | F128: 1310.11 | G128: 1318.4 | H128: 1331.48 | I128: 1349.49 | J128: 1372.66 | K128: 1401.25 | L128: 1435.64 | M128: 1471.02 | N128: 1507.43 | O128: 1544.89 | P128: 1583.44 | Q128: 1623.11 | R128: 1663.93 | S128: 1705.93 | T128: 1749.16 | U128: 1793.63 | V128: 1839.39 | W128: 1886.48 | X128: 1934.94 | Y128: 1984.8 | Z128: 2036.11 | AA128: 2088.91 | AB128: 2143.23 | AC128: 2199.14 | AD128: 2256.66 | AE128: 2315.85 | AF128: 2376.76 | AG128: 2439.44 | AH128: 2503.93 | AI128: 2570.29 | AK128: NJ Current Policy
A129: 9043 | B129: AR | C129: BAU Employment by ISIC Code by Year[ISIC 10T12] | D129: NoSettings | E129: 52606.7 | F129: 52991.7 | G129: 53352.5 | H129: 53688.6 | I129: 53999.2 | J129: 54283.8 | K129: 54541.9 | L129: 54773.1 | M129: 55005.4 | N129: 55238.8 | O129: 55473.5 | P129: 55709.3 | Q129: 55946.2 | R129: 56184.4 | S129: 56423.8 | T129: 56664.3 | U129: 56906.1 | V129: 57149 | W129: 57393.2 | X129: 57638.6 | Y129: 57885.2 | Z129: 58133.1 | AA129: 58382.2 | AB129: 58632.5 | AC129: 58884.1 | AD129: 59137 | AE129: 59391.1 | AF129: 59646.5 | AG129: 59903.1 | AH129: 60161.1 | AI129: 60420.3 | AK129: NJ Current Policy
A130: 9044 | B130: AR | C130: BAU Employment by ISIC Code by Year[ISIC 13T15] | D130: NoSettings | E130: 2977.13 | F130: 2964.95 | G130: 2953.62 | H130: 2943.13 | I130: 2933.46 | J130: 2924.6 | K130: 2916.55 | L130: 2909.3 | M130: 2902.08 | N130: 2894.87 | O130: 2887.69 | P130: 2880.52 | Q130: 2873.38 | R130: 2866.26 | S130: 2859.16 | T130: 2852.08 | U130: 2845.03 | V130: 2837.99 | W130: 2830.98 | X130: 2823.98 | Y130: 2817.01 | Z130: 2810.06 | AA130: 2803.13 | AB130: 2796.22 | AC130: 2789.33 | AD130: 2782.46 | AE130: 2775.62 | AF130: 2768.79 | AG130: 2761.98 | AH130: 2755.2 | AI130: 2748.43 | AK130: NJ Current Policy
A131: 9045 | B131: AR | C131: BAU Employment by ISIC Code by Year[ISIC 16] | D131: NoSettings | E131: 10700.7 | F131: 10879 | G131: 11019.6 | H131: 11120.7 | I131: 11180.6 | J131: 11198.4 | K131: 11173.7 | L131: 11106.6 | M131: 11040 | N131: 10973.8 | O131: 10908.1 | P131: 10842.9 | Q131: 10778.2 | R131: 10713.8 | S131: 10650 | T131: 10586.6 | U131: 10523.6 | V131: 10461.1 | W131: 10399 | X131: 10337.3 | Y131: 10276.1 | Z131: 10215.3 | AA131: 10154.9 | AB131: 10095 | AC131: 10035.4 | AD131: 9976.33 | AE131: 9917.63 | AF131: 9859.35 | AG131: 9801.47 | AH131: 9743.99 | AI131: 9686.92 | AK131: NJ Current Policy
A132: 9046 | B132: AR | C132: BAU Employment by ISIC Code by Year[ISIC 17T18] | D132: NoSettings | E132: 13531.2 | F132: 13522 | G132: 13499.4 | H132: 13463.2 | I132: 13413.7 | J132: 13351 | K132: 13275.3 | L132: 13186.8 | M132: 13099.1 | N132: 13012.1 | O132: 12925.7 | P132: 12840.1 | Q132: 12755.1 | R132: 12670.8 | S132: 12587.2 | T132: 12504.3 | U132: 12422 | V132: 12340.4 | W132: 12259.4 | X132: 12179.1 | Y132: 12099.4 | Z132: 12020.4 | AA132: 11942 | AB132: 11864.2 | AC132: 11787 | AD132: 11710.5 | AE132: 11634.6 | AF132: 11559.2 | AG132: 11484.5 | AH132: 11410.4 | AI132: 11336.9 | AK132: NJ Current Policy
A133: 9047 | B133: AR | C133: BAU Employment by ISIC Code by Year[ISIC 19] | D133: NoSettings | E133: 1252.07 | F133: 1259.13 | G133: 1265.94 | H133: 1272.49 | I133: 1278.78 | J133: 1284.79 | K133: 1290.52 | L133: 1295.98 | M133: 1301.46 | N133: 1306.97 | O133: 1312.5 | P133: 1318.07 | Q133: 1323.66 | R133: 1329.28 | S133: 1334.92 | T133: 1340.6 | U133: 1346.3 | V133: 1352.04 | W133: 1357.8 | X133: 1363.59 | Y133: 1369.41 | Z133: 1375.25 | AA133: 1381.13 | AB133: 1387.04 | AC133: 1392.97 | AD133: 1398.94 | AE133: 1404.94 | AF133: 1410.96 | AG133: 1417.02 | AH133: 1423.1 | AI133: 1429.22 | AK133: NJ Current Policy
A134: 9048 | B134: AR | C134: BAU Employment by ISIC Code by Year[ISIC 20] | D134: NoSettings | E134: 6120.95 | F134: 6226.95 | G134: 6325.04 | H134: 6414.7 | I134: 6495.43 | J134: 6566.77 | K134: 6628.33 | L134: 6679.73 | M134: 6731.6 | N134: 6783.94 | O134: 6836.74 | P134: 6890.03 | Q134: 6943.79 | R134: 6998.03 | S134: 7052.77 | T134: 7107.99 | U134: 7163.72 | V134: 7219.94 | W134: 7276.67 | X134: 7333.91 | Y134: 7391.67 | Z134: 7449.95 | AA134: 7508.75 | AB134: 7568.08 | AC134: 7627.94 | AD134: 7688.34 | AE134: 7749.29 | AF134: 7810.78 | AG134: 7872.83 | AH134: 7935.44 | AI134: 7998.61 | AK134: NJ Current Policy
A135: 9049 | B135: AR | C135: BAU Employment by ISIC Code by Year[ISIC 21] | D135: NoSettings | E135: 294.578 | F135: 294.367 | G135: 294.928 | H135: 296.262 | I135: 298.379 | J135: 301.298 | K135: 305.043 | L135: 309.648 | M135: 314.336 | N135: 319.108 | O135: 323.966 | P135: 328.912 | Q135: 333.946 | R135: 339.071 | S135: 344.289 | T135: 349.6 | U135: 355.007 | V135: 360.511 | W135: 366.115 | X135: 371.819 | Y135: 377.626 | Z135: 383.537 | AA135: 389.555 | AB135: 395.681 | AC135: 401.918 | AD135: 408.266 | AE135: 414.729 | AF135: 421.308 | AG135: 428.006 | AH135: 434.824 | AI135: 441.765 | AK135: NJ Current Policy
