Workbook

Sheet About
A1: SoFCtMbCtPRM Share of Forward Costs that Must Be Covered to Prevent Retirement for Merchant Plants | B1: Nebraska | C1: 46269 | F1: Alabama | G1: AL
B2: =VLOOKUP($B$1,$F$1:$G$51,2,FALSE) -> NE | F2: Alaska | G2: AK
A3: Sources: | B3: Retirement bar for merchant plants: 0.5 in multi-state organized capacity markets, 1.0 elsewhere (all plant types) - revised 2026-09-04 from the original flat 1.0 | F3: Arizona | G3: AZ
B4: Energy Innovation - internal design decision | F4: Arkansas | G4: AR
A5: State market data: | B5: Balancing-authority membership of the operating generator fleet, by state - U.S. Energy Information Administration (EIA), Preliminary Monthly Electric Generator Inventory (EIA-860M), June 2026 edition, Operating tab, https://www.eia.gov/electricity/data/eia860m/ | F5: California | G5: CA
B6: Columns Plant State, Balancing Authority Code, Nameplate Capacity (MW) and Status pasted for every operating generator on the 'EIA-860M BA' tab (same source extract as the SoCtICoS workbook, which holds all 37 columns). Accessed 2026-08-25. | F6: Colorado | G6: CO
A7: Notes: | F7: Connecticut | G7: CT
A8: Concept | B8: The retirement bar applied to the merchant share of each fleet. The effective bar is the capacity-weighted blend SoCtICoS x SoFCtMbCtPRCoS + (1 - SoCtICoS) x SoFCtMbCtPRM; see the SoCtICoS and SoFCtMbCtPRCoS workbooks for the other legs. | F8: Delaware | G8: DE
A9: What it does | B9: The retirement bar applied to the MERCHANT share of each fleet: the share of forward-going costs (fixed O&M plus sustaining CAPEX) that revenue modeled inside the state must cover for a plant to stay online. The model blends it with the cost-of-service leg: effective bar = SoCtICoS x SoFCtMbCtPRCoS + (1 - SoCtICoS) x SoFCtMbCtPRM. | F9: Florida | G9: FL
A10: Why below 1.0 in organized markets | B10: A state EPS represents only its own energy market and pays a capacity price only when the state itself is short on peak. A merchant plant inside a multi-state RTO also earns regional capacity-market revenue (PJM RPM, MISO PRA, ISO-NE FCM, SPP resource adequacy), ancillary services and bilateral contracts that the state model cannot see. A bar below 1.0 stands in for that unmodeled revenue until a regional market representation exists. There is no empirical basis for differentiating the share by plant type, so one value is applied to every technology in a state (design decision, 2026-09-04). | F10: Georgia | G10: GA
A11: State toggle | B11: The State Toggles tab carries one editable 1/0 flag per state, pre-filled from the EIA-860M share (1 if at least half the state's nameplate capacity sits in PJM/MISO/SPP/ISO-NE balancing authorities). 1 gives the inside bar, 0 the outside bar, blank falls back to the computed value. The default toggles put every state at exactly 0.5 or 1.0; the computed share is kept beside the toggle as the evidence for the default. | F11: Hawaii | G11: HI
A12: How the computed value works (fallback) | B12: RTO share = nameplate MW of the state's operating fleet whose Balancing Authority Code is flagged as a multi-state organized market (Parameters, BA table) / total nameplate MW in the state. Value = OutsideBar - (OutsideBar - InsideBar) x RTO share: a state wholly inside PJM/MISO/SPP/ISO-NE gets the inside bar (default 0.5), a state with no RTO capacity gets the outside bar (default 1.0), and split states (KY, MO, MS, NM, TX) are blended by capacity share. Single-state ISOs (ERCOT, NYISO, CAISO) are NOT flagged: their whole market is inside the state model, so the endogenous capacity mechanism already represents it. | F12: Idaho | G12: ID
A13: Calibration note | B13: 0.5 is the value at which PA nuclear (post-45U energy revenue covers 52-63% of recurring costs at a ~$20/MWh in-state price) is retained, matching Rhodium Taking Stock 2026 (no economic nuclear retirement in PA in any scenario) and consistent with PJM capacity revenue on the order of half of nuclear's going-forward costs at 2025-27 RPM clearing prices. It is a stated assumption, not a measured quantity; PA coal at 0.5 covers only 31-44% of its costs, so a modest gas-price rise stops its retirement. | F13: Illinois | G13: IL
A14: State configurability | B14: Cell B1 selects the region (state full name, or 'United States' for the national file); B2 derives the abbreviation and all calculations key on B2, the same convention as the SoCtICoS and SoFCtMbCtPRCoS workbooks. 'United States' returns the outside bar because the national model represents the whole market. | F14: Indiana | G14: IN
A15: Export | B15: The SoFCtMbCtPRM output tab mirrors SoFCtMbCtPRM.csv exactly (header + 24 rows). Set About!B1 to the state, recalculate, and export the tab. Per-state CSVs for all 48 states were generated with the same logic by edit_merchant_bar_workbook.py (state-eps-data-repository\EPS-test-folder), which also applied this edit to the workbook on 2026-09-04. | F15: Iowa | G15: IA
A16: Dependency | B16: Values below 1.0 are only appropriate together with the corrected existing-coal fixed O&M in CCaMC-AFOaMCpUC ($31,930/MW-yr for pre-2021 vintages, 2026-09-04); with the old $17,671 a uniform 0.5 freezes PA coal retirement. | F16: Kansas | G16: KS
F17: Kentucky | G17: KY
F18: Louisiana | G18: LA
F19: Maine | G19: ME
F20: Maryland | G20: MD
F21: Massachusetts | G21: MA
F22: Michigan | G22: MI
F23: Minnesota | G23: MN
F24: Mississippi | G24: MS
F25: Missouri | G25: MO
F26: Montana | G26: MT
F27: Nebraska | G27: NE
F28: Nevada | G28: NV
... F51: United States | G51: US

Sheet SoFCtMbCtPRM
A1: Unit: dimensionless (% of costs) | B1: Share of costs covered to be deemed profitable for merchant plants
A2: hard coal | B2: =ROUND(Calcs!$B$57,3) -> 0.5
A3: natural gas steam turbine | B3: =ROUND(Calcs!$B$57,3) -> 0.5
A4: natural gas combined cycle | B4: =ROUND(Calcs!$B$57,3) -> 0.5
A5: nuclear | B5: =ROUND(Calcs!$B$57,3) -> 0.5
A6: hydro | B6: =ROUND(Calcs!$B$57,3) -> 0.5
A7: onshore wind | B7: =ROUND(Calcs!$B$57,3) -> 0.5
A8: solar PV | B8: =ROUND(Calcs!$B$57,3) -> 0.5
A9: solar thermal | B9: =ROUND(Calcs!$B$57,3) -> 0.5
A10: biomass | B10: =ROUND(Calcs!$B$57,3) -> 0.5
A11: geothermal | B11: =ROUND(Calcs!$B$57,3) -> 0.5
A12: petroleum | B12: =ROUND(Calcs!$B$57,3) -> 0.5
A13: natural gas peaker | B13: =ROUND(Calcs!$B$57,3) -> 0.5
... A25: hydrogen combined cycle | B25: =ROUND(Calcs!$B$57,3) -> 0.5

Sheet Parameters
A1: Editable parameters (region selector is on the About tab, cell B1)
A2: Merchant bar INSIDE a multi-state organized capacity market (share of forward costs) | B2: 0.5 | D2: Balancing Authority Code | E2: Multi-state organized market? (1/0) | F2: Note | H2: Optional numeric state override (beats the toggle; empty = use toggle)
A3: Merchant bar OUTSIDE organized markets / single-state ISOs / national model | B3: 1 | D3: PJM | E3: 1 | F3: PJM Interconnection - RPM capacity market, 13 states + DC | H3: State | I3: Value
A4: Fallback when a state's toggle is blank: blend by capacity share (1) or threshold at RTO share >= 0.5 (0) | B4: 1 | D4: MISO | E4: 1 | F4: Midcontinent ISO - Planning Resource Auction, 15 states
D5: SWPP | E5: 1 | F5: Southwest Power Pool - resource adequacy requirement with bilateral capacity, 14 states
D6: ISNE | E6: 1 | F6: ISO New England - Forward Capacity Market, 6 states
D7: ERCO | E7: 0 | F7: ERCOT - single-state, energy-only; represented endogenously by the state model
D8: NYIS | E8: 0 | F8: NYISO - single-state ICAP market; represented endogenously
D9: CISO | E9: 0 | F9: CAISO - single-state resource adequacy; represented endogenously
D12: Any BA code not listed is treated as not organized (utility balancing area).

Sheet EIA-860M BA
A1: Plant State | B1: Balancing Authority Code | C1: Nameplate Capacity (MW) | D1: Status (code)
A2: AK | C2: 0.9 | D2: (SB)
A3: AK | C3: 0.9 | D3: (OP)
A4: AK | C4: 0.5 | D4: (OP)
A5: AK | C5: 0.4 | D5: (OP)
A6: AK | C6: 0.5 | D6: (OS)
A7: AK | C7: 0.5 | D7: (OS)
A8: AL | B8: SOCO | C8: 53.9 | D8: (OP)
A9: AL | B9: SOCO | C9: 153.1 | D9: (OP)
A10: AL | B10: SOCO | C10: 153.1 | D10: (OP)
A11: AL | B11: SOCO | C11: 403.7 | D11: (OP)
A12: AL | B12: SOCO | C12: 788.8 | D12: (OP)
A13: AL | B13: SOCO | C13: 170.1 | D13: (OP)
A14: AL | B14: SOCO | C14: 170.1 | D14: (OP)
A15: AL | B15: SOCO | C15: 195.2 | D15: (OP)
A16: AL | B16: SOCO | C16: 170.1 | D16: (OP)
A17: AL | B17: SOCO | C17: 170.1 | D17: (OP)
A18: AL | B18: SOCO | C18: 195.2 | D18: (OP)
A19: AL | B19: SOCO | C19: 464 | D19: (OP)
... A133: NE | B133: SWPP | C133: 248 | D133: (OP)
A134: AK | C134: 1.8 | D134: (OP)
A135: AK | C135: 2.2 | D135: (OP)
A136: AK | C136: 0.8 | D136: (OP)
A137: AK | C137: 0.4 | D137: (OP)
A138: AK | C138: 0.4 | D138: (OP)
A139: AK | C139: 1.2 | D139: (SB)
A140: AK | C140: 1.2 | D140: (SB)
A141: AK | C141: 1.1 | D141: (SB)
A142: AK | C142: 3.5 | D142: (SB)
A143: AK | C143: 1.1 | D143: (SB)
A144: AK | C144: 2.5 | D144: (SB)
A145: AK | C145: 2.6 | D145: (SB)
... A168: AK | C168: 1.6 | D168: (OS)
A169: AK | B169: NA | C169: 11.3 | D169: (OP)
A170: AK | B170: NA | C170: 11.3 | D170: (OP)
A171: AK | C171: 11.2 | D171: (OP)
A172: AK | C172: 11.2 | D172: (OP)
A173: AK | C173: 11.2 | D173: (OP)
A174: CA | B174: CISO | C174: 10.1 | D174: (SB)
A175: AK | C175: 48.9 | D175: (OP)
...

Sheet State Toggles
A1: State toggle: 1 = plants sit in a multi-state organized capacity market (merchant bar = Parameters!B2); 0 = they do not (merchant bar = Parameters!B3); blank = use the computed value per Parameters!B4
A2: Default toggle is pre-filled from the EIA-860M share (1 if RTO share >= 0.5). Edit column C to override a state; column B is evidence, not an input.
A4: State | B4: RTO share (computed, Calcs) | C4: Toggle (edit) | D4: Default from share | E4: Resulting merchant bar
A5: AL | B5: =Calcs!$D4 -> 0 | C5: 0 | D5: =IF(Calcs!$D4>=0.5,1,0) -> 0 | E5: =Calcs!$H4 -> 1
A6: AK | B6: =Calcs!$D5 -> 0 | C6: 0 | D6: =IF(Calcs!$D5>=0.5,1,0) -> 0 | E6: =Calcs!$H5 -> 1
A7: AZ | B7: =Calcs!$D6 -> 0 | C7: 0 | D7: =IF(Calcs!$D6>=0.5,1,0) -> 0 | E7: =Calcs!$H6 -> 1
A8: AR | B8: =Calcs!$D7 -> 0.91428318 | C8: 1 | D8: =IF(Calcs!$D7>=0.5,1,0) -> 1 | E8: =Calcs!$H7 -> 0.5
A9: CA | B9: =Calcs!$D8 -> 0 | C9: 0 | D9: =IF(Calcs!$D8>=0.5,1,0) -> 0 | E9: =Calcs!$H8 -> 1
A10: CO | B10: =Calcs!$D9 -> 0.0008316629 | C10: 0 | D10: =IF(Calcs!$D9>=0.5,1,0) -> 0 | E10: =Calcs!$H9 -> 1
A11: CT | B11: =Calcs!$D10 -> 1 | C11: 1 | D11: =IF(Calcs!$D10>=0.5,1,0) -> 1 | E11: =Calcs!$H10 -> 0.5
A12: DE | B12: =Calcs!$D11 -> 1 | C12: 1 | D12: =IF(Calcs!$D11>=0.5,1,0) -> 1 | E12: =Calcs!$H11 -> 0.5
A13: FL | B13: =Calcs!$D12 -> 0 | C13: 0 | D13: =IF(Calcs!$D12>=0.5,1,0) -> 0 | E13: =Calcs!$H12 -> 1
A14: GA | B14: =Calcs!$D13 -> 0 | C14: 0 | D14: =IF(Calcs!$D13>=0.5,1,0) -> 0 | E14: =Calcs!$H13 -> 1
A15: HI | B15: =Calcs!$D14 -> 0 | C15: 0 | D15: =IF(Calcs!$D14>=0.5,1,0) -> 0 | E15: =Calcs!$H14 -> 1
A16: ID | B16: =Calcs!$D15 -> 0 | C16: 0 | D16: =IF(Calcs!$D15>=0.5,1,0) -> 0 | E16: =Calcs!$H15 -> 1
... A54: WY | B54: =Calcs!$D53 -> 0 | C54: 0 | D54: =IF(Calcs!$D53>=0.5,1,0) -> 0 | E54: =Calcs!$H53 -> 1

Sheet Calcs
A1: RTO share and merchant bar by state (all operating generators, nameplate MW)
A3: State | B3: Total MW | C3: MW in multi-state organized markets | D3: RTO share | E3: Computed bar (blend) | F3: Computed bar (threshold) | G3: State toggle (from State Toggles tab) | H3: FINAL bar
A4: AL | B4: =SUMIFS('EIA-860M BA'!$C$2:$C$28197,'EIA-860M BA'!$A$2:$A$28197,$A4) -> 33050.4 | C4: =SUMPRODUCT(SUMIFS('EIA-860M BA'!$C$2:$C$28197,'EIA-860M BA'!$A$2:$A$28197,$A4,'EIA-860M BA'!$B$2:$B$28197,Parameters!$D$3:$D$9),Parameters!$E$3:$E$9) -> 0 | D4: =IFERROR($C4/$B4,0) -> 0 | E4: =Parameters!$B$3-(Parameters!$B$3-Parameters!$B$2)*$D4 -> 1 | F4: =IF($D4>=0.5,Parameters!$B$2,Parameters!$B$3) -> 1 | G4: =IF(ISNUMBER('State Toggles'!$C5),'State Toggles'!$C5,"") -> 0 | H4: =IF(COUNTIF(Parameters!$H$4:$H$60,$A4)>0,SUMIFS(Parameters!$I$4:$I$60,Parameters!$H$4:$H$60,$A4),IF($G4=1,Parameters!$B$2,IF($G4=0,Parameters!$B$3,IF(Parameters!$B$4=1,$E4,$F4)))) -> 1
A5: AK | B5: =SUMIFS('EIA-860M BA'!$C$2:$C$28197,'EIA-860M BA'!$A$2:$A$28197,$A5) -> 3116 | C5: =SUMPRODUCT(SUMIFS('EIA-860M BA'!$C$2:$C$28197,'EIA-860M BA'!$A$2:$A$28197,$A5,'EIA-860M BA'!$B$2:$B$28197,Parameters!$D$3:$D$9),Parameters!$E$3:$E$9) -> 0 | D5: =IFERROR($C5/$B5,0) -> 0 | E5: =Parameters!$B$3-(Parameters!$B$3-Parameters!$B$2)*$D5 -> 1 | F5: =IF($D5>=0.5,Parameters!$B$2,Parameters!$B$3) -> 1 | G5: =IF(ISNUMBER('State Toggles'!$C6),'State Toggles'!$C6,"") -> 0 | H5: =IF(COUNTIF(Parameters!$H$4:$H$60,$A5)>0,SUMIFS(Parameters!$I$4:$I$60,Parameters!$H$4:$H$60,$A5),IF($G5=1,Parameters!$B$2,IF($G5=0,Parameters!$B$3,IF(Parameters!$B$4=1,$E5,$F5)))) -> 1
A6: AZ | B6: =SUMIFS('EIA-860M BA'!$C$2:$C$28197,'EIA-860M BA'!$A$2:$A$28197,$A6) -> 43941.2 | C6: =SUMPRODUCT(SUMIFS('EIA-860M BA'!$C$2:$C$28197,'EIA-860M BA'!$A$2:$A$28197,$A6,'EIA-860M BA'!$B$2:$B$28197,Parameters!$D$3:$D$9),Parameters!$E$3:$E$9) -> 0 | D6: =IFERROR($C6/$B6,0) -> 0 | E6: =Parameters!$B$3-(Parameters!$B$3-Parameters!$B$2)*$D6 -> 1 | F6: =IF($D6>=0.5,Parameters!$B$2,Parameters!$B$3) -> 1 | G6: =IF(ISNUMBER('State Toggles'!$C7),'State Toggles'!$C7,"") -> 0 | H6: =IF(COUNTIF(Parameters!$H$4:$H$60,$A6)>0,SUMIFS(Parameters!$I$4:$I$60,Parameters!$H$4:$H$60,$A6),IF($G6=1,Parameters!$B$2,IF($G6=0,Parameters!$B$3,IF(Parameters!$B$4=1,$E6,$F6)))) -> 1
A7: AR | B7: =SUMIFS('EIA-860M BA'!$C$2:$C$28197,'EIA-860M BA'!$A$2:$A$28197,$A7) -> 19135.1 | C7: =SUMPRODUCT(SUMIFS('EIA-860M BA'!$C$2:$C$28197,'EIA-860M BA'!$A$2:$A$28197,$A7,'EIA-860M BA'!$B$2:$B$28197,Parameters!$D$3:$D$9),Parameters!$E$3:$E$9) -> 17494.9 | D7: =IFERROR($C7/$B7,0) -> 0.91428318 | E7: =Parameters!$B$3-(Parameters!$B$3-Parameters!$B$2)*$D7 -> 0.54285841 | F7: =IF($D7>=0.5,Parameters!$B$2,Parameters!$B$3) -> 0.5 | G7: =IF(ISNUMBER('State Toggles'!$C8),'State Toggles'!$C8,"") -> 1 | H7: =IF(COUNTIF(Parameters!$H$4:$H$60,$A7)>0,SUMIFS(Parameters!$I$4:$I$60,Parameters!$H$4:$H$60,$A7),IF($G7=1,Parameters!$B$2,IF($G7=0,Parameters!$B$3,IF(Parameters!$B$4=1,$E7,$F7)))) -> 0.5
A8: CA | B8: =SUMIFS('EIA-860M BA'!$C$2:$C$28197,'EIA-860M BA'!$A$2:$A$28197,$A8) -> 108657 | C8: =SUMPRODUCT(SUMIFS('EIA-860M BA'!$C$2:$C$28197,'EIA-860M BA'!$A$2:$A$28197,$A8,'EIA-860M BA'!$B$2:$B$28197,Parameters!$D$3:$D$9),Parameters!$E$3:$E$9) -> 0 | D8: =IFERROR($C8/$B8,0) -> 0 | E8: =Parameters!$B$3-(Parameters!$B$3-Parameters!$B$2)*$D8 -> 1 | F8: =IF($D8>=0.5,Parameters!$B$2,Parameters!$B$3) -> 1 | G8: =IF(ISNUMBER('State Toggles'!$C9),'State Toggles'!$C9,"") -> 0 | H8: =IF(COUNTIF(Parameters!$H$4:$H$60,$A8)>0,SUMIFS(Parameters!$I$4:$I$60,Parameters!$H$4:$H$60,$A8),IF($G8=1,Parameters!$B$2,IF($G8=0,Parameters!$B$3,IF(Parameters!$B$4=1,$E8,$F8)))) -> 1
A9: CO | B9: =SUMIFS('EIA-860M BA'!$C$2:$C$28197,'EIA-860M BA'!$A$2:$A$28197,$A9) -> 23447 | C9: =SUMPRODUCT(SUMIFS('EIA-860M BA'!$C$2:$C$28197,'EIA-860M BA'!$A$2:$A$28197,$A9,'EIA-860M BA'!$B$2:$B$28197,Parameters!$D$3:$D$9),Parameters!$E$3:$E$9) -> 19.5 | D9: =IFERROR($C9/$B9,0) -> 0.0008316629 | E9: =Parameters!$B$3-(Parameters!$B$3-Parameters!$B$2)*$D9 -> 0.99958417 | F9: =IF($D9>=0.5,Parameters!$B$2,Parameters!$B$3) -> 1 | G9: =IF(ISNUMBER('State Toggles'!$C10),'State Toggles'!$C10,"") -> 0 | H9: =IF(COUNTIF(Parameters!$H$4:$H$60,$A9)>0,SUMIFS(Parameters!$I$4:$I$60,Parameters!$H$4:$H$60,$A9),IF($G9=1,Parameters!$B$2,IF($G9=0,Parameters!$B$3,IF(Parameters!$B$4=1,$E9,$F9)))) -> 1
A10: CT | B10: =SUMIFS('EIA-860M BA'!$C$2:$C$28197,'EIA-860M BA'!$A$2:$A$28197,$A10) -> 10998.4 | C10: =SUMPRODUCT(SUMIFS('EIA-860M BA'!$C$2:$C$28197,'EIA-860M BA'!$A$2:$A$28197,$A10,'EIA-860M BA'!$B$2:$B$28197,Parameters!$D$3:$D$9),Parameters!$E$3:$E$9) -> 10998.4 | D10: =IFERROR($C10/$B10,0) -> 1 | E10: =Parameters!$B$3-(Parameters!$B$3-Parameters!$B$2)*$D10 -> 0.5 | F10: =IF($D10>=0.5,Parameters!$B$2,Parameters!$B$3) -> 0.5 | G10: =IF(ISNUMBER('State Toggles'!$C11),'State Toggles'!$C11,"") -> 1 | H10: =IF(COUNTIF(Parameters!$H$4:$H$60,$A10)>0,SUMIFS(Parameters!$I$4:$I$60,Parameters!$H$4:$H$60,$A10),IF($G10=1,Parameters!$B$2,IF($G10=0,Parameters!$B$3,IF(Parameters!$B$4=1,$E10,$F10)))) -> 0.5
A11: DE | B11: =SUMIFS('EIA-860M BA'!$C$2:$C$28197,'EIA-860M BA'!$A$2:$A$28197,$A11) -> 3036.5 | C11: =SUMPRODUCT(SUMIFS('EIA-860M BA'!$C$2:$C$28197,'EIA-860M BA'!$A$2:$A$28197,$A11,'EIA-860M BA'!$B$2:$B$28197,Parameters!$D$3:$D$9),Parameters!$E$3:$E$9) -> 3036.5 | D11: =IFERROR($C11/$B11,0) -> 1 | E11: =Parameters!$B$3-(Parameters!$B$3-Parameters!$B$2)*$D11 -> 0.5 | F11: =IF($D11>=0.5,Parameters!$B$2,Parameters!$B$3) -> 0.5 | G11: =IF(ISNUMBER('State Toggles'!$C12),'State Toggles'!$C12,"") -> 1 | H11: =IF(COUNTIF(Parameters!$H$4:$H$60,$A11)>0,SUMIFS(Parameters!$I$4:$I$60,Parameters!$H$4:$H$60,$A11),IF($G11=1,Parameters!$B$2,IF($G11=0,Parameters!$B$3,IF(Parameters!$B$4=1,$E11,$F11)))) -> 0.5
A12: FL | B12: =SUMIFS('EIA-860M BA'!$C$2:$C$28197,'EIA-860M BA'!$A$2:$A$28197,$A12) -> 81054.6 | C12: =SUMPRODUCT(SUMIFS('EIA-860M BA'!$C$2:$C$28197,'EIA-860M BA'!$A$2:$A$28197,$A12,'EIA-860M BA'!$B$2:$B$28197,Parameters!$D$3:$D$9),Parameters!$E$3:$E$9) -> 0 | D12: =IFERROR($C12/$B12,0) -> 0 | E12: =Parameters!$B$3-(Parameters!$B$3-Parameters!$B$2)*$D12 -> 1 | F12: =IF($D12>=0.5,Parameters!$B$2,Parameters!$B$3) -> 1 | G12: =IF(ISNUMBER('State Toggles'!$C13),'State Toggles'!$C13,"") -> 0 | H12: =IF(COUNTIF(Parameters!$H$4:$H$60,$A12)>0,SUMIFS(Parameters!$I$4:$I$60,Parameters!$H$4:$H$60,$A12),IF($G12=1,Parameters!$B$2,IF($G12=0,Parameters!$B$3,IF(Parameters!$B$4=1,$E12,$F12)))) -> 1
A13: GA | B13: =SUMIFS('EIA-860M BA'!$C$2:$C$28197,'EIA-860M BA'!$A$2:$A$28197,$A13) -> 43064.6 | C13: =SUMPRODUCT(SUMIFS('EIA-860M BA'!$C$2:$C$28197,'EIA-860M BA'!$A$2:$A$28197,$A13,'EIA-860M BA'!$B$2:$B$28197,Parameters!$D$3:$D$9),Parameters!$E$3:$E$9) -> 0 | D13: =IFERROR($C13/$B13,0) -> 0 | E13: =Parameters!$B$3-(Parameters!$B$3-Parameters!$B$2)*$D13 -> 1 | F13: =IF($D13>=0.5,Parameters!$B$2,Parameters!$B$3) -> 1 | G13: =IF(ISNUMBER('State Toggles'!$C14),'State Toggles'!$C14,"") -> 0 | H13: =IF(COUNTIF(Parameters!$H$4:$H$60,$A13)>0,SUMIFS(Parameters!$I$4:$I$60,Parameters!$H$4:$H$60,$A13),IF($G13=1,Parameters!$B$2,IF($G13=0,Parameters!$B$3,IF(Parameters!$B$4=1,$E13,$F13)))) -> 1
A14: HI | B14: =SUMIFS('EIA-860M BA'!$C$2:$C$28197,'EIA-860M BA'!$A$2:$A$28197,$A14) -> 3691.3 | C14: =SUMPRODUCT(SUMIFS('EIA-860M BA'!$C$2:$C$28197,'EIA-860M BA'!$A$2:$A$28197,$A14,'EIA-860M BA'!$B$2:$B$28197,Parameters!$D$3:$D$9),Parameters!$E$3:$E$9) -> 0 | D14: =IFERROR($C14/$B14,0) -> 0 | E14: =Parameters!$B$3-(Parameters!$B$3-Parameters!$B$2)*$D14 -> 1 | F14: =IF($D14>=0.5,Parameters!$B$2,Parameters!$B$3) -> 1 | G14: =IF(ISNUMBER('State Toggles'!$C15),'State Toggles'!$C15,"") -> 0 | H14: =IF(COUNTIF(Parameters!$H$4:$H$60,$A14)>0,SUMIFS(Parameters!$I$4:$I$60,Parameters!$H$4:$H$60,$A14),IF($G14=1,Parameters!$B$2,IF($G14=0,Parameters!$B$3,IF(Parameters!$B$4=1,$E14,$F14)))) -> 1
A15: ID | B15: =SUMIFS('EIA-860M BA'!$C$2:$C$28197,'EIA-860M BA'!$A$2:$A$28197,$A15) -> 6773.8 | C15: =SUMPRODUCT(SUMIFS('EIA-860M BA'!$C$2:$C$28197,'EIA-860M BA'!$A$2:$A$28197,$A15,'EIA-860M BA'!$B$2:$B$28197,Parameters!$D$3:$D$9),Parameters!$E$3:$E$9) -> 0 | D15: =IFERROR($C15/$B15,0) -> 0 | E15: =Parameters!$B$3-(Parameters!$B$3-Parameters!$B$2)*$D15 -> 1 | F15: =IF($D15>=0.5,Parameters!$B$2,Parameters!$B$3) -> 1 | G15: =IF(ISNUMBER('State Toggles'!$C16),'State Toggles'!$C16,"") -> 0 | H15: =IF(COUNTIF(Parameters!$H$4:$H$60,$A15)>0,SUMIFS(Parameters!$I$4:$I$60,Parameters!$H$4:$H$60,$A15),IF($G15=1,Parameters!$B$2,IF($G15=0,Parameters!$B$3,IF(Parameters!$B$4=1,$E15,$F15)))) -> 1
... A53: WY | B53: =SUMIFS('EIA-860M BA'!$C$2:$C$28197,'EIA-860M BA'!$A$2:$A$28197,$A53) -> 12734.5 | C53: =SUMPRODUCT(SUMIFS('EIA-860M BA'!$C$2:$C$28197,'EIA-860M BA'!$A$2:$A$28197,$A53,'EIA-860M BA'!$B$2:$B$28197,Parameters!$D$3:$D$9),Parameters!$E$3:$E$9) -> 0 | D53: =IFERROR($C53/$B53,0) -> 0 | E53: =Parameters!$B$3-(Parameters!$B$3-Parameters!$B$2)*$D53 -> 1 | F53: =IF($D53>=0.5,Parameters!$B$2,Parameters!$B$3) -> 1 | G53: =IF(ISNUMBER('State Toggles'!$C54),'State Toggles'!$C54,"") -> 0 | H53: =IF(COUNTIF(Parameters!$H$4:$H$60,$A53)>0,SUMIFS(Parameters!$I$4:$I$60,Parameters!$H$4:$H$60,$A53),IF($G53=1,Parameters!$B$2,IF($G53=0,Parameters!$B$3,IF(Parameters!$B$4=1,$E53,$F53)))) -> 1
A56: Selected region (About!B2) | B56: =About!$B$2 -> NE
A57: Selected region FINAL bar | B57: =IF($B$56="US",Parameters!$B$3,INDEX($H$4:$H$53,MATCH($B$56,$A$4:$A$53,0))) -> 0.5

Sheet Checks
A1: Validation checks
A2: All FINAL bars within [0,1]? | B2: =IF(AND(MIN(Calcs!$H$4:$H$53)>=0,MAX(Calcs!$H$4:$H$53)<=1),"PASS","FAIL") -> PASS
A3: PA fully in PJM (RTO share = 1)? | B3: =IF(ABS(INDEX(Calcs!$D$4:$D$53,MATCH("PA",Calcs!$A$4:$A$53,0))-1)<0.001,"PASS","FAIL") -> PASS
A4: TX mostly ERCOT (RTO share < 0.2)? | B4: =IF(INDEX(Calcs!$D$4:$D$53,MATCH("TX",Calcs!$A$4:$A$53,0))<0.2,"PASS","FAIL") -> PASS
A5: Output tab identical across all 24 technologies? | B5: =IF(MAX(SoFCtMbCtPRM!$B$2:$B$25)=MIN(SoFCtMbCtPRM!$B$2:$B$25),"PASS","FAIL") -> PASS
A6: Total 860M nameplate MW loaded (expect ~1.3 million) | B6: =SUM('EIA-860M BA'!$C$2:$C$28197) -> 1404855.7
