Workbook
Name Bucket: #REF!
Name DeliverabilityOptions: #REF!
Name elcc_adder: [1]Sheet1!$BJ$4:$BW$35
Name EndMonth: #REF!
Name Month: #REF!
Name pves_elcc: [1]Sheet1!$B$4:$BE$35
Name pves_elcc_pen: [1]Sheet1!$A$4:$A$35
Name pves_elcc_regrat: [1]Sheet1!$B$3:$BE$3
Name pves_elcc_zero: [1]Sheet1!$B$38:$BE$69
Name RA_Capacity: #REF!
Name SchedulingID: #REF!
Name StartMonth: #REF!
Name Zone: #REF!

Sheet About
A1: PTCF Peak Time Capacity Factors | B1: Nebraska | C1: 44307 | M1: Alabama | N1: AL
B2: =LOOKUP(B1,M1:N50,N1:N50) | M2: Alaska | N2: AK
A3: Source: | B3: California Market | E3: Texas Market | H3: Southwest Market | M3: Arizona | N3: AZ
B4: California Independent System Operator | E4: Electric Reliability Council of Texas | H4: Southwest Power Pool | M4: Arkansas | N4: AR
B5: 2020 | E5: 2016 | H5: 2019 | M5: California | N5: CA
B6: Final 2020 Net Qualifying Capacity for Resource Adequacy Resources | E6: CDR Peak Values for Solar PV and Wind by Season | H6: Solar and Wind ELCC Accreditation | M6: Colorado | N6: CO
B7: http://www.caiso.com/Documents/NetQualifyingCapacityList-2020.xls | E7: http://www.ercot.com/gridinfo/resource | H7: https://www.spp.org/documents/61025/elcc%20solar%20and%20wind%20accreditation.pdf | M7: Connecticut | N7: CT
B8: 2020 Technology Factors | M8: Delaware | N8: DE
M9: Florida | N9: FL
B10: Midwest Market | E10: Mid Atlantic Market | H10: California Market Energy | M10: Georgia | N10: GA
B11: Midcontinent Independent System Operator | E11: PJM | H11: CAISO | M11: Hawaii | N11: HI
B12: 2019 | E12: 2017 | H12: 2020 | M12: Idaho | N12: ID
B13: Planning Year 2020-2021 Wind & Solar Capacity Credit | E13: Class Average Capacity Factors | H13: 2019 Annual Report on Market Issues & Performance | M13: Illinois | N13: IL
B14: https://cdn.misoenergy.org/2020%20Wind%20&%20Solar%20Capacity%20Credit%20Report408144.pdf | E14: https://www.pjm.com/-/media/planning/res-adeq/class-average-wind-capacity-factors.ashx?la=en | H14: http://www.caiso.com/Documents/2019AnnualReportonMarketIssuesandPerformance.pdf | M14: Indiana | N14: IN
B15: p.16 | E15: p.5-6 | H15: Table 1.1 | M15: Iowa | N15: IA
M16: Kansas | N16: KS
B17: New England Market - Solar | E17: Offshore Wind, Onshore Wind for PJM, ISO-NE, and NYISO | H17: New York Market Energy | M17: Kentucky | N17: KY
B18: ISO New England | E18: LBNL | H18: NYISO | M18: Louisiana | N18: LA
B19: 2015 | E19: 2018 | H19: 2020 | M19: Maine | N19: ME
B20: Intermittent Resource Review | E20: Estimating the Value of Offshore Wind Along the United States’ Eastern Coast | H20: 2020 Load and Capacity Data | M20: Maryland | N20: MD
B21: http://www.iso-ne.com/static-assets/documents/2015/12/vrwg_intermittent_resource_qual_tool_status_update_12072015.pdf | E21: https://www.nps.edu/documents/114698888/117879842/Offshore_WInd_Value_Navy_Postgraduate_School_Final.pdf/f4368eea-e0e0-4fba-a925-00f5d365b887?t=1542325871000 | H21: https://www.nyiso.com/documents/20142/2226333/2020-Gold-Book-Final-Public.pdf/9ff426ab-e325-28bc-97cf-106d792593a1 | M21: Massachusetts | N21: MA
B22: pp. 4 & 7 | E22: p.27 | H22: Table I-1a | M22: Michigan | N22: MI
M23: Minnesota | N23: MN
H24: New England Market Energy | M24: Mississippi | N24: MS
H25: ISO-NE | M25: Missouri | N25: MO
B26: State Specific VA | E26: Hydro (VA) | H26: 2020 | M26: Montana | N26: MT
B27: Systems Advisory Model NREL Modeling tool | E27: PJM | H27: 2020 CELT Report | M27: Nebraska | N27: NE
B28: Solar, Wind modules | E28: https://www.pjm.com/-/media/committees-groups/committees/mc/20190425-somr/20190425-2018-imm-state-of-the-market-report-presentation.ashx | H28: https://www.iso-ne.com/system-planning/system-plans-studies/celt | M28: Nevada | N28: NV
B29: https://sam.nrel.gov/ | E29: Slide 14, Capacity factor 2018 | H29: Table 1.5.2 Energy | M29: New Hampshire | N29: NH
B30: Locations: Offshore Eastern VA (NREL AWS Representative File) | M30: New Jersey | N30: NJ
B31: Onshore: 37.5775° N, 79.7848° W Botetourt County | M31: New Mexico | N31: NM
B32: Solar: 37.51, -78.66 | M32: New York | N32: NY
M33: North Carolina | N33: NC
B34: SAM Simulation General | M34: North Dakota | N34: ND
B35: Systems Advisory Model NREL Modeling tool | M35: Ohio | N35: OH
B36: Solar, Wind modules | M36: Oklahoma | N36: OK
B37: https://sam.nrel.gov/ | M37: Oregon | N37: OR
B38: Solar: Geographic center of state (Lat/Long default when searching for state weather file), Detailed PV Model, No Financial Model, kW (DC) hourly data | M38: Pennsylvania | N38: PA
B39: Wind: Download weather file or AWS Representative File if available; 100m hub; kW capacity; 48 MWh system | M39: Rhode Island | N39: RI
B40: Prioritized Capacity values from Regional Transmission Operators where available | M40: South Carolina | N40: SC
...

Sheet ELCC Calcs
B1: SPP | C1: SPP | D1: MISO | E1: MISO | F1: PJM | G1: PJM | H1: WECC-RMRG | I1: WECC-RMRG | J1: WECC-NWPP_US | K1: WECC-NWPP_US | L1: WECC-SRSG | M1: WECC-SRSG | N1: WECC-CAMX | O1: WECC-CAMX | P1: ERCOT | Q1: ERCOT | R1: SERC-C | S1: SERC-C | T1: SERC-E | U1: SERC-E | V1: SERC-FP | W1: SERC-FP | X1: SERC-SE | Y1: SERC-SE | Z1: NPCC-NY | AA1: NPCC-NY | AB1: NPCC-NE | AC1: NPCC-NE
B2: Wind | C2: Solar | D2: Wind | E2: Solar | F2: Wind | G2: Solar | H2: Wind | I2: Solar | J2: Wind | K2: Solar | L2: Wind | M2: Solar | N2: Wind | O2: Solar | P2: Wind | Q2: Solar | R2: Wind | S2: Solar | T2: Wind | U2: Solar | V2: Wind | W2: Solar | X2: Wind | Y2: Solar | Z2: Wind | AA2: Solar | AB2: Wind | AC2: Solar
B3: SPPWind | C3: SPPSolar | D3: MISOWind | E3: MISOSolar | F3: PJMWind | G3: PJMSolar | H3: WECC-RMRGWind | I3: WECC-RMRGSolar | J3: WECC-NWPP_USWind | K3: WECC-NWPP_USSolar | L3: WECC-SRSGWind | M3: WECC-SRSGSolar | N3: WECC-CAMXWind | O3: WECC-CAMXSolar | P3: ERCOTWind | Q3: ERCOTSolar | R3: SERC-CWind | S3: SERC-CSolar | T3: SERC-EWind | U3: SERC-ESolar | V3: SERC-FPWind | W3: SERC-FPSolar | X3: SERC-SEWind | Y3: SERC-SESolar | Z3: NPCC-NYWind | AA3: NPCC-NYSolar | AB3: NPCC-NEWind | AC3: NPCC-NESolar
A4: s | B4: SPP Wind | C4: SPP Solar | D4: MISO Wind | E4: MISO Solar | F4: PJM Wind | G4: PJM Solar | H4: WECC-RMRG Combined PSCO, PRPA BH Wind | I4: WECC-RMRG Combined PSCO, PRPA BH Solar | J4: WECC-NWPP_US Wind | K4: WECC-NWPP_US Nevada Power Solar | L4: WECC-RMRG Combined PSCO, PRPA BH Wind | M4: WECC-SRSG APS Solar | N4: WECC-NWPP_US Wind | O4: WECC-CAMX CA Solar | P4: SPP Wind | Q4: ERCOT Solar | R4: SERC Eastern Interconnection Wind | S4: SERC-C Solar | T4: SERC Eastern Interconnection Wind | U4: SERC-E Solar | V4: SERC Eastern Interconnection Wind | W4: SERC-FP Solar | X4: SERC Eastern Interconnection Wind | Y4: SERC-SE Solar | Z4: NPCC Eastern Interconnection Wind | AA4: NPCC-NY RG&E Solar | AB4: NPCC Eastern Interconnection Wind | AC4: NPCC-NE Solar
A5: Penetration | B5: B | C5: D | D5: H | E5: J | F5: L | G5: N | H5: AO | I5: AM | J5: S | K5: U | L5: AO | M5: AA | N5: S | O5: AE | P5: B | Q5: AU | R5: AS | S5: AU | T5: AS | U5: AU | V5: AS | W5: AU | X5: AS | Y5: AU | Z5: AQ | AA5: X | AB5: AQ | AC5: AU
A6: Data | B6: C | C6: E | D6: I | E6: K | F6: M | G6: O | H6: AP | I6: AN | J6: T | K6: W | L6: AP | M6: AB | N6: T | O6: AF | P6: C | Q6: AV | R6: AT | S6: AW | T6: AT | U6: AX | V6: AT | W6: AY | X6: AT | Y6: AZ | Z6: AR | AA6: Z | AB6: AR | AC6: BA
A7: x | B7: ELCC_Raw!B16:B46 | C7: ELCC_Raw!D16:D46 | D7: ELCC_Raw!H16:H26 | E7: ELCC_Raw!J16:J27 | F7: ELCC_Raw!L16:L19 | G7: ELCC_Raw!N16:N21 | H7: ELCC_Raw!AO16:AO75 | I7: ELCC_Raw!AM16:AM90 | J7: ELCC_Raw!S16:S54 | K7: ELCC_Raw!U16:U21 | L7: ELCC_Raw!AO16:AO75 | M7: ELCC_Raw!AA16:AA62 | N7: ELCC_Raw!S16:S54 | O7: ELCC_Raw!AE16:AE60 | P7: ELCC_Raw!B16:B46 | Q7: ELCC_Raw!AU16:AU20 | R7: ELCC_Raw!AS16:AS17 | S7: ELCC_Raw!AU16:AU20 | T7: ELCC_Raw!AS16:AS17 | U7: ELCC_Raw!AU16:AU20 | V7: ELCC_Raw!AS16:AS17 | W7: ELCC_Raw!AU16:AU20 | X7: ELCC_Raw!AS16:AS17 | Y7: ELCC_Raw!AU16:AU20 | Z7: ELCC_Raw!AQ16:AQ17 | AA7: ELCC_Raw!X16:X21 | AB7: ELCC_Raw!AQ16:AQ17 | AC7: ELCC_Raw!AU16:AU20
A8: y | B8: ELCC_Raw!C16:C46 | C8: ELCC_Raw!E16:E46 | D8: ELCC_Raw!I16:I26 | E8: ELCC_Raw!K16:K27 | F8: ELCC_Raw!M16:M19 | G8: ELCC_Raw!O16:O21 | H8: ELCC_Raw!AP16:AP75 | I8: ELCC_Raw!AN16:AN90 | J8: ELCC_Raw!T16:T54 | K8: ELCC_Raw!W16:W21 | L8: ELCC_Raw!AP16:AP75 | M8: ELCC_Raw!AB16:AB62 | N8: ELCC_Raw!T16:T54 | O8: ELCC_Raw!AF16:AF60 | P8: ELCC_Raw!C16:C46 | Q8: ELCC_Raw!AV16:AV20 | R8: ELCC_Raw!AT16:AT17 | S8: ELCC_Raw!AW16:AW20 | T8: ELCC_Raw!AT16:AT17 | U8: ELCC_Raw!AX16:AX20 | V8: ELCC_Raw!AT16:AT17 | W8: ELCC_Raw!AY16:AY20 | X8: ELCC_Raw!AT16:AT17 | Y8: ELCC_Raw!AZ16:AZ20 | Z8: ELCC_Raw!AR16:AR17 | AA8: ELCC_Raw!Z16:Z21 | AB8: ELCC_Raw!AR16:AR17 | AC8: ELCC_Raw!BA16:BA20
A9: Max penetration for data | B9: 0.77700225 | C9: 0.77700225 | D9: 0.99899847 | E9: 0.91077567 | F9: 0.77523696 | G9: 1.1220256 | H9: 0.45165727 | I9: 0.35009699 | J9: 1.9328723 | K9: 0.2 | L9: 0.45165727 | M9: 0.23681544 | N9: 1.9328723 | O9: 0.66896898 | P9: 0.77700225 | Q9: 0.2 | R9: 0.4954495 | S9: 0.2 | T9: 0.4954495 | U9: 0.2 | V9: 0.4954495 | W9: 0.2 | X9: 0.4954495 | Y9: 0.2 | Z9: 0.4954495 | AA9: 0.2 | AB9: 0.4954495 | AC9: 0.2
A10: linear rsq | B10: 1 | C10: 0.93064422 | D10: 0.93399779 | E10: 0.66449955 | F10: 0.96413458 | G10: 0.89931191 | H10: 0.93660285 | I10: 0.98173011 | J10: 0.90606 | K10: 0.83138435 | L10: 0.93660285 | M10: 0.89461341 | N10: 0.90606 | O10: 0.97567404 | P10: 1 | Q10: 0.99945829 | R10: 1 | S10: 0.99908343 | T10: 1 | U10: 0.99555591 | V10: 1 | W10: 0.99634174 | X10: 1 | Y10: 0.99907822 | Z10: 1 | AA10: 0.94002428 | AB10: 1 | AC10: 0.99383549
A11: b | B11: -0.82888416 | C11: -2.1074875 | D11: -0.54691003 | E11: -1.9525004 | F11: -0.75733969 | G11: -1.55937 | H11: -1.2489841 | I11: -2.1634745 | J11: -0.61710116 | K11: -2.8875084 | L11: -1.2489841 | M11: -7.338611 | N11: -0.61710116 | O11: -1.7753386 | P11: -0.82888416 | Q11: -2.7048204 | R11: -0.22924672 | S11: -2.7700209 | T11: -0.22924672 | U11: -2.9064442 | V11: -0.22924672 | W11: -2.8502692 | X11: -0.22924672 | Y11: -2.6200825 | Z11: -0.22924672 | AA11: -4.6980295 | AB11: -0.22924672 | AC11: -3.1920878
A12: ln(a) | B12: -1.2993089 | C12: -0.29967518 | D12: -1.5916394 | E12: -1.0544425 | F12: -2.1162746 | G12: -0.83638408 | H12: -1.1915174 | I12: -0.71346716 | J12: -0.84810015 | K12: -0.1895607 | L12: -1.1915174 | M12: -0.40073081 | N12: -0.84810015 | O12: -0.54384783 | P12: -1.2993089 | Q12: -0.55500687 | R12: -1.6638868 | S12: -0.58778241 | T12: -1.6638868 | U12: -0.69230559 | V12: -1.6638868 | W12: -0.68295875 | X12: -1.6638868 | Y12: -0.46243124 | Z12: -1.6638868 | AA12: -0.28256214 | AB12: -1.6638868 | AC12: -0.84510937
A13: b | B13: -0.13583932 | C13: -0.36408608 | D13: -0.22725836 | E13: -0.34243858 | F13: -0.25176387 | G13: -0.47179086 | H13: -0.28297342 | I13: -0.40745551 | J13: -0.29932741 | K13: -0.14942421 | L13: -0.28297342 | M13: -0.56744112 | N13: -0.29932741 | O13: -0.49555952 | P13: -0.13583932 | Q13: -0.19912467 | R13: -0.092670085 | S13: -0.20511522 | T13: -0.092670085 | U13: -0.21791128 | V13: -0.092670085 | W13: -0.21355478 | X13: -0.092670085 | Y13: -0.19371905 | Z13: -0.092670085 | AA13: -0.27968947 | AB13: -0.092670085 | AC13: -0.23975296
A14: log(a) | B14: -0.77666217 | C14: -0.68202445 | D14: -0.89928558 | E14: -1.0468937 | F14: -1.1801283 | G14: -0.94403474 | H14: -0.83888107 | I14: -0.79919179 | J14: -0.66876019 | K14: -0.38044777 | L14: -0.83888107 | M14: -1.1284011 | N14: -0.66876019 | O14: -0.76816627 | P14: -0.77666217 | Q14: -0.58315231 | R14: -0.80020854 | S14: -0.60694845 | T14: -0.80020854 | U14: -0.67263829 | V14: -0.80020854 | W14: -0.6612297 | X14: -0.80020854 | Y14: -0.53314899 | Z14: -0.80020854 | AA14: -0.6536225 | AB14: -0.80020854 | AC14: -0.77602748
A15: Offset | B15: -0.018393131 | C15: -0.069920612 | D15: 0 | E15: 0 | F15: 0 | G15: -0.0086025554 | H15: 0 | I15: -0.0049875975 | J15: -0.0093342094 | K15: 0 | L15: 0 | M15: -0.015323317 | N15: -0.0093342094 | O15: -0.013807713 | P15: -0.018393131 | Q15: 0 | R15: 0 | S15: 0 | T15: 0 | U15: 0 | V15: 0 | W15: 0 | X15: 0 | Y15: 0 | Z15: 0 | AA15: 0 | AB15: 0 | AC15: 0
B16: 0.5 | C16: 0 | D16: 0.5 | E16: 0.5 | F16: 0.5 | G16: 0.5 | H16: 0.5 | I16: 0.5 | J16: 0.5 | K16: 0.7 | L16: 0.5 | M16: 0.25 | N16: 0.5 | O16: 0.5 | P16: 0.5 | Q16: 0.5 | R16: 0.5 | S16: 0.5 | T16: 1 | U16: 0.5 | V16: 0.5 | W16: 0.5 | X16: 1 | Y16: 0.5 | Z16: 1 | AA16: 0.5 | AB16: 1 | AC16: 0.5 | AG16: Solar | AH16: Wind
A17: 0 | B17: 0.26492089 | C17: 0.81793708 | D17: 0.19965938 | E17: 0.57691489 | F17: 0.115 | G17: 0.423 | H17: 0.30026189 | I17: 0.42647023 | J17: 0.42 | K17: 0.74642384 | L17: 0.30026189 | M17: 0.65655172 | N17: 0.42 | O17: 0.48439851 | P17: 0.26492089 | Q17: 0.535 | R17: 0.17580398 | S17: 0.51875 | T17: 0.17580398 | U17: 0.47 | V17: 0.17580398 | W17: 0.475 | X17: 0.17580398 | Y17: 0.59 | Z17: 0.17580398 | AA17: 0.69025271 | AB17: 0.17580398 | AC17: 0.40166667 | AE17: 0 | AF17: 0 | AG17: 0.423 | AH17: 0.115
A18: 0.05 | B18: 0.25732211 | C18: 0.63513424 | D18: 0.19965938 | E18: 0.32530582 | F18: 0.115 | G18: 0.41575813 | H18: 0.30026189 | I18: 0.42647023 | J18: 0.41679657 | K18: 0.74642384 | L18: 0.30026189 | M18: 0.48086207 | N18: 0.41679657 | O18: 0.48439851 | P18: 0.25732211 | Q18: 0.505 | R18: 0.17580398 | S18: 0.4875 | T18: 0.17580398 | U18: 0.435 | V18: 0.17580398 | W18: 0.44 | X18: 0.17580398 | Y18: 0.555 | Z18: 0.17580398 | AA18: 0.66714801 | AB18: 0.17580398 | AC18: 0.3675 | AE18: 1 | AF18: 0.05 | AG18: 0.41575813 | AH18: 0.115
A19: 0.1 | B19: 0.2490699 | C19: 0.6139431 | D19: 0.19965938 | E19: 0.27583017 | F19: 0.11461669 | G19: 0.38810832 | H19: 0.27794127 | I19: 0.39902038 | J19: 0.41279228 | K19: 0.74142857 | L19: 0.27794127 | M19: 0.30273946 | N19: 0.41279228 | O19: 0.48320359 | P19: 0.2490699 | Q19: 0.445 | R19: 0.17580398 | S19: 0.425 | T19: 0.17580398 | U19: 0.375 | V19: 0.17580398 | W19: 0.38 | X19: 0.17580398 | Y19: 0.4925 | Z19: 0.17580398 | AA19: 0.43610108 | AB19: 0.17580398 | AC19: 0.31333333 | AE19: 2 | AF19: 0.1 | AG19: 0.38810832 | AH19: 0.11461669
A20: 0.15 | B20: 0.24081768 | C20: 0.57671958 | D20: 0.19766407 | E20: 0.23661137 | F20: 0.10842503 | G20: 0.35753703 | H20: 0.24913281 | I20: 0.35491373 | J20: 0.40980046 | K20: 0.5335667 | L20: 0.24913281 | M20: 0.20857143 | N20: 0.40980046 | O20: 0.45985702 | P20: 0.24081768 | Q20: 0.385 | R20: 0.17580398 | S20: 0.36875 | T20: 0.17580398 | U20: 0.3225 | V20: 0.17580398 | W20: 0.33 | X20: 0.17580398 | Y20: 0.425 | Z20: 0.17580398 | AA20: 0.35523466 | AB20: 0.17580398 | AC20: 0.26416667 | AE20: 3 | AF20: 0.15 | AG20: 0.35753703 | AH20: 0.10842503
A21: 0.2 | B21: 0.23256547 | C21: 0.51783037 | D21: 0.18855101 | E21: 0.20032643 | F21: 0.10248892 | G21: 0.3243827 | H21: 0.22960643 | I21: 0.31608385 | J21: 0.41009656 | K21: 0.48395996 | L21: 0.22960643 | M21: 0.16235359 | N21: 0.41009656 | O21: 0.41644915 | P21: 0.23256547 | Q21: 0.34699451 | R21: 0.17580398 | S21: 0.33156962 | T21: 0.17580398 | U21: 0.29079669 | V21: 0.17580398 | W21: 0.29664003 | X21: 0.17580398 | Y21: 0.38653923 | Z21: 0.17580398 | AA21: 0.32141274 | AB21: 0.17580398 | AC21: 0.23659315 | AE21: 4 | AF21: 0.2 | AG21: 0.3243827 | AH21: 0.10248892
A22: 0.25 | B22: 0.22431325 | C22: 0.4455262 | D22: 0.17944669 | E22: 0.1792436 | F22: 0.098361149 | G22: 0.29122838 | H22: 0.2145645 | I22: 0.28000286 | J22: 0.40123295 | K22: 0.43504866 | L22: 0.2145645 | M22: 0.13395893 | N22: 0.40123295 | O22: 0.37741891 | P22: 0.22431325 | Q22: 0.31803829 | R22: 0.17580398 | S22: 0.30323164 | T22: 0.17580398 | U22: 0.26471138 | V22: 0.17580398 | W22: 0.27051183 | X22: 0.17580398 | Y22: 0.35518084 | Z22: 0.17580398 | AA22: 0.28004161 | AB22: 0.17580398 | AC22: 0.21344521 | AE22: 5 | AF22: 0.25 | AG22: 0.29122838 | AH22: 0.098361149
A23: 0.3 | B23: 0.21606104 | C23: 0.37994461 | D23: 0.17049941 | E23: 0.15950577 | F23: 0.094233379 | G23: 0.26273017 | H23: 0.20594862 | I23: 0.25890325 | J23: 0.39021685 | K23: 0.3930927 | L23: 0.20594862 | M23: 0.11370235 | N23: 0.39021685 | O23: 0.34071431 | P23: 0.21606104 | Q23: 0.29343908 | R23: 0.17580398 | S23: 0.27922734 | T23: 0.17580398 | U23: 0.2427488 | V23: 0.17580398 | W23: 0.2484608 | X23: 0.17580398 | Y23: 0.32844856 | Z23: 0.17580398 | AA23: 0.24752826 | AB23: 0.17580398 | AC23: 0.19418825 | AE23: 6 | AF23: 0.3 | AG23: 0.26273017 | AH23: 0.094233379
A24: 0.35 | B24: 0.20780882 | C24: 0.32834504 | D24: 0.16156641 | E24: 0.14576823 | F24: 0.090105609 | G24: 0.24151854 | H24: 0.19606908 | I24: 0.2316694 | J24: 0.37985941 | K24: 0.35694683 | L24: 0.19606908 | M24: 0.098757457 | N24: 0.37985941 | O24: 0.30629563 | P24: 0.20780882 | Q24: 0.27229438 | R24: 0.17481476 | S24: 0.25865247 | T24: 0.17481476 | U24: 0.22403507 | V24: 0.17481476 | W24: 0.22962733 | X24: 0.17481476 | Y24: 0.30538997 | Z24: 0.17481476 | AA24: 0.22169189 | AB24: 0.17481476 | AC24: 0.17797398 | AE24: 7 | AF24: 0.35 | AG24: 0.24151854 | AH24: 0.090105609
A25: 0.4 | B25: 0.19955661 | C25: 0.29203357 | D25: 0.15753521 | E25: 0.1327439 | F25: 0.086393092 | G25: 0.2203069 | H25: 0.18654286 | I25: 0.2134421 | J25: 0.36365414 | K25: 0.32572075 | L25: 0.18654286 | M25: 0.087427087 | N25: 0.36365414 | O25: 0.28075604 | P25: 0.19955661 | Q25: 0.25398355 | R25: 0.1728385 | S25: 0.24088456 | T25: 0.1728385 | U25: 0.20796767 | V25: 0.1728385 | W25: 0.21341943 | X25: 0.1728385 | Y25: 0.28535196 | Z25: 0.1728385 | AA25: 0.20099272 | AB25: 0.1728385 | AC25: 0.16421496 | AE25: 8 | AF25: 0.4 | AG25: 0.2203069 | AH25: 0.086393092
A26: 0.45 | B26: 0.19130439 | C26: 0.26537844 | D26: 0.15350401 | E26: 0.12051836 | F26: 0.083942228 | G26: 0.19909526 | H26: 0.17867115 | I26: 0.19746702 | J26: 0.34598145 | K26: 0.29869236 | L26: 0.17867115 | M26: 0.078627704 | N26: 0.34598145 | O26: 0.25654334 | P26: 0.19130439 | Q26: 0.23804487 | R26: 0.17086225 | S26: 0.22546046 | T26: 0.17086225 | U26: 0.19409844 | V26: 0.17086225 | W26: 0.19939685 | X26: 0.17086225 | Y26: 0.26784938 | Z26: 0.17086225 | AA26: 0.18429432 | AB26: 0.17086225 | AC26: 0.15247414 | AE26: 9 | AF26: 0.45 | AG26: 0.19909526 | AH26: 0.083942228
A27: 0.5 | B27: 0.18305218 | C27: 0.24547792 | D27: 0.14993114 | E27: 0.11297084 | F27: 0.081491365 | G27: 0.17788362 | H27: 0.16949698 | I27: 0.18336065 | J27: 0.32580317 | K27: 0.27526217 | L27: 0.16949698 | M27: 0.071640434 | N27: 0.32580317 | O27: 0.23986526 | P27: 0.18305218 | Q27: 0.22411738 | R27: 0.16890612 | S27: 0.21201838 | T27: 0.16888957 | U27: 0.18207783 | V27: 0.16890612 | W27: 0.18721608 | X27: 0.16888957 | Y27: 0.25250303 | Z27: 0.16888957 | AA27: 0.17073668 | AB27: 0.16888957 | AC27: 0.14241177 | AE27: 10 | AF27: 0.5 | AG27: 0.17788362 | AH27: 0.081491365
A28: 0.55 | B28: 0.17479996 | C28: 0.2270516 | D28: 0.14686154 | E28: 0.1067825 | F28: 0.079040501 | G28: 0.15667199 | H28: 0.16222699 | I28: 0.17083504 | J28: 0.30771653 | K28: 0.25492561 | L28: 0.16222699 | M28: 0.06597561 | N28: 0.30771653 | O28: 0.22044799 | P28: 0.17479996 | Q28: 0.21190967 | R28: 0.167201 | S28: 0.20026656 | T28: 0.16696476 | U28: 0.17162484 | V28: 0.167201 | W28: 0.17660068 | X28: 0.16696476 | Y28: 0.23900651 | Z28: 0.16696476 | AA28: 0.15965899 | AB28: 0.16696476 | AC28: 0.13375632 | AE28: 11 | AF28: 0.55 | AG28: 0.15667199 | AH28: 0.079040501
... A57: 2 | B57: 0.083697681 | C57: 0.091654593 | D57: 0.087955733 | E57: 0.038907502 | F57: 0.04098205 | G57: 0.041987696 | H57: 0.072045672 | I57: 0.058105885 | J57: 0.14010431 | K57: 0.11443761 | L57: 0.072045672 | M57: 0.022333548 | N57: 0.14010431 | O57: 0.055006022 | P57: 0.083697681 | Q57: 0.11501401 | R57: 0.13415195 | S57: 0.10831064 | T57: 0.11974626 | U57: 0.092103153 | V57: 0.13415195 | W57: 0.094915203 | X57: 0.11974626 | Y57: 0.12975586 | Z57: 0.11974626 | AA57: 0.091474749 | AB57: 0.11974626 | AC57: 0.071282677 | AE57: 0 | AF57: 2 | AG57: 0.041987696 | AH57: 0.04098205

Sheet Calculations
S1: State | T1: Region
S2: AZ | T2: AZ-NM-NV
S3: AR | T3: MISO
A4: State Specific PTCF (White if from SAM, Yellow if from balancing region) | G4: State Lookup | S4: CA | T4: CAISO
G5: =About!B2 | I5: Summer | J5: Winter | S5: CO | T5: RMPA
C6: Summer | D6: Winter | E6: Area | H6: Solar | I6: =ROUND(IF(SUMIFS(C$7:C$36,$B$7:$B$36,$H6,$A$7:$A$36,$G$5)=0,I40,SUMIFS(C$7:C$36,$B$7:$B$36,$H6,$A$7:$A$36,$G$5)),4) | J6: =ROUND(IF(SUMIFS(D$7:D$36,$B$7:$B$36,$H6,$A$7:$A$36,$G$5)=0,J40,SUMIFS(D$7:D$36,$B$7:$B$36,$H6,$A$7:$A$36,$G$5)),4) | S6: CT | T6: ISO-NE
A7: CA | B7: Offshore Wind | C7: 0.32 | D7: ='NREL SAM Modeling'!R12 | E7: =VLOOKUP(A7,Calculations!$S$2:$T$39,2,FALSE) | H7: Onshore Wind | I7: =ROUND(IF(SUMIFS(C$7:C$36,$B$7:$B$36,$H7,$A$7:$A$36,$G$5)=0,I41,SUMIFS(C$7:C$36,$B$7:$B$36,$H7,$A$7:$A$36,$G$5)),4) | J7: =ROUND(IF(SUMIFS(D$7:D$36,$B$7:$B$36,$H7,$A$7:$A$36,$G$5)=0,J41,SUMIFS(D$7:D$36,$B$7:$B$36,$H7,$A$7:$A$36,$G$5)),4) | S7: DE | T7: PJM
A8: CA | B8: Onshore Wind | C8: 0.21 | D8: 0.44 | E8: =VLOOKUP(A8,Calculations!$S$2:$T$39,2,FALSE) | H8: Offshore Wind | I8: =ROUND(IF(SUMIFS(C$7:C$36,$B$7:$B$36,$H8,$A$7:$A$36,$G$5)=0,I42,SUMIFS(C$7:C$36,$B$7:$B$36,$H8,$A$7:$A$36,$G$5)),4) | J8: =ROUND(IF(SUMIFS(D$7:D$36,$B$7:$B$36,$H8,$A$7:$A$36,$G$5)=0,J42,SUMIFS(D$7:D$36,$B$7:$B$36,$H8,$A$7:$A$36,$G$5)),4) | S8: IL | T8: MISO
A9: CA | B9: Solar | C9: 0.6 | E9: =VLOOKUP(A9,Calculations!$S$2:$T$39,2,FALSE) | S9: IN | T9: MISO
A10: CO | B10: Offshore Wind | C10: 0 | D10: 0 | E10: =VLOOKUP(A10,Calculations!$S$2:$T$39,2,FALSE) | F10: Note: Used ISO-NE for winter offshore | G10: *Red if unique weather outlier | L10: Peak Capacity Values from regional reports | S10: IA | T10: MISO
A11: CO | B11: Onshore Wind | C11: 0.1 | D11: 0.4931295 | E11: =VLOOKUP(A11,Calculations!$S$2:$T$39,2,FALSE) | G11: Pivoted NREL SAM Model with 2013 Weather Data | L11: Region | M11: Type | N11: Summer | O11: Winter | S11: KY | T11: MISO
A12: CO | B12: Solar | C12: 0.6 | D12: 0 | E12: =VLOOKUP(A12,Calculations!$S$2:$T$39,2,FALSE) | H12: Summer | I12: Winter | L12: MISO | M12: Onshore wind | N12: 0.166 | S12: LA | T12: MISO
A13: MN | B13: Offshore Wind | C13: 0 | D13: 0 | E13: =VLOOKUP(A13,Calculations!$S$2:$T$39,2,FALSE) | G13: CO Solar | H13: 0.045781803 | I13: 0 | L13: MISO | M13: Offshore wind | N13: 0 | O13: 0 | S13: ME | T13: ISO-NE
A14: MN | B14: Onshore Wind | C14: 0.166 | D14: ='State Raw Data'!M5 | E14: =VLOOKUP(A14,Calculations!$S$2:$T$39,2,FALSE) | G14: CO Wind | H14: 0.16044181 | I14: 0.4931295 | L14: MISO | M14: Solar | N14: 0.5 | O14: 0 | S14: MD | T14: PJM
A15: MN | B15: Solar | C15: 0.5 | D15: ='State Raw Data'!M4 | E15: =VLOOKUP(A15,Calculations!$S$2:$T$39,2,FALSE) | F15: Note: Used ISO-NE for winter offshore | G15: NM Solar | H15: 0.39769815 | I15: 0 | L15: PJM | M15: Onshore wind | N15: 0.176 | S15: MA | T15: ISO-NE
A16: NC | B16: Offshore Wind | C16: 0.31 | D16: 0.63 | E16: =VLOOKUP(A16,Calculations!$S$2:$T$39,2,FALSE) | G16: NM Wind | H16: 0.036845292 | I16: 0.60325458 | L16: PJM | M16: Offshore wind | N16: 0.31 | S16: MI | T16: MISO
A17: NC | B17: Onshore Wind | C17: 0.176 | D17: 0.26624417 | E17: =VLOOKUP(A17,Calculations!$S$2:$T$39,2,FALSE) | G17: NV Solar | H17: 0.28344215 | I17: 0 | L17: PJM | M17: Solar | N17: 0.6 | O17: 0 | S17: MN | T17: MISO
A18: NC | B18: Solar | C18: 0.6 | D18: 0 | E18: =VLOOKUP(A18,Calculations!$S$2:$T$39,2,FALSE) | G18: NV Wind | H18: 0.49697183 | I18: 0.32433838 | L18: ISO-NE | M18: Onshore wind | N18: 0.15 | O18: 0.3 | S18: MS | T18: MISO
A19: NM | B19: Offshore Wind | C19: 0 | D19: 0 | E19: =VLOOKUP(A19,Calculations!$S$2:$T$39,2,FALSE) | G19: PA Solar | H19: 0.58401577 | I19: 0 | L19: ISO-NE | M19: Offshore wind | N19: 0.24 | O19: 0.63 | S19: MO | T19: MISO
A20: NM | B20: Onshore Wind | C20: 0.1 | D20: 0.60325458 | E20: =VLOOKUP(A20,Calculations!$S$2:$T$39,2,FALSE) | F20: Note: Used PJM for winter onshore | G20: PA Wind | H20: 0.098838292 | I20: 0.32276841 | L20: ISO-NE | M20: Solar | O20: 0 | S20: MT | T20: MISO
A21: NM | B21: Solar | C21: 0.6 | D21: 0 | E21: =VLOOKUP(A21,Calculations!$S$2:$T$39,2,FALSE) | G21: NC Solar | H21: 0.55973706 | I21: 0 | L21: SPP | M21: Onshore wind | N21: 0.28 | S21: NE | T21: SPP
A22: NV | B22: Offshore Wind | C22: 0 | D22: 0 | E22: =VLOOKUP(A22,Calculations!$S$2:$T$39,2,FALSE) | G22: NC Wind | H22: 0.013816158 | I22: 0.052877792 | L22: SPP | M22: Offshore wind | S22: NV | T22: AZ-NM-NV
A23: NV | B23: Onshore Wind | C23: 0.1 | D23: 0.32433838 | E23: =VLOOKUP(A23,Calculations!$S$2:$T$39,2,FALSE) | G23: NC Offshore | H23: 0.11714883 | I23: 0.20541108 | L23: SPP | M23: Solar | N23: 0.607 | O23: 0 | S23: NH | T23: ISO-NE
A24: NV | B24: Solar | C24: 0.6 | D24: 0 | E24: =VLOOKUP(A24,Calculations!$S$2:$T$39,2,FALSE) | G24: VA Wind | H24: 0.049095125 | I24: 0.26624417 | L24: AZ-NM-NV | M24: Onshore wind | N24: 0.1 | S24: NJ | T24: PJM
A25: OR | B25: Offshore Wind | C25: 0.16242093 | D25: 0.32701142 | G25: VA Solar | H25: 0.24792836 | I25: 0 | L25: AZ-NM-NV | M25: Offshore wind | N25: 0 | O25: 0 | S25: NM | T25: AZ-NM-NV
A26: OR | B26: Onshore Wind | C26: 0.43855729 | D26: 0.20209106 | G26: VA Offshore | H26: 0.28893685 | I26: 0.30004379 | L26: AZ-NM-NV | M26: Solar | N26: 0.6 | O26: 0 | S26: NY | T26: NYISO
A27: OR | B27: Solar | C27: 0.46304027 | D27: 0 | G27: MN Wind | H27: 0.17618125 | I27: 0.20363206 | L27: RMPA | M27: Onshore wind | N27: 0.1 | S27: NC | T27: PJM
A28: PA | B28: Offshore Wind | C28: 0 | D28: 0 | E28: =VLOOKUP(A28,Calculations!$S$2:$T$39,2,FALSE) | G28: MN Solar | H28: 0.70541956 | I28: 0 | L28: RMPA | M28: Offshore wind | N28: 0 | O28: 0 | S28: ND | T28: MISO
A29: PA | B29: Onshore Wind | C29: 0.176 | D29: 0.32276841 | E29: =VLOOKUP(A29,Calculations!$S$2:$T$39,2,FALSE) | G29: OR Wind | H29: 0.43855729 | I29: 0.20209106 | L29: RMPA | M29: Solar | N29: 0.6 | O29: 0 | S29: OH | T29: PJM
A30: PA | B30: Solar | C30: 0.6 | D30: 0 | E30: =VLOOKUP(A30,Calculations!$S$2:$T$39,2,FALSE) | G30: OR Solar | H30: 0.46304027 | I30: 0 | S30: PA | T30: PJM
A31: VA | B31: Offshore Wind | C31: 0.31 | D31: 0.63 | E31: =VLOOKUP(A31,Calculations!$S$2:$T$39,2,FALSE) | G31: OR Offshore Wind | H31: 0.16242093 | I31: 0.32701142 | P31: Winter/summer | S31: RI | T31: ISO-NE
A32: VA | B32: Onshore Wind | C32: 0.176 | D32: 0.26624417 | E32: =VLOOKUP(A32,Calculations!$S$2:$T$39,2,FALSE) | G32: WI Solar | H32: 0.61769295 | I32: 0 | M32: NC Offshore | N32: 0.11714883 | O32: 0.20541108 | P32: =O32/N32 | S32: SD | T32: MISO
A33: VA | B33: Solar | C33: 0.6 | D33: 0 | E33: =VLOOKUP(A33,Calculations!$S$2:$T$39,2,FALSE) | G33: WI Onshore | H33: 0.29504608 | I33: 0.42463004 | M33: VA Offshore | N33: 0.28893685 | O33: 0.30004379 | P33: =O33/N33 | S33: TN | T33: PJM
A34: WI | B34: Offshore Wind | C34: 0.236306 | D34: 0.6402365 | E34: =VLOOKUP(A34,Calculations!$S$2:$T$39,2,FALSE) | G34: WI Offshore | H34: 0.236306 | I34: 0.6402365 | M34: OR Offshore Wind | N34: 0.16242093 | O34: 0.32701142 | P34: =O34/N34 | S34: TX | T34: ERCOT
A35: WI | B35: Onshore Wind | C35: 0.29504608 | D35: 0.42463004 | E35: =VLOOKUP(A35,Calculations!$S$2:$T$39,2,FALSE) | M35: WI Offshore | N35: 0.236306 | O35: 0.6402365 | P35: =O35/N35 | S35: VT | T35: ISO-NE
A36: WI | B36: Solar | C36: 0.61769295 | D36: 0 | E36: =VLOOKUP(A36,Calculations!$S$2:$T$39,2,FALSE) | N36: =AVERAGE(N32:N35) | O36: =AVERAGE(O32:O35) | P36: =AVERAGE(P32:P35) | S36: VA | T36: PJM
A37: Great lakes states included: | S37: WV | T37: PJM
A38: Illinois, Indiana, Michigan, Minnesota, Ohio, and Wisconsin. | F38: For all remaining states, the intermediate table below is used based on a rounded average of the previous states | M38: Average offshore winter to summer ratio | S38: WI | T38: MISO
A39: Offshore wind? | B39: 0: no, 1:yes | F39: Intermediate Values* | G39: =G5 | M39: =AVERAGE(P32:P35) | S39: WY | T39: RMPA
A40: AL | B40: 0 | F40: Solar | H40: Solar | I40: =K44 | J40: 0
...

Sheet NREL SAM Modeling
H6: Wind Nameplate | I6: Solar Nameplate (DC)
H7: 48000 | I7: 4.693
B8: CO Solar | C8: CO Wind | D8: NM Solar | E8: NM Wind | F8: NV Solar | G8: NV Wind | H8: PA Solar | I8: PA Wind | J8: NC Solar | K8: NC Wind | L8: NC Offshore | M8: VA Wind | N8: VA Solar | O8: VA Offshore | P8: MN Wind | Q8: MN Solar | R8: CA Offshore Wind | S8: CA onshore mountain | T8: CA onshore hill | U8: OR Solar | V8: OR Wind | W8: OR Offshore Wind | X8: WI Solar | Y8: WI Wind | Z8: WI Offshore Wind
A9: Summer Peak Hour | B9: =SUMIFS('State Peak Hours From NREL'!$D$5:$D$52,'State Peak Hours From NREL'!$C$5:$C$52,LEFT('NREL SAM Modeling'!B8,2)) | C9: =SUMIFS('State Peak Hours From NREL'!$D$5:$D$52,'State Peak Hours From NREL'!$C$5:$C$52,LEFT('NREL SAM Modeling'!C8,2)) | D9: =SUMIFS('State Peak Hours From NREL'!$D$5:$D$52,'State Peak Hours From NREL'!$C$5:$C$52,LEFT('NREL SAM Modeling'!D8,2)) | E9: =SUMIFS('State Peak Hours From NREL'!$D$5:$D$52,'State Peak Hours From NREL'!$C$5:$C$52,LEFT('NREL SAM Modeling'!E8,2)) | F9: =SUMIFS('State Peak Hours From NREL'!$D$5:$D$52,'State Peak Hours From NREL'!$C$5:$C$52,LEFT('NREL SAM Modeling'!F8,2)) | G9: =SUMIFS('State Peak Hours From NREL'!$D$5:$D$52,'State Peak Hours From NREL'!$C$5:$C$52,LEFT('NREL SAM Modeling'!G8,2)) | H9: =SUMIFS('State Peak Hours From NREL'!$D$5:$D$52,'State Peak Hours From NREL'!$C$5:$C$52,LEFT('NREL SAM Modeling'!H8,2)) | I9: =SUMIFS('State Peak Hours From NREL'!$D$5:$D$52,'State Peak Hours From NREL'!$C$5:$C$52,LEFT('NREL SAM Modeling'!I8,2)) | ... Z9: =SUMIFS('State Peak Hours From NREL'!$D$5:$D$52,'State Peak Hours From NREL'!$C$5:$C$52,LEFT('NREL SAM Modeling'!Z8,2))
A10: Winter Peak Hour | B10: =SUMIFS('State Peak Hours From NREL'!$F$5:$F$52,'State Peak Hours From NREL'!$C$5:$C$52,LEFT('NREL SAM Modeling'!B8,2)) | C10: =SUMIFS('State Peak Hours From NREL'!$F$5:$F$52,'State Peak Hours From NREL'!$C$5:$C$52,LEFT('NREL SAM Modeling'!C8,2)) | D10: =SUMIFS('State Peak Hours From NREL'!$F$5:$F$52,'State Peak Hours From NREL'!$C$5:$C$52,LEFT('NREL SAM Modeling'!D8,2)) | E10: =SUMIFS('State Peak Hours From NREL'!$F$5:$F$52,'State Peak Hours From NREL'!$C$5:$C$52,LEFT('NREL SAM Modeling'!E8,2)) | F10: =SUMIFS('State Peak Hours From NREL'!$F$5:$F$52,'State Peak Hours From NREL'!$C$5:$C$52,LEFT('NREL SAM Modeling'!F8,2)) | G10: =SUMIFS('State Peak Hours From NREL'!$F$5:$F$52,'State Peak Hours From NREL'!$C$5:$C$52,LEFT('NREL SAM Modeling'!G8,2)) | H10: =SUMIFS('State Peak Hours From NREL'!$F$5:$F$52,'State Peak Hours From NREL'!$C$5:$C$52,LEFT('NREL SAM Modeling'!H8,2)) | I10: =SUMIFS('State Peak Hours From NREL'!$F$5:$F$52,'State Peak Hours From NREL'!$C$5:$C$52,LEFT('NREL SAM Modeling'!I8,2)) | ... Z10: =SUMIFS('State Peak Hours From NREL'!$F$5:$F$52,'State Peak Hours From NREL'!$C$5:$C$52,LEFT('NREL SAM Modeling'!Z8,2))
A11: Summer Peak Cap Factor | B11: =MEDIAN(SUMIFS(B$14:B$8773,$A$14:$A$8773,B9),SUMIFS(B$14:B$8773,$A$14:$A$8773,B9-48),SUMIFS(B$14:B$8773,$A$14:$A$8773,B9-24),SUMIFS(B$14:B$8773,$A$14:$A$8773,B9+24),SUMIFS(B$14:B$8773,$A$14:$A$8773,B9+48))/(IF(RIGHT(B$8,5)="Solar",$I$7,$H$7)) | C11: =AVERAGE(SUMIFS(C$14:C$8773,$A$14:$A$8773,C9),SUMIFS(C$14:C$8773,$A$14:$A$8773,C9-48),SUMIFS(C$14:C$8773,$A$14:$A$8773,C9-24),SUMIFS(C$14:C$8773,$A$14:$A$8773,C9+24),SUMIFS(C$14:C$8773,$A$14:$A$8773,C9+48))/(IF(RIGHT(C$8,5)="Solar",$I$7,$H$7)) | D11: =AVERAGE(SUMIFS(D$14:D$8773,$A$14:$A$8773,D9),SUMIFS(D$14:D$8773,$A$14:$A$8773,D9-48),SUMIFS(D$14:D$8773,$A$14:$A$8773,D9-24),SUMIFS(D$14:D$8773,$A$14:$A$8773,D9+24),SUMIFS(D$14:D$8773,$A$14:$A$8773,D9+48))/(IF(RIGHT(D$8,5)="Solar",$I$7,$H$7)) | E11: =AVERAGE(SUMIFS(E$14:E$8773,$A$14:$A$8773,E9),SUMIFS(E$14:E$8773,$A$14:$A$8773,E9-48),SUMIFS(E$14:E$8773,$A$14:$A$8773,E9-24),SUMIFS(E$14:E$8773,$A$14:$A$8773,E9+24),SUMIFS(E$14:E$8773,$A$14:$A$8773,E9+48))/(IF(RIGHT(E$8,5)="Solar",$I$7,$H$7)) | F11: =AVERAGE(SUMIFS(F$14:F$8773,$A$14:$A$8773,F9),SUMIFS(F$14:F$8773,$A$14:$A$8773,F9-48),SUMIFS(F$14:F$8773,$A$14:$A$8773,F9-24),SUMIFS(F$14:F$8773,$A$14:$A$8773,F9+24),SUMIFS(F$14:F$8773,$A$14:$A$8773,F9+48))/(IF(RIGHT(F$8,5)="Solar",$I$7,$H$7)) | G11: =AVERAGE(SUMIFS(G$14:G$8773,$A$14:$A$8773,G9),SUMIFS(G$14:G$8773,$A$14:$A$8773,G9-48),SUMIFS(G$14:G$8773,$A$14:$A$8773,G9-24),SUMIFS(G$14:G$8773,$A$14:$A$8773,G9+24),SUMIFS(G$14:G$8773,$A$14:$A$8773,G9+48))/(IF(RIGHT(G$8,5)="Solar",$I$7,$H$7)) | H11: =AVERAGE(SUMIFS(H$14:H$8773,$A$14:$A$8773,H9),SUMIFS(H$14:H$8773,$A$14:$A$8773,H9-48),SUMIFS(H$14:H$8773,$A$14:$A$8773,H9-24),SUMIFS(H$14:H$8773,$A$14:$A$8773,H9+24),SUMIFS(H$14:H$8773,$A$14:$A$8773,H9+48))/(IF(RIGHT(H$8,5)="Solar",$I$7,$H$7)) | I11: =AVERAGE(SUMIFS(I$14:I$8773,$A$14:$A$8773,I9),SUMIFS(I$14:I$8773,$A$14:$A$8773,I9-48),SUMIFS(I$14:I$8773,$A$14:$A$8773,I9-24),SUMIFS(I$14:I$8773,$A$14:$A$8773,I9+24),SUMIFS(I$14:I$8773,$A$14:$A$8773,I9+48))/(IF(RIGHT(I$8,5)="Solar",$I$7,$H$7)) | J11: =AVERAGE(SUMIFS(J$14:J$8773,$A$14:$A$8773,J9),SUMIFS(J$14:J$8773,$A$14:$A$8773,J9-48),SUMIFS(J$14:J$8773,$A$14:$A$8773,J9-24),SUMIFS(J$14:J$8773,$A$14:$A$8773,J9+24),SUMIFS(J$14:J$8773,$A$14:$A$8773,J9+48))/(IF(RIGHT(J$8,5)="Solar",$I$7,$H$7)) | ... Z11: =AVERAGE(SUMIFS(Z$14:Z$8773,$A$14:$A$8773,Z9),SUMIFS(Z$14:Z$8773,$A$14:$A$8773,Z9-48),SUMIFS(Z$14:Z$8773,$A$14:$A$8773,Z9-24),SUMIFS(Z$14:Z$8773,$A$14:$A$8773,Z9+24),SUMIFS(Z$14:Z$8773,$A$14:$A$8773,Z9+48))/(IF(RIGHT(Z$8,5)="Solar",$I$7,$H$7))
A12: Winter Peak Cap Factor | B12: =AVERAGE(SUMIFS(B$14:B$8773,$A$14:$A$8773,B10),SUMIFS(B$14:B$8773,$A$14:$A$8773,B10-48),SUMIFS(B$14:B$8773,$A$14:$A$8773,B10-24),SUMIFS(B$14:B$8773,$A$14:$A$8773,B10+24),SUMIFS(B$14:B$8773,$A$14:$A$8773,B10+48))/(IF(RIGHT(B$8,5)="Solar",$I$7,$H$7)) | C12: =AVERAGE(SUMIFS(C$14:C$8773,$A$14:$A$8773,C10),SUMIFS(C$14:C$8773,$A$14:$A$8773,C10-48),SUMIFS(C$14:C$8773,$A$14:$A$8773,C10-24),SUMIFS(C$14:C$8773,$A$14:$A$8773,C10+24),SUMIFS(C$14:C$8773,$A$14:$A$8773,C10+48))/(IF(RIGHT(C$8,5)="Solar",$I$7,$H$7)) | D12: =AVERAGE(SUMIFS(D$14:D$8773,$A$14:$A$8773,D10),SUMIFS(D$14:D$8773,$A$14:$A$8773,D10-48),SUMIFS(D$14:D$8773,$A$14:$A$8773,D10-24),SUMIFS(D$14:D$8773,$A$14:$A$8773,D10+24),SUMIFS(D$14:D$8773,$A$14:$A$8773,D10+48))/(IF(RIGHT(D$8,5)="Solar",$I$7,$H$7)) | E12: =AVERAGE(SUMIFS(E$14:E$8773,$A$14:$A$8773,E10),SUMIFS(E$14:E$8773,$A$14:$A$8773,E10-48),SUMIFS(E$14:E$8773,$A$14:$A$8773,E10-24),SUMIFS(E$14:E$8773,$A$14:$A$8773,E10+24),SUMIFS(E$14:E$8773,$A$14:$A$8773,E10+48))/(IF(RIGHT(E$8,5)="Solar",$I$7,$H$7)) | F12: =AVERAGE(SUMIFS(F$14:F$8773,$A$14:$A$8773,F10),SUMIFS(F$14:F$8773,$A$14:$A$8773,F10-48),SUMIFS(F$14:F$8773,$A$14:$A$8773,F10-24),SUMIFS(F$14:F$8773,$A$14:$A$8773,F10+24),SUMIFS(F$14:F$8773,$A$14:$A$8773,F10+48))/(IF(RIGHT(F$8,5)="Solar",$I$7,$H$7)) | G12: =AVERAGE(SUMIFS(G$14:G$8773,$A$14:$A$8773,G10),SUMIFS(G$14:G$8773,$A$14:$A$8773,G10-48),SUMIFS(G$14:G$8773,$A$14:$A$8773,G10-24),SUMIFS(G$14:G$8773,$A$14:$A$8773,G10+24),SUMIFS(G$14:G$8773,$A$14:$A$8773,G10+48))/(IF(RIGHT(G$8,5)="Solar",$I$7,$H$7)) | H12: =AVERAGE(SUMIFS(H$14:H$8773,$A$14:$A$8773,H10),SUMIFS(H$14:H$8773,$A$14:$A$8773,H10-48),SUMIFS(H$14:H$8773,$A$14:$A$8773,H10-24),SUMIFS(H$14:H$8773,$A$14:$A$8773,H10+24),SUMIFS(H$14:H$8773,$A$14:$A$8773,H10+48))/(IF(RIGHT(H$8,5)="Solar",$I$7,$H$7)) | I12: =AVERAGE(SUMIFS(I$14:I$8773,$A$14:$A$8773,I10),SUMIFS(I$14:I$8773,$A$14:$A$8773,I10-48),SUMIFS(I$14:I$8773,$A$14:$A$8773,I10-24),SUMIFS(I$14:I$8773,$A$14:$A$8773,I10+24),SUMIFS(I$14:I$8773,$A$14:$A$8773,I10+48))/(IF(RIGHT(I$8,5)="Solar",$I$7,$H$7)) | ... M12: =AVERAGE(SUMIFS(M$14:M$8773,$A$14:$A$8773,M10),SUMIFS(M$14:M$8773,$A$14:$A$8773,M10-48),SUMIFS(M$14:M$8773,$A$14:$A$8773,M10-24),SUMIFS(M$14:M$8773,$A$14:$A$8773,M10+24),SUMIFS(M$14:M$8773,$A$14:$A$8773,M10+48))/(IF(RIGHT(M$8,5)="Solar",$I$7,$H$7)) | N12: 0 | O12: =AVERAGE(SUMIFS(O$14:O$8773,$A$14:$A$8773,O10),SUMIFS(O$14:O$8773,$A$14:$A$8773,O10-48),SUMIFS(O$14:O$8773,$A$14:$A$8773,O10-24),SUMIFS(O$14:O$8773,$A$14:$A$8773,O10+24),SUMIFS(O$14:O$8773,$A$14:$A$8773,O10+48))/(IF(RIGHT(O$8,5)="Solar",$I$7,$H$7)) | P12: =AVERAGE(SUMIFS(P$14:P$8773,$A$14:$A$8773,P10),SUMIFS(P$14:P$8773,$A$14:$A$8773,P10-48),SUMIFS(P$14:P$8773,$A$14:$A$8773,P10-24),SUMIFS(P$14:P$8773,$A$14:$A$8773,P10+24),SUMIFS(P$14:P$8773,$A$14:$A$8773,P10+48))/(IF(RIGHT(P$8,5)="Solar",$I$7,$H$7)) | Q12: =AVERAGE(SUMIFS(Q$14:Q$8773,$A$14:$A$8773,Q10),SUMIFS(Q$14:Q$8773,$A$14:$A$8773,Q10-48),SUMIFS(Q$14:Q$8773,$A$14:$A$8773,Q10-24),SUMIFS(Q$14:Q$8773,$A$14:$A$8773,Q10+24),SUMIFS(Q$14:Q$8773,$A$14:$A$8773,Q10+48))/(IF(RIGHT(Q$8,5)="Solar",$I$7,$H$7)) | R12: =AVERAGE(SUMIFS(R$14:R$8773,$A$14:$A$8773,R10),SUMIFS(R$14:R$8773,$A$14:$A$8773,R10-48),SUMIFS(R$14:R$8773,$A$14:$A$8773,R10-24),SUMIFS(R$14:R$8773,$A$14:$A$8773,R10+24),SUMIFS(R$14:R$8773,$A$14:$A$8773,R10+48))/(IF(RIGHT(R$8,5)="Solar",$I$7,$H$7)) | S12: =AVERAGE(SUMIFS(S$14:S$8773,$A$14:$A$8773,S10),SUMIFS(S$14:S$8773,$A$14:$A$8773,S10-48),SUMIFS(S$14:S$8773,$A$14:$A$8773,S10-24),SUMIFS(S$14:S$8773,$A$14:$A$8773,S10+24),SUMIFS(S$14:S$8773,$A$14:$A$8773,S10+48))/(IF(RIGHT(S$8,5)="Solar",$I$7,$H$7)) | T12: =AVERAGE(SUMIFS(T$14:T$8773,$A$14:$A$8773,T10),SUMIFS(T$14:T$8773,$A$14:$A$8773,T10-48),SUMIFS(T$14:T$8773,$A$14:$A$8773,T10-24),SUMIFS(T$14:T$8773,$A$14:$A$8773,T10+24),SUMIFS(T$14:T$8773,$A$14:$A$8773,T10+48))/(IF(RIGHT(T$8,5)="Solar",$I$7,$H$7)) | U12: =AVERAGE(SUMIFS(U$14:U$8773,$A$14:$A$8773,U10),SUMIFS(U$14:U$8773,$A$14:$A$8773,U10-48),SUMIFS(U$14:U$8773,$A$14:$A$8773,U10-24),SUMIFS(U$14:U$8773,$A$14:$A$8773,U10+24),SUMIFS(U$14:U$8773,$A$14:$A$8773,U10+48))/(IF(RIGHT(U$8,5)="Solar",$I$7,$H$7)) | V12: =AVERAGE(SUMIFS(V$14:V$8773,$A$14:$A$8773,V10),SUMIFS(V$14:V$8773,$A$14:$A$8773,V10-48),SUMIFS(V$14:V$8773,$A$14:$A$8773,V10-24),SUMIFS(V$14:V$8773,$A$14:$A$8773,V10+24),SUMIFS(V$14:V$8773,$A$14:$A$8773,V10+48))/(IF(RIGHT(V$8,5)="Solar",$I$7,$H$7)) | ... Z12: =AVERAGE(SUMIFS(Z$14:Z$8773,$A$14:$A$8773,Z10),SUMIFS(Z$14:Z$8773,$A$14:$A$8773,Z10-48),SUMIFS(Z$14:Z$8773,$A$14:$A$8773,Z10-24),SUMIFS(Z$14:Z$8773,$A$14:$A$8773,Z10+24),SUMIFS(Z$14:Z$8773,$A$14:$A$8773,Z10+48))/(IF(RIGHT(Z$8,5)="Solar",$I$7,$H$7))
A13: Hour | B13: SAM Runs | C13: C:\SAM\2020.2.29\wind_resource\CO Northeastern-Flat Lands.srw | E13: C:\SAM\2020.2.29\wind_resource\NM Eastern-Flat Lands.srw | G13: 100m NV (lat39.28_lon-114.92) | I13: SAM Downloaded Weather Files/lat40.90_lon-77.84__2013_100m.srw | K13: SAM Downloaded Weather Files/lat35.53_lon-79.13__2013_100m.srw | L13: C:\SAM\2020.2.29\wind_resource\NC Eastern-Ocean.srw | R13: C:\SAM\2020.2.29\wind_resource\CA Northern-Ocean.srw | S13: C:\SAM\2020.2.29\wind_resource\CA Southern-Mountainous.srw | T13: C:\SAM\2020.2.29\wind_resource\CA Northern-Rolling Hills.srw | U13: C:\SAM Downloaded Weather Files\oregon_43.940449_-120.605279_psm3_60_tmy.csv | V13: C:\SAM\2020.2.29\wind_resource\OR Northern-Flat Lands.srw | W13: C:\SAM\2020.2.29\wind_resource\OR Northwestern-Ocean.srw | X13: SAM Downloaded Weather Files\wisconsin_44.639954_-89.732969_psm3_60_tmy.csv | Y13: SAM Downloaded Weather Files/lat44.64_lon-89.73__2013_100m.srw | Z13: SAM Downloaded Weather Files/lat47.50_lon-89.00__2013_100m.srw
A14: 1 | B14: 0 | C14: 0 | D14: 0 | E14: 39827.1 | F14: 0 | G14: 1285.46 | H14: 0 | I14: 26776.4 | J14: 0 | K14: 29039.9 | L14: 26776.4 | M14: 8984.5 | N14: 0 | O14: 27284.3 | P14: 0 | Q14: 0 | R14: 17859.1 | S14: 33828.1 | T14: 459.432 | U14: 0 | V14: 40053.4 | W14: 40053.4 | X14: 0 | Y14: 1418.7 | Z14: 27966.4
A15: 2 | B15: 0 | C15: 4049.91 | D15: 0 | E15: 39822.6 | F15: 0 | G15: 3590.41 | H15: 0 | I15: 26826 | J15: 0 | K15: 18753.9 | L15: 26826 | M15: 2152.97 | N15: 0 | O15: 29743.2 | P15: 0 | Q15: 0 | R15: 18042.6 | S15: 28666.1 | T15: 8422.64 | U15: 0 | V15: 38213.7 | W15: 40053.4 | X15: 0 | Y15: 4811.35 | Z15: 24982.5
A16: 3 | B16: 0 | C16: 6640.54 | D16: 0 | E16: 39291.4 | F16: 0 | G16: 3072.77 | H16: 0 | I16: 24844.1 | J16: 0 | K16: 20003.8 | L16: 24844.1 | M16: 4603.57 | N16: 0 | O16: 27097.8 | P16: 0 | Q16: 0 | R16: 18903.6 | S16: 12811.1 | T16: 17207.4 | U16: 0 | V16: 39839.1 | W16: 40053.4 | X16: 0 | Y16: 3494.39 | Z16: 18886.1
A17: 4 | B17: 0 | C17: 8785.06 | D17: 0 | E17: 37965 | F17: 0 | G17: 2267.17 | H17: 0 | I17: 8208.99 | J17: 0 | K17: 20217.4 | L17: 8208.99 | M17: 1416.55 | N17: 0 | O17: 37583 | P17: 0 | Q17: 0 | R17: 20323.7 | S17: 3728.35 | T17: 24025.9 | U17: 0 | V17: 40053.4 | W17: 40053.4 | X17: 0 | Y17: 2405.03 | Z17: 16433.7
A18: 5 | B18: 0 | C18: 9152.22 | D18: 0 | E18: 31125 | F18: 0 | G18: 2934.64 | H18: 0 | I18: 4813.28 | J18: 0 | K18: 18113 | L18: 4813.28 | M18: 858.28 | N18: 0 | O18: 38434.1 | P18: 178.244 | Q18: 0 | R18: 10714.1 | S18: 4423.26 | T18: 18157.6 | U18: 0 | V18: 38819.6 | W18: 40053.4 | X18: 0 | Y18: 3530.13 | Z18: 10812.6
A19: 6 | B19: 0 | C19: 13898.3 | D19: 0 | E19: 16673.3 | F19: 0 | G19: 5001.58 | H19: 0 | I19: 1924.91 | J19: 0 | K19: 15159.1 | L19: 1924.91 | M19: 3759.26 | N19: 0 | O19: 37072.9 | P19: 0 | Q19: 0 | R19: 4572.32 | S19: 4878.9 | T19: 13133.9 | U19: 0 | V19: 27564.9 | W19: 40053.4 | X19: 0 | Y19: 2829.38 | Z19: 13871.8
A20: 7 | B20: 0 | C20: 20701.1 | D20: 0 | E20: 6400.84 | F20: 0 | G20: 4115.04 | H20: 0 | I20: 0 | J20: 0 | K20: 11716.5 | L20: 0 | M20: 3372.69 | N20: 0 | O20: 39345.8 | P20: 398.922 | Q20: 0 | R20: 9532.41 | S20: 11693.9 | T20: 36578 | U20: 0 | V20: 25921.2 | W20: 39819.4 | X20: 0 | Y20: 3068.63 | Z20: 20677
A21: 8 | B21: 0 | C21: 40053.4 | D21: 0.330034 | E21: 27347.8 | F21: 0.605969 | G21: 701.355 | H21: 0 | I21: 0 | J21: 0 | K21: 11219.1 | L21: 0 | M21: 0 | N21: 0 | O21: 39232 | P21: 136.08 | Q21: 0 | R21: 9979.42 | S21: 18277.2 | T21: 37188.9 | U21: 0 | V21: 39329.3 | W21: 40053.4 | X21: 0 | Y21: 3138.58 | Z21: 22450.5
A22: 9 | B22: 1.46217 | C22: 40053.4 | D22: 1.61082 | E22: 25056.7 | F22: 1.84499 | G22: 213.449 | H22: 0.0784848 | I22: 0 | J22: 0.999548 | K22: 12243.3 | L22: 0 | M22: 0 | N22: 0.500002 | O22: 38665.8 | P22: 178.191 | Q22: 0.0131877 | R22: 8567.34 | S22: 9973.19 | T22: 26712 | U22: 0.0398919 | V22: 36764.3 | W22: 40053.4 | X22: 0.351163 | Y22: 2836.48 | Z22: 27767.4
A23: 10 | B23: 2.53176 | C23: 40053.4 | D23: 2.63938 | E23: 11901.8 | F23: 2.75037 | G23: 89.1079 | H23: 0.550394 | I23: 420.201 | J23: 2.06125 | K23: 9537.11 | L23: 420.201 | M23: 0 | N23: 2.15778 | O23: 39770.8 | P23: 799.375 | Q23: 0.0950285 | R23: 8005.48 | S23: 1342.2 | T23: 13981.4 | U23: 0.319604 | V23: 30737.9 | W23: 40053.4 | X23: 0.866526 | Y23: 1064.22 | Z23: 33457.1
A24: 11 | B24: 3.23997 | C24: 40053.4 | D24: 3.3294 | E24: 6829.85 | F24: 3.28935 | G24: 827.171 | H24: 0.438738 | I24: 1414.32 | J24: 2.87266 | K24: 6493.88 | L24: 1414.32 | M24: 0 | N24: 2.85815 | O24: 40053.4 | P24: 928.596 | Q24: 0.154119 | R24: 8433.19 | S24: 0 | T24: 7415.01 | U24: 0.47243 | V24: 22124.1 | W24: 40053.4 | X24: 1.59269 | Y24: 652.528 | Z24: 36972.2
A25: 12 | B25: 3.60639 | C25: 40053.4 | D25: 3.69076 | E25: 5954.92 | F25: 3.50654 | G25: 67.6955 | H25: 0.880805 | I25: 9082.54 | J25: 3.32056 | K25: 6415.24 | L25: 9082.54 | M25: 536.381 | N25: 3.23221 | O25: 40053.4 | P25: 1090.66 | Q25: 0.308412 | R25: 4722.06 | S25: 0 | T25: 4673.11 | U25: 0.373704 | V25: 17967.4 | W25: 40053.4 | X25: 3.19955 | Y25: 863.181 | Z25: 38083.9
... A8773: 8760 | B8773: 0 | C8773: 2121.96 | D8773: 0 | E8773: 39569.5 | F8773: 0 | G8773: 625.734 | H8773: 0 | I8773: 15096.7 | J8773: 0 | K8773: 36678.7 | L8773: 15096.7 | M8773: 10489.5 | N8773: 0 | O8773: 31119.4 | P8773: 0 | Q8773: 0 | R8773: 25117.9 | S8773: 27766 | T8773: 0 | U8773: 0 | V8773: 40053.4 | W8773: 40053.4 | X8773: 0 | Y8773: 4682.08 | Z8773: 30472.1

Sheet State Peak Hours From NREL
A2: From NREL Electrification Futures Hourly Data (2018)
B4: Year | C4: State | D4: Summer Peak Hour | E4: Summer PeakLoad_MW | F4: Winter Peak Hour | G4: Winter PeakLoad_MW
A5: 4335 | B5: 2018 | C5: AL | D5: 4336 | E5: 16683.372 | F5: 78 | G5: 15463.174
A6: 13839 | B6: 2018 | C6: AR | D6: 5080 | E6: 9039.1163 | F6: 296 | G6: 6757.794
A7: 22816 | B7: 2018 | C7: AZ | D7: 5297 | E7: 16982.046 | F7: 296 | G7: 10157.787
A8: 31696 | B8: 2018 | C8: CA | D8: 5417 | E8: 53175.248 | F8: 8491 | G8: 36912.216
A9: 39281 | B9: 2018 | C9: CO | D9: 4242 | E9: 10023.686 | F9: 8490 | G9: 8649.6892
A10: 48590 | B10: 2018 | C10: CT | D10: 4791 | E10: 6487.0058 | F10: 68 | G10: 4612.6951
A11: 57350 | B11: 2018 | C11: DE | D11: 4791 | E11: 2467.8214 | F11: 80 | G11: 1931.7655
A12: 66302 | B12: 2018 | C12: FL | D12: 4983 | E12: 44005.574 | F12: 79 | G12: 40855.782
A13: 74440 | B13: 2018 | C13: GA | D13: 4361 | E13: 28102.416 | F13: 79 | G13: 24062.208
A14: 83799 | B14: 2018 | C14: IA | D14: 4960 | E14: 9261.9751 | F14: 283 | G14: 7077.8012
A15: 92247 | B15: 2018 | C15: ID | D15: 4648 | E15: 4560.1588 | F15: 272 | G15: 3546.9257
A16: 100863 | B16: 2018 | C16: IL | D16: 4504 | E16: 30588.17 | F16: 451 | G16: 19900.064
... A52: 416372 | B52: 2018 | C52: WY | D52: 4653 | E52: 2685.6806 | F52: 379 | G52: 2662.6141

Sheet CAISO - CF
A3: 2020 ELCC Values and Technology Factors
A4: Non-Dispatchable Solar, Wind, Biomass, Cogeneration, Geothermal, and
A5: Hydro Technology Factors for Compliance Year 2020
B8: Solar PV and Solar Thermal
B9: Month | C9: CY 2020 Solar ELCC
B10: 1 | C10: 0.04
B11: 2 | C11: 0.03
B12: 3 | C12: 0.18
B13: 4 | C13: 0.15
B14: 5 | C14: 0.16
B15: 6 | C15: 0.31
B16: 7 | C16: 0.39
B17: 8 | C17: 0.27
B18: 9 | C18: 0.14
B19: 10 | C19: 0.02
B20: 11 | C20: 0.02
B21: 12 | C21: 0
B24: Wind
B25: Month | C25: CY 2020 Wind ELCC
B26: 1 | C26: 0.14
B27: 2 | C27: 0.12
B28: 3 | C28: 0.28
B29: 4 | C29: 0.25
B30: 5 | C30: 0.25
B31: 6 | C31: 0.33
B32: 7 | C32: 0.23
B33: 8 | C33: 0.21
B34: 9 | C34: 0.15
B35: 10 | C35: 0.08
B36: 11 | C36: 0.12
B37: 12 | C37: 0.13
B47: Biomass
B48: Month | C48: 2016 | D48: 2017 | E48: 2018 | F48: CY 2020 Biomass Factor
B49: 1 | C49: 0.87 | D49: 0.73 | E49: 0.85 | F49: 0.82
B50: 2 | C50: 0.91 | D50: 0.85 | E50: 0.84 | F50: 0.86
B51: 3 | C51: 0.84 | D51: 0.82 | E51: 0.86 | F51: 0.84
B52: 4 | C52: 0.76 | D52: 0.74 | E52: 0.79 | F52: 0.76
B53: 5 | C53: 0.84 | D53: 0.83 | E53: 0.83 | F53: 0.83
B54: 6 | C54: 0.92 | D54: 0.88 | E54: 0.86 | F54: 0.89
B55: 7 | C55: 0.91 | D55: 0.83 | E55: 0.87 | F55: 0.87
...

Sheet ERCOT - CF
B1: PEAK AVERAGE WIND CAPACITY PERCENTAGES, WINTER PEAK SEASONS
J2: WINDPEAKPCT Values (Weighted Averages based on Installed Wind Capacity)*
B3: Winter Peak Ave. Wind Capacity Percentages and Total Unit Capacities | J3: Winter, Panhandle | K3: Winter, Coastal | L3: Winter, Other
B4: Top Twenty Peak Hours for Each year | J4: =SUMPRODUCT(C7:C16,D7:D16)/SUM(D7:D16) | K4: =SUMPRODUCT(E7:E16,F7:F16)/SUM(F7:F16) | L4: =SUMPRODUCT(G7:G16,H7:H16)/SUM(H7:H16)
B5: CDR Wind Region | C5: Panhandle | E5: Coastal | G5: Other
B6: Year | C6: Capacity Contribution Percentage | D6: Capacity (MW) | E6: Capacity Contribution Percentage | F6: Capacity (MW) | G6: Capacity Contribution Percentage | H6: Capacity (MW) | J6: * The methodology for calculating WINDPEAKPCT values is outlined in ERCOT Protocol Section 3.2.6.2.2. See: http://www.ercot.com/content/wcm/current_guides/53528/03-030120_Nodal.docx
B7: 2019-2020 | C7: 0.38116302 | D7: 4197.6 | E7: 0.33964313 | F7: 2974.4 | G7: 0.27527403 | H7: 15598.8
B8: 2018-2019 | C8: 0.39806301 | D8: 4197 | E8: 0.39119188 | F8: 2610.6 | G8: 0.20963421 | H8: 14730.2
B9: 2017-2018 | C9: 0.33292465 | D9: 4197 | E9: 0.51881614 | F9: 2382.6 | G9: 0.14262171 | H9: 11996.3
B10: 2016-2017 | C10: 0.19940455 | D10: 3609 | E10: 0.79338515 | F10: 2038.4 | G10: 0.14286179 | H10: 10821.7
B11: 2015-2016 | C11: 0.28446769 | D11: 2670.5 | E11: 0.27016577 | F11: 1875.4 | G11: 0.2844107 | H11: 10494.9
B12: 2014-2015 | C12: 0.22712979 | D12: 207 | E12: 0.42284952 | F12: 1671.4 | G12: 0.10700787 | H12: 8858.8
B13: 2013-2014 | C13: 0.36173637 | D13: 207 | E13: 0.43660053 | F13: 1269.7 | G13: 0.17265001 | H13: 8789.4
B14: 2012-2013 | C14: 0.23047625 | D14: 207 | E14: 0.32465499 | F14: 1066.4 | G14: 0.16685321 | H14: 7999.2
B15: 2011-2012 | C15: 0.38469327 | D15: 207 | E15: 0.15738836 | F15: 965.6 | G15: 0.20275638 | H15: 7670.7
B16: 2010-2011 | C16: 0.34467367 | D16: 206.957 | E16: 0.48410488 | F16: 965.55 | G16: 0.14303803 | H16: 8023.935
B19: PEAK AVERAGE SOLAR CAPACITY PERCENTAGES, WINTER PEAK SEASONS
F21: SOLARPEAKPCT Value (Weighted Average based on Installed Solar Capacity) *
B22: Winter Peak Ave. Solar Capacity Percentages and Total Unit Capacities | F22: Winter
B23: Top Twenty Peak Hours for Each year | F23: =SUMPRODUCT(C25:C27,D25:D27)/SUM(D25:D27)
B24: Year | C24: Capacity Contribution Percentage | D24: Capacity (MW)
B25: 2019/2020 | C25: 0.03868493 | D25: 2020.2
B26: 2018/2019 | C26: 0.091846314 | D26: 1404
B27: 2017/2018 | C27: 0.098614238 | D27: 928.7 | F27: * The methodology for calculating SOLARPEAKPCT values is outlined in ERCOT Protocol Section 3.2.6.2.2. See: http://www.ercot.com/content/wcm/current_guides/53528/03-030120_Nodal.docx
B32: PEAK AVERAGE SOLAR CAPACITY PERCENTAGES, SUMMER PEAK SEASONS
B34: Summer Peak Ave. Solar Capacity Percentages
B35: Top Twenty Peak Hours for Each year | F35: SOLARPEAKPCT Values *
B36: Year | C36: Average Solar Cap Percentage | D36: MW Solar Capacity | F36: =SUMPRODUCT(C37:C39,D37:D39)/SUM(D37:D39)
B37: 2019 | C37: 0.73991125 | D37: 1636
B38: 2018 | C38: 0.796 | D38: 1254
B39: 2017 | C39: 0.759 | D39: 715.8
B42: PEAK AVERAGE WIND CAPACITY PERCENTAGES, SUMMER PEAK SEASONS
J43: WINDPEAKPCT Values *
B44: Summer Peak Ave. Wind Capacity Percentages and Total Unit Capacities | J44: Summer, Panhandle | K44: Summer, Coastal | L44: Summer, Other
B45: Top Twenty Peak Hours for Each year | J45: =SUMPRODUCT(C48:C57,D48:D57)/SUM(D48:D57) | K45: =SUMPRODUCT(E48:E57,F48:F57)/SUM(F48:F57) | L45: =SUMPRODUCT(G48:G57,H48:H57)/SUM(H48:H57)
B46: CDR Wind Region | C46: Panhandle | E46: Coastal | G46: Other
B47: Year | C47: Capacity Contribution Percentage | D47: Capacity (MW) | E47: Capacity Contribution Percentage | F47: Capacity (MW) | G47: Capacity Contribution Percentage | H47: Capacity (MW) | J47: * The methodology for calculating WINDPEAKPCT values is outlined in ERCOT Protocol Section 3.2.6.2.2. See: http://www.ercot.com/content/wcm/current_guides/53528/03-101819_Nodal.docx
B48: 2019 | C48: 0.34116316 | D48: 4197 | E48: 0.75046787 | F48: 2811.6 | G48: 0.2215483 | H48: 14949.9
B49: 2018 | C49: 0.25601249 | D49: 4197 | E49: 0.52912899 | F49: 2610.6 | G49: 0.17106233 | H49: 14289.9
B50: 2017 | C50: 0.24883959 | D50: 3171.2 | E50: 0.62928179 | F50: 2038.4 | G50: 0.20176401 | H50: 12241.2
...

Sheet WECC
A1: Released: November 2017
A2: Next Update: November 2018
A4: Table 3B.1. WECC monthly peak hour demand, by North American Electric Reliability Corporation Assesment Area,
A5: 1996-2016 actual, 2017-2018 projected
A6: megawatts
A8: WECC | B8: Year | C8: January | D8: February | E8: March | F8: April | G8: May | H8: June | I8: July | J8: August | K8: September | L8: October | M8: November | N8: December
A9: Actual | B9: 1996 | C9: 95306 | D9: 94878 | E9: 86486 | F9: 89912 | G9: 91930 | H9: 99203 | I9: 108739 | J9: 107790 | K9: 98006 | L9: 95427 | M9: 87466 | N9: 94331
B10: 1997 | C10: 95886 | D10: 89483 | E10: 89505 | F10: 88124 | G10: 99796 | H10: 98340 | I10: 104361 | J10: 110001 | K10: 105659 | L10: 95236 | M10: 89470 | N10: 93132
B11: 1998 | C11: 95102 | D11: 90267 | E11: 89009 | F11: 88242 | G11: 84051 | H11: 97617 | I11: 111830 | J11: 115921 | K11: 112705 | L11: 92543 | M11: 88524 | N11: 101822
B12: 1999 | C12: 91641 | D12: 91773 | E12: 87599 | F12: 87821 | G12: 91165 | H12: 105404 | I12: 113629 | J12: 109873 | K12: 102526 | L12: 96329 | M12: 90741 | N12: 96875
B13: 2000 | C13: 95673 | D13: 91627 | E13: 91044 | F13: 94250 | G13: 104053 | H13: 111600 | I13: 114472 | J13: 114602 | K13: 107797 | L13: 97398 | M13: 95483 | N13: 97324
B14: 2001 | C14: 96766 | D14: 93801 | E14: 87641 | F14: 90023 | G14: 100484 | H14: 105427 | I14: 108629 | J14: 109119 | K14: 101320 | L14: 97762 | M14: 91851 | N14: 95286
B15: 2002 | C15: 96555 | D15: 93195 | E15: 90041 | F15: 88714 | G15: 104110 | H15: 111108 | I15: 119074 | J15: 114763 | K15: 111475 | L15: 99967 | M15: 92834 | N15: 95951
B16: 2003 | C16: 92602 | D16: 93831 | E16: 91002 | F16: 89713 | G16: 110358 | H16: 112627 | I16: 122537 | J16: 119473 | K16: 113594 | L16: 103327 | M16: 94291 | N16: 99793
B17: 2004 | C17: 102049 | D17: 95546 | E17: 95191 | F17: 101654 | G17: 105503 | H17: 111143 | I17: 123136 | J17: 122922 | K17: 116784 | L17: 96429 | M17: 100001 | N17: 101541
B18: 2005 | C18: 102464 | D18: 96789 | E18: 90859 | F18: 90623 | G18: 106680 | H18: 115821 | I18: 130760 | J18: 125253 | K18: 113824 | L18: 101470 | M18: 100361 | N18: 107493
B19: 2006 | C19: 99571 | D19: 101154 | E19: 97101 | F19: 93098 | G19: 110713 | H19: 129742 | I19: 142096 | J19: 127749 | K19: 122420 | L19: 103797 | M19: 107335 | N19: 108617
B20: 2007 | C20: 107097 | D20: 101215 | E20: 98234 | F20: 98980 | G20: 107541 | H20: 126064 | I20: 137488 | J20: 139389 | K20: 128226 | L20: 99594 | M20: 100700 | N20: 109607
B21: 2008 | C21: 110395 | D21: 104200 | E21: 97743 | F21: 106357 | G21: 120959 | H21: 134781 | I21: 134052 | J21: 134829 | K21: 122386 | L21: 115877 | M21: 100056 | N21: 113605
... B29: 2016 | C29: 100315 | D29: 99421 | E29: 91447 | F29: 92268 | G29: 103561 | H29: 133247 | I29: 139431 | J29: 131343 | K29: 115093 | L29: 96692 | M29: 96181 | N29: 10400
A30: Projected | B30: 2017E | C30: 104737 | D30: 102180 | E30: 98101 | F30: 93343 | G30: 108475 | H30: 125996 | I30: 131791 | J30: 133410 | K30: 125256 | L30: 104962 | M30: 102551 | N30: 110022
B31: 2018E | C31: 105492 | D31: 102228 | E31: 97638 | F31: 94039 | G31: 109456 | H31: 128140 | I31: 132648 | J31: 132558 | K31: 127899 | L31: 106243 | M31: 102527 | N31: 110955
Q37: https://www.nrel.gov/docs/fy15osti/64879.pdf
Q38: PG 9
Q39: Note: RMPA = CO, WY
Q40: Basin = Idaho, Northern Nevada, Utah

Sheet TRE
A1: Released: November 2017
A2: Next Update: November 2018
A4: Table 3B.1. TRE monthly peak hour demand, by North American Electric Reliability Corporation Assesment Area,
A5: 1996-2016 actual, 2017-2018 projected
A6: megawatts
A8: TRE | B8: Year | C8: January | D8: February | E8: March | F8: April | G8: May | H8: June | I8: July | J8: August | K8: September | L8: October | M8: November | N8: December
A9: Actual | B9: 1996 | C9: 36818 | D9: 37705 | E9: 34540 | F9: 35326 | G9: 43742 | H9: 46524 | I9: 47240 | J9: 46807 | K9: 41733 | L9: 34958 | M9: 34597 | N9: 39214
B10: 1997 | C10: 41280 | D10: 33120 | E10: 31783 | F10: 34216 | G10: 40857 | H10: 45687 | I10: 49705 | J10: 50468 | K10: 49005 | L10: 43533 | M10: 33624 | N10: 36458
B11: 1998 | C11: 35906 | D11: 33703 | E11: 36836 | F11: 35731 | G11: 48676 | H11: 52259 | I11: 53440 | J11: 54666 | K11: 51981 | L11: 46869 | M11: 32616 | N11: 40566
B12: 1999 | C12: 39537 | D12: 34343 | E12: 33383 | F12: 41080 | G12: 43529 | H12: 49628 | I12: 52925 | J12: 55529 | K12: 50447 | L12: 43706 | M12: 33615 | N12: 36685
B13: 2000 | C13: 39075 | D13: 34779 | E13: 38040 | F13: 40399 | G13: 50347 | H13: 49577 | I13: 55767 | J13: 57606 | K13: 57099 | L13: 47781 | M13: 35563 | N13: 44641
B14: 2001 | C14: 42995 | D14: 35091 | E14: 34090 | F14: 37017 | G14: 44606 | H14: 50918 | I14: 54846 | J14: 55201 | K14: 50073 | L14: 40796 | M14: 41608 | N14: 36557
B15: 2002 | C15: 43901 | D15: 43837 | E15: 43964 | F15: 49064 | G15: 49018 | H15: 51882 | I15: 54891 | J15: 56248 | K15: 51556 | L15: 49105 | M15: 35901 | N15: 40650
B16: 2003 | C16: 45433 | D16: 43498 | E16: 37554 | F16: 40579 | G16: 52909 | H16: 53637 | I16: 56251 | J16: 59996 | K16: 49502 | L16: 42651 | M16: 38608 | N16: 40782
B17: 2004 | C17: 42698 | D17: 42301 | E17: 34321 | F17: 39131 | G17: 48702 | H17: 54061 | I17: 56489 | J17: 58531 | K17: 55179 | L17: 47714 | M17: 37599 | N17: 44010
B18: 2005 | C18: 40966 | D18: 41095 | E18: 36115 | F18: 41219 | G18: 51947 | H18: 58140 | I18: 57319 | J18: 60210 | K18: 59524 | L18: 52107 | M18: 42470 | N18: 47948
B19: 2006 | C19: 38604 | D19: 43210 | E19: 38257 | F19: 51800 | G19: 54175 | H19: 57887 | I19: 61660 | J19: 62339 | K19: 56603 | L19: 50890 | M19: 45143 | N19: 46896
B20: 2007 | C20: 50404 | D20: 50408 | E20: 38827 | F20: 41710 | G20: 49222 | H20: 56427 | I20: 56754 | J20: 62188 | K20: 55091 | L20: 54102 | M20: 39993 | N20: 44443
B21: 2008 | C21: 46099 | D21: 45321.168 | E21: 42412.086 | F21: 45872.209 | G21: 56343.9 | H21: 59642.121 | I21: 61119.607 | J21: 62174.377 | K21: 56342.604 | L21: 46574.727 | M21: 38746.451 | N21: 47805.655
... B29: 2016 | C29: 49262.558 | D29: 47416.492 | E29: 43347.187 | F29: 50932.083 | G29: 57223.827 | H29: 64896.26 | I29: 67468.932 | J29: 71110.104 | K29: 66948.566 | L29: 59864.268 | M29: 50012.351 | N29: 57932.433
A30: Projected | B30: 2017E | C30: 54417.089 | D30: 52494.977 | E30: 46877.756 | F30: 51622.356 | G30: 58907.858 | H30: 66915.332 | I30: 68657.3 | J30: 72933.55 | K30: 64448.591 | L30: 56096.829 | M30: 45791.007 | N30: 52669.431
B31: 2018E | C31: 55003.088 | D31: 53084.39 | E31: 47485.515 | F31: 52357.575 | G31: 59695.215 | H31: 67905.306 | I31: 69666.623 | J31: 74149.387 | K31: 65482.963 | L31: 57090.494 | M31: 46784.411 | N31: 53494.896

Sheet MISO
A1: Released: November 2017
A2: Next Update: November 2018
A4: Table 3B.1. MISO monthly peak hour demand, by North American Electric Reliability Corporation Assesment Area,
A5: 1996-2016 actual, 2017-2018 projected
A6: megawatts
A8: MISO | B8: Year | C8: January | D8: February | E8: March | F8: April | G8: May | H8: June | I8: July | J8: August | K8: September | L8: October | M8: November | N8: December
A9: Actual | B9: 1996 | C9: NA | D9: NA | E9: NA | F9: NA | G9: NA | H9: NA | I9: NA | J9: NA | K9: NA | L9: NA | M9: NA | N9: NA
B10: 1997 | C10: NA | D10: NA | E10: NA | F10: NA | G10: NA | H10: NA | I10: NA | J10: NA | K10: NA | L10: NA | M10: NA | N10: NA
B11: 1998 | C11: NA | D11: NA | E11: NA | F11: NA | G11: NA | H11: NA | I11: NA | J11: NA | K11: NA | L11: NA | M11: NA | N11: NA
B12: 1999 | C12: NA | D12: NA | E12: NA | F12: NA | G12: NA | H12: NA | I12: NA | J12: NA | K12: NA | L12: NA | M12: NA | N12: NA
B13: 2000 | C13: NA | D13: NA | E13: NA | F13: NA | G13: NA | H13: NA | I13: NA | J13: NA | K13: NA | L13: NA | M13: NA | N13: NA
B14: 2001 | C14: NA | D14: NA | E14: NA | F14: NA | G14: NA | H14: NA | I14: NA | J14: NA | K14: NA | L14: NA | M14: NA | N14: NA
B15: 2002 | C15: NA | D15: NA | E15: NA | F15: NA | G15: NA | H15: NA | I15: NA | J15: NA | K15: NA | L15: NA | M15: NA | N15: NA
B16: 2003 | C16: NA | D16: NA | E16: NA | F16: NA | G16: NA | H16: NA | I16: NA | J16: NA | K16: NA | L16: NA | M16: NA | N16: NA
B17: 2004 | C17: NA | D17: NA | E17: NA | F17: NA | G17: NA | H17: NA | I17: NA | J17: NA | K17: NA | L17: NA | M17: NA | N17: NA
B18: 2005 | C18: NA | D18: NA | E18: NA | F18: NA | G18: NA | H18: NA | I18: NA | J18: NA | K18: NA | L18: NA | M18: NA | N18: NA
B19: 2006 | C19: NA | D19: NA | E19: NA | F19: NA | G19: NA | H19: NA | I19: NA | J19: NA | K19: NA | L19: NA | M19: NA | N19: NA
B20: 2007 | C20: NA | D20: NA | E20: NA | F20: NA | G20: NA | H20: NA | I20: NA | J20: NA | K20: NA | L20: NA | M20: NA | N20: NA
B21: 2008 | C21: NA | D21: NA | E21: NA | F21: NA | G21: NA | H21: NA | I21: NA | J21: NA | K21: NA | L21: NA | M21: NA | N21: NA
B22: 2009 | C22: NA | D22: NA | E22: NA | F22: NA | G22: NA | H22: NA | I22: NA | J22: NA | K22: NA | L22: NA | M22: NA | N22: NA
B23: 2010 | C23: 85264.71 | D23: 81835.57 | E23: 74562.29 | F23: 69824.01 | G23: 92068.42 | H23: 98927.17 | I23: 104024.22 | J23: 108346.11 | K23: 93747.63 | L23: 73309.84 | M23: 79454.15 | N23: 90848.02
B24: 2011 | C24: 85965.69 | D24: 87676.94 | E24: 76964.05 | F24: 68204.943 | G24: 75208.682 | H24: 91832.35 | I24: 98067.621 | J24: 96870.964 | K24: 87569.553 | L24: 71648.493 | M24: 72383.362 | N24: 79051.785
B25: 2012 | C25: 70600 | D25: 67013 | E25: 63375 | F25: 58449 | G25: 70656 | H25: 92955 | I25: 96769 | J25: 89327 | K25: 83877 | L25: 61312 | M25: 66201 | N25: 69270
B26: 2013 | C26: 93797.6 | D26: 92559.6 | E26: 85284.1 | F26: 79153.6 | G26: 98121.9 | H26: 110585.9 | I26: 121124.3 | J26: 117842.9 | K26: 115803.6 | L26: 89798.7 | M26: 90021 | N26: 95803.3
B27: 2014 | C27: 107927.3 | D27: 101304.4 | E27: 96058.7 | F27: 80236 | G27: 92600.3 | H27: 109196.2 | I27: 113506.9 | J27: 113429.2 | K27: 109527.4 | L27: 87007 | M27: 95703 | N27: 91339
