Workbook
Name IQ_CH: 110000
Name IQ_CQ: 5000
Name IQ_CY: 10000
Name IQ_DAILY: 500000
Name IQ_FH: 100000
Name IQ_FQ: 500
Name IQ_FY: 1000
Name IQ_LTM: 2000
Name IQ_MONTH: 15000
Name IQ_NTM: 6000
Name IQ_WEEK: 50000
Name IQ_YTD: 3000
Name Net_Generation_by_State__Type_1: #REF!
Name Net_Generation_by_State__Type_of_Producer__Energy_Source: #REF!

Sheet About
A1: BRPSPTY BAU Renewable Portfolio Std Percentage This Year | B1: Nebraska | C1: 44820 | F1: State | G1: State
B2: =LOOKUP(B1,F2:G51,G2:G51) -> NE | F2: Alabama | G2: AL
A3: Sources: | B3: RPS Laws by State | F3: Alaska | G3: AK
A4: (updated 9/15/22) | B4: Database of State Incentives for Renewables & Efficiency | F4: Arizona | G4: AZ
B5: 2021 | F5: Arkansas | G5: AR
B6: Program Type: Renewables Portfolio Standard | F6: California | G6: CA
B7: http://programs.dsireusa.org/system/program | F7: Colorado | G7: CO
F8: Connecticut | G8: CT
B9: National Conference of State Legislatures | F9: Delaware | G9: DE
B10: 2021 | F10: Florida | G10: FL
B11: State Renewable Porfolio Standards and Goals | F11: Georgia | G11: GA
B12: https://www.ncsl.org/research/energy/renewable-portfolio-standards.aspx | F12: Hawaii | G12: HI
F13: Idaho | G13: ID
B14: Generation by Utility Type (IOU, Coop, Muni, etc.) | F14: Illinois | G14: IL
B15: Energy Information Administration | F15: Indiana | G15: IN
B16: 2020 | F16: Iowa | G16: IA
B17: Electric Sales, Revenue, and Average Price | F17: Kansas | G17: KS
B18: https://www.eia.gov/electricity/sales_revenue_price/ | F18: Kentucky | G18: KY
B19: Table 10 | F19: Louisiana | G19: LA
F20: Maine | G20: ME
B21: Texas & Minnesota Generating Capacity | F21: Maryland | G21: MD
B22: Energy Information Administration | F22: Massachusetts | G22: MA
B23: 2019 | F23: Michigan | G23: MI
B24: State Electricity Profiles | F24: Minnesota | G24: MN
B25: https://www.eia.gov/electricity/state/ | F25: Mississippi | G25: MS
F26: Missouri | G26: MO
B27: State Shares of Nuclear and Hydro Generation | F27: Montana | G27: MT
B28: Energy Information Administration | F28: Nebraska | G28: NE
B29: 2020 (data vintage 2018) | F29: Nevada | G29: NV
B30: Detailed State Data | F30: New Hampshire | G30: NH
B31: Net Generation by State by Type of Producer by Energy Source | F31: New Jersey | G31: NJ
B32: https://www.eia.gov/electricity/data/state/ | F32: New Mexico | G32: NM
F33: New York | G33: NY
A34: Note: | F34: North Carolina | G34: NC
A35: The purpose of this variable is to specify the renewable portfolio standard | F35: North Dakota | G35: ND
A36: requirement that must be met in the BAU case (which the user may increase | F36: Ohio | G36: OH
A37: via a policy lever, affecting the policy case). | F37: Oklahoma | G37: OK
F38: Oregon | G38: OR
A39: In the United States, we set this to be a clean energy standard (CES). The CES is set at the state level, so we take a | F39: Pennsylvania | G39: PA
A40: generation-weighted average of state-level enacted CES levels. | F40: Rhode Island | G40: RI
...

Sheet RPS by State
G1: Annual Schedule Based on Interpretation of Law and Assumptions
A2: State | B2: Abbr. | C2: RPS Law Text | D2: Includes nuclear? | E2: Includes hydro? | F2: 2020 (start year) Sales (MWh) | G2: 2014 | H2: 2015 | I2: 2016 | J2: 2017 | K2: 2018 | L2: 2019 | M2: 2020 | N2: 2021 | O2: 2022 | P2: 2023 | Q2: 2024 | R2: 2025 | S2: 2026 | T2: 2027 | U2: 2028 | V2: 2029 | W2: 2030 | X2: 2031 | Y2: 2032 | Z2: 2033 | AA2: 2034 | AB2: 2035 | AC2: 2036 | AD2: 2037 | AE2: 2038 | AF2: 2039 | AG2: 2040 | AH2: 2041 | AI2: 2042 | AJ2: 2043 | AK2: 2044 | AL2: 2045 | AM2: 2046 | AN2: 2047 | AO2: 2048 | AP2: 2049 | AQ2: 2050
A3: Alabama | B3: AL | F3: =SUMIFS('EIA 2020 ESRAP Table 10'!E:E,'EIA 2020 ESRAP Table 10'!B:B,B3) -> 83378325 | G3: 0 | H3: 0 | I3: 0 | J3: 0 | K3: 0 | L3: 0 | M3: 0 | N3: 0 | O3: 0 | P3: 0 | Q3: 0 | R3: 0 | S3: 0 | T3: 0 | U3: 0 | V3: 0 | W3: 0 | X3: 0 | Y3: 0 | Z3: 0 | AA3: 0 | AB3: 0 | AC3: 0 | AD3: 0 | AE3: 0 | AF3: 0 | AG3: 0 | AH3: 0 | AI3: 0 | AJ3: 0 | AK3: 0 | AL3: 0 | AM3: 0 | AN3: 0 | AO3: 0 | AP3: 0 | AQ3: 0
A4: Alaska | B4: AK | F4: =SUMIFS('EIA 2020 ESRAP Table 10'!E:E,'EIA 2020 ESRAP Table 10'!B:B,B4) -> 6005515 | G4: 0 | H4: 0 | I4: 0 | J4: 0 | K4: 0 | L4: 0 | M4: 0 | N4: 0 | O4: 0 | P4: 0 | Q4: 0 | R4: 0 | S4: 0 | T4: 0 | U4: 0 | V4: 0 | W4: 0 | X4: 0 | Y4: 0 | Z4: 0 | AA4: 0 | AB4: 0 | AC4: 0 | AD4: 0 | AE4: 0 | AF4: 0 | AG4: 0 | AH4: 0 | AI4: 0 | AJ4: 0 | AK4: 0 | AL4: 0 | AM4: 0 | AN4: 0 | AO4: 0 | AP4: 0 | AQ4: 0
A5: Arizona | B5: AZ | C5: Specific percentages defined for each year through 2025 (see schedule at right) | F5: =SUMIFS('EIA 2020 ESRAP Table 10'!E:E,'EIA 2020 ESRAP Table 10'!B:B,B5) -> 81867671 | G5: 0.045 | H5: 0.05 | I5: 0.06 | J5: 0.07 | K5: 0.08 | L5: 0.09 | M5: 0.1 | N5: 0.11 | O5: 0.12 | P5: 0.13 | Q5: 0.14 | R5: 0.15 | S5: =$R5 -> 0.15 | T5: =$R5 -> 0.15 | U5: =$R5 -> 0.15 | V5: =$R5 -> 0.15 | W5: =$R5 -> 0.15 | X5: =$R5 -> 0.15 | Y5: =$R5 -> 0.15 | Z5: =$R5 -> 0.15 | ... AQ5: =$R5 -> 0.15
A6: Arkansas | B6: AR | F6: =SUMIFS('EIA 2020 ESRAP Table 10'!E:E,'EIA 2020 ESRAP Table 10'!B:B,B6) -> 45817238 | G6: 0 | H6: 0 | I6: 0 | J6: 0 | K6: 0 | L6: 0 | M6: 0 | N6: 0 | O6: 0 | P6: 0 | Q6: 0 | R6: 0 | S6: 0 | T6: 0 | U6: 0 | V6: 0 | W6: 0 | X6: 0 | Y6: 0 | Z6: 0 | AA6: 0 | AB6: 0 | AC6: 0 | AD6: 0 | AE6: 0 | AF6: 0 | AG6: 0 | AH6: 0 | AI6: 0 | AJ6: 0 | AK6: 0 | AL6: 0 | AM6: 0 | AN6: 0 | AO6: 0 | AP6: 0 | AQ6: 0
A7: California | B7: CA | C7: 20% in 2013, 25% in 2016, 33% in 2020, 44% in 2024, 52% in 2027, 60% in 2030. Executive order calls for 100% clean electricity by 2045. Applies to IOUs and municipal utilities | D7: 2045 target does, but Diablo Canyon will be retiring | E7: 2045 target does | F7: =SUMIFS('EIA 2020 ESRAP Table 10'!E:E,'EIA 2020 ESRAP Table 10'!B:B,B7) -> 177488484 | G7: =(0.25-0.2)/3+0.2 -> 0.21666667 | H7: =$G7+($I7-$G7)*(H$2-$G$2)/($I$2-$G$2) -> 0.21827761 | I7: =25%*SUM('Extra State Data'!B66:B67)/'Extra State Data'!B68 -> 0.21988855 | J7: =$I7+($M7-$I7)*(J$2-$I$2)/($M$2-$I$2) -> 0.23747964 | K7: =$I7+($M7-$I7)*(K$2-$I$2)/($M$2-$I$2) -> 0.25507072 | L7: =$I7+($M7-$I7)*(L$2-$I$2)/($M$2-$I$2) -> 0.27266181 | M7: =33%*SUM('Extra State Data'!B66:B67)/'Extra State Data'!B68 -> 0.29025289 | N7: =$M7+($Q7-$M7)*(N$2-$M$2)/($Q$2-$M$2) -> 0.31444063 | O7: =$M7+($Q7-$M7)*(O$2-$M$2)/($Q$2-$M$2) -> 0.33862837 | P7: =$M7+($Q7-$M7)*(P$2-$M$2)/($Q$2-$M$2) -> 0.36281611 | Q7: =44%*SUM('Extra State Data'!B66:B67)/'Extra State Data'!B68 -> 0.38700385 | R7: =$Q7+($T7-$Q7)*(R$2-$Q$2)/($T$2-$Q$2) -> 0.41045863 | S7: =$Q7+($T7-$Q7)*(S$2-$Q$2)/($T$2-$Q$2) -> 0.43391341 | T7: =52%*SUM('Extra State Data'!B66:B67)/'Extra State Data'!B68 -> 0.45736819 | U7: =$T7+($W7-$T7)*(U$2-$T$2)/($W$2-$T$2) -> 0.48082297 | V7: =$T7+($W7-$T7)*(V$2-$T$2)/($W$2-$T$2) -> 0.50427775 | W7: =60%*SUM('Extra State Data'!B66:B67)/'Extra State Data'!B68 -> 0.52773253 | X7: =($AL$7-$W$7)/COUNT($X$2:$AL$2)+W7 -> 0.55118731 | Y7: =($AL$7-$W$7)/COUNT($X$2:$AL$2)+X7 -> 0.57464208 | Z7: =($AL$7-$W$7)/COUNT($X$2:$AL$2)+Y7 -> 0.59809686 | AA7: =($AL$7-$W$7)/COUNT($X$2:$AL$2)+Z7 -> 0.62155164 | AB7: =($AL$7-$W$7)/COUNT($X$2:$AL$2)+AA7 -> 0.64500642 | AC7: =($AL$7-$W$7)/COUNT($X$2:$AL$2)+AB7 -> 0.6684612 | AD7: =($AL$7-$W$7)/COUNT($X$2:$AL$2)+AC7 -> 0.69191598 | AE7: =($AL$7-$W$7)/COUNT($X$2:$AL$2)+AD7 -> 0.71537076 | ... AK7: =($AL$7-$W$7)/COUNT($X$2:$AL$2)+AJ7 -> 0.85609943 | AL7: =100%*SUM('Extra State Data'!B66:B67)/'Extra State Data'!B68 -> 0.87955421 | AM7: =AL7 -> 0.87955421 | AN7: =AM7 -> 0.87955421 | AO7: =AN7 -> 0.87955421 | AP7: =AO7 -> 0.87955421 | AQ7: =AP7 -> 0.87955421
A8: Colorado | B8: CO | C8: IOUS: 12% (2011-2014), 20% (2015-2019), 30% (2020). Munis and small coops: 3% (2011-2014), 6% (2015-2019), 10% (2020). Large coops: 3% (2011-2014), 6% (2015-2019), 20% (2020). 100% clean energy by 2050 for utilities serving 500,000 or more customers | F8: =SUMIFS('EIA 2020 ESRAP Table 10'!E:E,'EIA 2020 ESRAP Table 10'!B:B,B8) -> 55965153 | G8: =(0.12*'Extra State Data'!B18+0.03*SUM('Extra State Data'!B19:B20))/SUM('Extra State Data'!B18:B20) -> 0.080983742 | H8: =(0.2*'Extra State Data'!B18+0.06*SUM('Extra State Data'!B19:B20))/SUM('Extra State Data'!B18:B20) -> 0.13930804 | I8: =$H8+($M8-$H8)*(I$2-$H$2)/($M$2-$H$2) -> 0.15844102 | J8: =$H8+($M8-$H8)*(J$2-$H$2)/($M$2-$H$2) -> 0.17757399 | K8: =$H8+($M8-$H8)*(K$2-$H$2)/($M$2-$H$2) -> 0.19670696 | L8: =$H8+($M8-$H8)*(L$2-$H$2)/($M$2-$H$2) -> 0.21583993 | M8: =(0.3*'Extra State Data'!B18+0.15*SUM('Extra State Data'!B19:B20))/SUM('Extra State Data'!B18:B20) -> 0.2349729 | N8: =($AQ$8-$M$8)/COUNT($N$2:$AQ$2)+M8 -> 0.24459805 | O8: =($AQ$8-$M$8)/COUNT($N$2:$AQ$2)+N8 -> 0.25422319 | P8: =($AQ$8-$M$8)/COUNT($N$2:$AQ$2)+O8 -> 0.26384834 | Q8: =($AQ$8-$M$8)/COUNT($N$2:$AQ$2)+P8 -> 0.27347348 | R8: =($AQ$8-$M$8)/COUNT($N$2:$AQ$2)+Q8 -> 0.28309863 | S8: =($AQ$8-$M$8)/COUNT($N$2:$AQ$2)+R8 -> 0.29272377 | T8: =($AQ$8-$M$8)/COUNT($N$2:$AQ$2)+S8 -> 0.30234892 | U8: =($AQ$8-$M$8)/COUNT($N$2:$AQ$2)+T8 -> 0.31197406 | ... AP8: =($AQ$8-$M$8)/COUNT($N$2:$AQ$2)+AO8 -> 0.5141021 | AQ8: =1*('Extra State Data'!B21/'Extra State Data'!B22) -> 0.52372725
A9: Connecticut | B9: CT | C9: Specific percentages defined for each year through 2020 (see schedule at right; reflects class I, II, and III total) | F9: =SUMIFS('EIA 2020 ESRAP Table 10'!E:E,'EIA 2020 ESRAP Table 10'!B:B,B9) -> 14001202 | G9: 0.18 | H9: 0.195 | I9: 0.21 | J9: 0.225 | K9: 0.25 | L9: 0.275 | M9: 0.29 | N9: 0.305 | O9: 0.32 | P9: 0.34 | Q9: 0.36 | R9: 0.38 | S9: =($W$9-$R$9)/COUNT($S$2:$W$2)+R9 -> 0.4 | T9: =($W$9-$R$9)/COUNT($S$2:$W$2)+S9 -> 0.42 | U9: =($W$9-$R$9)/COUNT($S$2:$W$2)+T9 -> 0.44 | V9: =($W$9-$R$9)/COUNT($S$2:$W$2)+U9 -> 0.46 | W9: 0.48 | X9: =$M9 -> 0.29 | Y9: =$M9 -> 0.29 | Z9: =$M9 -> 0.29 | AA9: =$M9 -> 0.29 | AB9: =$M9 -> 0.29 | AC9: =$M9 -> 0.29 | AD9: =$M9 -> 0.29 | AE9: =$M9 -> 0.29 | ... AQ9: =$M9 -> 0.29
A10: Delaware | B10: DE | C10: Specific percentages defined for each year through 2025 (see schedule at right) | F10: =SUMIFS('EIA 2020 ESRAP Table 10'!E:E,'EIA 2020 ESRAP Table 10'!B:B,B10) -> 7070213 | G10: 0.115 | H10: 0.13 | I10: 0.145 | J10: 0.16 | K10: 0.175 | L10: 0.19 | M10: 0.2 | N10: 0.21 | O10: 0.22 | P10: 0.23 | Q10: 0.24 | R10: 0.25 | S10: =$R10 -> 0.25 | T10: =$R10 -> 0.25 | U10: =$R10 -> 0.25 | V10: =$R10 -> 0.25 | W10: =$R10 -> 0.25 | X10: =$R10 -> 0.25 | Y10: =$R10 -> 0.25 | Z10: =$R10 -> 0.25 | ... AQ10: =$R10 -> 0.25
A11: Florida | B11: FL | C11: 7.5% by 2015 for JEA | F11: =SUMIFS('EIA 2020 ESRAP Table 10'!E:E,'EIA 2020 ESRAP Table 10'!B:B,B11) -> 242429912 | G11: =0.15*SUMIFS('EIA 2020 ESRAP Table 10'!$E$4:$E$2216,'EIA 2020 ESRAP Table 10'!B4:B2216,"FL",'EIA 2020 ESRAP Table 10'!A4:A2216,"JEA")/SUMIF('EIA 2020 ESRAP Table 10'!B4:B2216,"FL",'EIA 2020 ESRAP Table 10'!E4:E2216) -> 0.0074721225 | H11: =G11 -> 0.0074721225 | I11: =H11 -> 0.0074721225 | J11: =I11 -> 0.0074721225 | K11: =J11 -> 0.0074721225 | L11: =K11 -> 0.0074721225 | M11: =L11 -> 0.0074721225 | N11: =M11 -> 0.0074721225 | O11: =N11 -> 0.0074721225 | ... AQ11: =AP11 -> 0.0074721225
A12: Georgia | B12: GA | F12: =SUMIFS('EIA 2020 ESRAP Table 10'!E:E,'EIA 2020 ESRAP Table 10'!B:B,B12) -> 133483545 | G12: 0 | H12: 0 | I12: 0 | J12: 0 | K12: 0 | L12: 0 | M12: 0 | N12: 0 | O12: 0 | P12: 0 | Q12: 0 | R12: 0 | S12: 0 | T12: 0 | U12: 0 | V12: 0 | W12: 0 | X12: 0 | Y12: 0 | Z12: 0 | AA12: 0 | AB12: 0 | AC12: 0 | AD12: 0 | AE12: 0 | AF12: 0 | AG12: 0 | AH12: 0 | AI12: 0 | AJ12: 0 | AK12: 0 | AL12: 0 | AM12: 0 | AN12: 0 | AO12: 0 | AP12: 0 | AQ12: 0
A13: Hawaii | B13: HI | C13: 10% in 2010, 15% in 2015, 30% in 2020, 40% in 2030, 70% in 2040, 100% in 2045 | F13: =SUMIFS('EIA 2020 ESRAP Table 10'!E:E,'EIA 2020 ESRAP Table 10'!B:B,B13) -> 8723519 | G13: =0.1+(0.15-0.1)*(4/5) -> 0.14 | H13: 0.15 | I13: =$H13+($M13-$H13)*(I$2-$H$2)/($M$2-$H$2) -> 0.18 | J13: =$H13+($M13-$H13)*(J$2-$H$2)/($M$2-$H$2) -> 0.21 | K13: =$H13+($M13-$H13)*(K$2-$H$2)/($M$2-$H$2) -> 0.24 | L13: =$H13+($M13-$H13)*(L$2-$H$2)/($M$2-$H$2) -> 0.27 | M13: 0.3 | N13: =$M13+($W13-$M13)*(N$2-$M$2)/($W$2-$M$2) -> 0.31 | O13: =$M13+($W13-$M13)*(O$2-$M$2)/($W$2-$M$2) -> 0.32 | P13: =$M13+($W13-$M13)*(P$2-$M$2)/($W$2-$M$2) -> 0.33 | Q13: =$M13+($W13-$M13)*(Q$2-$M$2)/($W$2-$M$2) -> 0.34 | R13: =$M13+($W13-$M13)*(R$2-$M$2)/($W$2-$M$2) -> 0.35 | S13: =$M13+($W13-$M13)*(S$2-$M$2)/($W$2-$M$2) -> 0.36 | T13: =$M13+($W13-$M13)*(T$2-$M$2)/($W$2-$M$2) -> 0.37 | U13: =$M13+($W13-$M13)*(U$2-$M$2)/($W$2-$M$2) -> 0.38 | V13: =$M13+($W13-$M13)*(V$2-$M$2)/($W$2-$M$2) -> 0.39 | W13: 0.4 | X13: =$W13+($AG13-$W13)*(X$2-$W$2)/($AG$2-$W$2) -> 0.43 | Y13: =$W13+($AG13-$W13)*(Y$2-$W$2)/($AG$2-$W$2) -> 0.46 | Z13: =$W13+($AG13-$W13)*(Z$2-$W$2)/($AG$2-$W$2) -> 0.49 | AA13: =$W13+($AG13-$W13)*(AA$2-$W$2)/($AG$2-$W$2) -> 0.52 | AB13: =$W13+($AG13-$W13)*(AB$2-$W$2)/($AG$2-$W$2) -> 0.55 | AC13: =$W13+($AG13-$W13)*(AC$2-$W$2)/($AG$2-$W$2) -> 0.58 | AD13: =$W13+($AG13-$W13)*(AD$2-$W$2)/($AG$2-$W$2) -> 0.61 | AE13: =$W13+($AG13-$W13)*(AE$2-$W$2)/($AG$2-$W$2) -> 0.64 | AF13: =$W13+($AG13-$W13)*(AF$2-$W$2)/($AG$2-$W$2) -> 0.67 | AG13: 0.7 | AH13: =$AG13+($AL13-$AG13)*(AH$2-$AG$2)/($AL$2-$AG$2) -> 0.76 | AI13: =$AG13+($AL13-$AG13)*(AI$2-$AG$2)/($AL$2-$AG$2) -> 0.82 | AJ13: =$AG13+($AL13-$AG13)*(AJ$2-$AG$2)/($AL$2-$AG$2) -> 0.88 | AK13: =$AG13+($AL13-$AG13)*(AK$2-$AG$2)/($AL$2-$AG$2) -> 0.94 | AL13: 1 | AM13: =$AL13 -> 1 | AN13: =$AL13 -> 1 | AO13: =$AL13 -> 1 | AP13: =$AL13 -> 1 | AQ13: =$AL13 -> 1
A14: Idaho | B14: ID | F14: =SUMIFS('EIA 2020 ESRAP Table 10'!E:E,'EIA 2020 ESRAP Table 10'!B:B,B14) -> 24462146 | G14: 0 | H14: 0 | I14: 0 | J14: 0 | K14: 0 | L14: 0 | M14: 0 | N14: 0 | O14: 0 | P14: 0 | Q14: 0 | R14: 0 | S14: 0 | T14: 0 | U14: 0 | V14: 0 | W14: 0 | X14: 0 | Y14: 0 | Z14: 0 | AA14: 0 | AB14: 0 | AC14: 0 | AD14: 0 | AE14: 0 | AF14: 0 | AG14: 0 | AH14: 0 | AI14: 0 | AJ14: 0 | AK14: 0 | AL14: 0 | AM14: 0 | AN14: 0 | AO14: 0 | AP14: 0 | AQ14: 0
A15: Illinois | B15: IL | C15: Specific percentages defined for each year through 2026 (see schedule at right). CEJA requires 40% renewable energy by 2030 and 50% renewables by 2040. | F15: =SUMIFS('EIA 2020 ESRAP Table 10'!E:E,'EIA 2020 ESRAP Table 10'!B:B,B15) -> 50105868 | G15: 0.08 | H15: 0.09 | I15: 0.1 | J15: 0.115 | K15: 0.13 | L15: 0.145 | M15: 0.16 | N15: 0.175 | O15: 0.19 | P15: 0.205 | Q15: 0.22 | R15: 0.235 | S15: 0.25 | T15: 0.25 | U15: 0.25 | V15: 0.25 | W15: 0.4 | X15: =$W15+($AG15-$W15)*(X$2-$W$2)/($AG$2-$W$2) -> 0.41 | Y15: =$W15+($AG15-$W15)*(Y$2-$W$2)/($AG$2-$W$2) -> 0.42 | Z15: =$W15+($AG15-$W15)*(Z$2-$W$2)/($AG$2-$W$2) -> 0.43 | AA15: =$W15+($AG15-$W15)*(AA$2-$W$2)/($AG$2-$W$2) -> 0.44 | AB15: =$W15+($AG15-$W15)*(AB$2-$W$2)/($AG$2-$W$2) -> 0.45 | AC15: =$W15+($AG15-$W15)*(AC$2-$W$2)/($AG$2-$W$2) -> 0.46 | AD15: =$W15+($AG15-$W15)*(AD$2-$W$2)/($AG$2-$W$2) -> 0.47 | AE15: =$W15+($AG15-$W15)*(AE$2-$W$2)/($AG$2-$W$2) -> 0.48 | AF15: =$W15+($AG15-$W15)*(AF$2-$W$2)/($AG$2-$W$2) -> 0.49 | AG15: 0.5 | AH15: =AG15 -> 0.5 | AI15: =AH15 -> 0.5 | AJ15: =AI15 -> 0.5 | AK15: =AJ15 -> 0.5 | AL15: =AK15 -> 0.5 | AM15: =AL15 -> 0.5 | AN15: =AM15 -> 0.5 | AO15: =AN15 -> 0.5 | ... AQ15: =AP15 -> 0.5
A16: Indiana | B16: IN | C16: 4% (2013-2018), 7% (2019-2024), 10% (2025) | F16: =SUMIFS('EIA 2020 ESRAP Table 10'!E:E,'EIA 2020 ESRAP Table 10'!B:B,B16) -> 97204795 | G16: 0.04 | H16: =$G16+($L16-$G16)*(H$2-$G$2)/($L$2-$G$2) -> 0.046 | I16: =$G16+($L16-$G16)*(I$2-$G$2)/($L$2-$G$2) -> 0.052 | J16: =$G16+($L16-$G16)*(J$2-$G$2)/($L$2-$G$2) -> 0.058 | K16: =$G16+($L16-$G16)*(K$2-$G$2)/($L$2-$G$2) -> 0.064 | L16: 0.07 | M16: =$L16+($R16-$L16)*(M$2-$L$2)/($R$2-$L$2) -> 0.075 | N16: =$L16+($R16-$L16)*(N$2-$L$2)/($R$2-$L$2) -> 0.08 | O16: =$L16+($R16-$L16)*(O$2-$L$2)/($R$2-$L$2) -> 0.085 | P16: =$L16+($R16-$L16)*(P$2-$L$2)/($R$2-$L$2) -> 0.09 | Q16: =$L16+($R16-$L16)*(Q$2-$L$2)/($R$2-$L$2) -> 0.095 | R16: 0.1 | S16: =$R16 -> 0.1 | T16: =$R16 -> 0.1 | U16: =$R16 -> 0.1 | V16: =$R16 -> 0.1 | W16: =$R16 -> 0.1 | X16: =$R16 -> 0.1 | Y16: =$R16 -> 0.1 | Z16: =$R16 -> 0.1 | ... AQ16: =$R16 -> 0.1
A17: Iowa | B17: IA | F17: =SUMIFS('EIA 2020 ESRAP Table 10'!E:E,'EIA 2020 ESRAP Table 10'!B:B,B17) -> 50584492 | G17: 0 | H17: 0 | I17: 0 | J17: 0 | K17: 0 | L17: 0 | M17: 0 | N17: 0 | O17: 0 | P17: 0 | Q17: 0 | R17: 0 | S17: 0 | T17: 0 | U17: 0 | V17: 0 | W17: 0 | X17: 0 | Y17: 0 | Z17: 0 | AA17: 0 | AB17: 0 | AC17: 0 | AD17: 0 | AE17: 0 | AF17: 0 | AG17: 0 | AH17: 0 | AI17: 0 | AJ17: 0 | AK17: 0 | AL17: 0 | AM17: 0 | AN17: 0 | AO17: 0 | AP17: 0 | AQ17: 0
A18: Kansas | B18: KS | F18: =SUMIFS('EIA 2020 ESRAP Table 10'!E:E,'EIA 2020 ESRAP Table 10'!B:B,B18) -> 39499427 | G18: 0 | H18: 0 | I18: 0 | J18: 0 | K18: 0 | L18: 0 | M18: 0 | N18: 0 | O18: 0 | P18: 0 | Q18: 0 | R18: 0 | S18: 0 | T18: 0 | U18: 0 | V18: 0 | W18: 0 | X18: 0 | Y18: 0 | Z18: 0 | AA18: 0 | AB18: 0 | AC18: 0 | AD18: 0 | AE18: 0 | AF18: 0 | AG18: 0 | AH18: 0 | AI18: 0 | AJ18: 0 | AK18: 0 | AL18: 0 | AM18: 0 | AN18: 0 | AO18: 0 | AP18: 0 | AQ18: 0
A19: Kentucky | B19: KY | F19: =SUMIFS('EIA 2020 ESRAP Table 10'!E:E,'EIA 2020 ESRAP Table 10'!B:B,B19) -> 71680321 | G19: 0 | H19: 0 | I19: 0 | J19: 0 | K19: 0 | L19: 0 | M19: 0 | N19: 0 | O19: 0 | P19: 0 | Q19: 0 | R19: 0 | S19: 0 | T19: 0 | U19: 0 | V19: 0 | W19: 0 | X19: 0 | Y19: 0 | Z19: 0 | AA19: 0 | AB19: 0 | AC19: 0 | AD19: 0 | AE19: 0 | AF19: 0 | AG19: 0 | AH19: 0 | AI19: 0 | AJ19: 0 | AK19: 0 | AL19: 0 | AM19: 0 | AN19: 0 | AO19: 0 | AP19: 0 | AQ19: 0
A20: Louisiana | B20: LA | F20: =SUMIFS('EIA 2020 ESRAP Table 10'!E:E,'EIA 2020 ESRAP Table 10'!B:B,B20) -> 89173644 | G20: 0 | H20: 0 | I20: 0 | J20: 0 | K20: 0 | L20: 0 | M20: 0 | N20: 0 | O20: 0 | P20: 0 | Q20: 0 | R20: 0 | S20: 0 | T20: 0 | U20: 0 | V20: 0 | W20: 0 | X20: 0 | Y20: 0 | Z20: 0 | AA20: 0 | AB20: 0 | AC20: 0 | AD20: 0 | AE20: 0 | AF20: 0 | AG20: 0 | AH20: 0 | AI20: 0 | AJ20: 0 | AK20: 0 | AL20: 0 | AM20: 0 | AN20: 0 | AO20: 0 | AP20: 0 | AQ20: 0
A21: Maine | B21: ME | C21: RPS updated in 2019 to increase standard to 80% by 2030 and 100% by 2050. Note that previous RPS codified a goal of 40% by 2017 (still reflected in schedule, which then linearly extrapolates to reach subsequent benchmarks). | E21: yes | F21: =SUMIFS('EIA 2020 ESRAP Table 10'!E:E,'EIA 2020 ESRAP Table 10'!B:B,B21) -> 6244700 | G21: 0.07 | H21: 0.08 | I21: 0.09 | J21: 0.4 | K21: =J21+(($W$21-$J$21)/13) -> 0.43076923 | L21: =K21+(($W$21-$J$21)/13) -> 0.46153846 | M21: =L21+(($W$21-$J$21)/13) -> 0.49230769 | N21: =M21+(($W$21-$J$21)/13) -> 0.52307692 | O21: =N21+(($W$21-$J$21)/13) -> 0.55384615 | P21: =O21+(($W$21-$J$21)/13) -> 0.58461538 | Q21: =P21+(($W$21-$J$21)/13) -> 0.61538462 | R21: =Q21+(($W$21-$J$21)/13) -> 0.64615385 | ... V21: =U21+(($W$21-$J$21)/13) -> 0.76923077 | W21: 0.8 | X21: =W21+(($AQ$21-$W$21)/20) -> 0.81 | Y21: =X21+(($AQ$21-$W$21)/20) -> 0.82 | Z21: =Y21+(($AQ$21-$W$21)/20) -> 0.83 | AA21: =Z21+(($AQ$21-$W$21)/20) -> 0.84 | AB21: =AA21+(($AQ$21-$W$21)/20) -> 0.85 | AC21: =AB21+(($AQ$21-$W$21)/20) -> 0.86 | AD21: =AC21+(($AQ$21-$W$21)/20) -> 0.87 | AE21: =AD21+(($AQ$21-$W$21)/20) -> 0.88 | ... AP21: =AO21+(($AQ$21-$W$21)/20) -> 0.99 | AQ21: 1
A22: Maryland | B22: MD | C22: RPS updated in 2019 to increase standard to 30.5% in 2020 and 50% in 2030. Note that previous RPS codified a schedule through 2020, which is preserved here through 2019 (in this prior version, the state has built on its goal of achieving 25% renewable energy by 2020 on the schedule shown in the cells). | E22: yes | F22: =SUMIFS('EIA 2020 ESRAP Table 10'!E:E,'EIA 2020 ESRAP Table 10'!B:B,B22) -> 29323992 | G22: =0.0035+0.0995+0.025 -> 0.128 | H22: =0.005+0.1+0.025 -> 0.13 | I22: =0.007+0.12+0.025 -> 0.152 | J22: =0.0095+0.1215+0.025 -> 0.156 | K22: =0.014+0.144+0.025 -> 0.183 | L22: 0.204 | M22: 0.305 | N22: =($W$22-$M$22)/COUNT($N$2:$W$2)+M22 -> 0.3245 | O22: =($W$22-$M$22)/COUNT($N$2:$W$2)+N22 -> 0.344 | P22: =($W$22-$M$22)/COUNT($N$2:$W$2)+O22 -> 0.3635 | Q22: =($W$22-$M$22)/COUNT($N$2:$W$2)+P22 -> 0.383 | R22: =($W$22-$M$22)/COUNT($N$2:$W$2)+Q22 -> 0.4025 | S22: =($W$22-$M$22)/COUNT($N$2:$W$2)+R22 -> 0.422 | T22: =($W$22-$M$22)/COUNT($N$2:$W$2)+S22 -> 0.4415 | U22: =($W$22-$M$22)/COUNT($N$2:$W$2)+T22 -> 0.461 | V22: =($W$22-$M$22)/COUNT($N$2:$W$2)+U22 -> 0.4805 | W22: 0.5 | X22: =W22 -> 0.5 | Y22: =X22 -> 0.5 | Z22: =Y22 -> 0.5 | AA22: =Z22 -> 0.5 | AB22: =AA22 -> 0.5 | AC22: =AB22 -> 0.5 | AD22: =AC22 -> 0.5 | AE22: =AD22 -> 0.5 | ... AQ22: =AP22 -> 0.5
A23: Massachusetts | B23: MA | C23: RPS updated in 2018 to increase standard to 35% by 2030 and an additional 1% each year after (i.e., 55% by 2050). Before the year of update (2018), the RPS trajectory from the prior policy (1998/2015) is preserved. It was as follows: 2% from Class II (pre-1998) renewable sources, plus specific percentages of Class I renewables defined for each year through 2020 (9% in 2014 rising to 15% in 2020), plus 1% per year after 2020. | F23: =SUMIFS('EIA 2020 ESRAP Table 10'!E:E,'EIA 2020 ESRAP Table 10'!B:B,B23) -> 19254072 | G23: 0.1075 | H23: 0.12 | I23: 0.13 | J23: 0.14 | K23: 0.15 | L23: =K23+(($W$23-$K$23)/12) -> 0.16666667 | M23: =L23+(($W$23-$K$23)/12) -> 0.18333333 | N23: =M23+(($W$23-$K$23)/12) -> 0.2 | O23: =N23+(($W$23-$K$23)/12) -> 0.21666667 | P23: =O23+(($W$23-$K$23)/12) -> 0.23333333 | Q23: =P23+(($W$23-$K$23)/12) -> 0.25 | R23: =Q23+(($W$23-$K$23)/12) -> 0.26666667 | S23: =R23+(($W$23-$K$23)/12) -> 0.28333333 | ... V23: =U23+(($W$23-$K$23)/12) -> 0.33333333 | W23: 0.35 | X23: =W23+1% -> 0.36 | Y23: =X23+1% -> 0.37 | Z23: =Y23+1% -> 0.38 | AA23: =Z23+1% -> 0.39 | AB23: =AA23+1% -> 0.4 | AC23: =AB23+1% -> 0.41 | AD23: =AC23+1% -> 0.42 | AE23: =AD23+1% -> 0.43 | ... AQ23: =AP23+1% -> 0.55
A24: Michigan | B24: MI | C24: 10% in 2015-2018, 12.5% in 2019-2020, 15% in 2021. For 2014, see note on "About" tab. (note that Michigan also has non-binding goal of 35% by 2025, which it is set to exceed but is not modeled due to nature of goal) | F24: =SUMIFS('EIA 2020 ESRAP Table 10'!E:E,'EIA 2020 ESRAP Table 10'!B:B,B24) -> 88672937 | G24: 0.081 | H24: 0.1 | I24: =$H24 -> 0.1 | J24: =$H24 -> 0.1 | K24: 0.1 | L24: 0.125 | M24: 0.125 | N24: 0.15 | O24: =N24 -> 0.15 | P24: =O24 -> 0.15 | Q24: =P24 -> 0.15 | R24: =Q24 -> 0.15 | S24: =R24 -> 0.15 | T24: =S24 -> 0.15 | U24: =T24 -> 0.15 | V24: =U24 -> 0.15 | ... AQ24: =AP24 -> 0.15
A25: Minnesota | B25: MN | C25: Nuclear Utilities: 18% (2012), 25% (2016), 31.5% (2020). Other IOUs: 12% (2012), 17% (2016), 21.5% (2020), 26.5% (2025). Other utilities: 12% (2012), 17% (2016), 20% (2020), 25% (2025). | F25: =SUMIFS('EIA 2020 ESRAP Table 10'!E:E,'EIA 2020 ESRAP Table 10'!B:B,B25) -> 63468353 | G25: =(0.18*'Extra State Data'!$B$2+0.12*'Extra State Data'!$B$3+0.12*'Extra State Data'!$B$5)/'Extra State Data'!$B$4+(I25-((0.18*'Extra State Data'!$B$2+0.12*'Extra State Data'!$B$3+0.12*'Extra State Data'!$B$5)/'Extra State Data'!$B$4))/4*(G2-2013) -> 0.13260364 | H25: =$G25+($I25-$G25)*(H$2-$G$2)/($I$2-$G$2) -> 0.1513656 | I25: =(0.25*'Extra State Data'!$B$2+0.17*'Extra State Data'!$B$3+0.17*'Extra State Data'!$B$5)/'Extra State Data'!$B$4 -> 0.17012756 | J25: =$I25+($M25-$I25)*(J$2-$I$2)/($M$2-$I$2) -> 0.17997812 | K25: =$I25+($M25-$I25)*(K$2-$I$2)/($M$2-$I$2) -> 0.18982868 | L25: =$I25+($M25-$I25)*(L$2-$I$2)/($M$2-$I$2) -> 0.19967923 | M25: =(0.315*'Extra State Data'!$B$2+0.215*'Extra State Data'!$B$3+0.2*'Extra State Data'!$B$5)/'Extra State Data'!$B$4 -> 0.20952979 | N25: =$M25+($R25-$M25)*(N$2-$M$2)/($R$2-$M$2) -> 0.21951385 | O25: =$M25+($R25-$M25)*(O$2-$M$2)/($R$2-$M$2) -> 0.2294979 | P25: =$M25+($R25-$M25)*(P$2-$M$2)/($R$2-$M$2) -> 0.23948196 | Q25: =$M25+($R25-$M25)*(Q$2-$M$2)/($R$2-$M$2) -> 0.24946601 | R25: =(0.315*'Extra State Data'!$B$2+0.265*'Extra State Data'!$B$3+0.25*'Extra State Data'!$B$5)/'Extra State Data'!$B$4 -> 0.25945007 | S25: =$R25 -> 0.25945007 | T25: =$R25 -> 0.25945007 | U25: =$R25 -> 0.25945007 | V25: =$R25 -> 0.25945007 | W25: =$R25 -> 0.25945007 | X25: =$R25 -> 0.25945007 | Y25: =$R25 -> 0.25945007 | Z25: =$R25 -> 0.25945007 | ... AQ25: =$R25 -> 0.25945007
A26: Mississippi | B26: MS | F26: =SUMIFS('EIA 2020 ESRAP Table 10'!E:E,'EIA 2020 ESRAP Table 10'!B:B,B26) -> 91694180 | G26: 0 | H26: 0 | I26: 0 | J26: 0 | K26: 0 | L26: 0 | M26: 0 | N26: 0 | O26: 0 | P26: 0 | Q26: 0 | R26: 0 | S26: 0 | T26: 0 | U26: 0 | V26: 0 | W26: 0 | X26: 0 | Y26: 0 | Z26: 0 | AA26: 0 | AB26: 0 | AC26: 0 | AD26: 0 | AE26: 0 | AF26: 0 | AG26: 0 | AH26: 0 | AI26: 0 | AJ26: 0 | AK26: 0 | AL26: 0 | AM26: 0 | AN26: 0 | AO26: 0 | AP26: 0 | AQ26: 0
A27: Missouri | B27: MO | C27: IOUs: 5% (2014-2017), 10% (2018-2020), 15% (2021). No RPS for non-IOUs. | F27: =SUMIFS('EIA 2020 ESRAP Table 10'!E:E,'EIA 2020 ESRAP Table 10'!B:B,B27) -> 75850848 | G27: =0.05*'Extra State Data'!$B$37/'Extra State Data'!$B$38 -> 0.033869851 | H27: =$G27+($K27-$G27)*(H$2-$G$2)/($K$2-$G$2) -> 0.042337314 | I27: =$G27+($K27-$G27)*(I$2-$G$2)/($K$2-$G$2) -> 0.050804777 | J27: =$G27+($K27-$G27)*(J$2-$G$2)/($K$2-$G$2) -> 0.05927224 | K27: =0.1*'Extra State Data'!$B$37/'Extra State Data'!$B$38 -> 0.067739703 | L27: =$K27+($O27-$K27)*(L$2-$K$2)/($O$2-$K$2) -> 0.076207166 | M27: =$K27+($O27-$K27)*(M$2-$K$2)/($O$2-$K$2) -> 0.084674629 | N27: =$K27+($O27-$K27)*(N$2-$K$2)/($O$2-$K$2) -> 0.093142091 | O27: =0.15*'Extra State Data'!$B$37/'Extra State Data'!$B$38 -> 0.10160955 | P27: =$O27 -> 0.10160955 | Q27: =$O27 -> 0.10160955 | R27: =$O27 -> 0.10160955 | S27: =$O27 -> 0.10160955 | T27: =$O27 -> 0.10160955 | U27: =$O27 -> 0.10160955 | V27: =$O27 -> 0.10160955 | W27: =$O27 -> 0.10160955 | ... AQ27: =$O27 -> 0.10160955
A28: Montana | B28: MT | C28: 10% (2010-2014), 15% (2015) | F28: =SUMIFS('EIA 2020 ESRAP Table 10'!E:E,'EIA 2020 ESRAP Table 10'!B:B,B28) -> 23594570 | G28: =(0.15-0.1)*(4/5)+0.1 -> 0.14 | H28: 0.15 | I28: =$H28 -> 0.15 | J28: =$H28 -> 0.15 | K28: =$H28 -> 0.15 | L28: =$H28 -> 0.15 | M28: =$H28 -> 0.15 | N28: =$H28 -> 0.15 | O28: =$H28 -> 0.15 | P28: =$H28 -> 0.15 | ... AQ28: =$H28 -> 0.15
A29: Nebraska | B29: NE | F29: =SUMIFS('EIA 2020 ESRAP Table 10'!E:E,'EIA 2020 ESRAP Table 10'!B:B,B29) -> 61549218 | G29: 0 | H29: 0 | I29: 0 | J29: 0 | K29: 0 | L29: 0 | M29: 0 | N29: 0 | O29: 0 | P29: 0 | Q29: 0 | R29: 0 | S29: 0 | T29: 0 | U29: 0 | V29: 0 | W29: 0 | X29: 0 | Y29: 0 | Z29: 0 | AA29: 0 | AB29: 0 | AC29: 0 | AD29: 0 | AE29: 0 | AF29: 0 | AG29: 0 | AH29: 0 | AI29: 0 | AJ29: 0 | AK29: 0 | AL29: 0 | AM29: 0 | AN29: 0 | AO29: 0 | AP29: 0 | AQ29: 0
A30: Nevada | B30: NV | C30: IOUs: 18% (2013-2014), 20% (2015-2019), 22% (2020-2024), 50% (2030). No RPS for non-IOUs. | F30: =SUMIFS('EIA 2020 ESRAP Table 10'!E:E,'EIA 2020 ESRAP Table 10'!B:B,B30) -> 65411337 | G30: =0.18*'Extra State Data'!$B$42/'Extra State Data'!$B$43+(0.5*(H30-0.18*'Extra State Data'!$B$42/'Extra State Data'!$B$43)) -> 0.16889775 | H30: =0.2*'Extra State Data'!$B$42/'Extra State Data'!$B$43 -> 0.1777871 | I30: =$H30+($M30-$H30)*(I$2-$H$2)/($M$2-$H$2) -> 0.18134285 | J30: =$H30+($M30-$H30)*(J$2-$H$2)/($M$2-$H$2) -> 0.18489859 | K30: =$H30+($M30-$H30)*(K$2-$H$2)/($M$2-$H$2) -> 0.18845433 | L30: =$H30+($M30-$H30)*(L$2-$H$2)/($M$2-$H$2) -> 0.19201007 | M30: =0.22*'Extra State Data'!$B$42/'Extra State Data'!$B$43 -> 0.19556581 | N30: =($W$30-$M$30)/COUNT($N$2:$W$2)+M30 -> 0.22045601 | O30: =($W$30-$M$30)/COUNT($N$2:$W$2)+N30 -> 0.2453462 | P30: =($W$30-$M$30)/COUNT($N$2:$W$2)+O30 -> 0.2702364 | Q30: =($W$30-$M$30)/COUNT($N$2:$W$2)+P30 -> 0.29512659 | R30: =($W$30-$M$30)/COUNT($N$2:$W$2)+Q30 -> 0.32001679 | S30: =($W$30-$M$30)/COUNT($N$2:$W$2)+R30 -> 0.34490698 | T30: =($W$30-$M$30)/COUNT($N$2:$W$2)+S30 -> 0.36979718 | U30: =($W$30-$M$30)/COUNT($N$2:$W$2)+T30 -> 0.39468737 | V30: =($W$30-$M$30)/COUNT($N$2:$W$2)+U30 -> 0.41957756 | W30: =0.5*'Extra State Data'!$B$42/'Extra State Data'!$B$43 -> 0.44446776 | X30: =$R30 -> 0.32001679 | Y30: =$R30 -> 0.32001679 | Z30: =$R30 -> 0.32001679 | AA30: =$R30 -> 0.32001679 | AB30: =$R30 -> 0.32001679 | AC30: =$R30 -> 0.32001679 | AD30: =$R30 -> 0.32001679 | AE30: =$R30 -> 0.32001679 | ... AQ30: =$R30 -> 0.32001679
A31: New Hampshire | B31: NH | C31: IOUs, coops, and retail suppliers: specified percentages on right. These are for Class I, Class II, and Class III renewables, as we exclude hydro (Class IV). | F31: =SUMIFS('EIA 2020 ESRAP Table 10'!E:E,'EIA 2020 ESRAP Table 10'!B:B,B31) -> 10846143 | G31: =(0.072-0.014) -> 0.058 | H31: =0.083-0.015 -> 0.068 | I31: =0.092-0.015 -> 0.077 | J31: =0.176-0.015 -> 0.161 | K31: =0.185-0.015 -> 0.17 | L31: =0.194-0.015 -> 0.179 | M31: =0.207-0.015 -> 0.192 | N31: =0.216-0.015 -> 0.201 | O31: =0.225-0.015 -> 0.21 | P31: =0.234-0.015 -> 0.219 | Q31: =0.243-0.015 -> 0.228 | R31: =0.252-0.015 -> 0.237 | S31: =$R31 -> 0.237 | T31: =$R31 -> 0.237 | U31: =$R31 -> 0.237 | V31: =$R31 -> 0.237 | W31: =$R31 -> 0.237 | X31: =$R31 -> 0.237 | Y31: =$R31 -> 0.237 | Z31: =$R31 -> 0.237 | ... AQ31: =$R31 -> 0.237
A32: New Jersey | B32: NJ | C32: Specific percentages defined for each year through 2028 (see schedule at right). Excludes Tier II. | F32: =SUMIFS('EIA 2020 ESRAP Table 10'!E:E,'EIA 2020 ESRAP Table 10'!B:B,B32) -> 79865721 | G32: 0.07977 | H32: 0.08807 | I32: 0.08807 | J32: 0.10485 | K32: 0.12325 | L32: 0.14175 | M32: 0.16029 | N32: 0.21 | O32: =($R$32-$N$32)/COUNT($O$2:$R$2)+N32 -> 0.245 | P32: =($R$32-$N$32)/COUNT($O$2:$R$2)+O32 -> 0.28 | Q32: =($R$32-$N$32)/COUNT($O$2:$R$2)+P32 -> 0.315 | R32: 0.35 | S32: =($W$32-$R$32)/COUNT($S$2:$W$2)+R32 -> 0.38 | T32: =($W$32-$R$32)/COUNT($S$2:$W$2)+S32 -> 0.41 | U32: =($W$32-$R$32)/COUNT($S$2:$W$2)+T32 -> 0.44 | V32: =($W$32-$R$32)/COUNT($S$2:$W$2)+U32 -> 0.47 | W32: 0.5 | X32: =W32 -> 0.5 | Y32: =X32 -> 0.5 | Z32: =Y32 -> 0.5 | AA32: =Z32 -> 0.5 | AB32: =AA32 -> 0.5 | AC32: =AB32 -> 0.5 | AD32: =AC32 -> 0.5 | AE32: =AD32 -> 0.5 | ... AQ32: =AP32 -> 0.5
A33: New Mexico | B33: NM | C33: IOUs: required 20% by 2020; required 40% renewable energy by 2025; required 50% renewable energy by 2030; required 80% renewable energy by 2040; required 100% zero-carbon energy by 2045 Coops: required 40% renewable energy by 2025; required 50% renewable energy by 2030; target of 100% zero-carbon with at least 80% renewable energy by 2050 (target not included; schedule only reflects required shares) note that this schedule reflects legislation passed in 2019 and pre-2019 years preserved based on previously legislated trajectories. | D33: 2045/2050 goals | E33: yes | F33: =SUMIFS('EIA 2020 ESRAP Table 10'!E:E,'EIA 2020 ESRAP Table 10'!B:B,B33) -> 49616884 | G33: 0 | H33: =SUM(H56:H57) -> 0.11293332 | I33: =SUM(I56:I57) -> 0.12186577 | J33: =SUM(J56:J57) -> 0.13079822 | K33: =SUM(K56:K57) -> 0.13973068 | L33: =SUM(L56:L57) -> 0.14866313 | M33: =SUM(M56:M57) -> 0.16333744 | N33: =SUM(N56:N57) -> 0.20212958 | O33: =SUM(O56:O57) -> 0.24092171 | ... AQ33: =SUM(AQ56:AQ57) -> 0.78797792
A34: New York | B34: NY | C34: 29% in 2015, 70% in 2030 (note that the 2030 goal increased from 50% to 70% as of legislation in 2019) and 100% zero-emissions requirement by 2040. | D34: yes | E34: yes | F34: =SUMIFS('EIA 2020 ESRAP Table 10'!E:E,'EIA 2020 ESRAP Table 10'!B:B,B34) -> 145643139 | G34: 0 | H34: 0.29 | I34: =$H34+($W34-$H34)*(I$2-$H$2)/($W$2-$H$2) -> 0.31733333 | J34: =$H34+($W34-$H34)*(J$2-$H$2)/($W$2-$H$2) -> 0.34466667 | K34: =$H34+($W34-$H34)*(K$2-$H$2)/($W$2-$H$2) -> 0.372 | L34: =$H34+($W34-$H34)*(L$2-$H$2)/($W$2-$H$2) -> 0.39933333 | M34: =$H34+($W34-$H34)*(M$2-$H$2)/($W$2-$H$2) -> 0.42666667 | N34: =$H34+($W34-$H34)*(N$2-$H$2)/($W$2-$H$2) -> 0.454 | O34: =$H34+($W34-$H34)*(O$2-$H$2)/($W$2-$H$2) -> 0.48133333 | P34: =$H34+($W34-$H34)*(P$2-$H$2)/($W$2-$H$2) -> 0.50866667 | ... V34: =$H34+($W34-$H34)*(V$2-$H$2)/($W$2-$H$2) -> 0.67266667 | W34: 0.7 | X34: =$W34+($AG34-$W34)*(X$2-$W$2)/($AG$2-$W$2) -> 0.73 | Y34: =$W34+($AG34-$W34)*(Y$2-$W$2)/($AG$2-$W$2) -> 0.76 | Z34: =$W34+($AG34-$W34)*(Z$2-$W$2)/($AG$2-$W$2) -> 0.79 | AA34: =$W34+($AG34-$W34)*(AA$2-$W$2)/($AG$2-$W$2) -> 0.82 | AB34: =$W34+($AG34-$W34)*(AB$2-$W$2)/($AG$2-$W$2) -> 0.85 | AC34: =$W34+($AG34-$W34)*(AC$2-$W$2)/($AG$2-$W$2) -> 0.88 | AD34: =$W34+($AG34-$W34)*(AD$2-$W$2)/($AG$2-$W$2) -> 0.91 | AE34: =$W34+($AG34-$W34)*(AE$2-$W$2)/($AG$2-$W$2) -> 0.94 | AF34: =$W34+($AG34-$W34)*(AF$2-$W$2)/($AG$2-$W$2) -> 0.97 | AG34: 1 | AH34: =AG34 -> 1 | AI34: =AH34 -> 1 | AJ34: =AI34 -> 1 | AK34: =AJ34 -> 1 | AL34: =AK34 -> 1 | AM34: =AL34 -> 1 | AN34: =AM34 -> 1 | AO34: =AN34 -> 1 | ... AQ34: =AP34 -> 1
A35: North Carolina | B35: NC | C35: IOUs: 3% (2012-2014), 6% (2015-2017), 10% (2018-2020), 12.5% (2021). Munis and coops: 10% (2018). | F35: =SUMIFS('EIA 2020 ESRAP Table 10'!E:E,'EIA 2020 ESRAP Table 10'!B:B,B35) -> 266820020 | G35: =0.05*'Extra State Data'!$B$13/SUM('Extra State Data'!$B$13:$B$15) -> 0.041509835 | H35: =0.06*'Extra State Data'!$B$13/SUM('Extra State Data'!$B$13:$B$15) -> 0.049811802 | I35: =0.0733*'Extra State Data'!$B$13/SUM('Extra State Data'!$B$13:$B$15) -> 0.060853418 | J35: =0.0866*'Extra State Data'!$B$13/SUM('Extra State Data'!$B$13:$B$15) -> 0.071895034 | K35: =(0.1*'Extra State Data'!$B$13+0.1*SUM('Extra State Data'!$B$14:$B$15))/SUM('Extra State Data'!$B$13:$B$15) -> 0.1 | L35: =$K35+($N35-$K35)*(L$2-$K$2)/($N$2-$K$2) -> 0.10691831 | M35: =$K35+($N35-$K35)*(M$2-$K$2)/($N$2-$K$2) -> 0.11383661 | N35: =(0.125*'Extra State Data'!$B$13+0.1*SUM('Extra State Data'!$B$14:$B$15))/SUM('Extra State Data'!$B$13:$B$15) -> 0.12075492 | O35: =$N35 -> 0.12075492 | P35: =$N35 -> 0.12075492 | Q35: =$N35 -> 0.12075492 | R35: =$N35 -> 0.12075492 | S35: =$N35 -> 0.12075492 | T35: =$N35 -> 0.12075492 | U35: =$N35 -> 0.12075492 | V35: =$N35 -> 0.12075492 | ... AQ35: =$N35 -> 0.12075492
A36: North Dakota | B36: ND | F36: =SUMIFS('EIA 2020 ESRAP Table 10'!E:E,'EIA 2020 ESRAP Table 10'!B:B,B36) -> 43378707 | G36: 0 | H36: 0 | I36: 0 | J36: 0 | K36: 0 | L36: 0 | M36: 0 | N36: 0 | O36: 0 | P36: 0 | Q36: 0 | R36: 0 | S36: 0 | T36: 0 | U36: 0 | V36: 0 | W36: 0 | X36: 0 | Y36: 0 | Z36: 0 | AA36: 0 | AB36: 0 | AC36: 0 | AD36: 0 | AE36: 0 | AF36: 0 | AG36: 0 | AH36: 0 | AI36: 0 | AJ36: 0 | AK36: 0 | AL36: 0 | AM36: 0 | AN36: 0 | AO36: 0 | AP36: 0 | AQ36: 0
A37: Ohio | B37: OH | C37: IOUs: specific percentages defined for each year through 2026. No RPS for munis or coops. Note that Ohio reduced its RPS from 12.5% to 8.5% by 2026 as of 2019 and eliminated the RPS thereafter. The standard is thus not applied for the post-2026 years. | E37: yes | F37: =SUMIFS('EIA 2020 ESRAP Table 10'!E:E,'EIA 2020 ESRAP Table 10'!B:B,B37) -> 89444015 | G37: =0.025*'Extra State Data'!$B$52/'Extra State Data'!$B$53 -> 0.014520394 | H37: =0.025*'Extra State Data'!$B$52/'Extra State Data'!$B$53 -> 0.014520394 | I37: =0.025*'Extra State Data'!$B$52/'Extra State Data'!$B$53 -> 0.014520394 | J37: =0.035*'Extra State Data'!$B$52/'Extra State Data'!$B$53 -> 0.020328551 | K37: =0.045*'Extra State Data'!$B$52/'Extra State Data'!$B$53 -> 0.026136708 | L37: =0.055*'Extra State Data'!$B$52/'Extra State Data'!$B$53 -> 0.031944866 | M37: =0.055*'Extra State Data'!$B$52/'Extra State Data'!$B$53 -> 0.031944866 | N37: =0.06*'Extra State Data'!$B$52/'Extra State Data'!$B$53 -> 0.034848944 | O37: =0.065*'Extra State Data'!$B$52/'Extra State Data'!$B$53 -> 0.037753023 | P37: =0.07*'Extra State Data'!$B$52/'Extra State Data'!$B$53 -> 0.040657102 | Q37: =0.075*'Extra State Data'!$B$52/'Extra State Data'!$B$53 -> 0.043561181 | R37: =0.08*'Extra State Data'!$B$52/'Extra State Data'!$B$53 -> 0.046465259 | S37: =0.085*'Extra State Data'!$B$52/'Extra State Data'!$B$53 -> 0.049369338 | T37: 0 | U37: 0 | V37: 0 | W37: 0 | X37: 0 | Y37: 0 | Z37: 0 | AA37: 0 | AB37: 0 | AC37: 0 | AD37: 0 | AE37: 0 | AF37: 0 | AG37: 0 | AH37: 0 | AI37: 0 | AJ37: 0 | AK37: 0 | AL37: 0 | AM37: 0 | AN37: 0 | AO37: 0 | AP37: 0 | AQ37: 0
A38: Oklahoma | B38: OK | C38: Goal only; not included | F38: =SUMIFS('EIA 2020 ESRAP Table 10'!E:E,'EIA 2020 ESRAP Table 10'!B:B,B38) -> 127095251 | G38: 0 | H38: 0 | I38: 0 | J38: 0 | K38: 0 | L38: 0 | M38: 0 | N38: 0 | O38: 0 | P38: 0 | Q38: 0 | R38: 0 | S38: 0 | T38: 0 | U38: 0 | V38: 0 | W38: 0 | X38: 0 | Y38: 0 | Z38: 0 | AA38: 0 | AB38: 0 | AC38: 0 | AD38: 0 | AE38: 0 | AF38: 0 | AG38: 0 | AH38: 0 | AI38: 0 | AJ38: 0 | AK38: 0 | AL38: 0 | AM38: 0 | AN38: 0 | AO38: 0 | AP38: 0 | AQ38: 0
A39: Oregon | B39: OR | C39: Investor-owned utilities serving >3% state load: 5% (2011), 15% (2015), 20% (2020), 27% (2025), 35% (2030), 45% (2035), 50% (2040). Consumer-owned utilities serving >3% state load: 25% (2025). Utilities serving 1.5%-3% state load: 10% (2025). Utilities serving <1.5% state load: 5% (2025). | F39: =SUMIFS('EIA 2020 ESRAP Table 10'!E:E,'EIA 2020 ESRAP Table 10'!B:B,B39) -> 95963074 | G39: =((0.15*'Extra State Data'!$B$28/'Extra State Data'!$B$25)-(0.05*'Extra State Data'!$B$28/'Extra State Data'!$B$25))*(3/4)+(0.05*'Extra State Data'!$B$28/'Extra State Data'!$B$25) -> 0.081222261 | H39: =0.15*'Extra State Data'!$B$28/'Extra State Data'!$B$25 -> 0.097466713 | I39: =$H39+($M39-$H39)*(I$2-$H$2)/($M$2-$H$2) -> 0.10396449 | J39: =$H39+($M39-$H39)*(J$2-$H$2)/($M$2-$H$2) -> 0.11046228 | K39: =$H39+($M39-$H39)*(K$2-$H$2)/($M$2-$H$2) -> 0.11696006 | L39: =$H39+($M39-$H39)*(L$2-$H$2)/($M$2-$H$2) -> 0.12345784 | M39: =0.2*'Extra State Data'!$B$28/'Extra State Data'!$B$25 -> 0.12995562 | N39: =$M39+($R39-$M39)*(N$2-$M$2)/($R$2-$M$2) -> 0.14464659 | O39: =$M39+($R39-$M39)*(O$2-$M$2)/($R$2-$M$2) -> 0.15933757 | P39: =$M39+($R39-$M39)*(P$2-$M$2)/($R$2-$M$2) -> 0.17402855 | Q39: =$M39+($R39-$M39)*(Q$2-$M$2)/($R$2-$M$2) -> 0.18871952 | R39: =(0.25*'Extra State Data'!B28+0.25*'Extra State Data'!B29+0.1*'Extra State Data'!B30+0.05*'Extra State Data'!B31)/'Extra State Data'!$B$25 -> 0.2034105 | S39: =$R39+($W39-$R39)*(S$2-$R$2)/($W$2-$R$2) -> 0.21640606 | T39: =$R39+($W39-$R39)*(T$2-$R$2)/($W$2-$R$2) -> 0.22940162 | U39: =$R39+($W39-$R39)*(U$2-$R$2)/($W$2-$R$2) -> 0.24239718 | V39: =$R39+($W39-$R39)*(V$2-$R$2)/($W$2-$R$2) -> 0.25539275 | W39: =(0.35*'Extra State Data'!B28+0.25*'Extra State Data'!B29+0.1*'Extra State Data'!B30+0.05*'Extra State Data'!B31)/'Extra State Data'!$B$25 -> 0.26838831 | X39: =$W39+($AB39-$W39)*(X$2-$W$2)/($AB$2-$W$2) -> 0.28138387 | Y39: =$W39+($AB39-$W39)*(Y$2-$W$2)/($AB$2-$W$2) -> 0.29437943 | Z39: =$W39+($AB39-$W39)*(Z$2-$W$2)/($AB$2-$W$2) -> 0.30737499 | AA39: =$W39+($AB39-$W39)*(AA$2-$W$2)/($AB$2-$W$2) -> 0.32037055 | AB39: =(0.45*'Extra State Data'!B28+0.25*'Extra State Data'!B29+0.1*'Extra State Data'!B30+0.05*'Extra State Data'!B31)/'Extra State Data'!$B$25 -> 0.33336612 | AC39: =$AB39+($AG39-$AB39)*(AC$2-$AB$2)/($AG$2-$AB$2) -> 0.3398639 | AD39: =$AB39+($AG39-$AB39)*(AD$2-$AB$2)/($AG$2-$AB$2) -> 0.34636168 | AE39: =$AB39+($AG39-$AB39)*(AE$2-$AB$2)/($AG$2-$AB$2) -> 0.35285946 | AF39: =$AB39+($AG39-$AB39)*(AF$2-$AB$2)/($AG$2-$AB$2) -> 0.35935724 | AG39: =(0.5*'Extra State Data'!B28+0.25*'Extra State Data'!B29+0.1*'Extra State Data'!B30+0.05*'Extra State Data'!B31)/'Extra State Data'!$B$25 -> 0.36585502 | AH39: =$AG39 -> 0.36585502 | AI39: =$AG39 -> 0.36585502 | AJ39: =$AG39 -> 0.36585502 | AK39: =$AG39 -> 0.36585502 | AL39: =$AG39 -> 0.36585502 | AM39: =$AG39 -> 0.36585502 | AN39: =$AG39 -> 0.36585502 | AO39: =$AG39 -> 0.36585502 | ... AQ39: =$AG39 -> 0.36585502
A40: Pennsylvania | B40: PA | C40: Specific percentages defined for each year through 2021 (see schedule at right) | F40: =SUMIFS('EIA 2020 ESRAP Table 10'!E:E,'EIA 2020 ESRAP Table 10'!B:B,B40) -> 101546277 | G40: =0.045+0.062 -> 0.107 | H40: =0.05+0.062 -> 0.112 | I40: =0.055+0.082 -> 0.137 | J40: =0.06+0.082 -> 0.142 | K40: =0.065+0.082 -> 0.147 | L40: =0.07+0.082 -> 0.152 | M40: =0.075+0.082 -> 0.157 | N40: 0.18 | O40: =$N40 -> 0.18 | P40: =$N40 -> 0.18 | Q40: =$N40 -> 0.18 | R40: =$N40 -> 0.18 | S40: =$N40 -> 0.18 | T40: =$N40 -> 0.18 | U40: =$N40 -> 0.18 | V40: =$N40 -> 0.18 | ... AQ40: =$N40 -> 0.18
...

Sheet Webapp Output
B3: 2020 RPS | C3: 2030 RPS | D3: 2050 RPS
A4: AL | B4: ='RPS by State'!M3 -> 0 | C4: ='RPS by State'!W3 -> 0 | D4: ='RPS by State'!AQ3 -> 0
A5: AK | B5: ='RPS by State'!M4 -> 0 | C5: ='RPS by State'!W4 -> 0 | D5: ='RPS by State'!AQ4 -> 0
A6: AZ | B6: ='RPS by State'!M5 -> 0.1 | C6: ='RPS by State'!W5 -> 0.15 | D6: ='RPS by State'!AQ5 -> 0.15
A7: AR | B7: ='RPS by State'!M6 -> 0 | C7: ='RPS by State'!W6 -> 0 | D7: ='RPS by State'!AQ6 -> 0
A8: CA | B8: ='RPS by State'!M7 -> 0.29025289 | C8: ='RPS by State'!W7 -> 0.52773253 | D8: ='RPS by State'!AQ7 -> 0.87955421
A9: CO | B9: ='RPS by State'!M8 -> 0.2349729 | C9: ='RPS by State'!W8 -> 0.33122435 | D9: ='RPS by State'!AQ8 -> 0.52372725
A10: CT | B10: ='RPS by State'!M9 -> 0.29 | C10: ='RPS by State'!W9 -> 0.48 | D10: ='RPS by State'!AQ9 -> 0.29
A11: DE | B11: ='RPS by State'!M10 -> 0.2 | C11: ='RPS by State'!W10 -> 0.25 | D11: ='RPS by State'!AQ10 -> 0.25
A12: DC | B12: ='RPS by State'!M53 -> 0.2 | C12: ='RPS by State'!W53 -> 0.87 | D12: ='RPS by State'!AQ53 -> 1
A13: FL | B13: ='RPS by State'!M11 -> 0.0074721225 | C13: ='RPS by State'!W11 -> 0.0074721225 | D13: ='RPS by State'!AQ11 -> 0.0074721225
A14: GA | B14: ='RPS by State'!M12 -> 0 | C14: ='RPS by State'!W12 -> 0 | D14: ='RPS by State'!AQ12 -> 0
A15: HI | B15: ='RPS by State'!M13 -> 0.3 | C15: ='RPS by State'!W13 -> 0.4 | D15: ='RPS by State'!AQ13 -> 1
A16: ID | B16: ='RPS by State'!M14 -> 0 | C16: ='RPS by State'!W14 -> 0 | D16: ='RPS by State'!AQ14 -> 0
A17: IL | B17: ='RPS by State'!M15 -> 0.16 | C17: ='RPS by State'!W15 -> 0.4 | D17: ='RPS by State'!AQ15 -> 0.5
A18: IN | B18: ='RPS by State'!M16 -> 0.075 | C18: ='RPS by State'!W16 -> 0.1 | D18: ='RPS by State'!AQ16 -> 0.1
A19: IA | B19: ='RPS by State'!M17 -> 0 | C19: ='RPS by State'!W17 -> 0 | D19: ='RPS by State'!AQ17 -> 0
A20: KS | B20: ='RPS by State'!M18 -> 0 | C20: ='RPS by State'!W18 -> 0 | D20: ='RPS by State'!AQ18 -> 0
A21: KY | B21: ='RPS by State'!M19 -> 0 | C21: ='RPS by State'!W19 -> 0 | D21: ='RPS by State'!AQ19 -> 0
A22: LA | B22: ='RPS by State'!M20 -> 0 | C22: ='RPS by State'!W20 -> 0 | D22: ='RPS by State'!AQ20 -> 0
A23: ME | B23: ='RPS by State'!M21 -> 0.49230769 | C23: ='RPS by State'!W21 -> 0.8 | D23: ='RPS by State'!AQ21 -> 1
A24: MD | B24: ='RPS by State'!M22 -> 0.305 | C24: ='RPS by State'!W22 -> 0.5 | D24: ='RPS by State'!AQ22 -> 0.5
... A54: WY | B54: ='RPS by State'!M52 -> 0 | C54: ='RPS by State'!W52 -> 0 | D54: ='RPS by State'!AQ52 -> 0

Sheet EIA 2020 ESRAP Table 10
A1: 2020 Utility Bundled Sales to Ultimate Customers- Total
A2: (Data from forms EIA-861- schedules 4A & 4D and EIA-861S)
A3: Entity | B3: State | C3: Ownership | D3: Customers (Count) | E3: Sales (Megawatthours) | F3: Revenues (Thousands Dollars) | G3: Average Price (cents/kWh)
A4: Alaska Electric Light&Power Co | B4: AK | C4: Investor Owned | D4: 17403 | E4: 384981 | F4: 44688.6 | G4: 11.608001
A5: Alaska Power and Telephone Co | B5: AK | C5: Investor Owned | D5: 8168 | E5: 64407 | F5: 17068 | G5: 26.500225
A6: Alaska Village Elec Coop, Inc | B6: AK | C6: Cooperative | D6: 11513 | E6: 120835 | F6: 53906.3 | G6: 44.611495
A7: Anchorage Municipal Light and Power | B7: AK | C7: Municipal | D7: 31291 | E7: 732828 | F7: 121486.1 | G7: 16.57771
A8: Chugach Electric Assn Inc | B8: AK | C8: Cooperative | D8: 112593 | E8: 1212687 | F8: 226490.8 | G8: 18.676773
A9: Golden Valley Elec Assn Inc | B9: AK | C9: Cooperative | D9: 47059 | E9: 1221811 | F9: 236609 | G9: 19.365434
A10: Homer Electric Assn Inc | B10: AK | C10: Cooperative | D10: 32511 | E10: 437105 | F10: 103146.7 | G10: 23.597694
A11: Ketchikan Public Utilities | B11: AK | C11: Municipal | D11: 7856 | E11: 166832 | F11: 18488.7 | G11: 11.082226
A12: Kodiak Electric Assn Inc | B12: AK | C12: Cooperative | D12: 6086 | E12: 139401 | F12: 22998 | G12: 16.49773
A13: Kotzebue Electric Assn Inc | B13: AK | C13: Cooperative | D13: 1293 | E13: 18915 | F13: 7374.6 | G13: 38.988105
A14: Matanuska Electric Assn Inc | B14: AK | C14: Cooperative | D14: 66667 | E14: 751476 | F14: 153435.2 | G14: 20.417844
A15: TDX North Slope Generating Co | B15: AK | C15: Investor Owned | D15: 165 | E15: 53030 | F15: 11562 | G15: 21.802753
... A1371: MidAmerican Energy Services, LLC | B1371: TX | C1371: Retail Power Marketer | D1371: 15379 | E1371: 1999738 | F1371: 143170.7 | G1371: 7.1594729
A1372: Morgan Stanley Capital Grp Inc | B1372: TX | C1372: Retail Power Marketer | D1372: 1 | E1372: 0 | F1372: 20338 | G1372: .
A1373: Navarro County Elec Coop, Inc | B1373: TX | C1373: Cooperative | D1373: 17307 | E1373: 532085 | F1373: 40300.1 | G1373: 7.5739966
A1374: Navasota Valley Elec Coop, Inc | B1374: TX | C1374: Cooperative | D1374: 20147 | E1374: 369665 | F1374: 34610.7 | G1374: 9.3627203
A1375: NextEra Energy Services, LLC | B1375: TX | C1375: Retail Power Marketer | D1375: 276133 | E1375: 9802936 | F1375: 831334.9 | G1375: 8.4804685
A1376: North Plains Electric Coop Inc | B1376: TX | C1376: Cooperative | D1376: 7122 | E1376: 372752 | F1376: 32634 | G1376: 8.7548826
A1377: Nueces Electric Cooperative | B1377: TX | C1377: Cooperative | D1377: 44596 | E1377: 997403 | F1377: 89447 | G1377: 8.9679899
A1378: Our Energy LLC | B1378: TX | C1378: Retail Power Marketer | D1378: 62719 | E1378: 1500109 | F1378: 134502 | G1378: 8.9661485
A1379: Panola-Harrison Elec Coop, Inc | B1379: TX | C1379: Cooperative | D1379: 10806 | E1379: 199755 | F1379: 17688 | G1379: 8.8548472
A1380: Pedernales Electric Coop, Inc | B1380: TX | C1380: Cooperative | D1380: 379832 | E1380: 6533473 | F1380: 630919.9 | G1380: 9.6567308
A1381: Pogo Energy LLC | B1381: TX | C1381: Retail Power Marketer | D1381: 13647 | E1381: 162924 | F1381: 11194.6 | G1381: 6.8710564
A1382: Pro Power Providers | B1382: TX | C1382: Retail Power Marketer | D1382: 178 | E1382: 519 | F1382: 53.7 | G1382: 10.346821
A1383: Pulse Power, LLC | B1383: TX | C1383: Retail Power Marketer | D1383: 75356 | E1383: 1220110 | F1383: 128014 | G1383: 10.492005
A1384: Reliant Energy Retail Services | B1384: TX | C1384: Retail Power Marketer | D1384: 1404752 | E1384: 39602218 | F1384: 3880617.6 | G1384: 9.7989906
... A1619: Withheld | B1619: TX | C1619: Retail Power Marketer | D1619: 24 | E1619: 6454584 | F1619: 216095.6 | G1619: 3.34794
A1620: Adjustment 2020 | B1620: AK | C1620: Other | D1620: 35725 | E1620: 613269 | F1620: 155580.8 | G1620: .
A1621: Adjustment 2020 | B1621: AL | C1621: Other | D1621: 70418 | E1621: 1371994 | F1621: 153714.5 | G1621: .
A1622: Adjustment 2020 | B1622: AR | C1622: Other | D1622: 28612 | E1622: 606815 | F1622: 65621.9 | G1622: .
A1623: Adjustment 2020 | B1623: AZ | C1623: Other | D1623: -43153 | E1623: 1457512 | F1623: 123329.6 | G1623: .
A1624: Adjustment 2020 | B1624: CA | C1624: Other | D1624: -327155 | E1624: 1836367 | F1624: 273111.2 | G1624: .
A1625: Adjustment 2020 | B1625: CO | C1625: Other | D1625: 58520 | E1625: 1151881 | F1625: 159910.9 | G1625: .
A1626: Adjustment 2020 | B1626: CT | C1626: Other | D1626: -17583 | E1626: 291718 | F1626: 40488.7 | G1626: .
A1627: Adjustment 2020 | B1627: DC | C1627: Other | D1627: -536 | E1627: 0 | F1627: 0 | G1627: .
A1628: Adjustment 2020 | B1628: DE | C1628: Other | D1628: 14372 | E1628: 388579 | F1628: 44066.3 | G1628: .
A1629: Adjustment 2020 | B1629: FL | C1629: Other | D1629: 49950 | E1629: 1142488 | F1629: 131572.3 | G1629: .
...

Sheet Generation by State
A1: YEAR | B1: 2018
A3: Sum of GENERATION (Megawatthours) | B3: Column Labels
A4: Row Labels | B4: Coal | C4: Geothermal | D4: Hydroelectric Conventional | E4: Natural Gas | F4: Nuclear | G4: Other | H4: Other Biomass | I4: Other Gases | J4: Petroleum | K4: Pumped Storage | L4: Solar Thermal and Photovoltaic | M4: Total | N4: Wind | O4: Wood and Wood Derived Fuels | P4: Grand Total
A5: AK | B5: 1257128 | D5: 3328450 | E5: 5895805 | G5: -6200 | H5: 90948 | J5: 1618557 | M5: 12494718 | N5: 310030 | O5: 0 | P5: 24989436
A6: AL | B6: 63555040 | D6: 22286278 | E6: 117600839 | F6: 78925654 | G6: -98 | H6: 75344 | I6: 9608 | J6: 131407 | L6: 714504 | M6: 290115988 | O6: 6817414 | P6: 580231978
A7: AR | B7: 59992202 | D7: 6017550 | E7: 41247410 | F7: 25441636 | G7: 10174 | H7: 149900 | J7: 71034 | K7: 80490 | L7: 406826 | M7: 135998704 | O7: 2581480 | P7: 271997406
A8: AZ | B8: 61489246 | D8: 13964484 | E8: 74336150 | F8: 62194518 | G8: -5072 | H8: 74750 | J8: 99892 | K8: -9052 | L8: 10280753 | M8: 223850289 | N8: 1060380 | O8: 364240 | P8: 447700578
A9: CA | B9: 562656 | C9: 23353682 | D9: 52661333 | E9: 179208948 | F9: 36427038 | G9: 1657536 | H9: 5647697 | I9: 2907920 | J9: 137756 | K9: -297148 | L9: 53970354 | M9: 390530816 | N9: 28047902 | O9: 6245143 | P9: 781061633
A10: CO | B10: 52764120 | D10: 3650770 | E10: 32796879 | G10: 118584 | H10: 151576 | J10: 23764 | K10: -525476 | L10: 2124760 | M10: 110772557 | N10: 19490300 | O10: 177278 | P10: 221545112
A11: CT | B11: 659402 | D11: 1110638 | E11: 40012915 | F11: 33762984 | G11: 929466 | H11: 989398 | J11: 677914 | K11: 6942 | L11: 211110 | M11: 78907103 | N11: 24590 | O11: 521742 | P11: 157814204
A12: DC | E12: 45540 | H12: 113122 | J12: 0 | M12: 158662 | P12: 317324
A13: DE | B13: 546776 | E13: 10800310 | H13: 118202 | I13: 504360 | J13: 401649 | L13: 99578 | M13: 12481288 | N13: 10414 | P13: 24962577
A14: FL | B14: 60544401 | D14: 465148 | E14: 343744428 | F14: 58624698 | G14: 5966639 | H14: 5137975 | I14: 10976 | J14: 4154716 | L14: 4824126 | M14: 488504071 | O14: 5030960 | P14: 977008138
A15: GA | B15: 64361110 | D15: 7393736 | E15: 103944220 | F15: 68725352 | G15: 171578 | H15: 681876 | J15: 871468 | K15: -977508 | L15: 3991674 | M15: 258478742 | O15: 9315239 | P15: 516957487
A16: HI | B16: 2622406 | C16: 220178 | D16: 193040 | G16: 764538 | H16: 611025 | I16: 111444 | J16: 13497894 | L16: 369152 | M16: 19593546 | N16: 1203868 | O16: 0 | P16: 39187091
A17: IA | B17: 57105997 | D17: 1849722 | E17: 14680140 | F17: 9790798 | G17: 0 | H17: 418353 | J17: 221130 | L17: 22912 | M17: 126761138 | N17: 42668114 | O17: 3972 | P17: 253522276
A18: ID | B18: 40676 | C18: 166224 | D18: 22048684 | E18: 6557484 | G18: 127944 | H18: 192606 | J18: 114 | L18: 1111928 | M18: 36344240 | N18: 5310104 | O18: 788474 | P18: 72688478
A19: IL | B19: 119283848 | D19: 293056 | E19: 34481838 | F19: 196203054 | G19: 454256 | H19: 852742 | I19: 401632 | J19: 106222 | L19: 132100 | M19: 376006714 | N19: 23797968 | O19: 0 | P19: 752013430
A20: IN | B20: 154910458 | D20: 445322 | E20: 53633989 | G20: 641276 | H20: 919778 | I20: 4651626 | J20: 261234 | L20: 581434 | M20: 226919421 | N20: 10874306 | O20: 0 | P20: 453838844
A21: KS | B21: 40947966 | D21: 52840 | E21: 6011430 | F21: 18336578 | G21: 10020 | H21: 127102 | J21: 104032 | L21: 15454 | M21: 103420426 | N21: 37815004 | P21: 206840852
A22: KY | B22: 118336286 | D22: 8835666 | E22: 29229998 | G22: 127080 | H22: 203134 | J22: 139984 | L22: 78872 | M22: 157608994 | O22: 657974 | P22: 315217988
A23: LA | B23: 23573448 | D23: 2359710 | E23: 123563547 | F23: 34305164 | G23: 1286252 | H23: 157574 | I23: 5195916 | J23: 8755589 | L23: 3036 | M23: 204256969 | O23: 5056732 | P23: 408513937
A24: MA | B24: 0 | D24: 2267240 | E24: 36771643 | F24: 8883126 | G24: 1692828 | H24: 2124391 | J24: 921432 | K24: -927566 | L24: 1956623 | M24: 54345765 | N24: 441965 | O24: 214082 | P24: 108691529
A25: MD | B25: 20133847 | D25: 5661772 | E25: 27699345 | F25: 29975862 | G25: 652254 | H25: 834693 | J25: 520030 | L25: 793440 | M25: 87619296 | N25: 1139968 | O25: 208086 | P25: 175238593
A26: ME | B26: 141655 | D26: 6522108 | E26: 4661434 | G26: 741687 | H26: 304858 | J26: 378214 | L26: 24064 | M26: 22561400 | N26: 4768590 | O26: 5018791 | P26: 45122801
A27: MI | B27: 84661728 | D27: 3138398 | E27: 61973783 | F27: 60957388 | G27: 504625 | H27: 1914934 | I27: 3195274 | J27: 2427023 | K27: -1396910 | L27: 236306 | M27: 231674190 | N27: 10914504 | O27: 3147135 | P27: 463348378
A28: MN | B28: 46910712 | D28: 2107008 | E28: 17110588 | F28: 29202658 | G28: 810361 | H28: 1062466 | J28: 93148 | L28: 2084042 | M28: 123034883 | N28: 21427300 | O28: 2226600 | P28: 246069766
A29: MO | B29: 126710270 | D29: 1656784 | E29: 14100111 | F29: 21310558 | G29: 2016 | H29: 163860 | J29: 199510 | K29: 93814 | L29: 182462 | M29: 170190768 | N29: 5669354 | O29: 102030 | P29: 340381537
A30: MS | B30: 10560086 | E30: 98963622 | F30: 13838940 | G30: 0 | H30: 33108 | J30: 54620 | L30: 651706 | M30: 126947542 | O30: 2845462 | P30: 253895086
A31: MT | B31: 26720052 | D31: 22809218 | E31: 952740 | G31: 609344 | I31: 24830 | J31: 892008 | L31: 68024 | M31: 56425662 | N31: 4306784 | O31: 42662 | P31: 112851324
A32: NC | B32: 63380938 | D32: 13210858 | E32: 86891498 | F32: 84153898 | G32: 1070112 | H32: 1312689 | J32: 1266162 | K32: 0 | L32: 12220756 | M32: 268498994 | N32: 1085544 | O32: 3906538 | P32: 536997987
A33: ND | B33: 55081330 | D33: 6360308 | E33: 2038546 | G33: 103894 | H33: 2076 | I33: 101976 | J33: 76686 | M33: 85230642 | N33: 21465826 | P33: 170461284
A34: NE | B34: 46610416 | D34: 2764146 | E34: 1929580 | F34: 11264280 | G34: 0 | H34: 186626 | J34: 24948 | L34: 54224 | M34: 73932432 | N34: 11098212 | O34: 0 | P34: 147864864
A35: NH | B35: 1320614 | D35: 2709976 | E35: 5983078 | F35: 20123392 | G35: 95354 | H35: 276909 | J35: 356160 | M35: 34174312 | N35: 813318 | O35: 2495510 | P35: 68348623
A36: NJ | B36: 2386576 | D36: 71076 | E36: 77726983 | F36: 63964212 | G36: 1103838 | H36: 1869862 | I36: 424096 | J36: 724729 | K36: -230204 | L36: 1980840 | M36: 150067199 | N36: 45192 | P36: 300134399
A37: NM | B37: 26803064 | C37: 26276 | D37: 299092 | E37: 23256354 | G37: -1462 | H37: 42312 | J37: 41474 | L37: 2697152 | M37: 65347364 | N37: 12183102 | P37: 130694728
A38: NV | B38: 4970092 | C38: 6923964 | D38: 3762532 | E38: 53377223 | G38: 57564 | H38: 106132 | I38: 0 | J38: 20490 | L38: 9437790 | M38: 79280482 | N38: 624696 | P38: 158560965
A39: NY | B39: 1380771 | D39: 59260000 | E39: 101620853 | F39: 85838022 | G39: 1746290 | H39: 3231934 | I39: 0 | J39: 3181421 | K39: -861436 | L39: 594944 | M39: 265041001 | N39: 7996666 | O39: 1051536 | P39: 530082002
A40: OH | B40: 117453925 | D40: 488038 | E40: 88429003 | F40: 36630014 | G40: 10866 | H40: 945194 | I40: 1573781 | J40: 2631493 | L40: 238110 | M40: 252369220 | N40: 3500044 | O40: 468754 | P40: 504738442
A41: OK | B41: 29813494 | D41: 4069794 | E41: 83225972 | G41: 114150 | H41: 153690 | J41: 35955 | K41: -270102 | L41: 123252 | M41: 172447442 | N41: 54676456 | O41: 504780 | P41: 344894883
...

Sheet BAU Electricity Generation
A1: BAU Model Output
A2: Time (Year) | B2: 2018 | C2: 2019 | D2: 2020 | E2: 2021 | F2: 2022 | G2: 2023 | H2: 2024 | I2: 2025 | J2: 2026 | K2: 2027 | L2: 2028 | M2: 2029 | N2: 2030 | O2: 2031 | P2: 2032 | Q2: 2033 | R2: 2034 | S2: 2035 | T2: 2036 | U2: 2037 | V2: 2038 | W2: 2039 | X2: 2040 | Y2: 2041 | Z2: 2042 | AA2: 2043 | AB2: 2044 | AC2: 2045 | AD2: 2046 | AE2: 2047 | AF2: 2048 | AG2: 2049 | AH2: 2050
A3: Output Electricity Generation by Type[hard coal es] : MostRecentRun | B3: 1312.57 | C3: 991.638 | D3: 569.686 | E3: 1108.74 | F3: 770.419 | G3: 747.374 | H3: 762.709 | I3: 690.395 | J3: 696.332 | K3: 688.622 | L3: 701.898 | M3: 675.637 | N3: 673.765 | O3: 670.86 | P3: 719.61 | Q3: 732.427 | R3: 738.116 | S3: 738.558 | T3: 750.479 | U3: 746.253 | V3: 732.264 | W3: 731.028 | X3: 745.959 | Y3: 737.553 | Z3: 747.614 | AA3: 763.625 | AB3: 786.347 | AC3: 801.162 | AD3: 813.403 | AE3: 831.712 | AF3: 863.555 | AG3: 882.702 | AH3: 900.491
A4: Output Electricity Generation by Type[natural gas nonpeaker es] : MostRecentRun | B4: 803.981 | C4: 1135.94 | D4: 1382.6 | E4: 992.705 | F4: 1387.83 | G4: 1419.33 | H4: 1398.79 | I4: 1452.15 | J4: 1473.31 | K4: 1485.46 | L4: 1475.07 | M4: 1511.35 | N4: 1519.27 | O4: 1541.34 | P4: 1508.66 | Q4: 1518.21 | R4: 1535.11 | S4: 1561.14 | T4: 1576.42 | U4: 1611.61 | V4: 1655.4 | W4: 1689.76 | X4: 1705.43 | Y4: 1744.89 | Z4: 1764.43 | AA4: 1777.63 | AB4: 1781.07 | AC4: 1789.65 | AD4: 1802.86 | AE4: 1806.36 | AF4: 1791.32 | AG4: 1790.25 | AH4: 1787.6
A5: Output Electricity Generation by Type[nuclear es] : MostRecentRun | B5: 804.676 | C5: 795.476 | D5: 795.476 | E5: 767.878 | F5: 767.878 | G5: 767.878 | H5: 767.878 | I5: 749.479 | J5: 685.084 | K5: 685.084 | L5: 685.084 | M5: 685.084 | N5: 685.084 | O5: 685.084 | P5: 685.084 | Q5: 675.884 | R5: 666.685 | S5: 666.685 | T5: 666.685 | U5: 666.685 | V5: 666.685 | W5: 666.685 | X5: 657.485 | Y5: 657.485 | Z5: 657.485 | AA5: 648.286 | AB5: 648.286 | AC5: 648.286 | AD5: 648.286 | AE5: 648.286 | AF5: 648.286 | AG5: 648.286 | AH5: 648.286
A6: Output Electricity Generation by Type[hydro es] : MostRecentRun | B6: 387.217 | C6: 388.005 | D6: 388.205 | E6: 389.829 | F6: 391.664 | G6: 393.401 | H6: 395.172 | I6: 397.117 | J6: 399.011 | K6: 400.694 | L6: 402.354 | M6: 403.837 | N6: 405.548 | O6: 407.094 | P6: 408.867 | Q6: 410.727 | R6: 412.654 | S6: 414.577 | T6: 416.495 | U6: 418.417 | V6: 420.361 | W6: 422.266 | X6: 424.222 | Y6: 426.116 | Z6: 428.009 | AA6: 429.965 | AB6: 431.573 | AC6: 433.458 | AD6: 435.21 | AE6: 436.557 | AF6: 437.927 | AG6: 439.285 | AH6: 440.663
A7: Output Electricity Generation by Type[onshore wind es] : MostRecentRun | B7: 354.308 | C7: 392.616 | D7: 394.38 | E7: 409.083 | F7: 445.792 | G7: 478.051 | H7: 507.058 | I7: 552.124 | J7: 589.108 | K7: 604.685 | L7: 623.228 | M7: 642.611 | N7: 657.019 | O7: 672.019 | P7: 685.055 | Q7: 703.548 | R7: 725.61 | S7: 745.093 | T7: 764.133 | U7: 783.334 | V7: 805.542 | W7: 823.341 | X7: 846.651 | Y7: 864.505 | Z7: 881.464 | AA7: 903.127 | AB7: 920.661 | AC7: 937.896 | AD7: 952.812 | AE7: 968.331 | AF7: 983.995 | AG7: 997.513 | AH7: 1014
A8: Output Electricity Generation by Type[solar PV es] : MostRecentRun | B8: 49.2678 | C8: 49.2357 | D8: 49.1944 | E8: 50.5357 | F8: 55.0311 | G8: 59.3664 | H8: 63.0271 | I8: 78.2438 | J8: 100.23 | K8: 103.935 | L8: 109.387 | M8: 115.201 | N8: 118.763 | O8: 120.474 | P8: 121.553 | Q8: 125.796 | R8: 132.112 | S8: 135.856 | T8: 139.345 | U8: 143.285 | V8: 148.97 | W8: 153.41 | X8: 159.949 | Y8: 164.012 | Z8: 168.451 | AA8: 174.917 | AB8: 180.217 | AC8: 186.712 | AD8: 193.155 | AE8: 199.532 | AF8: 206.54 | AG8: 211.98 | AH8: 219.141
A9: Output Electricity Generation by Type[solar thermal es] : MostRecentRun | B9: 3.35722 | C9: 3.35722 | D9: 3.35722 | E9: 3.35722 | F9: 3.35722 | G9: 3.35722 | H9: 3.35722 | I9: 4.19355 | J9: 5.02989 | K9: 5.86622 | L9: 7.53889 | M9: 10.0479 | N9: 12.5569 | O9: 15.0659 | P9: 17.5749 | Q9: 20.9202 | R9: 24.2656 | S9: 27.6109 | T9: 30.9563 | U9: 34.3016 | V9: 37.6469 | W9: 40.9923 | X9: 44.3376 | Y9: 47.683 | Z9: 51.0283 | AA9: 54.3736 | AB9: 57.719 | AC9: 61.0643 | AD9: 64.4097 | AE9: 67.755 | AF9: 71.1003 | AG9: 74.4457 | AH9: 77.791
A10: Output Electricity Generation by Type[biomass es] : MostRecentRun | B10: 3.46983 | C10: 1.89993 | D10: 0.775379 | E10: 2.69711 | F10: 1.79214 | G10: 1.99152 | H10: 2.27277 | I10: 2.73235 | J10: 2.86434 | K10: 2.87692 | L10: 3.0811 | M10: 3.10335 | N10: 3.24719 | O10: 3.18312 | P10: 3.57894 | Q10: 3.7421 | R10: 3.84695 | S10: 3.96144 | T10: 4.2084 | U10: 4.24017 | V10: 4.2264 | W10: 4.28396 | X10: 4.52572 | Y10: 4.43341 | Z10: 4.57116 | AA10: 4.78726 | AB10: 5.13146 | AC10: 5.42373 | AD10: 5.6495 | AE10: 5.96895 | AF10: 6.65945 | AG10: 7.1413 | AH10: 7.6137
A11: Output Electricity Generation by Type[geothermal es] : MostRecentRun | B11: 16.3097 | C11: 16.4523 | D11: 16.4523 | E11: 17.3793 | F11: 18.9481 | G11: 20.5881 | H11: 22.2995 | I11: 24.1534 | J11: 26.0074 | K11: 27.79 | L11: 29.644 | M11: 31.498 | N11: 33.3519 | O11: 35.2059 | P11: 37.0599 | Q11: 38.9138 | R11: 40.7678 | S11: 42.6218 | T11: 44.4757 | U11: 46.3297 | V11: 48.1837 | W11: 50.0376 | X11: 51.8916 | Y11: 53.7456 | Z11: 55.5995 | AA11: 57.4535 | AB11: 59.3075 | AC11: 61.1614 | AD11: 63.0154 | AE11: 64.8694 | AF11: 66.7233 | AG11: 68.506 | AH11: 70.36
