Workbook
Name cities: 'Solar by State'!$B$61:$B$65

Sheet About
A1: BAU Expected Capacity Factors | B1: Nebraska | C1: 44307
B2: =LOOKUP(B1,I10:J59,J10:J59)
A3: Source: | B3: Existing Capacity Factors, Except for Coal, Solar PV, and Onshore Wind (and capacity factor for newly built Nuclear) | D3: Existing and New Offshore Wind, New Solar Thermal Capacity Factors; Trends for New Solar PV and Onshore Wind Capacity Factors
B4: Energy Information Administration | D4: National Renewable Energy Lab
B5: 2019 | D5: 2020
B6: Electric Power Annual 2018 | D6: Annual Technology Baseline (ATB) Spreadsheet - 2020 Final
B7: http://www.eia.gov/electricity/annual/ | D7: https://atb.nrel.gov/
B8: Tables 4.8.A and 4.8.B
B10: Existing Capacity Factor for Hard Coal, Lignite, Solar PV, and Onshore Wind | I10: Alabama | J10: AL
B11: Energy Information Administration | I11: Alaska | J11: AK
B12: 2020 | I12: Arizona | J12: AZ
B13: Forms 860 and 923 | I13: Arkansas | J13: AR
B14: https://www.eia.gov/electricity/ | I14: California | J14: CA
B15: Form 860: 3_1_Generator_Y2018 (Operable tab) and Form 923: EIA923_Schedules_2_3_4_5_M_12_2018, (Page 1 Generator and Fuel Data tab) | I15: Colorado | J15: CO
I16: Connecticut | J16: CT
B17: Gridlab 2035 Study | I17: Delaware | J17: DE
B18: Berkley and Gridab | I18: Florida | J18: FL
B19: 2020 | I19: Georgia | J19: GA
B20: Regional and State Generation Capacity | I20: Hawaii | J20: HI
B21: https://www.2035report.com/downloads/ | I21: Idaho | J21: ID
I22: Illinois | J22: IL
I23: Indiana | J23: IN
I24: Iowa | J24: IA
I25: Kansas | J25: KS
I26: Kentucky | J26: KY
A27: Notes | I27: Louisiana | J27: LA
A28: This variable represents the capacity factors that electricity suppliers expect to run each type of | I28: Maine | J28: ME
A29: power plant. Given the choice, an electricity supplier would sooner build a new nonpeaker power | I29: Maryland | J29: MD
A30: plant than attempt to rely on running a nonpeaker plant at greater than its Expected Capacity Factor. | I30: Massachusetts | J30: MA
I31: Michigan | J31: MI
A32: For all sources other than nuclear, onshore/offshore wind, solar PV, we assume a 10% improvement in the | I32: Minnesota | J32: MN
A33: target capacity factor of new units relative to the observed capacity factor of existing units. | I33: Mississippi | J33: MS
A34: This is meant to account for improvements in efficiency (e.g. heat rate) that are likely to make the unit | I34: Missouri | J34: MO
A35: more cost-effective to run, and therefore likely to increase the amount it is dispatched. | I35: Montana | J35: MT
I36: Nebraska | J36: NE
A37: For onshore/offshore wind, solar PV, and solar thermal we take capacity factors for new resources from the NREL ATB. | I37: Nevada | J37: NV
A38: These types of plants tend to be limited by resources rather than dispatch cost. For onshore and offshore wind, | I38: New Hampshire | J38: NH
A39: we average based on a subset of the ATB classes. | I39: New Jersey | J39: NJ
I40: New Mexico | J40: NM
A41: For nuclear, we assume that new plants will operate at the same level of efficiency as existing plants, | I41: New York | J41: NY
...

Sheet NREL ATB
A1: ATB Solar - Utility PV
B2: Basis Year
B3: 2018 | C3: 2019 | D3: 2020 | E3: 2021 | F3: 2022 | G3: 2023 | H3: 2024 | I3: 2025 | J3: 2026 | K3: 2027 | L3: 2028 | M3: 2029 | N3: 2030 | O3: 2031 | P3: 2032 | Q3: 2033 | R3: 2034 | S3: 2035 | T3: 2036 | U3: 2037 | V3: 2038 | W3: 2039 | X3: 2040 | Y3: 2041 | Z3: 2042 | AA3: 2043 | AB3: 2044 | AC3: 2045 | AD3: 2046 | AE3: 2047 | AF3: 2048 | AG3: 2049 | AH3: 2050
A4: Utility PV - Seattle - Advanced | B4: 0.21802831 | C4: 0.22141786 | D4: 0.22480741 | E4: 0.22819696 | F4: 0.23158652 | G4: 0.23497607 | H4: 0.23836562 | I4: 0.24175517 | J4: 0.24514472 | K4: 0.24853428 | L4: 0.25192383 | M4: 0.25531338 | N4: 0.25870293 | O4: 0.26020969 | P4: 0.26171644 | Q4: 0.26322319 | R4: 0.26472994 | S4: 0.2662367 | T4: 0.26774345 | U4: 0.2692502 | V4: 0.27075695 | W4: 0.2722637 | X4: 0.27377046 | Y4: 0.27527721 | Z4: 0.27678396 | AA4: 0.27829071 | AB4: 0.27979747 | AC4: 0.28130422 | AD4: 0.28281097 | AE4: 0.28431772 | AF4: 0.28582448 | AG4: 0.28733123 | AH4: 0.28883798
A5: Utility PV - Seattle - Moderate | B5: 0.21802831 | C5: 0.21957153 | D5: 0.22111476 | E5: 0.22265798 | F5: 0.22420121 | G5: 0.22574444 | H5: 0.22728766 | I5: 0.22883089 | J5: 0.23037411 | K5: 0.23191734 | L5: 0.23346057 | M5: 0.23500379 | N5: 0.23654702 | O5: 0.23765481 | P5: 0.23876261 | Q5: 0.2398704 | R5: 0.2409782 | S5: 0.242086 | T5: 0.24319379 | U5: 0.24430159 | V5: 0.24540938 | W5: 0.24651718 | X5: 0.24762498 | Y5: 0.24873277 | Z5: 0.24984057 | AA5: 0.25094836 | AB5: 0.25205616 | AC5: 0.25316395 | AD5: 0.25427175 | AE5: 0.25537955 | AF5: 0.25648734 | AG5: 0.25759514 | AH5: 0.25870293
A6: Utility PV - Seattle - Conservative | B6: 0.21802831 | C6: 0.21802831 | D6: 0.21802831 | E6: 0.21802831 | F6: 0.21802831 | G6: 0.21802831 | H6: 0.21802831 | I6: 0.21802831 | J6: 0.21802831 | K6: 0.21802831 | L6: 0.21802831 | M6: 0.21802831 | N6: 0.21802831 | O6: 0.21895424 | P6: 0.21988018 | Q6: 0.22080611 | R6: 0.22173205 | S6: 0.22265798 | T6: 0.22358392 | U6: 0.22450985 | V6: 0.22543579 | W6: 0.22636173 | X6: 0.22728766 | Y6: 0.2282136 | Z6: 0.22913953 | AA6: 0.23006547 | AB6: 0.2309914 | AC6: 0.23191734 | AD6: 0.23284327 | AE6: 0.23376921 | AF6: 0.23469515 | AG6: 0.23562108 | AH6: 0.23654702
A7: Utility PV - Chicago - Advanced | B7: 0.25165533 | C7: 0.25542499 | D7: 0.25919464 | E7: 0.2629643 | F7: 0.26673396 | G7: 0.27050362 | H7: 0.27427328 | I7: 0.27804293 | J7: 0.28181259 | K7: 0.28558225 | L7: 0.28935191 | M7: 0.29312157 | N7: 0.29689122 | O7: 0.29846458 | P7: 0.30003793 | Q7: 0.30161129 | R7: 0.30318464 | S7: 0.304758 | T7: 0.30633135 | U7: 0.30790471 | V7: 0.30947806 | W7: 0.31105142 | X7: 0.31262477 | Y7: 0.31419812 | Z7: 0.31577148 | AA7: 0.31734483 | AB7: 0.31891819 | AC7: 0.32049154 | AD7: 0.3220649 | AE7: 0.32363825 | AF7: 0.32521161 | AG7: 0.32678496 | AH7: 0.32835832
A8: Utility PV - Chicago - Moderate | B8: 0.25165533 | C8: 0.25337412 | D8: 0.25509291 | E8: 0.2568117 | F8: 0.25853049 | G8: 0.26024927 | H8: 0.26196806 | I8: 0.26368685 | J8: 0.26540564 | K8: 0.26712443 | L8: 0.26884322 | M8: 0.27056201 | N8: 0.2722808 | O8: 0.27351132 | P8: 0.27474184 | Q8: 0.27597236 | R8: 0.27720288 | S8: 0.27843341 | T8: 0.27966393 | U8: 0.28089445 | V8: 0.28212497 | W8: 0.28335549 | X8: 0.28458601 | Y8: 0.28581653 | Z8: 0.28704705 | AA8: 0.28827758 | AB8: 0.2895081 | AC8: 0.29073862 | AD8: 0.29196914 | AE8: 0.29319966 | AF8: 0.29443018 | AG8: 0.2956607 | AH8: 0.29689122
A9: Utility PV - Chicago - Conservative | B9: 0.25165533 | C9: 0.25165533 | D9: 0.25165533 | E9: 0.25165533 | F9: 0.25165533 | G9: 0.25165533 | H9: 0.25165533 | I9: 0.25165533 | J9: 0.25165533 | K9: 0.25165533 | L9: 0.25165533 | M9: 0.25165533 | N9: 0.25165533 | O9: 0.2526866 | P9: 0.25371788 | Q9: 0.25474915 | R9: 0.25578042 | S9: 0.2568117 | T9: 0.25784297 | U9: 0.25887424 | V9: 0.25990552 | W9: 0.26093679 | X9: 0.26196806 | Y9: 0.26299934 | Z9: 0.26403061 | AA9: 0.26506188 | AB9: 0.26609316 | AC9: 0.26712443 | AD9: 0.26815571 | AE9: 0.26918698 | AF9: 0.27021825 | AG9: 0.27124953 | AH9: 0.2722808
A10: Utility PV - Kansas City - Advanced | B10: 0.27223835 | C10: 0.27597289 | D10: 0.27970742 | E10: 0.28344195 | F10: 0.28717649 | G10: 0.29091102 | H10: 0.29464555 | I10: 0.29838009 | J10: 0.30211462 | K10: 0.30584915 | L10: 0.30958369 | M10: 0.31331822 | N10: 0.31705275 | O10: 0.3188157 | P10: 0.32057865 | Q10: 0.32234159 | R10: 0.32410454 | S10: 0.32586749 | T10: 0.32763043 | U10: 0.32939338 | V10: 0.33115633 | W10: 0.33291928 | X10: 0.33468222 | Y10: 0.33644517 | Z10: 0.33820812 | AA10: 0.33997106 | AB10: 0.34173401 | AC10: 0.34349696 | AD10: 0.34525991 | AE10: 0.34702285 | AF10: 0.3487858 | AG10: 0.35054875 | AH10: 0.35231169
A11: Utility PV - Kansas City - Moderate | B11: 0.27223835 | C11: 0.27395061 | D11: 0.27566287 | E11: 0.27737512 | F11: 0.27908738 | G11: 0.28079964 | H11: 0.28251189 | I11: 0.28422415 | J11: 0.2859364 | K11: 0.28764866 | L11: 0.28936092 | M11: 0.29107317 | N11: 0.29278543 | O11: 0.2939988 | P11: 0.29521216 | Q11: 0.29642553 | R11: 0.29763889 | S11: 0.29885226 | T11: 0.30006563 | U11: 0.30127899 | V11: 0.30249236 | W11: 0.30370572 | X11: 0.30491909 | Y11: 0.30613246 | Z11: 0.30734582 | AA11: 0.30855919 | AB11: 0.30977256 | AC11: 0.31098592 | AD11: 0.31219929 | AE11: 0.31341265 | AF11: 0.31462602 | AG11: 0.31583939 | AH11: 0.31705275
A12: Utility PV - Kansas City - Conservative | B12: 0.27223835 | C12: 0.27223835 | D12: 0.27223835 | E12: 0.27223835 | F12: 0.27223835 | G12: 0.27223835 | H12: 0.27223835 | I12: 0.27223835 | J12: 0.27223835 | K12: 0.27223835 | L12: 0.27223835 | M12: 0.27223835 | N12: 0.27223835 | O12: 0.27326571 | P12: 0.27429306 | Q12: 0.27532042 | R12: 0.27634777 | S12: 0.27737512 | T12: 0.27840248 | U12: 0.27942983 | V12: 0.28045718 | W12: 0.28148454 | X12: 0.28251189 | Y12: 0.28353925 | Z12: 0.2845666 | AA12: 0.28559395 | AB12: 0.28662131 | AC12: 0.28764866 | AD12: 0.28867601 | AE12: 0.28970337 | AF12: 0.29073072 | AG12: 0.29175808 | AH12: 0.29278543
A13: Utility PV - Los Angeles - Advanced | B13: 0.31886897 | C13: 0.32241414 | D13: 0.3259593 | E13: 0.32950447 | F13: 0.33304964 | G13: 0.3365948 | H13: 0.34013997 | I13: 0.34368513 | J13: 0.3472303 | K13: 0.35077547 | L13: 0.35432063 | M13: 0.3578658 | N13: 0.36141097 | O13: 0.36316593 | P13: 0.36492089 | Q13: 0.36667585 | R13: 0.3684308 | S13: 0.37018576 | T13: 0.37194072 | U13: 0.37369568 | V13: 0.37545064 | W13: 0.3772056 | X13: 0.37896056 | Y13: 0.38071552 | Z13: 0.38247048 | AA13: 0.38422544 | AB13: 0.3859804 | AC13: 0.38773536 | AD13: 0.38949032 | AE13: 0.39124528 | AF13: 0.39300024 | AG13: 0.3947552 | AH13: 0.39651016
A14: Utility PV - Los Angeles - Moderate | B14: 0.31886897 | C14: 0.32051742 | D14: 0.32216587 | E14: 0.32381432 | F14: 0.32546277 | G14: 0.32711122 | H14: 0.32875968 | I14: 0.33040813 | J14: 0.33205658 | K14: 0.33370503 | L14: 0.33535348 | M14: 0.33700193 | N14: 0.33865038 | O14: 0.33978841 | P14: 0.34092644 | Q14: 0.34206447 | R14: 0.3432025 | S14: 0.34434053 | T14: 0.34547856 | U14: 0.34661659 | V14: 0.34775461 | W14: 0.34889264 | X14: 0.35003067 | Y14: 0.3511687 | Z14: 0.35230673 | AA14: 0.35344476 | AB14: 0.35458279 | AC14: 0.35572082 | AD14: 0.35685885 | AE14: 0.35799688 | AF14: 0.35913491 | AG14: 0.36027294 | AH14: 0.36141097
A15: Utility PV - Los Angeles - Conservative | B15: 0.31886897 | C15: 0.31886897 | D15: 0.31886897 | E15: 0.31886897 | F15: 0.31886897 | G15: 0.31886897 | H15: 0.31886897 | I15: 0.31886897 | J15: 0.31886897 | K15: 0.31886897 | L15: 0.31886897 | M15: 0.31886897 | N15: 0.31886897 | O15: 0.31985804 | P15: 0.32084711 | Q15: 0.32183618 | R15: 0.32282525 | S15: 0.32381432 | T15: 0.32480339 | U15: 0.32579246 | V15: 0.32678153 | W15: 0.3277706 | X15: 0.32875968 | Y15: 0.32974875 | Z15: 0.33073782 | AA15: 0.33172689 | AB15: 0.33271596 | AC15: 0.33370503 | AD15: 0.3346941 | AE15: 0.33568317 | AF15: 0.33667224 | AG15: 0.33766131 | AH15: 0.33865038
... A18: Utility PV - Daggett, CA - Conservative | B18: 0.35146192 | C18: 0.35146192 | D18: 0.35146192 | E18: 0.35146192 | F18: 0.35146192 | G18: 0.35146192 | H18: 0.35146192 | I18: 0.35146192 | J18: 0.35146192 | K18: 0.35146192 | L18: 0.35146192 | M18: 0.35146192 | N18: 0.35146192 | O18: 0.35250097 | P18: 0.35354002 | Q18: 0.35457908 | R18: 0.35561813 | S18: 0.35665718 | T18: 0.35769624 | U18: 0.35873529 | V18: 0.35977434 | W18: 0.3608134 | X18: 0.36185245 | Y18: 0.3628915 | Z18: 0.36393056 | AA18: 0.36496961 | AB18: 0.36600866 | AC18: 0.36704772 | AD18: 0.36808677 | AE18: 0.36912582 | AF18: 0.37016487 | AG18: 0.37120393 | AH18: 0.37224298
A20: Average | B20: =AVERAGE(B4:B18) | C20: =AVERAGE(C4:C18) | D20: =AVERAGE(D4:D18) | E20: =AVERAGE(E4:E18) | F20: =AVERAGE(F4:F18) | G20: =AVERAGE(G4:G18) | H20: =AVERAGE(H4:H18) | I20: =AVERAGE(I4:I18) | ... AH20: =AVERAGE(AH4:AH18)
A22: ATB Solar Thermal
B23: 2018 | C23: 2019 | D23: 2020 | E23: 2021 | F23: 2022 | G23: 2023 | H23: 2024 | I23: 2025 | J23: 2026 | K23: 2027 | L23: 2028 | M23: 2029 | N23: 2030 | O23: 2031 | P23: 2032 | Q23: 2033 | R23: 2034 | S23: 2035 | T23: 2036 | U23: 2037 | V23: 2038 | W23: 2039 | X23: 2040 | Y23: 2041 | Z23: 2042 | AA23: 2043 | AB23: 2044 | AC23: 2045 | AD23: 2046 | AE23: 2047 | AF23: 2048 | AG23: 2049 | AH23: 2050
A24: 10hrs TES - Class 1 - Advanced | B24: 0.504 | C24: 0.504 | D24: 0.504 | E24: 0.504 | F24: 0.504 | G24: 0.504 | H24: 0.504 | I24: 0.504 | J24: 0.504 | K24: 0.504 | L24: 0.504 | M24: 0.504 | N24: 0.504 | O24: 0.504 | P24: 0.504 | Q24: 0.504 | R24: 0.504 | S24: 0.504 | T24: 0.504 | U24: 0.504 | V24: 0.504 | W24: 0.504 | X24: 0.504 | Y24: 0.504 | Z24: 0.504 | AA24: 0.504 | AB24: 0.504 | AC24: 0.504 | AD24: 0.504 | AE24: 0.504 | AF24: 0.504 | AG24: 0.504 | AH24: 0.504
A25: 10hrs TES - Class 1 - Moderate | B25: 0.504 | C25: 0.504 | D25: 0.504 | E25: 0.504 | F25: 0.504 | G25: 0.504 | H25: 0.504 | I25: 0.504 | J25: 0.504 | K25: 0.504 | L25: 0.504 | M25: 0.504 | N25: 0.504 | O25: 0.504 | P25: 0.504 | Q25: 0.504 | R25: 0.504 | S25: 0.504 | T25: 0.504 | U25: 0.504 | V25: 0.504 | W25: 0.504 | X25: 0.504 | Y25: 0.504 | Z25: 0.504 | AA25: 0.504 | AB25: 0.504 | AC25: 0.504 | AD25: 0.504 | AE25: 0.504 | AF25: 0.504 | AG25: 0.504 | AH25: 0.504
A26: 10hrs TES - Class 1 - Conservative | B26: 0.504 | C26: 0.504 | D26: 0.504 | E26: 0.504 | F26: 0.504 | G26: 0.504 | H26: 0.504 | I26: 0.504 | J26: 0.504 | K26: 0.504 | L26: 0.504 | M26: 0.504 | N26: 0.504 | O26: 0.504 | P26: 0.504 | Q26: 0.504 | R26: 0.504 | S26: 0.504 | T26: 0.504 | U26: 0.504 | V26: 0.504 | W26: 0.504 | X26: 0.504 | Y26: 0.504 | Z26: 0.504 | AA26: 0.504 | AB26: 0.504 | AC26: 0.504 | AD26: 0.504 | AE26: 0.504 | AF26: 0.504 | AG26: 0.504 | AH26: 0.504
A27: 10hrs TES - Class 3 - Advanced | B27: 0.612 | C27: 0.612 | D27: 0.612 | E27: 0.612 | F27: 0.612 | G27: 0.612 | H27: 0.612 | I27: 0.612 | J27: 0.612 | K27: 0.612 | L27: 0.612 | M27: 0.612 | N27: 0.612 | O27: 0.612 | P27: 0.612 | Q27: 0.612 | R27: 0.612 | S27: 0.612 | T27: 0.612 | U27: 0.612 | V27: 0.612 | W27: 0.612 | X27: 0.612 | Y27: 0.612 | Z27: 0.612 | AA27: 0.612 | AB27: 0.612 | AC27: 0.612 | AD27: 0.612 | AE27: 0.612 | AF27: 0.612 | AG27: 0.612 | AH27: 0.612
A28: 10hrs TES - Class 3 - Moderate | B28: 0.612 | C28: 0.612 | D28: 0.612 | E28: 0.612 | F28: 0.612 | G28: 0.612 | H28: 0.612 | I28: 0.612 | J28: 0.612 | K28: 0.612 | L28: 0.612 | M28: 0.612 | N28: 0.612 | O28: 0.612 | P28: 0.612 | Q28: 0.612 | R28: 0.612 | S28: 0.612 | T28: 0.612 | U28: 0.612 | V28: 0.612 | W28: 0.612 | X28: 0.612 | Y28: 0.612 | Z28: 0.612 | AA28: 0.612 | AB28: 0.612 | AC28: 0.612 | AD28: 0.612 | AE28: 0.612 | AF28: 0.612 | AG28: 0.612 | AH28: 0.612
A29: 10hrs TES - Class 3 - Conservative | B29: 0.612 | C29: 0.612 | D29: 0.612 | E29: 0.612 | F29: 0.612 | G29: 0.612 | H29: 0.612 | I29: 0.612 | J29: 0.612 | K29: 0.612 | L29: 0.612 | M29: 0.612 | N29: 0.612 | O29: 0.612 | P29: 0.612 | Q29: 0.612 | R29: 0.612 | S29: 0.612 | T29: 0.612 | U29: 0.612 | V29: 0.612 | W29: 0.612 | X29: 0.612 | Y29: 0.612 | Z29: 0.612 | AA29: 0.612 | AB29: 0.612 | AC29: 0.612 | AD29: 0.612 | AE29: 0.612 | AF29: 0.612 | AG29: 0.612 | AH29: 0.612
A30: 10hrs TES - Class 5 - Advanced | B30: 0.638 | C30: 0.638 | D30: 0.638 | E30: 0.638 | F30: 0.638 | G30: 0.638 | H30: 0.638 | I30: 0.638 | J30: 0.638 | K30: 0.638 | L30: 0.638 | M30: 0.638 | N30: 0.638 | O30: 0.638 | P30: 0.638 | Q30: 0.638 | R30: 0.638 | S30: 0.638 | T30: 0.638 | U30: 0.638 | V30: 0.638 | W30: 0.638 | X30: 0.638 | Y30: 0.638 | Z30: 0.638 | AA30: 0.638 | AB30: 0.638 | AC30: 0.638 | AD30: 0.638 | AE30: 0.638 | AF30: 0.638 | AG30: 0.638 | AH30: 0.638
A31: 10hrs TES - Class 5 - Moderate | B31: 0.638 | C31: 0.638 | D31: 0.638 | E31: 0.638 | F31: 0.638 | G31: 0.638 | H31: 0.638 | I31: 0.638 | J31: 0.638 | K31: 0.638 | L31: 0.638 | M31: 0.638 | N31: 0.638 | O31: 0.638 | P31: 0.638 | Q31: 0.638 | R31: 0.638 | S31: 0.638 | T31: 0.638 | U31: 0.638 | V31: 0.638 | W31: 0.638 | X31: 0.638 | Y31: 0.638 | Z31: 0.638 | AA31: 0.638 | AB31: 0.638 | AC31: 0.638 | AD31: 0.638 | AE31: 0.638 | AF31: 0.638 | AG31: 0.638 | AH31: 0.638
A32: 10hrs TES - Class 5 - Conservative | B32: 0.638 | C32: 0.638 | D32: 0.638 | E32: 0.638 | F32: 0.638 | G32: 0.638 | H32: 0.638 | I32: 0.638 | J32: 0.638 | K32: 0.638 | L32: 0.638 | M32: 0.638 | N32: 0.638 | O32: 0.638 | P32: 0.638 | Q32: 0.638 | R32: 0.638 | S32: 0.638 | T32: 0.638 | U32: 0.638 | V32: 0.638 | W32: 0.638 | X32: 0.638 | Y32: 0.638 | Z32: 0.638 | AA32: 0.638 | AB32: 0.638 | AC32: 0.638 | AD32: 0.638 | AE32: 0.638 | AF32: 0.638 | AG32: 0.638 | AH32: 0.638
A35: ATB Onshore Wind
B36: 2018 | C36: 2019 | D36: 2020 | E36: 2021 | F36: 2022 | G36: 2023 | H36: 2024 | I36: 2025 | J36: 2026 | K36: 2027 | L36: 2028 | M36: 2029 | N36: 2030 | O36: 2031 | P36: 2032 | Q36: 2033 | R36: 2034 | S36: 2035 | T36: 2036 | U36: 2037 | V36: 2038 | W36: 2039 | X36: 2040 | Y36: 2041 | Z36: 2042 | AA36: 2043 | AB36: 2044 | AC36: 2045 | AD36: 2046 | AE36: 2047 | AF36: 2048 | AG36: 2049 | AH36: 2050
A37: Class 1 - Advanced | B37: 0.521036 | C37: 0.52499633 | D37: 0.52895667 | E37: 0.532917 | F37: 0.53687733 | G37: 0.54083767 | H37: 0.544798 | I37: 0.54875833 | J37: 0.55271867 | K37: 0.556679 | L37: 0.56063933 | M37: 0.56459967 | N37: 0.56856 | O37: 0.56912856 | P37: 0.56969712 | Q37: 0.57026568 | R37: 0.57083424 | S37: 0.5714028 | T37: 0.57197136 | U37: 0.57253992 | V37: 0.57310848 | W37: 0.57367704 | X37: 0.5742456 | Y37: 0.57481416 | Z37: 0.57538272 | AA37: 0.57595128 | AB37: 0.57651984 | AC37: 0.5770884 | AD37: 0.57765696 | AE37: 0.57822552 | AF37: 0.57879408 | AG37: 0.57936264 | AH37: 0.5799312
A38: Class 1 - Moderate | B38: 0.521036 | C38: 0.52281058 | D38: 0.52458517 | E38: 0.52635975 | F38: 0.52813433 | G38: 0.52990892 | H38: 0.5316835 | I38: 0.53345808 | J38: 0.53523267 | K38: 0.53700725 | L38: 0.53878183 | M38: 0.54055642 | N38: 0.542331 | O38: 0.54260217 | P38: 0.54287333 | Q38: 0.5431445 | R38: 0.54341566 | S38: 0.54368683 | T38: 0.54395799 | U38: 0.54422916 | V38: 0.54450032 | W38: 0.54477149 | X38: 0.54504265 | Y38: 0.54531382 | Z38: 0.54558499 | AA38: 0.54585615 | AB38: 0.54612732 | AC38: 0.54639848 | AD38: 0.54666965 | AE38: 0.54694081 | AF38: 0.54721198 | AG38: 0.54748314 | AH38: 0.54775431
A39: Class 1 - Conservative | B39: 0.521036 | C39: 0.52003258 | D39: 0.51902917 | E39: 0.51802575 | F39: 0.51702233 | G39: 0.51601892 | H39: 0.5150155 | I39: 0.51401208 | J39: 0.51300867 | K39: 0.51200525 | L39: 0.51100183 | M39: 0.50999842 | N39: 0.508995 | O39: 0.50912225 | P39: 0.5092495 | Q39: 0.50937675 | R39: 0.50950399 | S39: 0.50963124 | T39: 0.50975849 | U39: 0.50988574 | V39: 0.51001299 | W39: 0.51014024 | X39: 0.51026749 | Y39: 0.51039474 | Z39: 0.51052198 | AA39: 0.51064923 | AB39: 0.51077648 | AC39: 0.51090373 | AD39: 0.51103098 | AE39: 0.51115823 | AF39: 0.51128548 | AG39: 0.51141273 | AH39: 0.51153997
A40: Class 2 - Advanced | B40: 0.467398 | C40: 0.47223067 | D40: 0.47706333 | E40: 0.481896 | F40: 0.48672867 | G40: 0.49156133 | H40: 0.496394 | I40: 0.50122667 | J40: 0.50605933 | K40: 0.510892 | L40: 0.51572467 | M40: 0.52055733 | N40: 0.52539 | O40: 0.52617808 | P40: 0.52696617 | Q40: 0.52775425 | R40: 0.52854234 | S40: 0.52933043 | T40: 0.53011851 | U40: 0.5309066 | V40: 0.53169468 | W40: 0.53248277 | X40: 0.53327085 | Y40: 0.53405894 | Z40: 0.53484702 | AA40: 0.53563511 | AB40: 0.53642319 | AC40: 0.53721127 | AD40: 0.53799936 | AE40: 0.53878744 | AF40: 0.53957553 | AG40: 0.54036361 | AH40: 0.5411517
A41: Class 2 - Moderate | B41: 0.467398 | C41: 0.46998767 | D41: 0.47257733 | E41: 0.475167 | F41: 0.47775667 | G41: 0.48034633 | H41: 0.482936 | I41: 0.48552567 | J41: 0.48811533 | K41: 0.490705 | L41: 0.49329467 | M41: 0.49588433 | N41: 0.498474 | O41: 0.49884786 | P41: 0.49922171 | Q41: 0.49959557 | R41: 0.49996942 | S41: 0.50034328 | T41: 0.50071713 | U41: 0.50109099 | V41: 0.50146484 | W41: 0.5018387 | X41: 0.50221255 | Y41: 0.50258641 | Z41: 0.50296027 | AA41: 0.50333412 | AB41: 0.50370798 | AC41: 0.50408183 | AD41: 0.50445569 | AE41: 0.50482954 | AF41: 0.5052034 | AG41: 0.50557725 | AH41: 0.50595111
A42: Class 2 - Conservative | B42: 0.467398 | C42: 0.467337 | D42: 0.467276 | E42: 0.467215 | F42: 0.467154 | G42: 0.467093 | H42: 0.467032 | I42: 0.466971 | J42: 0.46691 | K42: 0.466849 | L42: 0.466788 | M42: 0.466727 | N42: 0.466666 | O42: 0.466841 | P42: 0.467016 | Q42: 0.467191 | R42: 0.467366 | S42: 0.467541 | T42: 0.467716 | U42: 0.467891 | V42: 0.468066 | W42: 0.468241 | X42: 0.468416 | Y42: 0.468591 | Z42: 0.468766 | AA42: 0.468941 | AB42: 0.469116 | AC42: 0.469291 | AD42: 0.469466 | AE42: 0.469641 | AF42: 0.469816 | AG42: 0.469991 | AH42: 0.470166
A43: Class 3 - Advanced | B43: 0.446015 | C43: 0.45147075 | D43: 0.4569265 | E43: 0.46238225 | F43: 0.467838 | G43: 0.47329375 | H43: 0.4787495 | I43: 0.48420525 | J43: 0.489661 | K43: 0.49511675 | L43: 0.5005725 | M43: 0.50602825 | N43: 0.511484 | O43: 0.51250697 | P43: 0.51352994 | Q43: 0.5145529 | R43: 0.51557587 | S43: 0.51659884 | T43: 0.51762181 | U43: 0.51864478 | V43: 0.51966774 | W43: 0.52069071 | X43: 0.52171368 | Y43: 0.52273665 | Z43: 0.52375962 | AA43: 0.52478258 | AB43: 0.52580555 | AC43: 0.52682852 | AD43: 0.52785149 | AE43: 0.52887446 | AF43: 0.52989742 | AG43: 0.53092039 | AH43: 0.53194336
A44: Class 3 - Moderate | B44: 0.446015 | C44: 0.44923592 | D44: 0.45245683 | E44: 0.45567775 | F44: 0.45889867 | G44: 0.46211958 | H44: 0.4653405 | I44: 0.46856142 | J44: 0.47178233 | K44: 0.47500325 | L44: 0.47822417 | M44: 0.48144508 | N44: 0.484666 | O44: 0.48515067 | P44: 0.48563533 | Q44: 0.48612 | R44: 0.48660466 | S44: 0.48708933 | T44: 0.487574 | U44: 0.48805866 | V44: 0.48854333 | W44: 0.48902799 | X44: 0.48951266 | Y44: 0.48999733 | Z44: 0.49048199 | AA44: 0.49096666 | AB44: 0.49145132 | AC44: 0.49193599 | AD44: 0.49242066 | AE44: 0.49290532 | AF44: 0.49338999 | AG44: 0.49387465 | AH44: 0.49435932
A45: Class 3 - Conservative | B45: 0.446015 | C45: 0.44662708 | D45: 0.44723917 | E45: 0.44785125 | F45: 0.44846333 | G45: 0.44907542 | H45: 0.4496875 | I45: 0.45029958 | J45: 0.45091167 | K45: 0.45152375 | L45: 0.45213583 | M45: 0.45274792 | N45: 0.45336 | O45: 0.45358668 | P45: 0.45381336 | Q45: 0.45404004 | R45: 0.45426672 | S45: 0.4544934 | T45: 0.45472008 | U45: 0.45494676 | V45: 0.45517344 | W45: 0.45540012 | X45: 0.4556268 | Y45: 0.45585348 | Z45: 0.45608016 | AA45: 0.45630684 | AB45: 0.45653352 | AC45: 0.4567602 | AD45: 0.45698688 | AE45: 0.45721356 | AF45: 0.45744024 | AG45: 0.45766692 | AH45: 0.4578936
A46: Class 4 - Advanced | B46: 0.428546 | C46: 0.43429175 | D46: 0.4400375 | E46: 0.44578325 | F46: 0.451529 | G46: 0.45727475 | H46: 0.4630205 | I46: 0.46876625 | J46: 0.474512 | K46: 0.48025775 | L46: 0.4860035 | M46: 0.49174925 | N46: 0.497495 | O46: 0.49873874 | P46: 0.49998247 | Q46: 0.50122621 | R46: 0.50246995 | S46: 0.50371369 | T46: 0.50495743 | U46: 0.50620116 | V46: 0.5074449 | W46: 0.50868864 | X46: 0.50993237 | Y46: 0.51117611 | Z46: 0.51241985 | AA46: 0.51366359 | AB46: 0.51490733 | AC46: 0.51615106 | AD46: 0.5173948 | AE46: 0.51863854 | AF46: 0.51988228 | AG46: 0.52112601 | AH46: 0.52236975
...

Sheet Wind By State
B1: Wind
A2: State | B2: 2018 | C2: 2019 | D2: 2020 | E2: 2021 | F2: 2022 | G2: 2023 | H2: 2024 | I2: 2025 | J2: 2026 | K2: 2027 | L2: 2028 | M2: 2029 | N2: 2030 | O2: 2031 | P2: 2032 | Q2: 2033 | R2: 2034 | S2: 2035 | T2: 2036 | U2: 2037 | V2: 2038 | W2: 2039 | X2: 2040 | Y2: 2041 | Z2: 2042 | AA2: 2043 | AB2: 2044 | AC2: 2045 | AD2: 2046 | AE2: 2047 | AF2: 2048 | AG2: 2049 | AH2: 2050
A3: =About!B2 | B3: {=TRANSPOSE(L69:L101)} | C3: 0.3407211 | D3: 0.34427495 | E3: 0.3478288 | F3: 0.35138265 | G3: 0.3549365 | H3: 0.35849035 | I3: 0.3620442 | J3: 0.36559805 | K3: 0.3691519 | L3: 0.37270575 | M3: 0.3762596 | N3: 0.37981345 | O3: 0.38054642 | P3: 0.38127939 | Q3: 0.38201236 | R3: 0.38274533 | S3: 0.38347831 | T3: 0.38421128 | U3: 0.38494425 | V3: 0.38567722 | W3: 0.38641019 | X3: 0.38714316 | Y3: 0.38787614 | Z3: 0.38860911 | AA3: 0.38934208 | AB3: 0.39007505 | AC3: 0.39080802 | AD3: 0.39154099 | AE3: 0.39227397 | AF3: 0.39300694 | AG3: 0.39373991 | AH3: 0.39447288
B7: 1 | C7: 2 | D7: 3 | E7: 4 | F7: 5 | G7: 6 | H7: 7 | I7: 8 | J7: 9 | K7: 10
A8: =About!B1 | B8: =SUMIFS(B12:B59,$A$12:$A$59,$A$3) | C8: =SUMIFS(C12:C59,$A$12:$A$59,$A$3) | D8: =SUMIFS(D12:D59,$A$12:$A$59,$A$3) | E8: =SUMIFS(E12:E59,$A$12:$A$59,$A$3) | F8: =SUMIFS(F12:F59,$A$12:$A$59,$A$3) | G8: =SUMIFS(G12:G59,$A$12:$A$59,$A$3) | H8: =SUMIFS(H12:H59,$A$12:$A$59,$A$3) | I8: =SUMIFS(I12:I59,$A$12:$A$59,$A$3) | ... K8: =SUMIFS(K12:K59,$A$12:$A$59,$A$3)
B10: Capacity by Wind TRG Class (MW)
A11: State | B11: 1 | C11: 2 | D11: 3 | E11: 4 | F11: 5 | G11: 6 | H11: 7 | I11: 8 | J11: 9 | K11: 10 | L11: Weighted Class | M11: Weighted Class by Capacity
A12: AL | B12: 0 | C12: 0 | D12: 0 | E12: 0 | F12: 2 | G12: 72 | H12: 1761 | I12: 24172 | J12: 105097 | K12: 11782 | L12: =SUMPRODUCT(B12:K12,$B$11:$K$11)/SUM(B12:K12)
A13: AR | B13: 6 | C13: 6 | D13: 8 | E13: 45 | F13: 363 | G13: 4896 | H13: 48185 | I13: 65971 | J13: 37039 | K13: 5811 | L13: =SUMPRODUCT(B13:K13,$B$11:$K$11)/SUM(B13:K13)
A14: AZ | B14: 0 | C14: 0 | D14: 0 | E14: 1 | F14: 36 | G14: 1750 | H14: 34679 | I14: 120345 | J14: 206319 | K14: 111836 | L14: =SUMPRODUCT(B14:K14,$B$11:$K$11)/SUM(B14:K14)
A15: CA | B15: 94 | C15: 55 | D15: 94 | E15: 75 | F15: 886 | G15: 5076 | H15: 19020 | I15: 46418 | J15: 75107 | K15: 156550 | L15: =SUMPRODUCT(B15:K15,$B$11:$K$11)/SUM(B15:K15)
A16: CO | B16: 227 | C16: 618 | D16: 954 | E16: 19027 | F16: 70367 | G16: 84010 | H16: 78984 | I16: 59735 | J16: 42556 | K16: 38899 | L16: =SUMPRODUCT(B16:K16,$B$11:$K$11)/SUM(B16:K16)
A17: CT | B17: 0 | C17: 0 | D17: 0 | E17: 0 | F17: 0 | G17: 0 | H17: 16 | I17: 539 | J17: 885 | K17: 239 | L17: =SUMPRODUCT(B17:K17,$B$11:$K$11)/SUM(B17:K17)
A18: DE | B18: 0 | C18: 0 | D18: 0 | E18: 0 | F18: 0 | G18: 0 | H18: 6 | I18: 522 | J18: 227 | K18: 0 | L18: =SUMPRODUCT(B18:K18,$B$11:$K$11)/SUM(B18:K18)
A19: FL | B19: 0 | C19: 0 | D19: 0 | E19: 0 | F19: 0 | G19: 0 | H19: 774 | I19: 13626 | J19: 22006 | K19: 1839 | L19: =SUMPRODUCT(B19:K19,$B$11:$K$11)/SUM(B19:K19)
A20: GA | B20: 0 | C20: 0 | D20: 0 | E20: 0 | F20: 5 | G20: 49 | H20: 424 | I20: 11407 | J20: 73098 | K20: 8657 | L20: =SUMPRODUCT(B20:K20,$B$11:$K$11)/SUM(B20:K20)
A21: IA | B21: 99 | C21: 3514 | D21: 15717 | E21: 43324 | F21: 111326 | G21: 77613 | H21: 27407 | I21: 552 | J21: 17 | K21: 0 | L21: =SUMPRODUCT(B21:K21,$B$11:$K$11)/SUM(B21:K21)
A22: ID | B22: 31 | C22: 21 | D22: 44 | E22: 60 | F22: 427 | G22: 3322 | H22: 41862 | I22: 77921 | J22: 37556 | K22: 51588 | L22: =SUMPRODUCT(B22:K22,$B$11:$K$11)/SUM(B22:K22)
A23: IL | B23: 0 | C23: 0 | D23: 0 | E23: 0 | F23: 5645 | G23: 77347 | H23: 72097 | I23: 34004 | J23: 2254 | K23: 3 | L23: =SUMPRODUCT(B23:K23,$B$11:$K$11)/SUM(B23:K23)
... A59: WY | B59: 15209 | C59: 3980 | D59: 13639 | E59: 18533 | F59: 78414 | G59: 144895 | H59: 84042 | I59: 57684 | J59: 34444 | K59: 21578 | L59: =SUMPRODUCT(B59:K59,$B$11:$K$11)/SUM(B59:K59)
A64: Source | B64: https://windexchange.energy.gov/maps-data/321
B68: Class 1 - Moderate | C68: Class 2 - Moderate | D68: Class 3 - Moderate | E68: Class 4 - Moderate | F68: Class 5 - Moderate | G68: Class 6 - Moderate | H68: Class 7 - Moderate | I68: Class 8 - Moderate | J68: Class 9 - Moderate | K68: Class 10 - Moderate
A69: 2018 | B69: =INDEX('NREL ATB'!$B$37:$AH$66,MATCH('Wind By State'!B$68,'NREL ATB'!$A$37:$A$66,0),MATCH('Wind By State'!$A69,'NREL ATB'!$B$36:$AH$36,0)) | C69: =INDEX('NREL ATB'!$B$37:$AH$66,MATCH('Wind By State'!C$68,'NREL ATB'!$A$37:$A$66,0),MATCH('Wind By State'!$A69,'NREL ATB'!$B$36:$AH$36,0)) | D69: =INDEX('NREL ATB'!$B$37:$AH$66,MATCH('Wind By State'!D$68,'NREL ATB'!$A$37:$A$66,0),MATCH('Wind By State'!$A69,'NREL ATB'!$B$36:$AH$36,0)) | E69: =INDEX('NREL ATB'!$B$37:$AH$66,MATCH('Wind By State'!E$68,'NREL ATB'!$A$37:$A$66,0),MATCH('Wind By State'!$A69,'NREL ATB'!$B$36:$AH$36,0)) | F69: =INDEX('NREL ATB'!$B$37:$AH$66,MATCH('Wind By State'!F$68,'NREL ATB'!$A$37:$A$66,0),MATCH('Wind By State'!$A69,'NREL ATB'!$B$36:$AH$36,0)) | G69: =INDEX('NREL ATB'!$B$37:$AH$66,MATCH('Wind By State'!G$68,'NREL ATB'!$A$37:$A$66,0),MATCH('Wind By State'!$A69,'NREL ATB'!$B$36:$AH$36,0)) | H69: =INDEX('NREL ATB'!$B$37:$AH$66,MATCH('Wind By State'!H$68,'NREL ATB'!$A$37:$A$66,0),MATCH('Wind By State'!$A69,'NREL ATB'!$B$36:$AH$36,0)) | I69: =INDEX('NREL ATB'!$B$37:$AH$66,MATCH('Wind By State'!I$68,'NREL ATB'!$A$37:$A$66,0),MATCH('Wind By State'!$A69,'NREL ATB'!$B$36:$AH$36,0)) | ... K69: =INDEX('NREL ATB'!$B$37:$AH$66,MATCH('Wind By State'!K$68,'NREL ATB'!$A$37:$A$66,0),MATCH('Wind By State'!$A69,'NREL ATB'!$B$36:$AH$36,0)) | L69: =SUMPRODUCT($B69:$K69,$B$8:$K$8)/SUM($B$8:$K$8)
A70: 2019 | B70: =INDEX('NREL ATB'!$B$37:$AH$66,MATCH('Wind By State'!B$68,'NREL ATB'!$A$37:$A$66,0),MATCH('Wind By State'!$A70,'NREL ATB'!$B$36:$AH$36,0)) | C70: =INDEX('NREL ATB'!$B$37:$AH$66,MATCH('Wind By State'!C$68,'NREL ATB'!$A$37:$A$66,0),MATCH('Wind By State'!$A70,'NREL ATB'!$B$36:$AH$36,0)) | D70: =INDEX('NREL ATB'!$B$37:$AH$66,MATCH('Wind By State'!D$68,'NREL ATB'!$A$37:$A$66,0),MATCH('Wind By State'!$A70,'NREL ATB'!$B$36:$AH$36,0)) | E70: =INDEX('NREL ATB'!$B$37:$AH$66,MATCH('Wind By State'!E$68,'NREL ATB'!$A$37:$A$66,0),MATCH('Wind By State'!$A70,'NREL ATB'!$B$36:$AH$36,0)) | F70: =INDEX('NREL ATB'!$B$37:$AH$66,MATCH('Wind By State'!F$68,'NREL ATB'!$A$37:$A$66,0),MATCH('Wind By State'!$A70,'NREL ATB'!$B$36:$AH$36,0)) | G70: =INDEX('NREL ATB'!$B$37:$AH$66,MATCH('Wind By State'!G$68,'NREL ATB'!$A$37:$A$66,0),MATCH('Wind By State'!$A70,'NREL ATB'!$B$36:$AH$36,0)) | H70: =INDEX('NREL ATB'!$B$37:$AH$66,MATCH('Wind By State'!H$68,'NREL ATB'!$A$37:$A$66,0),MATCH('Wind By State'!$A70,'NREL ATB'!$B$36:$AH$36,0)) | I70: =INDEX('NREL ATB'!$B$37:$AH$66,MATCH('Wind By State'!I$68,'NREL ATB'!$A$37:$A$66,0),MATCH('Wind By State'!$A70,'NREL ATB'!$B$36:$AH$36,0)) | ... K70: =INDEX('NREL ATB'!$B$37:$AH$66,MATCH('Wind By State'!K$68,'NREL ATB'!$A$37:$A$66,0),MATCH('Wind By State'!$A70,'NREL ATB'!$B$36:$AH$36,0)) | L70: =SUMPRODUCT($B70:$K70,$B$8:$K$8)/SUM($B$8:$K$8)
A71: 2020 | B71: =INDEX('NREL ATB'!$B$37:$AH$66,MATCH('Wind By State'!B$68,'NREL ATB'!$A$37:$A$66,0),MATCH('Wind By State'!$A71,'NREL ATB'!$B$36:$AH$36,0)) | C71: =INDEX('NREL ATB'!$B$37:$AH$66,MATCH('Wind By State'!C$68,'NREL ATB'!$A$37:$A$66,0),MATCH('Wind By State'!$A71,'NREL ATB'!$B$36:$AH$36,0)) | D71: =INDEX('NREL ATB'!$B$37:$AH$66,MATCH('Wind By State'!D$68,'NREL ATB'!$A$37:$A$66,0),MATCH('Wind By State'!$A71,'NREL ATB'!$B$36:$AH$36,0)) | E71: =INDEX('NREL ATB'!$B$37:$AH$66,MATCH('Wind By State'!E$68,'NREL ATB'!$A$37:$A$66,0),MATCH('Wind By State'!$A71,'NREL ATB'!$B$36:$AH$36,0)) | F71: =INDEX('NREL ATB'!$B$37:$AH$66,MATCH('Wind By State'!F$68,'NREL ATB'!$A$37:$A$66,0),MATCH('Wind By State'!$A71,'NREL ATB'!$B$36:$AH$36,0)) | G71: =INDEX('NREL ATB'!$B$37:$AH$66,MATCH('Wind By State'!G$68,'NREL ATB'!$A$37:$A$66,0),MATCH('Wind By State'!$A71,'NREL ATB'!$B$36:$AH$36,0)) | H71: =INDEX('NREL ATB'!$B$37:$AH$66,MATCH('Wind By State'!H$68,'NREL ATB'!$A$37:$A$66,0),MATCH('Wind By State'!$A71,'NREL ATB'!$B$36:$AH$36,0)) | I71: =INDEX('NREL ATB'!$B$37:$AH$66,MATCH('Wind By State'!I$68,'NREL ATB'!$A$37:$A$66,0),MATCH('Wind By State'!$A71,'NREL ATB'!$B$36:$AH$36,0)) | ... K71: =INDEX('NREL ATB'!$B$37:$AH$66,MATCH('Wind By State'!K$68,'NREL ATB'!$A$37:$A$66,0),MATCH('Wind By State'!$A71,'NREL ATB'!$B$36:$AH$36,0)) | L71: =SUMPRODUCT($B71:$K71,$B$8:$K$8)/SUM($B$8:$K$8)
A72: 2021 | B72: =INDEX('NREL ATB'!$B$37:$AH$66,MATCH('Wind By State'!B$68,'NREL ATB'!$A$37:$A$66,0),MATCH('Wind By State'!$A72,'NREL ATB'!$B$36:$AH$36,0)) | C72: =INDEX('NREL ATB'!$B$37:$AH$66,MATCH('Wind By State'!C$68,'NREL ATB'!$A$37:$A$66,0),MATCH('Wind By State'!$A72,'NREL ATB'!$B$36:$AH$36,0)) | D72: =INDEX('NREL ATB'!$B$37:$AH$66,MATCH('Wind By State'!D$68,'NREL ATB'!$A$37:$A$66,0),MATCH('Wind By State'!$A72,'NREL ATB'!$B$36:$AH$36,0)) | E72: =INDEX('NREL ATB'!$B$37:$AH$66,MATCH('Wind By State'!E$68,'NREL ATB'!$A$37:$A$66,0),MATCH('Wind By State'!$A72,'NREL ATB'!$B$36:$AH$36,0)) | F72: =INDEX('NREL ATB'!$B$37:$AH$66,MATCH('Wind By State'!F$68,'NREL ATB'!$A$37:$A$66,0),MATCH('Wind By State'!$A72,'NREL ATB'!$B$36:$AH$36,0)) | G72: =INDEX('NREL ATB'!$B$37:$AH$66,MATCH('Wind By State'!G$68,'NREL ATB'!$A$37:$A$66,0),MATCH('Wind By State'!$A72,'NREL ATB'!$B$36:$AH$36,0)) | H72: =INDEX('NREL ATB'!$B$37:$AH$66,MATCH('Wind By State'!H$68,'NREL ATB'!$A$37:$A$66,0),MATCH('Wind By State'!$A72,'NREL ATB'!$B$36:$AH$36,0)) | I72: =INDEX('NREL ATB'!$B$37:$AH$66,MATCH('Wind By State'!I$68,'NREL ATB'!$A$37:$A$66,0),MATCH('Wind By State'!$A72,'NREL ATB'!$B$36:$AH$36,0)) | ... K72: =INDEX('NREL ATB'!$B$37:$AH$66,MATCH('Wind By State'!K$68,'NREL ATB'!$A$37:$A$66,0),MATCH('Wind By State'!$A72,'NREL ATB'!$B$36:$AH$36,0)) | L72: =SUMPRODUCT($B72:$K72,$B$8:$K$8)/SUM($B$8:$K$8)
A73: 2022 | B73: =INDEX('NREL ATB'!$B$37:$AH$66,MATCH('Wind By State'!B$68,'NREL ATB'!$A$37:$A$66,0),MATCH('Wind By State'!$A73,'NREL ATB'!$B$36:$AH$36,0)) | C73: =INDEX('NREL ATB'!$B$37:$AH$66,MATCH('Wind By State'!C$68,'NREL ATB'!$A$37:$A$66,0),MATCH('Wind By State'!$A73,'NREL ATB'!$B$36:$AH$36,0)) | D73: =INDEX('NREL ATB'!$B$37:$AH$66,MATCH('Wind By State'!D$68,'NREL ATB'!$A$37:$A$66,0),MATCH('Wind By State'!$A73,'NREL ATB'!$B$36:$AH$36,0)) | E73: =INDEX('NREL ATB'!$B$37:$AH$66,MATCH('Wind By State'!E$68,'NREL ATB'!$A$37:$A$66,0),MATCH('Wind By State'!$A73,'NREL ATB'!$B$36:$AH$36,0)) | F73: =INDEX('NREL ATB'!$B$37:$AH$66,MATCH('Wind By State'!F$68,'NREL ATB'!$A$37:$A$66,0),MATCH('Wind By State'!$A73,'NREL ATB'!$B$36:$AH$36,0)) | G73: =INDEX('NREL ATB'!$B$37:$AH$66,MATCH('Wind By State'!G$68,'NREL ATB'!$A$37:$A$66,0),MATCH('Wind By State'!$A73,'NREL ATB'!$B$36:$AH$36,0)) | H73: =INDEX('NREL ATB'!$B$37:$AH$66,MATCH('Wind By State'!H$68,'NREL ATB'!$A$37:$A$66,0),MATCH('Wind By State'!$A73,'NREL ATB'!$B$36:$AH$36,0)) | I73: =INDEX('NREL ATB'!$B$37:$AH$66,MATCH('Wind By State'!I$68,'NREL ATB'!$A$37:$A$66,0),MATCH('Wind By State'!$A73,'NREL ATB'!$B$36:$AH$36,0)) | ... K73: =INDEX('NREL ATB'!$B$37:$AH$66,MATCH('Wind By State'!K$68,'NREL ATB'!$A$37:$A$66,0),MATCH('Wind By State'!$A73,'NREL ATB'!$B$36:$AH$36,0)) | L73: =SUMPRODUCT($B73:$K73,$B$8:$K$8)/SUM($B$8:$K$8)
A74: 2023 | B74: =INDEX('NREL ATB'!$B$37:$AH$66,MATCH('Wind By State'!B$68,'NREL ATB'!$A$37:$A$66,0),MATCH('Wind By State'!$A74,'NREL ATB'!$B$36:$AH$36,0)) | C74: =INDEX('NREL ATB'!$B$37:$AH$66,MATCH('Wind By State'!C$68,'NREL ATB'!$A$37:$A$66,0),MATCH('Wind By State'!$A74,'NREL ATB'!$B$36:$AH$36,0)) | D74: =INDEX('NREL ATB'!$B$37:$AH$66,MATCH('Wind By State'!D$68,'NREL ATB'!$A$37:$A$66,0),MATCH('Wind By State'!$A74,'NREL ATB'!$B$36:$AH$36,0)) | E74: =INDEX('NREL ATB'!$B$37:$AH$66,MATCH('Wind By State'!E$68,'NREL ATB'!$A$37:$A$66,0),MATCH('Wind By State'!$A74,'NREL ATB'!$B$36:$AH$36,0)) | F74: =INDEX('NREL ATB'!$B$37:$AH$66,MATCH('Wind By State'!F$68,'NREL ATB'!$A$37:$A$66,0),MATCH('Wind By State'!$A74,'NREL ATB'!$B$36:$AH$36,0)) | G74: =INDEX('NREL ATB'!$B$37:$AH$66,MATCH('Wind By State'!G$68,'NREL ATB'!$A$37:$A$66,0),MATCH('Wind By State'!$A74,'NREL ATB'!$B$36:$AH$36,0)) | H74: =INDEX('NREL ATB'!$B$37:$AH$66,MATCH('Wind By State'!H$68,'NREL ATB'!$A$37:$A$66,0),MATCH('Wind By State'!$A74,'NREL ATB'!$B$36:$AH$36,0)) | I74: =INDEX('NREL ATB'!$B$37:$AH$66,MATCH('Wind By State'!I$68,'NREL ATB'!$A$37:$A$66,0),MATCH('Wind By State'!$A74,'NREL ATB'!$B$36:$AH$36,0)) | ... K74: =INDEX('NREL ATB'!$B$37:$AH$66,MATCH('Wind By State'!K$68,'NREL ATB'!$A$37:$A$66,0),MATCH('Wind By State'!$A74,'NREL ATB'!$B$36:$AH$36,0)) | L74: =SUMPRODUCT($B74:$K74,$B$8:$K$8)/SUM($B$8:$K$8)
A75: 2024 | B75: =INDEX('NREL ATB'!$B$37:$AH$66,MATCH('Wind By State'!B$68,'NREL ATB'!$A$37:$A$66,0),MATCH('Wind By State'!$A75,'NREL ATB'!$B$36:$AH$36,0)) | C75: =INDEX('NREL ATB'!$B$37:$AH$66,MATCH('Wind By State'!C$68,'NREL ATB'!$A$37:$A$66,0),MATCH('Wind By State'!$A75,'NREL ATB'!$B$36:$AH$36,0)) | D75: =INDEX('NREL ATB'!$B$37:$AH$66,MATCH('Wind By State'!D$68,'NREL ATB'!$A$37:$A$66,0),MATCH('Wind By State'!$A75,'NREL ATB'!$B$36:$AH$36,0)) | E75: =INDEX('NREL ATB'!$B$37:$AH$66,MATCH('Wind By State'!E$68,'NREL ATB'!$A$37:$A$66,0),MATCH('Wind By State'!$A75,'NREL ATB'!$B$36:$AH$36,0)) | F75: =INDEX('NREL ATB'!$B$37:$AH$66,MATCH('Wind By State'!F$68,'NREL ATB'!$A$37:$A$66,0),MATCH('Wind By State'!$A75,'NREL ATB'!$B$36:$AH$36,0)) | G75: =INDEX('NREL ATB'!$B$37:$AH$66,MATCH('Wind By State'!G$68,'NREL ATB'!$A$37:$A$66,0),MATCH('Wind By State'!$A75,'NREL ATB'!$B$36:$AH$36,0)) | H75: =INDEX('NREL ATB'!$B$37:$AH$66,MATCH('Wind By State'!H$68,'NREL ATB'!$A$37:$A$66,0),MATCH('Wind By State'!$A75,'NREL ATB'!$B$36:$AH$36,0)) | I75: =INDEX('NREL ATB'!$B$37:$AH$66,MATCH('Wind By State'!I$68,'NREL ATB'!$A$37:$A$66,0),MATCH('Wind By State'!$A75,'NREL ATB'!$B$36:$AH$36,0)) | ... K75: =INDEX('NREL ATB'!$B$37:$AH$66,MATCH('Wind By State'!K$68,'NREL ATB'!$A$37:$A$66,0),MATCH('Wind By State'!$A75,'NREL ATB'!$B$36:$AH$36,0)) | L75: =SUMPRODUCT($B75:$K75,$B$8:$K$8)/SUM($B$8:$K$8)
A76: 2025 | B76: =INDEX('NREL ATB'!$B$37:$AH$66,MATCH('Wind By State'!B$68,'NREL ATB'!$A$37:$A$66,0),MATCH('Wind By State'!$A76,'NREL ATB'!$B$36:$AH$36,0)) | C76: =INDEX('NREL ATB'!$B$37:$AH$66,MATCH('Wind By State'!C$68,'NREL ATB'!$A$37:$A$66,0),MATCH('Wind By State'!$A76,'NREL ATB'!$B$36:$AH$36,0)) | D76: =INDEX('NREL ATB'!$B$37:$AH$66,MATCH('Wind By State'!D$68,'NREL ATB'!$A$37:$A$66,0),MATCH('Wind By State'!$A76,'NREL ATB'!$B$36:$AH$36,0)) | E76: =INDEX('NREL ATB'!$B$37:$AH$66,MATCH('Wind By State'!E$68,'NREL ATB'!$A$37:$A$66,0),MATCH('Wind By State'!$A76,'NREL ATB'!$B$36:$AH$36,0)) | F76: =INDEX('NREL ATB'!$B$37:$AH$66,MATCH('Wind By State'!F$68,'NREL ATB'!$A$37:$A$66,0),MATCH('Wind By State'!$A76,'NREL ATB'!$B$36:$AH$36,0)) | G76: =INDEX('NREL ATB'!$B$37:$AH$66,MATCH('Wind By State'!G$68,'NREL ATB'!$A$37:$A$66,0),MATCH('Wind By State'!$A76,'NREL ATB'!$B$36:$AH$36,0)) | H76: =INDEX('NREL ATB'!$B$37:$AH$66,MATCH('Wind By State'!H$68,'NREL ATB'!$A$37:$A$66,0),MATCH('Wind By State'!$A76,'NREL ATB'!$B$36:$AH$36,0)) | I76: =INDEX('NREL ATB'!$B$37:$AH$66,MATCH('Wind By State'!I$68,'NREL ATB'!$A$37:$A$66,0),MATCH('Wind By State'!$A76,'NREL ATB'!$B$36:$AH$36,0)) | ... K76: =INDEX('NREL ATB'!$B$37:$AH$66,MATCH('Wind By State'!K$68,'NREL ATB'!$A$37:$A$66,0),MATCH('Wind By State'!$A76,'NREL ATB'!$B$36:$AH$36,0)) | L76: =SUMPRODUCT($B76:$K76,$B$8:$K$8)/SUM($B$8:$K$8)
A77: 2026 | B77: =INDEX('NREL ATB'!$B$37:$AH$66,MATCH('Wind By State'!B$68,'NREL ATB'!$A$37:$A$66,0),MATCH('Wind By State'!$A77,'NREL ATB'!$B$36:$AH$36,0)) | C77: =INDEX('NREL ATB'!$B$37:$AH$66,MATCH('Wind By State'!C$68,'NREL ATB'!$A$37:$A$66,0),MATCH('Wind By State'!$A77,'NREL ATB'!$B$36:$AH$36,0)) | D77: =INDEX('NREL ATB'!$B$37:$AH$66,MATCH('Wind By State'!D$68,'NREL ATB'!$A$37:$A$66,0),MATCH('Wind By State'!$A77,'NREL ATB'!$B$36:$AH$36,0)) | E77: =INDEX('NREL ATB'!$B$37:$AH$66,MATCH('Wind By State'!E$68,'NREL ATB'!$A$37:$A$66,0),MATCH('Wind By State'!$A77,'NREL ATB'!$B$36:$AH$36,0)) | F77: =INDEX('NREL ATB'!$B$37:$AH$66,MATCH('Wind By State'!F$68,'NREL ATB'!$A$37:$A$66,0),MATCH('Wind By State'!$A77,'NREL ATB'!$B$36:$AH$36,0)) | G77: =INDEX('NREL ATB'!$B$37:$AH$66,MATCH('Wind By State'!G$68,'NREL ATB'!$A$37:$A$66,0),MATCH('Wind By State'!$A77,'NREL ATB'!$B$36:$AH$36,0)) | H77: =INDEX('NREL ATB'!$B$37:$AH$66,MATCH('Wind By State'!H$68,'NREL ATB'!$A$37:$A$66,0),MATCH('Wind By State'!$A77,'NREL ATB'!$B$36:$AH$36,0)) | I77: =INDEX('NREL ATB'!$B$37:$AH$66,MATCH('Wind By State'!I$68,'NREL ATB'!$A$37:$A$66,0),MATCH('Wind By State'!$A77,'NREL ATB'!$B$36:$AH$36,0)) | ... K77: =INDEX('NREL ATB'!$B$37:$AH$66,MATCH('Wind By State'!K$68,'NREL ATB'!$A$37:$A$66,0),MATCH('Wind By State'!$A77,'NREL ATB'!$B$36:$AH$36,0)) | L77: =SUMPRODUCT($B77:$K77,$B$8:$K$8)/SUM($B$8:$K$8)
A78: 2027 | B78: =INDEX('NREL ATB'!$B$37:$AH$66,MATCH('Wind By State'!B$68,'NREL ATB'!$A$37:$A$66,0),MATCH('Wind By State'!$A78,'NREL ATB'!$B$36:$AH$36,0)) | C78: =INDEX('NREL ATB'!$B$37:$AH$66,MATCH('Wind By State'!C$68,'NREL ATB'!$A$37:$A$66,0),MATCH('Wind By State'!$A78,'NREL ATB'!$B$36:$AH$36,0)) | D78: =INDEX('NREL ATB'!$B$37:$AH$66,MATCH('Wind By State'!D$68,'NREL ATB'!$A$37:$A$66,0),MATCH('Wind By State'!$A78,'NREL ATB'!$B$36:$AH$36,0)) | E78: =INDEX('NREL ATB'!$B$37:$AH$66,MATCH('Wind By State'!E$68,'NREL ATB'!$A$37:$A$66,0),MATCH('Wind By State'!$A78,'NREL ATB'!$B$36:$AH$36,0)) | F78: =INDEX('NREL ATB'!$B$37:$AH$66,MATCH('Wind By State'!F$68,'NREL ATB'!$A$37:$A$66,0),MATCH('Wind By State'!$A78,'NREL ATB'!$B$36:$AH$36,0)) | G78: =INDEX('NREL ATB'!$B$37:$AH$66,MATCH('Wind By State'!G$68,'NREL ATB'!$A$37:$A$66,0),MATCH('Wind By State'!$A78,'NREL ATB'!$B$36:$AH$36,0)) | H78: =INDEX('NREL ATB'!$B$37:$AH$66,MATCH('Wind By State'!H$68,'NREL ATB'!$A$37:$A$66,0),MATCH('Wind By State'!$A78,'NREL ATB'!$B$36:$AH$36,0)) | I78: =INDEX('NREL ATB'!$B$37:$AH$66,MATCH('Wind By State'!I$68,'NREL ATB'!$A$37:$A$66,0),MATCH('Wind By State'!$A78,'NREL ATB'!$B$36:$AH$36,0)) | ... K78: =INDEX('NREL ATB'!$B$37:$AH$66,MATCH('Wind By State'!K$68,'NREL ATB'!$A$37:$A$66,0),MATCH('Wind By State'!$A78,'NREL ATB'!$B$36:$AH$36,0)) | L78: =SUMPRODUCT($B78:$K78,$B$8:$K$8)/SUM($B$8:$K$8)
A79: 2028 | B79: =INDEX('NREL ATB'!$B$37:$AH$66,MATCH('Wind By State'!B$68,'NREL ATB'!$A$37:$A$66,0),MATCH('Wind By State'!$A79,'NREL ATB'!$B$36:$AH$36,0)) | C79: =INDEX('NREL ATB'!$B$37:$AH$66,MATCH('Wind By State'!C$68,'NREL ATB'!$A$37:$A$66,0),MATCH('Wind By State'!$A79,'NREL ATB'!$B$36:$AH$36,0)) | D79: =INDEX('NREL ATB'!$B$37:$AH$66,MATCH('Wind By State'!D$68,'NREL ATB'!$A$37:$A$66,0),MATCH('Wind By State'!$A79,'NREL ATB'!$B$36:$AH$36,0)) | E79: =INDEX('NREL ATB'!$B$37:$AH$66,MATCH('Wind By State'!E$68,'NREL ATB'!$A$37:$A$66,0),MATCH('Wind By State'!$A79,'NREL ATB'!$B$36:$AH$36,0)) | F79: =INDEX('NREL ATB'!$B$37:$AH$66,MATCH('Wind By State'!F$68,'NREL ATB'!$A$37:$A$66,0),MATCH('Wind By State'!$A79,'NREL ATB'!$B$36:$AH$36,0)) | G79: =INDEX('NREL ATB'!$B$37:$AH$66,MATCH('Wind By State'!G$68,'NREL ATB'!$A$37:$A$66,0),MATCH('Wind By State'!$A79,'NREL ATB'!$B$36:$AH$36,0)) | H79: =INDEX('NREL ATB'!$B$37:$AH$66,MATCH('Wind By State'!H$68,'NREL ATB'!$A$37:$A$66,0),MATCH('Wind By State'!$A79,'NREL ATB'!$B$36:$AH$36,0)) | I79: =INDEX('NREL ATB'!$B$37:$AH$66,MATCH('Wind By State'!I$68,'NREL ATB'!$A$37:$A$66,0),MATCH('Wind By State'!$A79,'NREL ATB'!$B$36:$AH$36,0)) | ... K79: =INDEX('NREL ATB'!$B$37:$AH$66,MATCH('Wind By State'!K$68,'NREL ATB'!$A$37:$A$66,0),MATCH('Wind By State'!$A79,'NREL ATB'!$B$36:$AH$36,0)) | L79: =SUMPRODUCT($B79:$K79,$B$8:$K$8)/SUM($B$8:$K$8)
A80: 2029 | B80: =INDEX('NREL ATB'!$B$37:$AH$66,MATCH('Wind By State'!B$68,'NREL ATB'!$A$37:$A$66,0),MATCH('Wind By State'!$A80,'NREL ATB'!$B$36:$AH$36,0)) | C80: =INDEX('NREL ATB'!$B$37:$AH$66,MATCH('Wind By State'!C$68,'NREL ATB'!$A$37:$A$66,0),MATCH('Wind By State'!$A80,'NREL ATB'!$B$36:$AH$36,0)) | D80: =INDEX('NREL ATB'!$B$37:$AH$66,MATCH('Wind By State'!D$68,'NREL ATB'!$A$37:$A$66,0),MATCH('Wind By State'!$A80,'NREL ATB'!$B$36:$AH$36,0)) | E80: =INDEX('NREL ATB'!$B$37:$AH$66,MATCH('Wind By State'!E$68,'NREL ATB'!$A$37:$A$66,0),MATCH('Wind By State'!$A80,'NREL ATB'!$B$36:$AH$36,0)) | F80: =INDEX('NREL ATB'!$B$37:$AH$66,MATCH('Wind By State'!F$68,'NREL ATB'!$A$37:$A$66,0),MATCH('Wind By State'!$A80,'NREL ATB'!$B$36:$AH$36,0)) | G80: =INDEX('NREL ATB'!$B$37:$AH$66,MATCH('Wind By State'!G$68,'NREL ATB'!$A$37:$A$66,0),MATCH('Wind By State'!$A80,'NREL ATB'!$B$36:$AH$36,0)) | H80: =INDEX('NREL ATB'!$B$37:$AH$66,MATCH('Wind By State'!H$68,'NREL ATB'!$A$37:$A$66,0),MATCH('Wind By State'!$A80,'NREL ATB'!$B$36:$AH$36,0)) | I80: =INDEX('NREL ATB'!$B$37:$AH$66,MATCH('Wind By State'!I$68,'NREL ATB'!$A$37:$A$66,0),MATCH('Wind By State'!$A80,'NREL ATB'!$B$36:$AH$36,0)) | ... K80: =INDEX('NREL ATB'!$B$37:$AH$66,MATCH('Wind By State'!K$68,'NREL ATB'!$A$37:$A$66,0),MATCH('Wind By State'!$A80,'NREL ATB'!$B$36:$AH$36,0)) | L80: =SUMPRODUCT($B80:$K80,$B$8:$K$8)/SUM($B$8:$K$8)
... A101: 2050 | B101: =INDEX('NREL ATB'!$B$37:$AH$66,MATCH('Wind By State'!B$68,'NREL ATB'!$A$37:$A$66,0),MATCH('Wind By State'!$A101,'NREL ATB'!$B$36:$AH$36,0)) | C101: =INDEX('NREL ATB'!$B$37:$AH$66,MATCH('Wind By State'!C$68,'NREL ATB'!$A$37:$A$66,0),MATCH('Wind By State'!$A101,'NREL ATB'!$B$36:$AH$36,0)) | D101: =INDEX('NREL ATB'!$B$37:$AH$66,MATCH('Wind By State'!D$68,'NREL ATB'!$A$37:$A$66,0),MATCH('Wind By State'!$A101,'NREL ATB'!$B$36:$AH$36,0)) | E101: =INDEX('NREL ATB'!$B$37:$AH$66,MATCH('Wind By State'!E$68,'NREL ATB'!$A$37:$A$66,0),MATCH('Wind By State'!$A101,'NREL ATB'!$B$36:$AH$36,0)) | F101: =INDEX('NREL ATB'!$B$37:$AH$66,MATCH('Wind By State'!F$68,'NREL ATB'!$A$37:$A$66,0),MATCH('Wind By State'!$A101,'NREL ATB'!$B$36:$AH$36,0)) | G101: =INDEX('NREL ATB'!$B$37:$AH$66,MATCH('Wind By State'!G$68,'NREL ATB'!$A$37:$A$66,0),MATCH('Wind By State'!$A101,'NREL ATB'!$B$36:$AH$36,0)) | H101: =INDEX('NREL ATB'!$B$37:$AH$66,MATCH('Wind By State'!H$68,'NREL ATB'!$A$37:$A$66,0),MATCH('Wind By State'!$A101,'NREL ATB'!$B$36:$AH$36,0)) | I101: =INDEX('NREL ATB'!$B$37:$AH$66,MATCH('Wind By State'!I$68,'NREL ATB'!$A$37:$A$66,0),MATCH('Wind By State'!$A101,'NREL ATB'!$B$36:$AH$36,0)) | ... K101: =INDEX('NREL ATB'!$B$37:$AH$66,MATCH('Wind By State'!K$68,'NREL ATB'!$A$37:$A$66,0),MATCH('Wind By State'!$A101,'NREL ATB'!$B$36:$AH$36,0)) | L101: =SUMPRODUCT($B101:$K101,$B$8:$K$8)/SUM($B$8:$K$8)

Sheet Solar by State
C1: 2018 | D1: 2019 | E1: 2020 | F1: 2021 | G1: 2022 | H1: 2023 | I1: 2024 | J1: 2025 | K1: 2026 | L1: 2027 | M1: 2028 | N1: 2029 | O1: 2030 | P1: 2031 | Q1: 2032 | R1: 2033 | S1: 2034 | T1: 2035 | U1: 2036 | V1: 2037 | W1: 2038 | X1: 2039 | Y1: 2040 | Z1: 2041 | AA1: 2042 | AB1: 2043 | AC1: 2044 | AD1: 2045 | AE1: 2046 | AF1: 2047 | AG1: 2048 | AH1: 2049 | AI1: 2050
A2: State | B2: =About!B1
A3: Closest Rep City (Latitude) | B3: =LOOKUP(B2,A8:C58,C8:C58) | C3: =SUMIFS(B75:B79,$A75:$A79,$B3) | D3: =SUMIFS(C75:C79,$A75:$A79,$B3) | E3: =SUMIFS(D75:D79,$A75:$A79,$B3) | F3: =SUMIFS(E75:E79,$A75:$A79,$B3) | G3: =SUMIFS(F75:F79,$A75:$A79,$B3) | H3: =SUMIFS(G75:G79,$A75:$A79,$B3) | I3: =SUMIFS(H75:H79,$A75:$A79,$B3) | J3: =SUMIFS(I75:I79,$A75:$A79,$B3) | ... AI3: =SUMIFS(AH75:AH79,$A75:$A79,$B3)
A7: State or federal district | B7: Location (N)
A8: Alabama | B8: 32.7794 | C8: {=INDEX(A$61:A$65,MATCH(MIN(ABS(cities-B8)),ABS(cities-B8),0))}
A9: Alaska | B9: 64.0685 | C9: {=INDEX(A$61:A$65,MATCH(MIN(ABS(cities-B9)),ABS(cities-B9),0))}
A10: Arizona | B10: 34.2744 | C10: {=INDEX(A$61:A$65,MATCH(MIN(ABS(cities-B10)),ABS(cities-B10),0))}
A11: Arkansas | B11: 34.8938 | C11: {=INDEX(A$61:A$65,MATCH(MIN(ABS(cities-B11)),ABS(cities-B11),0))}
A12: California | B12: 37.1841 | C12: {=INDEX(A$61:A$65,MATCH(MIN(ABS(cities-B12)),ABS(cities-B12),0))}
A13: Colorado | B13: 38.9972 | C13: {=INDEX(A$61:A$65,MATCH(MIN(ABS(cities-B13)),ABS(cities-B13),0))}
A14: Connecticut | B14: 41.6219 | C14: {=INDEX(A$61:A$65,MATCH(MIN(ABS(cities-B14)),ABS(cities-B14),0))}
A15: Delaware | B15: 38.9896 | C15: {=INDEX(A$61:A$65,MATCH(MIN(ABS(cities-B15)),ABS(cities-B15),0))}
A16: District of Columbia | B16: 38.9101 | C16: {=INDEX(A$61:A$65,MATCH(MIN(ABS(cities-B16)),ABS(cities-B16),0))}
A17: Florida | B17: 28.6305 | C17: {=INDEX(A$61:A$65,MATCH(MIN(ABS(cities-B17)),ABS(cities-B17),0))}
A18: Georgia | B18: 32.6415 | C18: {=INDEX(A$61:A$65,MATCH(MIN(ABS(cities-B18)),ABS(cities-B18),0))}
A19: Hawaii | B19: 20.2927 | C19: {=INDEX(A$61:A$65,MATCH(MIN(ABS(cities-B19)),ABS(cities-B19),0))}
... A58: Wyoming | B58: 42.9957 | C58: {=INDEX(A$61:A$65,MATCH(MIN(ABS(cities-B58)),ABS(cities-B58),0))}
B60: Latitude (N)
A61: Seattle | B61: 47.6062
A62: Chicago | B62: 41.8781
A63: Kansas City | B63: 39.0997
A64: Los Angeles | B64: 34.0522
A65: Daggett | B65: 34.864
B74: 2018 | C74: 2019 | D74: 2020 | E74: 2021 | F74: 2022 | G74: 2023 | H74: 2024 | I74: 2025 | J74: 2026 | K74: 2027 | L74: 2028 | M74: 2029 | N74: 2030 | O74: 2031 | P74: 2032 | Q74: 2033 | R74: 2034 | S74: 2035 | T74: 2036 | U74: 2037 | V74: 2038 | W74: 2039 | X74: 2040 | Y74: 2041 | Z74: 2042 | AA74: 2043 | AB74: 2044 | AC74: 2045 | AD74: 2046 | AE74: 2047 | AF74: 2048 | AG74: 2049 | AH74: 2050
A75: Seattle | B75: 0.21802831 | C75: 0.21957153 | D75: 0.22111476 | E75: 0.22265798 | F75: 0.22420121 | G75: 0.22574444 | H75: 0.22728766 | I75: 0.22883089 | J75: 0.23037411 | K75: 0.23191734 | L75: 0.23346057 | M75: 0.23500379 | N75: 0.23654702 | O75: 0.23765481 | P75: 0.23876261 | Q75: 0.2398704 | R75: 0.2409782 | S75: 0.242086 | T75: 0.24319379 | U75: 0.24430159 | V75: 0.24540938 | W75: 0.24651718 | X75: 0.24762498 | Y75: 0.24873277 | Z75: 0.24984057 | AA75: 0.25094836 | AB75: 0.25205616 | AC75: 0.25316395 | AD75: 0.25427175 | AE75: 0.25537955 | AF75: 0.25648734 | AG75: 0.25759514 | AH75: 0.25870293
A76: Chicago | B76: 0.25165533 | C76: 0.25337412 | D76: 0.25509291 | E76: 0.2568117 | F76: 0.25853049 | G76: 0.26024927 | H76: 0.26196806 | I76: 0.26368685 | J76: 0.26540564 | K76: 0.26712443 | L76: 0.26884322 | M76: 0.27056201 | N76: 0.2722808 | O76: 0.27351132 | P76: 0.27474184 | Q76: 0.27597236 | R76: 0.27720288 | S76: 0.27843341 | T76: 0.27966393 | U76: 0.28089445 | V76: 0.28212497 | W76: 0.28335549 | X76: 0.28458601 | Y76: 0.28581653 | Z76: 0.28704705 | AA76: 0.28827758 | AB76: 0.2895081 | AC76: 0.29073862 | AD76: 0.29196914 | AE76: 0.29319966 | AF76: 0.29443018 | AG76: 0.2956607 | AH76: 0.29689122
A77: Kansas City | B77: 0.27223835 | C77: 0.27395061 | D77: 0.27566287 | E77: 0.27737512 | F77: 0.27908738 | G77: 0.28079964 | H77: 0.28251189 | I77: 0.28422415 | J77: 0.2859364 | K77: 0.28764866 | L77: 0.28936092 | M77: 0.29107317 | N77: 0.29278543 | O77: 0.2939988 | P77: 0.29521216 | Q77: 0.29642553 | R77: 0.29763889 | S77: 0.29885226 | T77: 0.30006563 | U77: 0.30127899 | V77: 0.30249236 | W77: 0.30370572 | X77: 0.30491909 | Y77: 0.30613246 | Z77: 0.30734582 | AA77: 0.30855919 | AB77: 0.30977256 | AC77: 0.31098592 | AD77: 0.31219929 | AE77: 0.31341265 | AF77: 0.31462602 | AG77: 0.31583939 | AH77: 0.31705275
A78: Los Angeles | B78: 0.31886897 | C78: 0.32051742 | D78: 0.32216587 | E78: 0.32381432 | F78: 0.32546277 | G78: 0.32711122 | H78: 0.32875968 | I78: 0.33040813 | J78: 0.33205658 | K78: 0.33370503 | L78: 0.33535348 | M78: 0.33700193 | N78: 0.33865038 | O78: 0.33978841 | P78: 0.34092644 | Q78: 0.34206447 | R78: 0.3432025 | S78: 0.34434053 | T78: 0.34547856 | U78: 0.34661659 | V78: 0.34775461 | W78: 0.34889264 | X78: 0.35003067 | Y78: 0.3511687 | Z78: 0.35230673 | AA78: 0.35344476 | AB78: 0.35458279 | AC78: 0.35572082 | AD78: 0.35685885 | AE78: 0.35799688 | AF78: 0.35913491 | AG78: 0.36027294 | AH78: 0.36141097
A79: Daggett | B79: 0.35146192 | C79: 0.35319367 | D79: 0.35492543 | E79: 0.35665718 | F79: 0.35838894 | G79: 0.36012069 | H79: 0.36185245 | I79: 0.3635842 | J79: 0.36531596 | K79: 0.36704772 | L79: 0.36877947 | M79: 0.37051123 | N79: 0.37224298 | O79: 0.37337602 | P79: 0.37450905 | Q79: 0.37564209 | R79: 0.37677513 | S79: 0.37790816 | T79: 0.3790412 | U79: 0.38017424 | V79: 0.38130727 | W79: 0.38244031 | X79: 0.38357335 | Y79: 0.38470638 | Z79: 0.38583942 | AA79: 0.38697246 | AB79: 0.38810549 | AC79: 0.38923853 | AD79: 0.39037157 | AE79: 0.3915046 | AF79: 0.39263764 | AG79: 0.39377068 | AH79: 0.39490372

Sheet Table 4.8.B
A1: Table 4.08.B. Capacity Factors for Utility Scale Generators Primarily Using Non-Fossil Fuels
B2: Geothermal | D2: Hydroelectric | F2: Nuclear | H2: Other Biomass | J2: Other Gas | L2: Solar | P2: Wind | R2: Wood
A3: Year/Month | L3: Photovoltaic | N3: Thermal
B4: Time Adjusted Capacity | C4: Capacity Factor | D4: Time Adjusted Capacity | E4: Capacity Factor | F4: Time Adjusted Capacity | G4: Capacity Factor | H4: Time Adjusted Capacity | I4: Capacity Factor | J4: Time Adjusted Capacity | K4: Capacity Factor | L4: Time Adjusted Capacity | M4: Capacity Factor | N4: Time Adjusted Capacity | O4: Capacity Factor | P4: Time Adjusted Capacity | Q4: Capacity Factor | R4: Time Adjusted Capacity | S4: Capacity Factor
A5: Annual Data
A6: 2008 | B6: 2225.4 | C6: 0.743 | D6: 77925.2 | E6: 0.371 | F6: 100754.9 | G6: 0.911 | H6: 4112.4 | I6: 0.648 | J6: 1882 | K6: 0.468 | L6: 42.8 | M6: 0.192 | N6: 507.5 | O6: 0.195 | P6: 19275.3 | Q6: 0.317 | R6: 6970 | S6: 0.636
A7: 2009 | B7: 2278 | C7: 0.73 | D7: 78500.4 | E7: 0.396 | F7: 101003.7 | G7: 0.903 | H7: 4183.9 | I7: 0.65 | J7: 1752.2 | K7: 0.434 | L7: 81.9 | M7: 0.2 | N7: 468.2 | O7: 0.236 | P7: 28996.9 | Q7: 0.281 | R7: 6936.4 | S7: 0.617
A8: 2010 | B8: 2392.1 | C8: 0.716 | D8: 78810.3 | E8: 0.375 | F8: 101167.4 | G8: 0.911 | H8: 4298.7 | I8: 0.642 | J8: 1929 | K8: 0.505 | L8: 206.8 | M8: 0.202 | N8: 473 | O8: 0.245 | P8: 35702.6 | Q8: 0.297 | R8: 6991.5 | S8: 0.615
A9: 2011 | B9: 2407.9 | C9: 0.715 | D9: 78564.7 | E9: 0.458 | F9: 101265.1 | G9: 0.891 | H9: 4469.8 | I9: 0.642 | J9: 1902.7 | K9: 0.541 | L9: 537 | M9: 0.19 | N9: 485.3 | O9: 0.239 | P9: 42019.2 | Q9: 0.321 | R9: 7000.3 | S9: 0.596
A10: 2012 | B10: 2531.8 | C10: 0.683 | D10: 78296.6 | E10: 0.396 | F10: 101166 | G10: 0.866 | H10: 4639.7 | I10: 0.633 | J10: 1802.8 | K10: 0.596 | L10: 1527.1 | M10: 0.204 | N10: 476 | O10: 0.236 | P10: 49458 | Q10: 0.318 | R10: 7089.1 | S10: 0.613
A11: 2013 | B11: 2509.5 | C11: 0.718 | D11: 78873.5 | E11: 0.388 | F11: 99006.8 | G11: 0.908 | H11: 4949.7 | I11: 0.623 | J11: 2171.6 | K11: 0.559 | L11: 3525.2 | M11: 0.245 | N11: 552.1 | O11: 0.174 | P11: 59175.6 | Q11: 0.324 | R11: 7887.9 | S11: 0.59
A12: 2014 | B12: 2513.3 | C12: 0.72 | D12: 79582.8 | E12: 0.372 | F12: 98569.3 | G12: 0.917 | H12: 5114.6 | I12: 0.627 | J12: 1994 | K12: 0.54 | L12: 6555.6 | M12: 0.256 | N12: 1445.3 | O12: 0.183 | P12: 60587.8 | Q12: 0.34 | R12: 8319.7 | S12: 0.6
A13: 2015 | B13: 2523 | C13: 0.719 | D13: 79650.8 | E13: 0.357 | F13: 98614.6 | G13: 0.923 | H13: 5104.5 | I13: 0.626 | J13: 2527.7 | K13: 0.608 | L13: 9521.6 | M13: 0.255 | N13: 1697.3 | O13: 0.217 | P13: 67106.2 | Q13: 0.322 | R13: 9024.5 | S13: 0.593
A14: 2016 | B14: 2516.6 | C14: 0.716 | D14: 79806 | E14: 0.382 | F14: 99364.8 | G14: 0.923 | H14: 5099.5 | I14: 0.627 | J14: 2458.8 | K14: 0.648 | L14: 14161.4 | M14: 0.25 | N14: 1757.9 | O14: 0.221 | P14: 74162.7 | Q14: 0.345 | R14: 8979.8 | S14: 0.583
A15: 2017 | B15: 2460.4 | C15: 0.732 | D15: 79698.8 | E15: 0.43 | F15: 99619.5 | G15: 0.923 | H15: 5125.6 | I15: 0.618 | J15: 2375.8 | K15: 0.628 | L15: 21940.9 | M15: 0.256 | N15: 1757.9 | O15: 0.218 | P15: 83355.6 | Q15: 0.346 | R15: 8807.5 | S15: 0.602
A16: 2018 | B16: 2391.5 | C16: 0.76 | D16: 79771.9 | E16: 0.419 | F16: 99605.2 | G16: 0.925 | H16: 5059 | I16: 0.618 | J16: 2543.9 | K16: 0.654 | L16: 27143.3 | M16: 0.251 | N16: 1757.9 | O16: 0.236 | P16: 89228.5 | Q16: 0.346 | R16: 8760.2 | S16: 0.606
A17: Year 2016
A18: January | B18: 2516.6 | C18: 0.711 | D18: 79588 | E18: 0.432 | F18: 98920.9 | G18: 0.986 | H18: 5074.6 | I18: 0.616 | J18: 2460.1 | K18: 0.699 | L18: 12223.1 | M18: 0.151 | N18: 1757.9 | O18: 0.068 | P18: 72600.5 | Q18: 0.339 | R18: 8998.3 | S18: 0.614
A19: February | B19: 2516.6 | C19: 0.71 | D19: 79677.6 | E19: 0.435 | F19: 98920.9 | G19: 0.953 | H19: 5083.9 | I19: 0.612 | J19: 2460.1 | K19: 0.705 | L19: 12470.5 | M19: 0.228 | N19: 1757.9 | O19: 0.195 | P19: 73061.4 | Q19: 0.396 | R19: 8996.9 | S19: 0.617
A20: March | B20: 2516.6 | C20: 0.702 | D20: 79734.6 | E20: 0.462 | F20: 98920.9 | G20: 0.899 | H20: 5080 | I20: 0.609 | J20: 2460.1 | K20: 0.669 | L20: 12611.2 | M20: 0.247 | N20: 1757.9 | O20: 0.196 | P20: 73059.9 | Q20: 0.401 | R20: 8989.1 | S20: 0.582
A21: April | B21: 2516.6 | C21: 0.667 | D21: 79763.9 | E21: 0.45 | F21: 98920.9 | G21: 0.881 | H21: 5073.5 | I21: 0.629 | J21: 2460.1 | K21: 0.677 | L21: 12822 | M21: 0.271 | N21: 1757.9 | O21: 0.209 | P21: 73394.7 | Q21: 0.393 | R21: 8986.1 | S21: 0.524
A22: May | B22: 2516.6 | C22: 0.717 | D22: 79801.3 | E22: 0.429 | F22: 98920.9 | G22: 0.905 | H22: 5104.2 | I22: 0.651 | J22: 2460.1 | K22: 0.655 | L22: 13298 | M22: 0.3 | N22: 1757.9 | O22: 0.288 | P22: 73582.3 | Q22: 0.341 | R22: 8988.1 | S22: 0.54
A23: June | B23: 2516.6 | C23: 0.691 | D23: 79802.5 | E23: 0.404 | F23: 98920.9 | G23: 0.942 | H23: 5105.4 | I23: 0.638 | J23: 2460.1 | K23: 0.624 | L23: 13419.8 | M23: 0.302 | N23: 1757.9 | O23: 0.335 | P23: 73854.8 | Q23: 0.305 | R23: 8988.1 | S23: 0.584
A24: July | B24: 2516.6 | C24: 0.7 | D24: 79839.1 | E24: 0.36 | F24: 100042.9 | G24: 0.945 | H24: 5111.9 | I24: 0.634 | J24: 2460.1 | K24: 0.609 | L24: 13635.3 | M24: 0.315 | N24: 1757.9 | O24: 0.369 | P24: 74276.5 | Q24: 0.318 | R24: 8988.1 | S24: 0.602
A25: August | B25: 2516.6 | C25: 0.707 | D25: 79866.5 | E25: 0.329 | F25: 100042.9 | G25: 0.961 | H25: 5111 | I25: 0.633 | J25: 2456.9 | K25: 0.623 | L25: 14360.4 | M25: 0.316 | N25: 1757.9 | O25: 0.292 | P25: 74700.1 | Q25: 0.244 | R25: 8970.1 | S25: 0.614
A26: September | B26: 2516.6 | C26: 0.732 | D26: 79866.3 | E26: 0.285 | F26: 100042.9 | G26: 0.909 | H26: 5112.2 | I26: 0.612 | J26: 2456.9 | K26: 0.622 | L26: 15298.1 | M26: 0.284 | N26: 1757.9 | O26: 0.302 | P26: 74721.5 | Q26: 0.304 | R26: 8970.1 | S26: 0.582
A27: October | B27: 2516.6 | C27: 0.723 | D27: 79904.3 | E27: 0.292 | F27: 99564.8 | G27: 0.817 | H27: 5122.7 | I27: 0.578 | J27: 2456.9 | K27: 0.593 | L27: 16064.3 | M27: 0.239 | N27: 1757.9 | O27: 0.19 | P27: 74844.5 | Q27: 0.363 | R27: 8970.1 | S27: 0.54
A28: November | B28: 2516.6 | C28: 0.753 | D28: 79910.8 | E28: 0.327 | F28: 99564.8 | G28: 0.909 | H28: 5125.6 | I28: 0.65 | J28: 2456.9 | K28: 0.644 | L28: 16477.2 | M28: 0.203 | N28: 1757.9 | O28: 0.144 | P28: 75455.5 | Q28: 0.353 | R28: 8977.2 | S28: 0.586
A29: December | B29: 2516.6 | C29: 0.777 | D29: 79912.8 | E29: 0.379 | F29: 99564.8 | G29: 0.968 | H29: 5088.8 | I29: 0.657 | J29: 2456.9 | K29: 0.664 | L29: 17192 | M29: 0.162 | N29: 1757.9 | O29: 0.07 | P29: 76354.3 | Q29: 0.388 | R29: 8936.1 | S29: 0.617
A30: Year 2017
A31: January | B31: 2511.1 | C31: 0.749 | D31: 79657.2 | E31: 0.449 | F31: 99609.9 | G31: 0.987 | H31: 5095.1 | I31: 0.642 | J31: 2375.8 | K31: 0.638 | L31: 20249.8 | M31: 0.146 | N31: 1757.9 | O31: 0.073 | P31: 81337.2 | Q31: 0.342 | R31: 8748.6 | S31: 0.614
A32: February | B32: 2511.1 | C32: 0.73 | D32: 79657.2 | E32: 0.446 | F32: 99609.9 | G32: 0.95 | H32: 5097.3 | I32: 0.632 | J32: 2375.8 | K32: 0.654 | L32: 20603.7 | M32: 0.186 | N32: 1757.9 | O32: 0.116 | P32: 81713 | Q32: 0.402 | R32: 8748.6 | S32: 0.616
A33: March | B33: 2451.1 | C33: 0.738 | D33: 79657.2 | E33: 0.5 | F33: 99609.9 | G33: 0.878 | H33: 5097.3 | I33: 0.611 | J33: 2375.8 | K33: 0.648 | L33: 20792.6 | M33: 0.267 | N33: 1757.9 | O33: 0.229 | P33: 81962.1 | Q33: 0.418 | R33: 8741.6 | S33: 0.6
A34: April | B34: 2451.1 | C34: 0.756 | D34: 79660.1 | E34: 0.513 | F34: 99609.9 | G34: 0.792 | H34: 5105.7 | I34: 0.6 | J34: 2375.8 | K34: 0.618 | L34: 21177.9 | M34: 0.296 | N34: 1757.9 | O34: 0.248 | P34: 83041.4 | Q34: 0.424 | R34: 8789.1 | S34: 0.564
A35: May | B35: 2451.1 | C35: 0.71 | D35: 79660.1 | E35: 0.55 | F35: 99609.9 | G35: 0.828 | H35: 5122.7 | I35: 0.625 | J35: 2375.8 | K35: 0.581 | L35: 21700.6 | M35: 0.331 | N35: 1757.9 | O35: 0.309 | P35: 83182.1 | Q35: 0.372 | R35: 8796.6 | S35: 0.55
A36: June | B36: 2451.1 | C36: 0.724 | D36: 79660.1 | E36: 0.533 | F36: 99609.9 | G36: 0.935 | H36: 5126.7 | I36: 0.628 | J36: 2375.8 | K36: 0.591 | L36: 22006.1 | M36: 0.354 | N36: 1757.9 | O36: 0.379 | P36: 83313.5 | Q36: 0.334 | R36: 8802.9 | S36: 0.606
A37: July | B37: 2451.1 | C37: 0.749 | D37: 79667.4 | E37: 0.448 | F37: 99628.9 | G37: 0.962 | H37: 5145.2 | I37: 0.617 | J37: 2375.8 | K37: 0.589 | L37: 22242.6 | M37: 0.315 | N37: 1757.9 | O37: 0.253 | P37: 83498.6 | Q37: 0.258 | R37: 8802.9 | S37: 0.621
A38: August | B38: 2451.1 | C38: 0.744 | D38: 79614.2 | E38: 0.371 | F38: 99628.9 | G38: 0.977 | H38: 5147.3 | I38: 0.62 | J38: 2375.8 | K38: 0.65 | L38: 22356.4 | M38: 0.299 | N38: 1757.9 | O38: 0.275 | P38: 83980.6 | Q38: 0.222 | R38: 8856.4 | S38: 0.633
