Workbook
Name billion_kw_to_MW: About!$B$39
Name gigwatt_to_megawatt: About!$B$40
Name Percent_rural: About!$A$37
Name Percent_Urban: About!$A$36

Sheet About
A1: BDEQ BAU Electricity Output from Distributed Sources | B1: Nebraska | C1: 46260 | F1: State | G1: State
A2: BDEQ BAU Distributed Electricity Source Capacity | B2: =LOOKUP(B1,F2:G51,G2:G51) -> NE | F2: Alabama | G2: AL
F3: Alaska | G3: AK
A4: Sources: | B4: res v commercial breakdown | F4: Arizona | G4: AZ
B5: Energy Information Administration | F5: Arkansas | G5: AR
B6: 2023 | F6: California | G6: CA
B7: Annual Electric Power Industry Report, Form EIA-861 detailed data files | F7: Colorado | G7: CO
B8: https://www.eia.gov/electricity/data/eia861/ | F8: Connecticut | G8: CT
B9: Net_metering_2022 | F9: Delaware | G9: DE
F10: Florida | G10: FL
B11: Urban vs. Rural Residential Households | F11: Georgia | G11: GA
B12: Energy Information Administration | F12: Hawaii | G12: HI
B13: 2018 | F13: Idaho | G13: ID
B14: Residential Energy Consumption Survey (RECS) | F14: Illinois | G14: IL
B15: https://www.eia.gov/consumption/residential/data/2015/hc/hc2.1.xlsx | F15: Indiana | G15: IN
B16: Table HC2.1 | F16: Iowa | G16: IA
F17: Kansas | G17: KS
B18: Solar for All awards | F18: Kentucky | G18: KY
B19: US Environmental Protection Agency, Greenhouse Gas Reduction Fund - Solar for All | F19: Louisiana | G19: LA
B20: Selected applicants announced 22 April 2024; program terminated 7 August 2025 | F20: Maine | G20: ME
B21: https://19january2025snapshot.epa.gov/greenhouse-gas-reduction-fund/solar-all | F21: Maryland | G21: MD
B22: Award table reproduced on the 'SFA Awards' tab of this workbook | F22: Massachusetts | G22: MA
B23: 2026 | F23: Michigan | G23: MI
F24: Minnesota | G24: MN
B25: State population weights | F25: Mississippi | G25: MS
B26: US Census Bureau, 2020 Census resident population | F26: Missouri | G26: MO
B27: Reproduced on the 'SFA Multistate Split' tab of this workbook | F27: Montana | G27: MT
F28: Nebraska | G28: NE
A29: Notes | F29: Nevada | G29: NV
A30: The variable "BCEU BAU Components Energy Use" includes only "purchased electricity" | F30: New Hampshire | G30: NH
A31: (i.e. that which buildings get from the grid, not generate on-site), so the quantities | F31: New Jersey | G31: NJ
A32: of generation in this variable are additional. Electricity Output is reported in MWh and | F32: New Mexico | G32: NM
A33: Capacity is reported in MW | F33: New York | G33: NY
F34: North Carolina | G34: NC
A35: Urban Rural Split | F35: North Dakota | G35: ND
A36: 0.80118443 | B36: Urban | F36: Ohio | G36: OH
A37: 0.19881557 | B37: Rural | F37: Oklahoma | G37: OK
F38: Oregon | G38: OR
A39: Conversion from billion kilowatthours to megawatthours | B39: 1000000 | F39: Pennsylvania | G39: PA
A40: Conversion from gigawatts to megawatts | B40: 1000 | F40: Rhode Island | G40: RI
...

Sheet States
A1: Utility Characteristics | F1: Photovoltaic | AP1: Wind | BE1: Other | BT1: All Technologies
F2: Capacity MW | L2: Installations | Q2: Storage Capacity (MW) | V2: Storage Installations | AA2: Virtual Capacity (MW) | AF2: Virtual Customers | AK2: Energy Sold Back MWh | AP2: Capacity MW | AU2: Installations | AZ2: Energy Sold Back MWh | BE2: Capacity MW | BJ2: Installations | BO2: Energy Sold Back MWh | BT2: Capacity MW | BY2: Installations | CD2: Energy Sold Back MWh
A3: Year | B3: State | C3: Utility Number | D3: Utility Name | E3: BA Code | F3: Type | G3: Residential | H3: Commercial | I3: Industrial | J3: Transportation | K3: Total | L3: Residential | M3: Commercial | N3: Industrial | O3: Transportation | P3: Total | Q3: Residential | R3: Commercial | S3: Industrial | T3: Transportation | U3: Total | V3: Residential | W3: Commercial | X3: Industrial | Y3: Transportation | Z3: Total | AA3: Residential | AB3: Commercial | AC3: Industrial | AD3: Transportation | AE3: Total | AF3: Residential | AG3: Commercial | AH3: Industrial | AI3: Transportation | AJ3: Total | AK3: Residential | AL3: Commercial | AM3: Industrial | AN3: Transportation | AO3: Total | AP3: Residential | AQ3: Commercial | AR3: Industrial | AS3: Transportation | AT3: Total | AU3: Residential | AV3: Commercial | AW3: Industrial | AX3: Transportation | AY3: Total | AZ3: Residential | BA3: Commercial | BB3: Industrial | BC3: Transportation | BD3: Total | BE3: Residential | BF3: Commercial | BG3: Industrial | BH3: Transportation | BI3: Total | BJ3: Residential | BK3: Commercial | BL3: Industrial | BM3: Transportation | BN3: Total | BO3: Residential | BP3: Commercial | BQ3: Industrial | BR3: Transportation | BS3: Total | BT3: Residential | BU3: Commercial | BV3: Industrial | BW3: Transportation | BX3: Total | BY3: Residential | BZ3: Commercial | CA3: Industrial | CB3: Transportation | CC3: Total | CD3: Residential | CE3: Commercial | CF3: Industrial | CG3: Transportation | CH3: Total
A4: 2022 | B4: AK | C4: 219 | D4: Alaska Power and Telephone Co | E4: NA | F4: AC | G4: 0.012 | H4: 0.021 | I4: . | J4: . | K4: 0.033 | L4: 3 | M4: 2 | N4: . | O4: . | P4: 5 | Q4: . | R4: . | S4: . | T4: . | U4: . | V4: . | W4: . | X4: . | Y4: . | Z4: . | AA4: . | AB4: . | AC4: . | AD4: . | AE4: . | AF4: . | AG4: . | AH4: . | AI4: . | AJ4: . | AK4: 1.919 | AL4: 4.06 | AM4: . | AN4: . | AO4: 5.979 | AP4: . | AQ4: . | AR4: . | AS4: . | AT4: 0 | AU4: . | AV4: . | AW4: . | AX4: . | AY4: 0 | AZ4: . | BA4: . | BB4: . | BC4: . | BD4: 0 | BE4: 0.005 | BF4: . | BG4: . | BH4: . | BI4: 0.005 | BJ4: 1 | BK4: . | BL4: . | BM4: . | BN4: 1 | BO4: 0 | BP4: . | BQ4: . | BR4: . | BS4: 0 | BT4: 0.017 | BU4: 0.021 | BV4: 0 | BW4: 0 | BX4: 0.038 | BY4: 4 | BZ4: 2 | CA4: 0 | CB4: 0 | CC4: 6 | CD4: 1.919 | CE4: 4.06 | CF4: 0 | CG4: 0 | CH4: 5.979
A5: 2022 | B5: AK | C5: 3522 | D5: Chugach Electric Assn Inc | E5: CEA | F5: AC | G5: 3.373 | H5: 0.639 | I5: . | J5: . | K5: 4.012 | L5: 716 | M5: 61 | N5: . | O5: . | P5: 777 | Q5: . | R5: . | S5: . | T5: . | U5: . | V5: . | W5: . | X5: . | Y5: . | Z5: . | AA5: . | AB5: . | AC5: . | AD5: . | AE5: . | AF5: . | AG5: . | AH5: . | AI5: . | AJ5: . | AK5: . | AL5: . | AM5: . | AN5: . | AO5: 0 | AP5: . | AQ5: 0.01 | AR5: . | AS5: . | AT5: 0.01 | AU5: . | AV5: 4 | AW5: . | AX5: . | AY5: 4 | AZ5: . | BA5: . | BB5: . | BC5: . | BD5: 0 | BE5: . | BF5: . | BG5: . | BH5: . | BI5: 0 | BJ5: . | BK5: . | BL5: . | BM5: . | BN5: 0 | BO5: . | BP5: . | BQ5: . | BR5: . | BS5: 0 | BT5: 3.373 | BU5: 0.649 | BV5: 0 | BW5: 0 | BX5: 4.022 | BY5: 716 | BZ5: 65 | CA5: 0 | CB5: 0 | CC5: 781 | CD5: 0 | CE5: 0 | CF5: 0 | CG5: 0 | CH5: 0
A6: 2022 | B6: AK | C6: 7353 | D6: Golden Valley Elec Assn Inc | E6: NA | F6: AC | G6: 2.876 | H6: 0.422 | I6: 0.067 | J6: 0 | K6: 3.365 | L6: 556 | M6: 42 | N6: 5 | O6: 0 | P6: 603 | Q6: . | R6: . | S6: . | T6: . | U6: . | V6: . | W6: . | X6: . | Y6: . | Z6: . | AA6: . | AB6: . | AC6: . | AD6: . | AE6: . | AF6: . | AG6: . | AH6: . | AI6: . | AJ6: . | AK6: 404.969 | AL6: 44.365 | AM6: 0 | AN6: 0 | AO6: 449.334 | AP6: 0.013 | AQ6: 0.012 | AR6: 0 | AS6: 0 | AT6: 0.025 | AU6: 4 | AV6: 2 | AW6: 0 | AX6: 0 | AY6: 6 | AZ6: . | BA6: . | BB6: . | BC6: . | BD6: 0 | BE6: . | BF6: . | BG6: . | BH6: . | BI6: 0 | BJ6: . | BK6: . | BL6: . | BM6: . | BN6: 0 | BO6: . | BP6: . | BQ6: . | BR6: . | BS6: 0 | BT6: 2.889 | BU6: 0.434 | BV6: 0.067 | BW6: 0 | BX6: 3.39 | BY6: 560 | BZ6: 44 | CA6: 5 | CB6: 0 | CC6: 609 | CD6: 404.969 | CE6: 44.365 | CF6: 0 | CG6: 0 | CH6: 449.334
A7: 2022 | B7: AK | C7: 11824 | D7: Matanuska Electric Assn Inc | E7: NA | F7: AC | G7: 2.206 | H7: 0.284 | I7: . | J7: . | K7: 2.49 | L7: 347 | M7: 23 | N7: . | O7: . | P7: 370 | Q7: . | R7: . | S7: . | T7: . | U7: . | V7: . | W7: . | X7: . | Y7: . | Z7: . | AA7: . | AB7: . | AC7: . | AD7: . | AE7: . | AF7: . | AG7: . | AH7: . | AI7: . | AJ7: . | AK7: . | AL7: . | AM7: . | AN7: . | AO7: 0 | AP7: 0.064 | AQ7: 0.016 | AR7: . | AS7: . | AT7: 0.08 | AU7: 20 | AV7: 3 | AW7: . | AX7: . | AY7: 23 | AZ7: . | BA7: . | BB7: . | BC7: . | BD7: 0 | BE7: 0.048 | BF7: 0.004 | BG7: . | BH7: . | BI7: 0.052 | BJ7: 7 | BK7: 1 | BL7: . | BM7: . | BN7: 8 | BO7: . | BP7: . | BQ7: . | BR7: . | BS7: 0 | BT7: 2.318 | BU7: 0.304 | BV7: 0 | BW7: 0 | BX7: 2.622 | BY7: 374 | BZ7: 27 | CA7: 0 | CB7: 0 | CC7: 401 | CD7: 0 | CE7: 0 | CF7: 0 | CG7: 0 | CH7: 0
A8: 2022 | B8: AK | C8: 19558 | D8: Homer Electric Assn Inc | E8: NA | F8: DC | G8: 2.511 | H8: 0.782 | I8: 0 | J8: 0 | K8: 3.293 | L8: 451 | M8: 47 | N8: 0 | O8: 0 | P8: 498 | Q8: . | R8: . | S8: . | T8: . | U8: . | V8: . | W8: . | X8: . | Y8: . | Z8: . | AA8: . | AB8: . | AC8: . | AD8: . | AE8: . | AF8: . | AG8: . | AH8: . | AI8: . | AJ8: . | AK8: 1268.392 | AL8: 61.066 | AM8: . | AN8: . | AO8: 1329.458 | AP8: 0.109 | AQ8: 0.008 | AR8: . | AS8: . | AT8: 0.117 | AU8: 32 | AV8: 2 | AW8: . | AX8: . | AY8: 34 | AZ8: 18.174 | BA8: 1.586 | BB8: . | BC8: . | BD8: 19.76 | BE8: . | BF8: . | BG8: . | BH8: . | BI8: 0 | BJ8: . | BK8: . | BL8: . | BM8: . | BN8: 0 | BO8: . | BP8: . | BQ8: . | BR8: . | BS8: 0 | BT8: 2.62 | BU8: 0.79 | BV8: 0 | BW8: 0 | BX8: 3.41 | BY8: 483 | BZ8: 49 | CA8: 0 | CB8: 0 | CC8: 532 | CD8: 1286.566 | CE8: 62.652 | CF8: 0 | CG8: 0 | CH8: 1349.218
A9: 2022 | B9: AK | C9: 99999 | D9: Adjustment 2022 | E9: NA | G9: -0.438 | H9: -0.136 | I9: 0 | J9: 0 | K9: -0.574 | L9: . | M9: . | N9: . | O9: . | P9: . | Q9: . | R9: . | S9: . | T9: . | U9: . | V9: . | W9: . | X9: . | Y9: . | Z9: . | AA9: . | AB9: . | AC9: . | AD9: . | AE9: . | AF9: . | AG9: . | AH9: . | AI9: . | AJ9: . | AK9: . | AL9: . | AM9: . | AN9: . | AO9: . | AP9: . | AQ9: . | AR9: . | AS9: . | AT9: . | AU9: . | AV9: . | AW9: . | AX9: . | AY9: . | AZ9: . | BA9: . | BB9: . | BC9: . | BD9: . | BE9: . | BF9: . | BG9: . | BH9: . | BI9: . | BJ9: . | BK9: . | BL9: . | BM9: . | BN9: . | BO9: . | BP9: . | BQ9: . | BR9: . | BS9: . | BT9: -0.438 | BU9: -0.136 | BV9: 0 | BW9: 0 | BX9: -0.574 | BY9: . | BZ9: . | CA9: . | CB9: . | CC9: . | CD9: . | CE9: . | CF9: . | CG9: . | CH9: .
A10: 2022 | B10: AL | C10: 3222 | D10: Central Alabama Electric Coop | E10: SOCO | F10: DC | G10: 0.157 | H10: . | I10: . | J10: . | K10: 0.157 | L10: 23 | M10: . | N10: . | O10: . | P10: 23 | Q10: . | R10: . | S10: . | T10: . | U10: . | V10: . | W10: . | X10: . | Y10: . | Z10: . | AA10: . | AB10: . | AC10: . | AD10: . | AE10: . | AF10: . | AG10: . | AH10: . | AI10: . | AJ10: . | AK10: 1.78 | AL10: . | AM10: . | AN10: . | AO10: 1.78 | AP10: . | AQ10: . | AR10: . | AS10: . | AT10: 0 | AU10: . | AV10: . | AW10: . | AX10: . | AY10: 0 | AZ10: . | BA10: . | BB10: . | BC10: . | BD10: 0 | BE10: . | BF10: . | BG10: . | BH10: . | BI10: 0 | BJ10: . | BK10: . | BL10: . | BM10: . | BN10: 0 | BO10: . | BP10: . | BQ10: . | BR10: . | BS10: 0 | BT10: 0.157 | BU10: 0 | BV10: 0 | BW10: 0 | BX10: 0.157 | BY10: 23 | BZ10: 0 | CA10: 0 | CB10: 0 | CC10: 23 | CD10: 1.78 | CE10: 0 | CF10: 0 | CG10: 0 | CH10: 1.78
A11: 2022 | B11: AL | C11: 4327 | D11: Coosa Valley Electric Coop Inc | E11: SOCO | F11: AC | G11: 0.01 | H11: . | I11: . | J11: . | K11: 0.01 | L11: 1 | M11: . | N11: . | O11: . | P11: 1 | Q11: . | R11: . | S11: . | T11: . | U11: 0 | V11: . | W11: . | X11: . | Y11: . | Z11: 0 | AA11: . | AB11: . | AC11: . | AD11: . | AE11: 0 | AF11: . | AG11: . | AH11: . | AI11: . | AJ11: 0 | AK11: . | AL11: . | AM11: . | AN11: . | AO11: 0 | AP11: . | AQ11: . | AR11: . | AS11: . | AT11: 0 | AU11: . | AV11: . | AW11: . | AX11: . | AY11: 0 | AZ11: . | BA11: . | BB11: . | BC11: . | BD11: 0 | BE11: . | BF11: . | BG11: . | BH11: . | BI11: 0 | BJ11: . | BK11: . | BL11: . | BM11: . | BN11: 0 | BO11: . | BP11: . | BQ11: . | BR11: . | BS11: 0 | BT11: 0.01 | BU11: 0 | BV11: 0 | BW11: 0 | BX11: 0.01 | BY11: 1 | BZ11: 0 | CA11: 0 | CB11: 0 | CC11: 1 | CD11: 0 | CE11: 0 | CF11: 0 | CG11: 0 | CH11: 0
A12: 2022 | B12: AL | C12: 4430 | D12: Covington Electric Coop, Inc | E12: SOCO | F12: AC | G12: 0.058 | H12: . | I12: . | J12: . | K12: 0.058 | L12: 8 | M12: . | N12: . | O12: . | P12: 8 | Q12: . | R12: . | S12: . | T12: . | U12: . | V12: . | W12: . | X12: . | Y12: . | Z12: . | AA12: . | AB12: . | AC12: . | AD12: . | AE12: . | AF12: . | AG12: . | AH12: . | AI12: . | AJ12: . | AK12: 23.312 | AL12: . | AM12: . | AN12: . | AO12: 23.312 | AP12: . | AQ12: . | AR12: . | AS12: . | AT12: 0 | AU12: . | AV12: . | AW12: . | AX12: . | AY12: 0 | AZ12: . | BA12: . | BB12: . | BC12: . | BD12: 0 | BE12: . | BF12: . | BG12: . | BH12: . | BI12: 0 | BJ12: . | BK12: . | BL12: . | BM12: . | BN12: 0 | BO12: . | BP12: . | BQ12: . | BR12: . | BS12: 0 | BT12: 0.058 | BU12: 0 | BV12: 0 | BW12: 0 | BX12: 0.058 | BY12: 8 | BZ12: 0 | CA12: 0 | CB12: 0 | CC12: 8 | CD12: 23.312 | CE12: 0 | CF12: 0 | CG12: 0 | CH12: 23.312
A13: 2022 | B13: AL | C13: 6491 | D13: Foley Board of Utilities | E13: SOCO | F13: AC | G13: 0.19 | H13: 0.5 | I13: . | J13: . | K13: 0.69 | L13: 19 | M13: 5 | N13: . | O13: . | P13: 24 | Q13: . | R13: . | S13: . | T13: . | U13: . | V13: . | W13: . | X13: . | Y13: . | Z13: . | AA13: . | AB13: . | AC13: . | AD13: . | AE13: . | AF13: . | AG13: . | AH13: . | AI13: . | AJ13: . | AK13: . | AL13: . | AM13: . | AN13: . | AO13: 0 | AP13: . | AQ13: . | AR13: . | AS13: . | AT13: 0 | AU13: . | AV13: . | AW13: . | AX13: . | AY13: 0 | AZ13: . | BA13: . | BB13: . | BC13: . | BD13: 0 | BE13: . | BF13: . | BG13: . | BH13: . | BI13: 0 | BJ13: . | BK13: . | BL13: . | BM13: . | BN13: 0 | BO13: . | BP13: . | BQ13: . | BR13: . | BS13: 0 | BT13: 0.19 | BU13: 0.5 | BV13: 0 | BW13: 0 | BX13: 0.69 | BY13: 19 | BZ13: 5 | CA13: 0 | CB13: 0 | CC13: 24 | CD13: 0 | CE13: 0 | CF13: 0 | CG13: 0 | CH13: 0
A14: 2022 | B14: AL | C14: 17646 | D14: Southern Pine Elec Coop, Inc | E14: SOCO | F14: AC | G14: 0.001 | H14: . | I14: . | J14: . | K14: 0.001 | L14: 2 | M14: . | N14: . | O14: . | P14: 2 | Q14: . | R14: . | S14: . | T14: . | U14: . | V14: . | W14: . | X14: . | Y14: . | Z14: . | AA14: . | AB14: . | AC14: . | AD14: . | AE14: . | AF14: . | AG14: . | AH14: . | AI14: . | AJ14: . | AK14: . | AL14: . | AM14: . | AN14: . | AO14: 0 | AP14: 0.001 | AQ14: . | AR14: . | AS14: . | AT14: 0.001 | AU14: 1 | AV14: . | AW14: . | AX14: . | AY14: 1 | AZ14: . | BA14: . | BB14: . | BC14: . | BD14: 0 | BE14: . | BF14: . | BG14: . | BH14: . | BI14: 0 | BJ14: . | BK14: . | BL14: . | BM14: . | BN14: 0 | BO14: . | BP14: . | BQ14: . | BR14: . | BS14: 0 | BT14: 0.002 | BU14: 0 | BV14: 0 | BW14: 0 | BX14: 0.002 | BY14: 3 | BZ14: 0 | CA14: 0 | CB14: 0 | CC14: 3 | CD14: 0 | CE14: 0 | CF14: 0 | CG14: 0 | CH14: 0
A15: 2022 | B15: AL | C15: 99999 | D15: Adjustment 2022 | E15: SOCO | G15: -0.027 | H15: . | I15: . | J15: . | K15: -0.027 | L15: . | M15: . | N15: . | O15: . | P15: . | Q15: . | R15: . | S15: . | T15: . | U15: . | V15: . | W15: . | X15: . | Y15: . | Z15: . | AA15: . | AB15: . | AC15: . | AD15: . | AE15: . | AF15: . | AG15: . | AH15: . | AI15: . | AJ15: . | AK15: . | AL15: . | AM15: . | AN15: . | AO15: . | AP15: . | AQ15: . | AR15: . | AS15: . | AT15: . | AU15: . | AV15: . | AW15: . | AX15: . | AY15: . | AZ15: . | BA15: . | BB15: . | BC15: . | BD15: . | BE15: . | BF15: . | BG15: . | BH15: . | BI15: . | BJ15: . | BK15: . | BL15: . | BM15: . | BN15: . | BO15: . | BP15: . | BQ15: . | BR15: . | BS15: . | BT15: -0.027 | BU15: . | BV15: . | BW15: . | BX15: -0.027 | BY15: . | BZ15: . | CA15: . | CB15: . | CC15: . | CD15: . | CE15: . | CF15: . | CG15: . | CH15: .
A16: 2022 | B16: AR | C16: 814 | D16: Entergy Arkansas LLC | E16: MISO | F16: DC | G16: 46.03 | H16: 34.92 | I16: 3.449 | J16: . | K16: 84.399 | L16: 4253 | M16: 189 | N16: 26 | O16: . | P16: 4468 | Q16: . | R16: . | S16: . | T16: . | U16: . | V16: . | W16: . | X16: . | Y16: . | Z16: . | AA16: . | AB16: . | AC16: . | AD16: . | AE16: . | AF16: . | AG16: . | AH16: . | AI16: . | AJ16: . | AK16: . | AL16: . | AM16: . | AN16: . | AO16: 0 | AP16: 0.007 | AQ16: 0.002 | AR16: 0.006 | AS16: . | AT16: 0.015 | AU16: 1 | AV16: 1 | AW16: 2 | AX16: . | AY16: 4 | AZ16: . | BA16: . | BB16: . | BC16: . | BD16: 0 | BE16: . | BF16: . | BG16: . | BH16: . | BI16: 0 | BJ16: . | BK16: . | BL16: . | BM16: . | BN16: 0 | BO16: . | BP16: . | BQ16: . | BR16: . | BS16: 0 | BT16: 46.037 | BU16: 34.922 | BV16: 3.455 | BW16: 0 | BX16: 84.414 | BY16: 4254 | BZ16: 190 | CA16: 28 | CB16: 0 | CC16: 4472 | CD16: 0 | CE16: 0 | CF16: 0 | CG16: 0 | CH16: 0
A17: 2022 | B17: AR | C17: 817 | D17: Arkansas Valley Elec Coop Corp | E17: SWPP | F17: DC | G17: 7.318 | H17: 1.822 | I17: . | J17: . | K17: 9.14 | L17: 699 | M17: 12 | N17: . | O17: . | P17: 711 | Q17: . | R17: . | S17: . | T17: . | U17: . | V17: . | W17: . | X17: . | Y17: . | Z17: . | AA17: . | AB17: . | AC17: . | AD17: . | AE17: . | AF17: . | AG17: . | AH17: . | AI17: . | AJ17: . | AK17: 4094.546 | AL17: 2272.106 | AM17: . | AN17: . | AO17: 6366.652 | AP17: 0.007 | AQ17: . | AR17: . | AS17: . | AT17: 0.007 | AU17: 2 | AV17: . | AW17: . | AX17: . | AY17: 2 | AZ17: 0 | BA17: . | BB17: . | BC17: . | BD17: 0 | BE17: . | BF17: . | BG17: . | BH17: . | BI17: 0 | BJ17: . | BK17: . | BL17: . | BM17: . | BN17: 0 | BO17: . | BP17: . | BQ17: . | BR17: . | BS17: 0 | BT17: 7.325 | BU17: 1.822 | BV17: 0 | BW17: 0 | BX17: 9.147 | BY17: 701 | BZ17: 12 | CA17: 0 | CB17: 0 | CC17: 713 | CD17: 4094.546 | CE17: 2272.106 | CF17: 0 | CG17: 0 | CH17: 6366.652
A18: 2022 | B18: AR | C18: 1586 | D18: City of Bentonville - (AR) | E18: SWPP | F18: DC | G18: 6.3 | H18: 3.6 | I18: . | J18: . | K18: 9.9 | L18: 252 | M18: 12 | N18: . | O18: . | P18: 264 | Q18: . | R18: . | S18: . | T18: . | U18: . | V18: . | W18: . | X18: . | Y18: . | Z18: . | AA18: . | AB18: . | AC18: . | AD18: . | AE18: . | AF18: . | AG18: . | AH18: . | AI18: . | AJ18: . | AK18: . | AL18: . | AM18: . | AN18: . | AO18: 0 | AP18: . | AQ18: . | AR18: . | AS18: . | AT18: 0 | AU18: . | AV18: . | AW18: . | AX18: . | AY18: 0 | AZ18: . | BA18: . | BB18: . | BC18: . | BD18: 0 | BE18: . | BF18: . | BG18: . | BH18: . | BI18: 0 | BJ18: . | BK18: . | BL18: . | BM18: . | BN18: 0 | BO18: . | BP18: . | BQ18: . | BR18: . | BS18: 0 | BT18: 6.3 | BU18: 3.6 | BV18: 0 | BW18: 0 | BX18: 9.9 | BY18: 252 | BZ18: 12 | CA18: 0 | CB18: 0 | CC18: 264 | CD18: 0 | CE18: 0 | CF18: 0 | CG18: 0 | CH18: 0
A19: 2022 | B19: AR | C19: 2678 | D19: C & L Electric Coop Corp | E19: MISO | F19: DC | G19: 1.971 | H19: 3.576 | I19: . | J19: . | K19: 5.547 | L19: 169 | M19: 16 | N19: . | O19: . | P19: 185 | Q19: . | R19: . | S19: . | T19: . | U19: . | V19: . | W19: . | X19: . | Y19: . | Z19: . | AA19: . | AB19: . | AC19: . | AD19: . | AE19: . | AF19: . | AG19: . | AH19: . | AI19: . | AJ19: . | AK19: . | AL19: . | AM19: . | AN19: . | AO19: 0 | AP19: . | AQ19: . | AR19: . | AS19: . | AT19: 0 | AU19: . | AV19: . | AW19: . | AX19: . | AY19: 0 | AZ19: . | BA19: . | BB19: . | BC19: . | BD19: 0 | BE19: . | BF19: . | BG19: . | BH19: . | BI19: 0 | BJ19: . | BK19: . | BL19: . | BM19: . | BN19: 0 | BO19: . | BP19: . | BQ19: . | BR19: . | BS19: 0 | BT19: 1.971 | BU19: 3.576 | BV19: 0 | BW19: 0 | BX19: 5.547 | BY19: 169 | BZ19: 16 | CA19: 0 | CB19: 0 | CC19: 185 | CD19: 0 | CE19: 0 | CF19: 0 | CG19: 0 | CH19: 0
A20: 2022 | B20: AR | C20: 3093 | D20: Carroll Electric Coop Corp - (AR) | E20: SWPP | F20: DC | G20: 12.77 | H20: . | I20: . | J20: . | K20: 12.77 | L20: 1564 | M20: . | N20: . | O20: . | P20: 1564 | Q20: . | R20: . | S20: . | T20: . | U20: . | V20: . | W20: . | X20: . | Y20: . | Z20: . | AA20: . | AB20: . | AC20: . | AD20: . | AE20: . | AF20: . | AG20: . | AH20: . | AI20: . | AJ20: . | AK20: . | AL20: . | AM20: . | AN20: . | AO20: 0 | AP20: 0.019 | AQ20: . | AR20: . | AS20: . | AT20: 0.019 | AU20: 3 | AV20: . | AW20: . | AX20: . | AY20: 3 | AZ20: . | BA20: . | BB20: . | BC20: . | BD20: 0 | BE20: . | BF20: . | BG20: . | BH20: . | BI20: 0 | BJ20: . | BK20: . | BL20: . | BM20: . | BN20: 0 | BO20: . | BP20: . | BQ20: . | BR20: . | BS20: 0 | BT20: 12.789 | BU20: 0 | BV20: 0 | BW20: 0 | BX20: 12.789 | BY20: 1567 | BZ20: 0 | CA20: 0 | CB20: 0 | CC20: 1567 | CD20: 0 | CE20: 0 | CF20: 0 | CG20: 0 | CH20: 0
A21: 2022 | B21: AR | C21: 3712 | D21: Clay County Electric Coop Corp | E21: MISO | F21: AC | G21: 0.165 | H21: 0.463 | I21: . | J21: . | K21: 0.628 | L21: 23 | M21: 4 | N21: . | O21: . | P21: 27 | Q21: . | R21: . | S21: . | T21: . | U21: . | V21: . | W21: . | X21: . | Y21: . | Z21: . | AA21: . | AB21: . | AC21: . | AD21: . | AE21: . | AF21: . | AG21: . | AH21: . | AI21: . | AJ21: . | AK21: . | AL21: . | AM21: . | AN21: . | AO21: 0 | AP21: . | AQ21: . | AR21: . | AS21: . | AT21: 0 | AU21: . | AV21: . | AW21: . | AX21: . | AY21: 0 | AZ21: . | BA21: . | BB21: . | BC21: . | BD21: 0 | BE21: . | BF21: . | BG21: . | BH21: . | BI21: 0 | BJ21: . | BK21: . | BL21: . | BM21: . | BN21: 0 | BO21: . | BP21: . | BQ21: . | BR21: . | BS21: 0 | BT21: 0.165 | BU21: 0.463 | BV21: 0 | BW21: 0 | BX21: 0.628 | BY21: 23 | BZ21: 4 | CA21: 0 | CB21: 0 | CC21: 27 | CD21: 0 | CE21: 0 | CF21: 0 | CG21: 0 | CH21: 0
A22: 2022 | B22: AR | C22: 4280 | D22: Conway Corporation | E22: MISO | F22: AC | G22: 0.361 | H22: . | I22: . | J22: . | K22: 0.361 | L22: 56 | M22: . | N22: . | O22: . | P22: 56 | Q22: . | R22: . | S22: . | T22: . | U22: . | V22: . | W22: . | X22: . | Y22: . | Z22: . | AA22: . | AB22: . | AC22: . | AD22: . | AE22: . | AF22: . | AG22: . | AH22: . | AI22: . | AJ22: . | AK22: . | AL22: . | AM22: . | AN22: . | AO22: 0 | AP22: . | AQ22: . | AR22: . | AS22: . | AT22: 0 | AU22: . | AV22: . | AW22: . | AX22: . | AY22: 0 | AZ22: . | BA22: . | BB22: . | BC22: . | BD22: 0 | BE22: . | BF22: . | BG22: . | BH22: . | BI22: 0 | BJ22: . | BK22: . | BL22: . | BM22: . | BN22: 0 | BO22: . | BP22: . | BQ22: . | BR22: . | BS22: 0 | BT22: 0.361 | BU22: 0 | BV22: 0 | BW22: 0 | BX22: 0.361 | BY22: 56 | BZ22: 0 | CA22: 0 | CB22: 0 | CC22: 56 | CD22: 0 | CE22: 0 | CF22: 0 | CG22: 0 | CH22: 0
A23: 2022 | B23: AR | C23: 4509 | D23: Craighead Electric Coop Corp | E23: MISO | F23: AC | G23: 0.848 | H23: 3.2 | I23: . | J23: . | K23: 4.048 | L23: 87 | M23: 8 | N23: . | O23: . | P23: 95 | Q23: 0.012 | R23: 3 | S23: . | T23: . | U23: 3.012 | V23: 3 | W23: 6 | X23: . | Y23: . | Z23: 9 | AA23: . | AB23: . | AC23: . | AD23: . | AE23: 0 | AF23: . | AG23: . | AH23: . | AI23: . | AJ23: 0 | AK23: . | AL23: . | AM23: . | AN23: . | AO23: 0 | AP23: . | AQ23: . | AR23: . | AS23: . | AT23: 0 | AU23: . | AV23: . | AW23: . | AX23: . | AY23: 0 | AZ23: . | BA23: . | BB23: . | BC23: . | BD23: 0 | BE23: . | BF23: . | BG23: . | BH23: . | BI23: 0 | BJ23: . | BK23: . | BL23: . | BM23: . | BN23: 0 | BO23: . | BP23: . | BQ23: . | BR23: . | BS23: 0 | BT23: 0.848 | BU23: 3.2 | BV23: 0 | BW23: 0 | BX23: 4.048 | BY23: 87 | BZ23: 8 | CA23: 0 | CB23: 0 | CC23: 95 | CD23: 0 | CE23: 0 | CF23: 0 | CG23: 0 | CH23: 0
A24: 2022 | B24: AR | C24: 5860 | D24: Empire District Electric Co | E24: SWPP | F24: DC | G24: 0.688 | H24: . | I24: . | J24: . | K24: 0.688 | L24: 89 | M24: . | N24: . | O24: . | P24: 89 | Q24: . | R24: . | S24: . | T24: . | U24: . | V24: . | W24: . | X24: . | Y24: . | Z24: . | AA24: . | AB24: . | AC24: . | AD24: . | AE24: . | AF24: . | AG24: . | AH24: . | AI24: . | AJ24: . | AK24: . | AL24: . | AM24: . | AN24: . | AO24: 0 | AP24: . | AQ24: . | AR24: . | AS24: . | AT24: 0 | AU24: . | AV24: . | AW24: . | AX24: . | AY24: 0 | AZ24: . | BA24: . | BB24: . | BC24: . | BD24: 0 | BE24: . | BF24: . | BG24: . | BH24: . | BI24: 0 | BJ24: . | BK24: . | BL24: . | BM24: . | BN24: 0 | BO24: . | BP24: . | BQ24: . | BR24: . | BS24: 0 | BT24: 0.688 | BU24: 0 | BV24: 0 | BW24: 0 | BX24: 0.688 | BY24: 89 | BZ24: 0 | CA24: 0 | CB24: 0 | CC24: 89 | CD24: 0 | CE24: 0 | CF24: 0 | CG24: 0 | CH24: 0
A25: 2022 | B25: AR | C25: 6342 | D25: First Electric Coop Corp | E25: MISO | F25: AC | G25: 12.462 | H25: 0.446 | I25: 0.791 | J25: . | K25: 13.699 | L25: 1329 | M25: 8 | N25: 7 | O25: . | P25: 1344 | Q25: . | R25: . | S25: . | T25: . | U25: . | V25: . | W25: . | X25: . | Y25: . | Z25: . | AA25: . | AB25: . | AC25: . | AD25: . | AE25: . | AF25: . | AG25: . | AH25: . | AI25: . | AJ25: . | AK25: . | AL25: . | AM25: . | AN25: . | AO25: 0 | AP25: . | AQ25: . | AR25: . | AS25: . | AT25: 0 | AU25: . | AV25: . | AW25: . | AX25: . | AY25: 0 | AZ25: . | BA25: . | BB25: . | BC25: . | BD25: 0 | BE25: . | BF25: . | BG25: . | BH25: . | BI25: 0 | BJ25: . | BK25: . | BL25: . | BM25: . | BN25: 0 | BO25: . | BP25: . | BQ25: . | BR25: . | BS25: 0 | BT25: 12.462 | BU25: 0.446 | BV25: 0.791 | BW25: 0 | BX25: 13.699 | BY25: 1329 | BZ25: 8 | CA25: 7 | CB25: 0 | CC25: 1344 | CD25: 0 | CE25: 0 | CF25: 0 | CG25: 0 | CH25: 0
A26: 2022 | B26: AR | C26: 8840 | D26: City of Hope | E26: MISO | F26: AC | G26: 0.141 | H26: 1.23 | I26: . | J26: . | K26: 1.371 | L26: 16 | M26: 23 | N26: . | O26: . | P26: 39 | Q26: . | R26: . | S26: . | T26: . | U26: . | V26: . | W26: . | X26: . | Y26: . | Z26: . | AA26: . | AB26: . | AC26: . | AD26: . | AE26: . | AF26: . | AG26: . | AH26: . | AI26: . | AJ26: . | AK26: . | AL26: . | AM26: . | AN26: . | AO26: 0 | AP26: . | AQ26: . | AR26: . | AS26: . | AT26: 0 | AU26: . | AV26: . | AW26: . | AX26: . | AY26: 0 | AZ26: . | BA26: . | BB26: . | BC26: . | BD26: 0 | BE26: . | BF26: . | BG26: . | BH26: . | BI26: 0 | BJ26: . | BK26: . | BL26: . | BM26: . | BN26: 0 | BO26: . | BP26: . | BQ26: . | BR26: . | BS26: 0 | BT26: 0.141 | BU26: 1.23 | BV26: 0 | BW26: 0 | BX26: 1.371 | BY26: 16 | BZ26: 23 | CA26: 0 | CB26: 0 | CC26: 39 | CD26: 0 | CE26: 0 | CF26: 0 | CG26: 0 | CH26: 0
A27: 2022 | B27: AR | C27: 9879 | D27: City Water and Light Plant | E27: MISO | F27: AC | G27: 0.215 | H27: 0.042 | I27: 0.133 | J27: . | K27: 0.39 | L27: 28 | M27: 2 | N27: 1 | O27: . | P27: 31 | Q27: . | R27: . | S27: . | T27: . | U27: . | V27: . | W27: . | X27: . | Y27: . | Z27: . | AA27: . | AB27: . | AC27: . | AD27: . | AE27: . | AF27: . | AG27: . | AH27: . | AI27: . | AJ27: . | AK27: . | AL27: . | AM27: . | AN27: . | AO27: 0 | AP27: . | AQ27: . | AR27: . | AS27: . | AT27: 0 | AU27: . | AV27: . | AW27: . | AX27: . | AY27: 0 | AZ27: . | BA27: . | BB27: . | BC27: . | BD27: 0 | BE27: . | BF27: . | BG27: . | BH27: . | BI27: 0 | BJ27: . | BK27: . | BL27: . | BM27: . | BN27: 0 | BO27: . | BP27: . | BQ27: . | BR27: . | BS27: 0 | BT27: 0.215 | BU27: 0.042 | BV27: 0.133 | BW27: 0 | BX27: 0.39 | BY27: 28 | BZ27: 2 | CA27: 1 | CB27: 0 | CC27: 31 | CD27: 0 | CE27: 0 | CF27: 0 | CG27: 0 | CH27: 0
A28: 2022 | B28: AR | C28: 12681 | D28: Mississippi County Electric Co | E28: MISO | F28: AC | G28: 0.053 | H28: 1 | I28: . | J28: . | K28: 1.053 | L28: 5 | M28: 4 | N28: . | O28: . | P28: 9 | Q28: . | R28: . | S28: . | T28: . | U28: 0 | V28: . | W28: . | X28: . | Y28: . | Z28: 0 | AA28: . | AB28: . | AC28: . | AD28: . | AE28: 0 | AF28: . | AG28: . | AH28: . | AI28: . | AJ28: 0 | AK28: . | AL28: . | AM28: . | AN28: . | AO28: 0 | AP28: . | AQ28: . | AR28: . | AS28: . | AT28: 0 | AU28: . | AV28: . | AW28: . | AX28: . | AY28: 0 | AZ28: . | BA28: . | BB28: . | BC28: . | BD28: 0 | BE28: . | BF28: . | BG28: . | BH28: . | BI28: 0 | BJ28: . | BK28: . | BL28: . | BM28: . | BN28: 0 | BO28: . | BP28: . | BQ28: . | BR28: . | BS28: 0 | BT28: 0.053 | BU28: 1 | BV28: 0 | BW28: 0 | BX28: 1.053 | BY28: 5 | BZ28: 4 | CA28: 0 | CB28: 0 | CC28: 9 | CD28: 0 | CE28: 0 | CF28: 0 | CG28: 0 | CH28: 0
A29: 2022 | B29: AR | C29: 13676 | D29: North Arkansas Elec Coop, Inc | E29: MISO | F29: DC | G29: 2.979 | H29: . | I29: . | J29: . | K29: 2.979 | L29: 234 | M29: . | N29: . | O29: . | P29: 234 | Q29: . | R29: . | S29: . | T29: . | U29: . | V29: . | W29: . | X29: . | Y29: . | Z29: . | AA29: . | AB29: . | AC29: . | AD29: . | AE29: . | AF29: . | AG29: . | AH29: . | AI29: . | AJ29: . | AK29: . | AL29: . | AM29: . | AN29: . | AO29: 0 | AP29: 0.013 | AQ29: . | AR29: . | AS29: . | AT29: 0.013 | AU29: 5 | AV29: . | AW29: . | AX29: . | AY29: 5 | AZ29: . | BA29: . | BB29: . | BC29: . | BD29: 0 | BE29: . | BF29: . | BG29: . | BH29: . | BI29: 0 | BJ29: . | BK29: . | BL29: . | BM29: . | BN29: 0 | BO29: . | BP29: . | BQ29: . | BR29: . | BS29: 0 | BT29: 2.992 | BU29: 0 | BV29: 0 | BW29: 0 | BX29: 2.992 | BY29: 239 | BZ29: 0 | CA29: 0 | CB29: 0 | CC29: 239 | CD29: 0 | CE29: 0 | CF29: 0 | CG29: 0 | CH29: 0
A30: 2022 | B30: AR | C30: 13718 | D30: City of North Little Rock - (AR) | E30: MISO | F30: AC | G30: 1.85 | H30: 0.28 | I30: 2.45 | J30: 0 | K30: 4.58 | L30: 241 | M30: 5 | N30: 2 | O30: 0 | P30: 248 | Q30: . | R30: . | S30: . | T30: . | U30: . | V30: . | W30: . | X30: . | Y30: . | Z30: . | AA30: . | AB30: . | AC30: . | AD30: . | AE30: . | AF30: . | AG30: . | AH30: . | AI30: . | AJ30: . | AK30: . | AL30: . | AM30: . | AN30: . | AO30: 0 | AP30: . | AQ30: . | AR30: . | AS30: . | AT30: 0 | AU30: . | AV30: . | AW30: . | AX30: . | AY30: 0 | AZ30: . | BA30: . | BB30: . | BC30: . | BD30: 0 | BE30: . | BF30: . | BG30: . | BH30: . | BI30: 0 | BJ30: . | BK30: . | BL30: . | BM30: . | BN30: 0 | BO30: . | BP30: . | BQ30: . | BR30: . | BS30: 0 | BT30: 1.85 | BU30: 0.28 | BV30: 2.45 | BW30: 0 | BX30: 4.58 | BY30: 241 | BZ30: 5 | CA30: 2 | CB30: 0 | CC30: 248 | CD30: 0 | CE30: 0 | CF30: 0 | CG30: 0 | CH30: 0
A31: 2022 | B31: AR | C31: 14063 | D31: Oklahoma Gas & Electric Co | E31: SWPP | F31: AC | G31: 2.657 | H31: 1.19 | I31: 0 | J31: 0 | K31: 3.847 | L31: 349 | M31: 16 | N31: 0 | O31: 0 | P31: 365 | Q31: 0 | R31: 0 | S31: 0 | T31: 0 | U31: 0 | V31: 0 | W31: 0 | X31: 0 | Y31: 0 | Z31: 0 | AA31: 1.551 | AB31: 1.444 | AC31: 0.023 | AD31: 0 | AE31: 3.018 | AF31: 420 | AG31: 397 | AH31: 2 | AI31: 0 | AJ31: 819 | AK31: 0 | AL31: 0 | AM31: 0 | AN31: 0 | AO31: 0 | AP31: 0.007 | AQ31: 0.001 | AR31: 0 | AS31: 0 | AT31: 0.008 | AU31: 2 | AV31: 1 | AW31: 0 | AX31: 0 | AY31: 3 | AZ31: 0 | BA31: 0 | BB31: 0 | BC31: 0 | BD31: 0 | BE31: 0 | BF31: 0 | BG31: 0 | BH31: 0 | BI31: 0 | BJ31: 0 | BK31: 0 | BL31: 0 | BM31: 0 | BN31: 0 | BO31: 0 | BP31: 0 | BQ31: 0 | BR31: 0 | BS31: 0 | BT31: 4.215 | BU31: 2.635 | BV31: 0.023 | BW31: 0 | BX31: 6.873 | BY31: 771 | BZ31: 414 | CA31: 2 | CB31: 0 | CC31: 1187 | CD31: 0 | CE31: 0 | CF31: 0 | CG31: 0 | CH31: 0
A32: 2022 | B32: AR | C32: 14289 | D32: Ozarks Electric Coop Corp - (AR) | E32: SWPP | F32: AC | G32: 8.129 | H32: 0.955 | I32: 15.314 | J32: . | K32: 24.398 | L32: 1119 | M32: 15 | N32: 11 | O32: . | P32: 1145 | Q32: . | R32: . | S32: . | T32: . | U32: . | V32: . | W32: . | X32: . | Y32: . | Z32: . | AA32: . | AB32: . | AC32: . | AD32: . | AE32: . | AF32: . | AG32: . | AH32: . | AI32: . | AJ32: . | AK32: . | AL32: . | AM32: . | AN32: . | AO32: 0 | AP32: . | AQ32: 0.009 | AR32: . | AS32: . | AT32: 0.009 | AU32: . | AV32: 1 | AW32: . | AX32: . | AY32: 1 | AZ32: . | BA32: . | BB32: . | BC32: . | BD32: 0 | BE32: . | BF32: . | BG32: . | BH32: . | BI32: 0 | BJ32: . | BK32: . | BL32: . | BM32: . | BN32: 0 | BO32: . | BP32: . | BQ32: . | BR32: . | BS32: 0 | BT32: 8.129 | BU32: 0.964 | BV32: 15.314 | BW32: 0 | BX32: 24.407 | BY32: 1119 | BZ32: 16 | CA32: 11 | CB32: 0 | CC32: 1146 | CD32: 0 | CE32: 0 | CF32: 0 | CG32: 0 | CH32: 0
A33: 2022 | B33: AR | C33: 14446 | D33: Paragould Light & Water Comm | E33: SPA | F33: AC | G33: 0.164 | H33: . | I33: . | J33: . | K33: 0.164 | L33: 13 | M33: . | N33: . | O33: . | P33: 13 | Q33: . | R33: . | S33: . | T33: . | U33: 0 | V33: . | W33: . | X33: . | Y33: . | Z33: 0 | AA33: . | AB33: . | AC33: . | AD33: . | AE33: 0 | AF33: . | AG33: . | AH33: . | AI33: . | AJ33: 0 | AK33: . | AL33: . | AM33: . | AN33: . | AO33: 0 | AP33: . | AQ33: . | AR33: . | AS33: . | AT33: 0 | AU33: . | AV33: . | AW33: . | AX33: . | AY33: 0 | AZ33: . | BA33: . | BB33: . | BC33: . | BD33: 0 | BE33: . | BF33: . | BG33: . | BH33: . | BI33: 0 | BJ33: . | BK33: . | BL33: . | BM33: . | BN33: 0 | BO33: . | BP33: . | BQ33: . | BR33: . | BS33: 0 | BT33: 0.164 | BU33: 0 | BV33: 0 | BW33: 0 | BX33: 0.164 | BY33: 13 | BZ33: 0 | CA33: 0 | CB33: 0 | CC33: 13 | CD33: 0 | CE33: 0 | CF33: 0 | CG33: 0 | CH33: 0
A34: 2022 | B34: AR | C34: 14864 | D34: Petit Jean Electric Coop Corp | E34: MISO | F34: AC | G34: 0.684 | H34: 0.45 | I34: . | J34: . | K34: 1.134 | L34: 68 | M34: 1 | N34: . | O34: . | P34: 69 | Q34: . | R34: . | S34: . | T34: . | U34: . | V34: . | W34: . | X34: . | Y34: . | Z34: . | AA34: . | AB34: . | AC34: . | AD34: . | AE34: . | AF34: . | AG34: . | AH34: . | AI34: . | AJ34: . | AK34: . | AL34: . | AM34: . | AN34: . | AO34: 0 | AP34: . | AQ34: . | AR34: . | AS34: . | AT34: 0 | AU34: . | AV34: . | AW34: . | AX34: . | AY34: 0 | AZ34: . | BA34: . | BB34: . | BC34: . | BD34: 0 | BE34: . | BF34: . | BG34: . | BH34: . | BI34: 0 | BJ34: . | BK34: . | BL34: . | BM34: . | BN34: 0 | BO34: . | BP34: . | BQ34: . | BR34: . | BS34: 0 | BT34: 0.684 | BU34: 0.45 | BV34: 0 | BW34: 0 | BX34: 1.134 | BY34: 68 | BZ34: 1 | CA34: 0 | CB34: 0 | CC34: 69 | CD34: 0 | CE34: 0 | CF34: 0 | CG34: 0 | CH34: 0
A35: 2022 | B35: AR | C35: 17184 | D35: City of Siloam Springs - (AR) | E35: SWPP | F35: AC | G35: 0.35 | H35: . | I35: . | J35: . | K35: 0.35 | L35: 51 | M35: . | N35: . | O35: . | P35: 51 | Q35: 0 | R35: . | S35: . | T35: . | U35: 0 | V35: 0 | W35: . | X35: . | Y35: . | Z35: 0 | AA35: 0 | AB35: . | AC35: . | AD35: . | AE35: 0 | AF35: 0 | AG35: . | AH35: . | AI35: . | AJ35: 0 | AK35: . | AL35: . | AM35: . | AN35: . | AO35: 0 | AP35: 0 | AQ35: . | AR35: . | AS35: . | AT35: 0 | AU35: 0 | AV35: . | AW35: . | AX35: . | AY35: 0 | AZ35: 0 | BA35: . | BB35: . | BC35: . | BD35: 0 | BE35: 0 | BF35: . | BG35: . | BH35: . | BI35: 0 | BJ35: 0 | BK35: . | BL35: . | BM35: . | BN35: 0 | BO35: 0 | BP35: . | BQ35: . | BR35: . | BS35: 0 | BT35: 0.35 | BU35: 0 | BV35: 0 | BW35: 0 | BX35: 0.35 | BY35: 51 | BZ35: 0 | CA35: 0 | CB35: 0 | CC35: 51 | CD35: 0 | CE35: 0 | CF35: 0 | CG35: 0 | CH35: 0
A36: 2022 | B36: AR | C36: 17671 | D36: Southwest Arkansas E C C | E36: MISO | F36: AC | G36: 0.763 | H36: 0.067 | I36: . | J36: . | K36: 0.83 | L36: 77 | M36: 3 | N36: . | O36: . | P36: 80 | Q36: . | R36: . | S36: . | T36: . | U36: . | V36: . | W36: . | X36: . | Y36: . | Z36: . | AA36: . | AB36: . | AC36: . | AD36: . | AE36: . | AF36: . | AG36: . | AH36: . | AI36: . | AJ36: . | AK36: . | AL36: . | AM36: . | AN36: . | AO36: 0 | AP36: . | AQ36: . | AR36: . | AS36: . | AT36: 0 | AU36: . | AV36: . | AW36: . | AX36: . | AY36: 0 | AZ36: . | BA36: . | BB36: . | BC36: . | BD36: 0 | BE36: . | BF36: . | BG36: . | BH36: . | BI36: 0 | BJ36: . | BK36: . | BL36: . | BM36: . | BN36: 0 | BO36: . | BP36: . | BQ36: . | BR36: . | BS36: 0 | BT36: 0.763 | BU36: 0.067 | BV36: 0 | BW36: 0 | BX36: 0.83 | BY36: 77 | BZ36: 3 | CA36: 0 | CB36: 0 | CC36: 80 | CD36: 0 | CE36: 0 | CF36: 0 | CG36: 0 | CH36: 0
A37: 2022 | B37: AR | C37: 17698 | D37: Southwestern Electric Power Co | E37: SWPP | F37: AC | G37: 6.504 | H37: 3.91 | I37: 0.7 | J37: . | K37: 11.114 | L37: 988 | M37: 45 | N37: 1 | O37: . | P37: 1034 | Q37: 0.427 | R37: . | S37: . | T37: . | U37: 0.427 | V37: 4 | W37: . | X37: . | Y37: . | Z37: 4 | AA37: 0.052 | AB37: 0.463 | AC37: . | AD37: . | AE37: 0.515 | AF37: 6 | AG37: 5 | AH37: . | AI37: . | AJ37: 11 | AK37: 3892.35 | AL37: 4251.13 | AM37: 307.9 | AN37: . | AO37: 8451.38 | AP37: . | AQ37: 0.005 | AR37: . | AS37: . | AT37: 0.005 | AU37: . | AV37: 2 | AW37: . | AX37: . | AY37: 2 | AZ37: . | BA37: 0.249 | BB37: . | BC37: . | BD37: 0.249 | BE37: . | BF37: . | BG37: . | BH37: . | BI37: 0 | BJ37: . | BK37: . | BL37: . | BM37: . | BN37: 0 | BO37: . | BP37: . | BQ37: . | BR37: . | BS37: 0 | BT37: 6.556 | BU37: 4.378 | BV37: 0.7 | BW37: 0 | BX37: 11.634 | BY37: 994 | BZ37: 52 | CA37: 1 | CB37: 0 | CC37: 1047 | CD37: 3892.35 | CE37: 4251.379 | CF37: 307.9 | CG37: 0 | CH37: 8451.629
A38: 2022 | B38: AR | C38: 20963 | D38: Woodruff Electric Coop Corp | E38: MISO | F38: AC | G38: 0.288 | H38: 2.213 | I38: . | J38: . | K38: 2.501 | L38: 25 | M38: 7 | N38: . | O38: . | P38: 32 | Q38: . | R38: . | S38: . | T38: . | U38: . | V38: . | W38: . | X38: . | Y38: . | Z38: . | AA38: . | AB38: . | AC38: . | AD38: . | AE38: . | AF38: . | AG38: . | AH38: . | AI38: . | AJ38: . | AK38: . | AL38: . | AM38: . | AN38: . | AO38: 0 | AP38: 0.003 | AQ38: . | AR38: . | AS38: . | AT38: 0.003 | AU38: 1 | AV38: . | AW38: . | AX38: . | AY38: 1 | AZ38: . | BA38: . | BB38: . | BC38: . | BD38: 0 | BE38: . | BF38: . | BG38: . | BH38: . | BI38: 0 | BJ38: . | BK38: . | BL38: . | BM38: . | BN38: 0 | BO38: . | BP38: . | BQ38: . | BR38: . | BS38: 0 | BT38: 0.291 | BU38: 2.213 | BV38: 0 | BW38: 0 | BX38: 2.504 | BY38: 26 | BZ38: 7 | CA38: 0 | CB38: 0 | CC38: 33 | CD38: 0 | CE38: 0 | CF38: 0 | CG38: 0 | CH38: 0
A39: 2022 | B39: AR | C39: 99999 | D39: Adjustment 2022 | E39: MISO | G39: -8.891 | H39: -6.714 | I39: -0.602 | J39: . | K39: -16.206 | L39: . | M39: . | N39: . | O39: . | P39: . | Q39: . | R39: . | S39: . | T39: . | U39: . | V39: . | W39: . | X39: . | Y39: . | Z39: . | AA39: . | AB39: . | AC39: . | AD39: . | AE39: . | AF39: . | AG39: . | AH39: . | AI39: . | AJ39: . | AK39: . | AL39: . | AM39: . | AN39: . | AO39: . | AP39: . | AQ39: . | AR39: . | AS39: . | AT39: . | AU39: . | AV39: . | AW39: . | AX39: . | AY39: . | AZ39: . | BA39: . | BB39: . | BC39: . | BD39: . | BE39: . | BF39: . | BG39: . | BH39: . | BI39: . | BJ39: . | BK39: . | BL39: . | BM39: . | BN39: . | BO39: . | BP39: . | BQ39: . | BR39: . | BS39: . | BT39: -8.891 | BU39: -6.714 | BV39: -0.602 | BW39: . | BX39: -16.206 | BY39: . | BZ39: . | CA39: . | CB39: . | CC39: . | CD39: . | CE39: . | CF39: . | CG39: . | CH39: .
A40: 2022 | B40: AR | C40: 99999 | D40: Adjustment 2022 | E40: SWPP | G40: -4.722 | H40: -0.946 | I40: . | J40: . | K40: -5.668 | L40: . | M40: . | N40: . | O40: . | P40: . | Q40: . | R40: . | S40: . | T40: . | U40: . | V40: . | W40: . | X40: . | Y40: . | Z40: . | AA40: . | AB40: . | AC40: . | AD40: . | AE40: . | AF40: . | AG40: . | AH40: . | AI40: . | AJ40: . | AK40: . | AL40: . | AM40: . | AN40: . | AO40: . | AP40: . | AQ40: . | AR40: . | AS40: . | AT40: . | AU40: . | AV40: . | AW40: . | AX40: . | AY40: . | AZ40: . | BA40: . | BB40: . | BC40: . | BD40: . | BE40: . | BF40: . | BG40: . | BH40: . | BI40: . | BJ40: . | BK40: . | BL40: . | BM40: . | BN40: . | BO40: . | BP40: . | BQ40: . | BR40: . | BS40: . | BT40: -4.722 | BU40: -0.946 | BV40: . | BW40: . | BX40: -5.668 | BY40: . | BZ40: . | CA40: . | CB40: . | CC40: . | CD40: . | CE40: . | CF40: . | CG40: . | CH40: .
...

Sheet SFA Awards
A1: Solar for All - EPA award table and program assumptions
A2: STEP 1 of 3. Raw EPA record (tan). Everything downstream is derived from it: SFA Awards -> SFA Multistate Split -> Solar for All -> calcs -> output tabs.
A3: Source: EPA 19 January 2025 snapshot of the Solar for All recipients table (the live page was removed after the program was terminated).
A4: https://19january2025snapshot.epa.gov/greenhouse-gas-reduction-fund/solar-all
A6: PROGRAM ASSUMPTIONS (blue = editable input)
A7: Program capacity deployed or unlocked (MW) | B7: 4000 | C7: EPA press release, 22 April 2024: 'over 4 GW'
A8: Total program grant ($) | B8: 7000000000 | C8: EPA press release, 22 April 2024
A9: National factor (MW per $) | B9: =B7/B8 -> 5.7142857e-07 | C9: 4,000 MW / $7.0B, applied uniformly to every award
A10: Implied grant cost ($/W) | B10: =B8/(B7*1000000) -> 1.75 | C10: grant $ per watt unlocked - NOT the installed cost of solar
A12: EPA Region | B12: Grantee Type | C12: Grantee Name | D12: Geography Served | E12: State | F12: Split key | G12: Category | H12: Award Amount ($) | I12: Allocated capacity (MW)
A13: 1 | B13: State | C13: Executive Office of the State of New Hampshire | D13: NH | E13: NH | G13: Single-state | H13: 43510000 | I13: =H13*$B$9 -> 24.862857
A14: 1 | B14: State | C14: Massachusetts Department of Energy Resources | D14: MA | E14: MA | G14: Single-state | H14: 156120000 | I14: =H14*$B$9 -> 89.211429
A15: 1 | B15: State | C15: Rhode Island Office of Energy Resources | D15: RI | E15: RI | G15: Single-state | H15: 49330000 | I15: =H15*$B$9 -> 28.188571
A16: 1 | B16: State | C16: Connecticut Department of Energy and Environmental Protection | D16: CT | E16: CT | G16: Single-state | H16: 62450000 | I16: =H16*$B$9 -> 35.685714
A17: 1 | B17: State | C17: Maine Governor's Energy Office | D17: ME | E17: ME | G17: Single-state | H17: 62120000 | I17: =H17*$B$9 -> 35.497143
A18: 1 | B18: State | C18: Vermont Department of Public Service | D18: VT | E18: VT | G18: Single-state | H18: 62450000 | I18: =H18*$B$9 -> 35.685714
A19: Multi | B19: Multistate Nonprofit | C19: Inclusive Prosperity Capital, Inc. (Community Power Coalition) | D19: Multistate (~44 states) | F19: Inclusive Prosperity Capital | G19: Multistate/National | H19: 249300000 | I19: =H19*$B$9 -> 142.45714
A20: 2 | B20: State | C20: New Jersey Board of Public Utilities | D20: NJ | E20: NJ | G20: Single-state | H20: 156120000 | I20: =H20*$B$9 -> 89.211429
A21: 2 | B21: State | C21: New York State Energy Research and Development Authority (NYSERDA) | D21: NY | E21: NY | G21: Single-state | H21: 249800000 | I21: =H21*$B$9 -> 142.74286
A22: 2 | B22: State | C22: Puerto Rico Office of Management and Budget | D22: PR | E22: PR | G22: Single-state | H22: 156120000 | I22: =H22*$B$9 -> 89.211429
A23: 2 | B23: State | C23: U.S. Virgin Islands Energy Office | D23: VI | E23: VI | G23: Single-state | H23: 62450000 | I23: =H23*$B$9 -> 35.685714
A24: 3 | B24: State | C24: District of Columbia Government | D24: DC | E24: DC | G24: Single-state | H24: 62450000 | I24: =H24*$B$9 -> 35.685714
A25: 3 | B25: State | C25: Maryland Clean Energy Center | D25: MD | E25: MD | G25: Single-state | H25: 62450000 | I25: =H25*$B$9 -> 35.685714
A26: 3 | B26: State | C26: Pennsylvania Energy Development Authority | D26: PA | E26: PA | G26: Single-state | H26: 156120000 | I26: =H26*$B$9 -> 89.211429
A27: 3 | B27: State | C27: Virginia Department of Energy | D27: VA | E27: VA | G27: Single-state | H27: 156120000 | I27: =H27*$B$9 -> 89.211429
A28: 3 | B28: State | C28: West Virginia Office of Energy | D28: WV | E28: WV | G28: Single-state | H28: 106180000 | I28: =H28*$B$9 -> 60.674286
A29: Multi | B29: Multistate Nonprofit | C29: Groundswell Inc. | D29: Multistate (AL,AR,FL,GA,MS,NC,SC,VA) | F29: Groundswell | G29: Multistate/National | H29: 156120000 | I29: =H29*$B$9 -> 89.211429
A30: 4 | B30: State | C30: Department of Environment & Conservation, Tennessee | D30: TN | E30: TN | G30: Single-state | H30: 156120000 | I30: =H30*$B$9 -> 89.211429
A31: 4 | B31: State | C31: Kentucky Energy and Environment Cabinet | D31: KY | E31: KY | G31: Single-state | H31: 62450000 | I31: =H31*$B$9 -> 35.685714
A32: 4 | B32: State | C32: North Carolina Department of Environmental Quality | D32: NC | E32: NC | G32: Single-state | H32: 156120000 | I32: =H32*$B$9 -> 89.211429
A33: 4 | B33: State | C33: South Carolina Office of Resilience | D33: SC | E33: SC | G33: Single-state | H33: 124440000 | I33: =H33*$B$9 -> 71.108571
A34: 4 | B34: Nonprofit | C34: Hope Enterprise Corporation | D34: MS | E34: MS | G34: Single-state | H34: 62450000 | I34: =H34*$B$9 -> 35.685714
A35: 4 | B35: Nonprofit | C35: Solar and Energy Loan Fund of St. Lucie County (SELF) | D35: FL | E35: FL | G35: Single-state | H35: 156120000 | I35: =H35*$B$9 -> 89.211429
A36: 4 | B36: Nonprofit | C36: The Capital Good Fund | D36: GA | E36: GA | G36: Single-state | H36: 156010000 | I36: =H36*$B$9 -> 89.148571
A37: 5 | B37: State | C37: Illinois Finance Authority | D37: IL | E37: IL | G37: Single-state | H37: 156120000 | I37: =H37*$B$9 -> 89.211429
A38: 5 | B38: State | C38: Minnesota Department of Commerce | D38: MN | E38: MN | G38: Single-state | H38: 62450000 | I38: =H38*$B$9 -> 35.685714
A39: 5 | B39: State | C39: State of Michigan, Dept. of Environment, Great Lakes, and Energy | D39: MI | E39: MI | G39: Single-state | H39: 156120000 | I39: =H39*$B$9 -> 89.211429
A40: 5 | B40: State | C40: State of Ohio Office of Budget and Management | D40: OH | E40: OH | G40: Single-state | H40: 156120000 | I40: =H40*$B$9 -> 89.211429
A41: 5 | B41: State | C41: Wisconsin Economic Development Corporation | D41: WI | E41: WI | G41: Single-state | H41: 62450000 | I41: =H41*$B$9 -> 35.685714
A42: 5 | B42: Nonprofit | C42: Indiana Community Action Association (IN-CAA) | D42: IN | E42: IN | G42: Single-state | H42: 117470000 | I42: =H42*$B$9 -> 67.125714
...

Sheet SFA Multistate Split
A1: Solar for All - apportioning the 9 multistate, tribal and nationwide awards
A2: STEP 2 of 3. These awards serve more than one state, so each is split across the jurisdictions it serves in proportion to 2020 Census resident population.
A3: Member-state lists (column A/B of the lower table) and populations (right-hand table) are the only raw entries here; every dollar and MW figure is a formula.
H4: Source: U.S. Census Bureau, 2020 Census resident population.
A5: THE NINE AWARDS | H5: STATE POPULATION WEIGHTS
A6: Grantee (split key) | B6: Award ($) | C6: # jurisdictions | D6: Geography basis | H6: State | I6: Name | J6: Population (2020 Census)
A7: Inclusive Prosperity Capital | B7: =SUMIFS('SFA Awards'!$H$13:$H$72,'SFA Awards'!$F$13:$F$72,$A7) -> 249300000 | C7: =COUNTIFS($A$25:$A$225,$A7) -> 52 | D7: Nationwide proxy: 50 states + DC + PR | H7: AK | I7: Alaska | J7: 733391
A8: Groundswell | B8: =SUMIFS('SFA Awards'!$H$13:$H$72,'SFA Awards'!$F$13:$F$72,$A8) -> 156120000 | C8: =COUNTIFS($A$25:$A$225,$A8) -> 8 | D8: AL, AR, FL, GA, MS, NC, SC, VA (per EPA award summary, Allocation tab) | H8: AL | I8: Alabama | J8: 5024279
A9: MTERA | B9: =SUMIFS('SFA Awards'!$H$13:$H$72,'SFA Awards'!$F$13:$F$72,$A9) -> 62330000 | C9: =COUNTIFS($A$25:$A$225,$A9) -> 3 | D9: Tribal: MN, WI, MI (per EPA award summary, Allocation tab) | H9: AR | I9: Arkansas | J9: 3011524
A10: Growth Opportunity Partners | B10: =SUMIFS('SFA Awards'!$H$13:$H$72,'SFA Awards'!$F$13:$F$72,$A10) -> 156120000 | C10: =COUNTIFS($A$25:$A$225,$A10) -> 8 | D10: IN, KS, MI, MO, PA, NY, OH, WV (per EPA award summary, Allocation tab) | H10: AZ | I10: Arizona | J10: 7151502
A11: Clean Energy Fund of Texas | B11: =SUMIFS('SFA Awards'!$H$13:$H$72,'SFA Awards'!$F$13:$F$72,$A11) -> 156120000 | C11: =COUNTIFS($A$25:$A$225,$A11) -> 19 | D11: CHARGE program: 18 states + DC (AL, AR, DE, FL, GA, KY, LA, MD, MS, NM, NC, OK, PA, SC, TN, TX, VA, WV, DC) | H11: CA | I11: California | J11: 39538223
A12: Oweesta | B12: =SUMIFS('SFA Awards'!$H$13:$H$72,'SFA Awards'!$F$13:$F$72,$A12) -> 156120000 | C12: =COUNTIFS($A$25:$A$225,$A12) -> 50 | D12: Tribal lands nationwide: all 50 states | H12: CO | I12: Colorado | J12: 5773714
A13: Three Affiliated Tribes (MHA) | B13: =SUMIFS('SFA Awards'!$H$13:$H$72,'SFA Awards'!$F$13:$F$72,$A13) -> 135580000 | C13: =COUNTIFS($A$25:$A$225,$A13) -> 5 | D13: Tribal: ND, SD, MT, WY, WI (per EPA award summary, Allocation tab) | H13: CT | I13: Connecticut | J13: 3605944
A14: GRID WIN-SFA | B14: =SUMIFS('SFA Awards'!$H$13:$H$72,'SFA Awards'!$F$13:$F$72,$A14) -> 62450000 | C14: =COUNTIFS($A$25:$A$225,$A14) -> 5 | D14: Tribal, priority states: AZ, CO, NV, NM, UT (per EPA award summary, Allocation tab) | H14: DC | I14: District of Columbia | J14: 689545
A15: GRID SANAH | B15: =SUMIFS('SFA Awards'!$H$13:$H$72,'SFA Awards'!$F$13:$F$72,$A15) -> 249800000 | C15: =COUNTIFS($A$25:$A$225,$A15) -> 51 | D15: Nationwide affordable housing: 50 states + DC | H15: DE | I15: Delaware | J15: 989948
A16: TOTAL | B16: =SUM(B7:B15) -> 1383940000 | C16: =SUM(C7:C15) -> 201 | H16: FL | I16: Florida | J16: 21538187
H17: GA | I17: Georgia | J17: 10711908
H18: HI | I18: Hawaii | J18: 1455271
H19: IA | I19: Iowa | J19: 3190369
H20: ID | I20: Idaho | J20: 1839106
H21: IL | I21: Illinois | J21: 12812508
H22: IN | I22: Indiana | J22: 6785528
A23: AWARD x JURISDICTION SPLIT | H23: KS | I23: Kansas | J23: 2937880
A24: Grantee (split key) | B24: State | C24: Population | D24: Share of award | E24: Allocated ($) | F24: Allocated (MW) | H24: KY | I24: Kentucky | J24: 4505836
A25: Inclusive Prosperity Capital | B25: AK | C25: =SUMIFS($J$7:$J$58,$H$7:$H$58,$B25) -> 733391 | D25: =C25/SUMIFS($C$25:$C$225,$A$25:$A$225,$A25) -> 0.002190959 | E25: =D25*SUMIFS($B$7:$B$15,$A$7:$A$15,$A25) -> 546206.08 | F25: =E25*'SFA Awards'!$B$9 -> 0.31211776 | H25: LA | I25: Louisiana | J25: 4657757
A26: Inclusive Prosperity Capital | B26: AL | C26: =SUMIFS($J$7:$J$58,$H$7:$H$58,$B26) -> 5024279 | D26: =C26/SUMIFS($C$25:$C$225,$A$25:$A$225,$A26) -> 0.015009714 | E26: =D26*SUMIFS($B$7:$B$15,$A$7:$A$15,$A26) -> 3741921.7 | F26: =E26*'SFA Awards'!$B$9 -> 2.138241 | H26: MA | I26: Massachusetts | J26: 7029917
A27: Inclusive Prosperity Capital | B27: AR | C27: =SUMIFS($J$7:$J$58,$H$7:$H$58,$B27) -> 3011524 | D27: =C27/SUMIFS($C$25:$C$225,$A$25:$A$225,$A27) -> 0.0089967365 | E27: =D27*SUMIFS($B$7:$B$15,$A$7:$A$15,$A27) -> 2242886.4 | F27: =E27*'SFA Awards'!$B$9 -> 1.2816494 | H27: MD | I27: Maryland | J27: 6177224
A28: Inclusive Prosperity Capital | B28: AZ | C28: =SUMIFS($J$7:$J$58,$H$7:$H$58,$B28) -> 7151502 | D28: =C28/SUMIFS($C$25:$C$225,$A$25:$A$225,$A28) -> 0.021364658 | E28: =D28*SUMIFS($B$7:$B$15,$A$7:$A$15,$A28) -> 5326209.2 | F28: =E28*'SFA Awards'!$B$9 -> 3.0435481 | H28: ME | I28: Maine | J28: 1362359
A29: Inclusive Prosperity Capital | B29: CA | C29: =SUMIFS($J$7:$J$58,$H$7:$H$58,$B29) -> 39538223 | D29: =C29/SUMIFS($C$25:$C$225,$A$25:$A$225,$A29) -> 0.11811793 | E29: =D29*SUMIFS($B$7:$B$15,$A$7:$A$15,$A29) -> 29446799 | F29: =E29*'SFA Awards'!$B$9 -> 16.826743 | H29: MI | I29: Michigan | J29: 10077331
A30: Inclusive Prosperity Capital | B30: CO | C30: =SUMIFS($J$7:$J$58,$H$7:$H$58,$B30) -> 5773714 | D30: =C30/SUMIFS($C$25:$C$225,$A$25:$A$225,$A30) -> 0.017248604 | E30: =D30*SUMIFS($B$7:$B$15,$A$7:$A$15,$A30) -> 4300076.9 | F30: =E30*'SFA Awards'!$B$9 -> 2.4571868 | H30: MN | I30: Minnesota | J30: 5706494
A31: Inclusive Prosperity Capital | B31: CT | C31: =SUMIFS($J$7:$J$58,$H$7:$H$58,$B31) -> 3605944 | D31: =C31/SUMIFS($C$25:$C$225,$A$25:$A$225,$A31) -> 0.010772529 | E31: =D31*SUMIFS($B$7:$B$15,$A$7:$A$15,$A31) -> 2685591.4 | F31: =E31*'SFA Awards'!$B$9 -> 1.5346236 | H31: MO | I31: Missouri | J31: 6154913
A32: Inclusive Prosperity Capital | B32: DC | C32: =SUMIFS($J$7:$J$58,$H$7:$H$58,$B32) -> 689545 | D32: =C32/SUMIFS($C$25:$C$225,$A$25:$A$225,$A32) -> 0.0020599719 | E32: =D32*SUMIFS($B$7:$B$15,$A$7:$A$15,$A32) -> 513550.98 | F32: =E32*'SFA Awards'!$B$9 -> 0.29345771 | H32: MS | I32: Mississippi | J32: 2961279
A33: Inclusive Prosperity Capital | B33: DE | C33: =SUMIFS($J$7:$J$58,$H$7:$H$58,$B33) -> 989948 | D33: =C33/SUMIFS($C$25:$C$225,$A$25:$A$225,$A33) -> 0.0029574067 | E33: =D33*SUMIFS($B$7:$B$15,$A$7:$A$15,$A33) -> 737281.5 | F33: =E33*'SFA Awards'!$B$9 -> 0.42130371 | H33: MT | I33: Montana | J33: 1084225
A34: Inclusive Prosperity Capital | B34: FL | C34: =SUMIFS($J$7:$J$58,$H$7:$H$58,$B34) -> 21538187 | D34: =C34/SUMIFS($C$25:$C$225,$A$25:$A$225,$A34) -> 0.064343965 | E34: =D34*SUMIFS($B$7:$B$15,$A$7:$A$15,$A34) -> 16040950 | F34: =E34*'SFA Awards'!$B$9 -> 9.1662574 | H34: NC | I34: North Carolina | J34: 10439388
A35: Inclusive Prosperity Capital | B35: GA | C35: =SUMIFS($J$7:$J$58,$H$7:$H$58,$B35) -> 10711908 | D35: =C35/SUMIFS($C$25:$C$225,$A$25:$A$225,$A35) -> 0.032001144 | E35: =D35*SUMIFS($B$7:$B$15,$A$7:$A$15,$A35) -> 7977885.3 | F35: =E35*'SFA Awards'!$B$9 -> 4.5587916 | H35: ND | I35: North Dakota | J35: 779094
A36: Inclusive Prosperity Capital | B36: HI | C36: =SUMIFS($J$7:$J$58,$H$7:$H$58,$B36) -> 1455271 | D36: =C36/SUMIFS($C$25:$C$225,$A$25:$A$225,$A36) -> 0.0043475296 | E36: =D36*SUMIFS($B$7:$B$15,$A$7:$A$15,$A36) -> 1083839.1 | F36: =E36*'SFA Awards'!$B$9 -> 0.61933665 | H36: NE | I36: Nebraska | J36: 1961504
... A58: Inclusive Prosperity Capital | B58: NV | C58: =SUMIFS($J$7:$J$58,$H$7:$H$58,$B58) -> 3104614 | D58: =C58/SUMIFS($C$25:$C$225,$A$25:$A$225,$A58) -> 0.009274837 | E58: =D58*SUMIFS($B$7:$B$15,$A$7:$A$15,$A58) -> 2312216.9 | F58: =E58*'SFA Awards'!$B$9 -> 1.3212668 | H58: WY | I58: Wyoming | J58: 576851
A59: Inclusive Prosperity Capital | B59: NY | C59: =SUMIFS($J$7:$J$58,$H$7:$H$58,$B59) -> 20201249 | D59: =C59/SUMIFS($C$25:$C$225,$A$25:$A$225,$A59) -> 0.060349947 | E59: =D59*SUMIFS($B$7:$B$15,$A$7:$A$15,$A59) -> 15045242 | F59: =E59*'SFA Awards'!$B$9 -> 8.5972811 | H59: TOTAL | J59: =SUM(J7:J58) -> 334735155
A60: Inclusive Prosperity Capital | B60: OH | C60: =SUMIFS($J$7:$J$58,$H$7:$H$58,$B60) -> 11799448 | D60: =C60/SUMIFS($C$25:$C$225,$A$25:$A$225,$A60) -> 0.035250101 | E60: =D60*SUMIFS($B$7:$B$15,$A$7:$A$15,$A60) -> 8787850.2 | F60: =E60*'SFA Awards'!$B$9 -> 5.0216287
A61: Inclusive Prosperity Capital | B61: OK | C61: =SUMIFS($J$7:$J$58,$H$7:$H$58,$B61) -> 3959353 | D61: =C61/SUMIFS($C$25:$C$225,$A$25:$A$225,$A61) -> 0.011828315 | E61: =D61*SUMIFS($B$7:$B$15,$A$7:$A$15,$A61) -> 2948799 | F61: =E61*'SFA Awards'!$B$9 -> 1.685028
...

Sheet Solar for All
A1: Solar for All - capacity by state
A2: STEP 3 of 3. Direct awards (from 'SFA Awards') plus each state's share of the multistate awards (from 'SFA Multistate Split'), converted to MW at the national factor.
A3: These are the PLANNED figures from the awards as made. The program was cancelled, so this file models the counterfactual in which it proceeded. (EPA announced on 7 August 2025 it would not implement it; the 4 July 2025 law rescinded the funds.)
A4: Column F is what the 'calcs' tab reads. Nothing on this tab is typed in by hand.
A6: State | B6: Name (uppercase) | C6: Direct + in-state tribal awards ($) | D6: Multistate / tribal share ($) | E6: Total ($) | F6: Total (MW) | G6: % of program
A7: AK | B7: ALASKA | C7: =SUMIFS('SFA Awards'!$H$13:$H$72,'SFA Awards'!$E$13:$E$72,$A7) -> 124900000 | D7: =SUMIFS('SFA Multistate Split'!$E$25:$E$225,'SFA Multistate Split'!$B$25:$B$225,$A7) -> 1445097.1 | E7: =C7+D7 -> 1.263451e+08 | F7: =E7*'SFA Awards'!$B$9 -> 72.197198 | G7: =E7/'SFA Awards'!$B$8 -> 0.0180493
A8: AL | B8: ALABAMA | C8: =SUMIFS('SFA Awards'!$H$13:$H$72,'SFA Awards'!$E$13:$E$72,$A8) -> 0 | D8: =SUMIFS('SFA Multistate Split'!$E$25:$E$225,'SFA Multistate Split'!$B$25:$B$225,$A8) -> 27079413 | E8: =C8+D8 -> 27079413 | F8: =E8*'SFA Awards'!$B$9 -> 15.473951 | G8: =E8/'SFA Awards'!$B$8 -> 0.0038684876
A9: AR | B9: ARKANSAS | C9: =SUMIFS('SFA Awards'!$H$13:$H$72,'SFA Awards'!$E$13:$E$72,$A9) -> 93670000 | D9: =SUMIFS('SFA Multistate Split'!$E$25:$E$225,'SFA Multistate Split'!$B$25:$B$225,$A9) -> 16231245 | E9: =C9+D9 -> 1.0990125e+08 | F9: =E9*'SFA Awards'!$B$9 -> 62.800711 | G9: =E9/'SFA Awards'!$B$8 -> 0.015700178
A10: AZ | B10: ARIZONA | C10: =SUMIFS('SFA Awards'!$H$13:$H$72,'SFA Awards'!$E$13:$E$72,$A10) -> 181240000 | D10: =SUMIFS('SFA Multistate Split'!$E$25:$E$225,'SFA Multistate Split'!$B$25:$B$225,$A10) -> 34942753 | E10: =C10+D10 -> 2.1618275e+08 | F10: =E10*'SFA Awards'!$B$9 -> 123.533 | G10: =E10/'SFA Awards'!$B$8 -> 0.03088325
A11: CA | B11: CALIFORNIA | C11: =SUMIFS('SFA Awards'!$H$13:$H$72,'SFA Awards'!$E$13:$E$72,$A11) -> 249800000 | D11: =SUMIFS('SFA Multistate Split'!$E$25:$E$225,'SFA Multistate Split'!$B$25:$B$225,$A11) -> 77907378 | E11: =C11+D11 -> 3.2770738e+08 | F11: =E11*'SFA Awards'!$B$9 -> 187.26136 | G11: =E11/'SFA Awards'!$B$8 -> 0.04681534
A12: CO | B12: COLORADO | C12: =SUMIFS('SFA Awards'!$H$13:$H$72,'SFA Awards'!$E$13:$E$72,$A12) -> 156120000 | D12: =SUMIFS('SFA Multistate Split'!$E$25:$E$225,'SFA Multistate Split'!$B$25:$B$225,$A12) -> 28210782 | E12: =C12+D12 -> 1.8433078e+08 | F12: =E12*'SFA Awards'!$B$9 -> 105.33188 | G12: =E12/'SFA Awards'!$B$8 -> 0.026332969
A13: CT | B13: CONNECTICUT | C13: =SUMIFS('SFA Awards'!$H$13:$H$72,'SFA Awards'!$E$13:$E$72,$A13) -> 62450000 | D13: =SUMIFS('SFA Multistate Split'!$E$25:$E$225,'SFA Multistate Split'!$B$25:$B$225,$A13) -> 7105267.3 | E13: =C13+D13 -> 69555267 | F13: =E13*'SFA Awards'!$B$9 -> 39.745867 | G13: =E13/'SFA Awards'!$B$8 -> 0.0099364668
A14: DC | B14: DISTRICT OF COLUMBIA | C14: =SUMIFS('SFA Awards'!$H$13:$H$72,'SFA Awards'!$E$13:$E$72,$A14) -> 62450000 | D14: =SUMIFS('SFA Multistate Split'!$E$25:$E$225,'SFA Multistate Split'!$B$25:$B$225,$A14) -> 1794634.9 | E14: =C14+D14 -> 64244635 | F14: =E14*'SFA Awards'!$B$9 -> 36.71122 | G14: =E14/'SFA Awards'!$B$8 -> 0.009177805
A15: DE | B15: DELAWARE | C15: =SUMIFS('SFA Awards'!$H$13:$H$72,'SFA Awards'!$E$13:$E$72,$A15) -> 0 | D15: =SUMIFS('SFA Multistate Split'!$E$25:$E$225,'SFA Multistate Split'!$B$25:$B$225,$A15) -> 3043734.3 | E15: =C15+D15 -> 3043734.3 | F15: =E15*'SFA Awards'!$B$9 -> 1.7392767 | G15: =E15/'SFA Awards'!$B$8 -> 0.00043481918
A16: FL | B16: FLORIDA | C16: =SUMIFS('SFA Awards'!$H$13:$H$72,'SFA Awards'!$E$13:$E$72,$A16) -> 156120000 | D16: =SUMIFS('SFA Multistate Split'!$E$25:$E$225,'SFA Multistate Split'!$B$25:$B$225,$A16) -> 1.1608461e+08 | E16: =C16+D16 -> 2.7220461e+08 | F16: =E16*'SFA Awards'!$B$9 -> 155.54549 | G16: =E16/'SFA Awards'!$B$8 -> 0.038886373
A17: GA | B17: GEORGIA | C17: =SUMIFS('SFA Awards'!$H$13:$H$72,'SFA Awards'!$E$13:$E$72,$A17) -> 156010000 | D17: =SUMIFS('SFA Multistate Split'!$E$25:$E$225,'SFA Multistate Split'!$B$25:$B$225,$A17) -> 57734092 | E17: =C17+D17 -> 2.1374409e+08 | F17: =E17*'SFA Awards'!$B$9 -> 122.13948 | G17: =E17/'SFA Awards'!$B$8 -> 0.03053487
A18: GU | B18: GUAM | C18: =SUMIFS('SFA Awards'!$H$13:$H$72,'SFA Awards'!$E$13:$E$72,$A18) -> 62450000 | D18: =SUMIFS('SFA Multistate Split'!$E$25:$E$225,'SFA Multistate Split'!$B$25:$B$225,$A18) -> 0 | E18: =C18+D18 -> 62450000 | F18: =E18*'SFA Awards'!$B$9 -> 35.685714 | G18: =E18/'SFA Awards'!$B$8 -> 0.0089214286
... A60: WY | B60: WYOMING | C60: =SUMIFS('SFA Awards'!$H$13:$H$72,'SFA Awards'!$E$13:$E$72,$A60) -> 30260000 | D60: =SUMIFS('SFA Multistate Split'!$E$25:$E$225,'SFA Multistate Split'!$B$25:$B$225,$A60) -> 9618722.8 | E60: =C60+D60 -> 39878723 | F60: =E60*'SFA Awards'!$B$9 -> 22.787842 | G60: =E60/'SFA Awards'!$B$8 -> 0.0056969604
A61: TOTAL | C61: =SUM(C7:C60) -> 5616060000 | D61: =SUM(D7:D60) -> 1383940000 | E61: =SUM(E7:E60) -> 7e+09 | F61: =SUM(F7:F60) -> 4000 | G61: =SUM(G7:G60) -> 1
A62: Check vs. program totals | E62: =IF(ROUND(E61,2)='SFA Awards'!$B$8,"OK","MISMATCH") -> OK | F62: =IF(ROUND(F61,6)='SFA Awards'!$B$7,"OK","MISMATCH") -> OK
A64: DC, GU, PR and VI appear here for completeness but have no EPS state model; the 48 modelled states cover about 95% of program MW.

Sheet calcs
A1: CiDESCTY - Change in Distributed Electricity Source Capacities This Year
A2: Counterfactual: the residential distributed solar the EPA Solar for All grants would have added
A4: State (from About tab) | B4: =About!$B$1 -> Nebraska
A5: State abbreviation | B5: =About!$B$2 -> NE
A6: State name (uppercase, for lookups) | B6: =UPPER($B$4) -> NEBRASKA
A8: Solar for All capacity, all sectors (MW) | B8: =SUMIFS('Solar for All'!$F$7:$F$60,'Solar for All'!$A$7:$A$60,$B$5) -> 37.894292 | C8: from the 'Solar for All' tab, which is built up from the two SFA source tabs
A9: Urban residential share of households | B9: =SUMIFS('res v com'!$J:$J,'res v com'!$I:$I,$B$6) -> 0.731
A10: Rural residential share of households | B10: =SUMIFS('res v com'!$K:$K,'res v com'!$I:$I,$B$6) -> 0.269
A11: Check: urban + rural = 1 | B11: =IF(ROUND(B9+B10,6)=1,"OK","CHECK") -> OK
A13: Deployment window (blue = editable input)
A14: First year capacity is added | B14: 2025
A15: Last year capacity is added | B15: 2029
A16: Capacity is spread evenly across the window; Solar for All awards were made in April 2024 with five-year performance periods.
A18: Annual profile
A19: year | B19: 2021 | C19: 2022 | D19: 2023 | E19: 2024 | F19: 2025 | G19: 2026 | H19: 2027 | I19: 2028 | J19: 2029 | K19: 2030 | L19: 2031 | M19: 2032 | N19: 2033 | O19: 2034 | P19: 2035 | Q19: 2036 | R19: 2037 | S19: 2038 | T19: 2039 | U19: 2040 | V19: 2041 | W19: 2042 | X19: 2043 | Y19: 2044 | Z19: 2045 | AA19: 2046 | AB19: 2047 | AC19: 2048 | AD19: 2049 | AE19: 2050
A20: share of capacity deployed | B20: =IF(AND(B$19>=$B$14,B$19<=$B$15),1/($B$15-$B$14+1),0) -> 0 | C20: =IF(AND(C$19>=$B$14,C$19<=$B$15),1/($B$15-$B$14+1),0) -> 0 | D20: =IF(AND(D$19>=$B$14,D$19<=$B$15),1/($B$15-$B$14+1),0) -> 0 | E20: =IF(AND(E$19>=$B$14,E$19<=$B$15),1/($B$15-$B$14+1),0) -> 0 | F20: =IF(AND(F$19>=$B$14,F$19<=$B$15),1/($B$15-$B$14+1),0) -> 0.2 | G20: =IF(AND(G$19>=$B$14,G$19<=$B$15),1/($B$15-$B$14+1),0) -> 0.2 | H20: =IF(AND(H$19>=$B$14,H$19<=$B$15),1/($B$15-$B$14+1),0) -> 0.2 | I20: =IF(AND(I$19>=$B$14,I$19<=$B$15),1/($B$15-$B$14+1),0) -> 0.2 | ... AE20: =IF(AND(AE$19>=$B$14,AE$19<=$B$15),1/($B$15-$B$14+1),0) -> 0
