Workbook

Sheet About
A1: BPCiObIC BAU Percent Change in Output by ISIC Code | B1: Nebraska | C1: 44810
A3: Source: | B3: Future Year Projected Changes in Output by ISIC Code
B4: U.S. EIA
B5: 2021
B6: Annual Energy Outlook 2021
B7: https://www.eia.gov/outlooks/aeo/tables_ref.php
B8: Table 23: Industrial Sector Macroeconomic Indicators
B10: U.S. Bureau of Labor Statistics
B11: 2020
B12: Industry Output and Employment
B13: https://www.bls.gov/emp/tables/industry-employment-and-output.htm
B14: Table 2.7: Output and Employment by Industry
B16: GDP Projection
B17: OECD
B18: 2018
B19: Quarterly National Accounts
B20: https://data.oecd.org/gdp/gdp-long-term-forecast.htm
B21: Real GDP long-term forecast
A23: Notes
A25: We need a set of scaling factors to convert the I/O variables that contain static data (for one historical year)
A26: to future time series data.
A28: We base these scaling factors on the projected change in output for each ISIC code, which is readily
A29: available disaggregated by ISIC code. It is crucial for these projections to be disaggregated by ISIC code,
A30: because we need to know how industries grow or shrink relative to one-another, not just how they
A31: grow or shrink overall to fit GDP growth.
A33: For the U.S., we use projections from the BLS and EIA AEO. The BLS has growth rates for all ISIC codes,
A34: but only out to 2029. The EIA has projections for only certain ISIC codes, but out to 2050.
A35: Our static I/O data largely comes from the OECD database and is for year 2015.
A37: We use EIA and BLS to find growth rates out to 2050 (see the "Growth Rates" tab). We smooth
A38: the transition around 2020 to avoid discontinuities.
... A60: output currency year in web-app/OCCF). Therefore, we use these conversion factors:
A62: 1.052913 | B62: 2012 dollars per 2010 dollar
A63: =10^6 -> 1000000 | B63: dollars per million dollars

Sheet BLS Table 2.7
A1: Table 2.7 Employment and Output by Industry
A2: Industry | B2: 2017 NAICS | C2: Employment | J2: Output
C3: Thousands of Jobs | F3: Change | H3: Compound Annual Rate of Change | J3: Billions of Chained 2012 Dollars | M3: Compound Annual Rate of Change
C4: 2009 | D4: 2019 | E4: 2029 | F4: 2009 - 2019 | G4: 2019 - 2029 | H4: 2009 - 2019 | I4: 2019 - 2029 | J4: 2009 | K4: 2019 | L4: 2029 | M4: 2009 - 2019 | N4: 2019 - 2029 | O4: Assigned ISIC Code
A5: Total(1)(2) | C5: 143036.4 | D5: 162795.6 | E5: 168834.7 | F5: 19759.2 | G5: 6039.1 | H5: 1.3 | I5: 0.4 | J5: 27293.3 | K5: 34049.9 | L5: 40867.6 | M5: 2.2 | N5: 1.8
A7: Nonagriculture wage and salary | B7: NA | C7: 132029.2 | D7: 151709.7 | E7: 158115.6 | F7: 19680.5 | G7: 6405.9 | H7: 1.4 | I7: 0.4 | J7: 26836.2 | K7: 33487.1 | L7: 40193.3 | M7: 2.2 | N7: 1.8
A8: Mining | B8: 21 | C8: 643.3 | D8: 684.6 | E8: 777.8 | F8: 41.3 | G8: 93.2 | H8: 0.6 | I8: 1.3 | J8: 485.8 | K8: 635.3 | L8: 835.5 | M8: 2.7 | N8: 2.8
A9: Oil and gas extraction | B9: 211 | C9: 159.8 | D9: 150.1 | E9: 129.7 | F9: -9.7 | G9: -20.4 | H9: -0.6 | I9: -1.4 | J9: 278.2 | K9: 474.3 | L9: 659.6 | M9: 5.5 | N9: 3.4 | O9: ISIC 06
A10: Mining, except oil and gas | B10: 212 | C10: 208.3 | D10: 191.4 | E10: 193.9 | F10: -16.9 | G10: 2.5 | H10: -0.8 | I10: 0.1 | J10: 124.6 | K10: 108.1 | L10: 114.2 | M10: -1.4 | N10: 0.6
A11: Coal mining | B11: 2121 | C11: 81.5 | D11: 51.9 | E11: 43.6 | F11: -29.6 | G11: -8.3 | H11: -4.4 | I11: -1.7 | J11: 50.9 | K11: 44.8 | L11: 43.8 | M11: -1.3 | N11: -0.2 | O11: ISIC 05
A12: Metal ore mining | B12: 2122 | C12: 34.8 | D12: 41.8 | E12: 48.6 | F12: 7 | G12: 6.8 | H12: 1.8 | I12: 1.5 | J12: 40.9 | K12: 36.2 | L12: 38 | M12: -1.2 | N12: 0.5 | O12: ISIC 07T08
A13: Nonmetallic mineral mining and quarrying | B13: 2123 | C13: 92 | D13: 97.7 | E13: 101.7 | F13: 5.7 | G13: 4 | H13: 0.6 | I13: 0.4 | J13: 33.4 | K13: 27.3 | L13: 32.2 | M13: -2 | N13: 1.6 | O13: ISIC 07T08
A14: Support activities for mining | B14: 213 | C14: 275.2 | D14: 343.1 | E14: 454.2 | F14: 67.9 | G14: 111.1 | H14: 2.2 | I14: 2.8 | J14: 83.5 | K14: 82.3 | L14: 109 | M14: -0.1 | N14: 2.9 | O14: ISIC 09
A15: Utilities | B15: 22 | C15: 560.1 | D15: 549 | E15: 506.7 | F15: -11.1 | G15: -42.3 | H15: -0.2 | I15: -0.8 | J15: 443.6 | K15: 458.6 | L15: 534.5 | M15: 0.3 | N15: 1.5
A16: Electric power generation, transmission and distribution | B16: 2211 | C16: 404.1 | D16: 385.5 | E16: 352 | F16: -18.6 | G16: -33.5 | H16: -0.5 | I16: -0.9 | J16: 340.5 | K16: 357 | L16: 422.3 | M16: 0.5 | N16: 1.7 | O16: ISIC 351
A17: Natural gas distribution | B17: 2212 | C17: 108.7 | D17: 110.3 | E17: 99 | F17: 1.6 | G17: -11.3 | H17: 0.1 | I17: -1.1 | J17: 88.7 | K17: 90.8 | L17: 98.8 | M17: 0.2 | N17: 0.8 | O17: ISIC 352T353
A18: Water, sewage and other systems | B18: 2213 | C18: 47.3 | D18: 53.2 | E18: 55.6 | F18: 5.9 | G18: 2.4 | H18: 1.2 | I18: 0.4 | J18: 13 | K18: 11.4 | L18: 12.8 | M18: -1.3 | N18: 1.1 | O18: ISIC 36T39
A19: Construction | B19: 23 | C19: 6016.5 | D19: 7492.2 | E19: 7792.4 | F19: 1475.7 | G19: 300.2 | H19: 2.2 | I19: 0.4 | J19: 1161.5 | K19: 1418.9 | L19: 1616.3 | M19: 2 | N19: 1.3 | O19: ISIC 41T43
A20: Manufacturing | B20: 31-33 | C20: 11847.9 | D20: 12839.5 | E20: 12394.7 | F20: 991.6 | G20: -444.8 | H20: 0.8 | I20: -0.4 | J20: 5261.6 | K20: 6384.1 | L20: 7434 | M20: 2 | N20: 1.5
A21: Food manufacturing | B21: 311 | C21: 1456.4 | D21: 1643.2 | E21: 1649.6 | F21: 186.8 | G21: 6.4 | H21: 1.2 | I21: 0 | J21: 736 | K21: 825 | L21: 972.1 | M21: 1.1 | N21: 1.7 | O21: ISIC 10T12
A22: Animal food manufacturing | B22: 3111 | C22: 51.8 | D22: 64 | E22: 74.8 | F22: 12.2 | G22: 10.8 | H22: 2.1 | I22: 1.6 | J22: 52.7 | K22: 65.7 | L22: 80.7 | M22: 2.2 | N22: 2.1
A23: Grain and oilseed milling | B23: 3112 | C23: 59.7 | D23: 60.6 | E23: 56.1 | F23: 0.9 | G23: -4.5 | H23: 0.1 | I23: -0.8 | J23: 95 | K23: 142.7 | L23: 178.5 | M23: 4.2 | N23: 2.3
A24: Sugar and confectionery product manufacturing | B24: 3113 | C24: 70.9 | D24: 78.8 | E24: 66.8 | F24: 7.9 | G24: -12 | H24: 1.1 | I24: -1.6 | J24: 33.5 | K24: 37.1 | L24: 38.6 | M24: 1 | N24: 0.4
A25: Fruit and vegetable preserving and specialty food manufacturing | B25: 3114 | C25: 172.3 | D25: 173.3 | E25: 158.7 | F25: 1 | G25: -14.6 | H25: 0.1 | I25: -0.9 | J25: 64.7 | K25: 66.6 | L25: 72.5 | M25: 0.3 | N25: 0.9
A26: Dairy product manufacturing | B26: 3115 | C26: 130.7 | D26: 155.6 | E26: 158.7 | F26: 24.9 | G26: 3.1 | H26: 1.8 | I26: 0.2 | J26: 116.8 | K26: 123.1 | L26: 149.4 | M26: 0.5 | N26: 2
A27: Animal slaughtering and processing | B27: 3116 | C27: 497.2 | D27: 531.4 | E27: 545.4 | F27: 34.2 | G27: 14 | H27: 0.7 | I27: 0.3 | J27: 213.2 | K27: 219.9 | L27: 257.9 | M27: 0.3 | N27: 1.6
A28: Seafood product preparation and packaging | B28: 3117 | C28: 38.1 | D28: 35.3 | E28: 29.3 | F28: -2.8 | G28: -6 | H28: -0.8 | I28: -1.8 | J28: 11.6 | K28: 10.9 | L28: 13 | M28: -0.6 | N28: 1.8
A29: Bakeries and tortilla manufacturing | B29: 3118 | C29: 273 | D29: 315.8 | E29: 303.1 | F29: 42.8 | G29: -12.7 | H29: 1.5 | I29: -0.4 | J29: 60.7 | K29: 66.3 | L29: 74.8 | M29: 0.9 | N29: 1.2
A30: Other food manufacturing | B30: 3119 | C30: 162.7 | D30: 228.4 | E30: 256.7 | F30: 65.7 | G30: 28.3 | H30: 3.5 | I30: 1.2 | J30: 88.4 | K30: 96.8 | L30: 115 | M30: 0.9 | N30: 1.7
A31: Beverage and tobacco product | B31: 312 | C31: 187.4 | D31: 285.8 | E31: 296.1 | F31: 98.4 | G31: 10.3 | H31: 4.3 | I31: 0.4 | J31: 167.3 | K31: 168.2 | L31: 181.3 | M31: 0.1 | N31: 0.8 | O31: ISIC 10T12
A32: Beverage manufacturing | B32: 3121 | C32: 168.7 | D32: 275 | E32: 289.4 | F32: 106.3 | G32: 14.4 | H32: 5 | I32: 0.5 | J32: 103.9 | K32: 121.8 | L32: 148.2 | M32: 1.6 | N32: 2
A33: Tobacco manufacturing | B33: 3122 | C33: 18.7 | D33: 11.3 | E33: 6.7 | F33: -7.4 | G33: -4.7 | H33: -4.9 | I33: -5.2 | J33: 63.7 | K33: 47.3 | L33: 38.3 | M33: -2.9 | N33: -2.1
A34: Textile mills and textile product mills | B34: 313,314 | C34: 250.1 | D34: 222 | E34: 198.3 | F34: -28.1 | G34: -23.7 | H34: -1.2 | I34: -1.1 | J34: 51.3 | K34: 52.8 | L34: 50.3 | M34: 0.3 | N34: -0.5 | O34: ISIC 13T15
A35: Apparel, leather and allied product manufacturing | B35: 315, 316 | C35: 196.5 | D35: 137.7 | E35: 94.2 | F35: -58.8 | G35: -43.5 | H35: -3.5 | I35: -3.7 | J35: 25.6 | K35: 19.1 | L35: 20.1 | M35: -2.8 | N35: 0.5 | O35: ISIC 13T15
A36: Wood product manufacturing | B36: 321 | C36: 360.2 | D36: 408.8 | E36: 382.3 | F36: 48.6 | G36: -26.5 | H36: 1.3 | I36: -0.7 | J36: 74.2 | K36: 94.1 | L36: 108.3 | M36: 2.4 | N36: 1.4 | O36: ISIC 16
A37: Sawmills and wood preservation | B37: 3211 | C37: 83.2 | D37: 92.3 | E37: 85.3 | F37: 9.1 | G37: -7 | H37: 1 | I37: -0.8 | J37: 21.4 | K37: 26 | L37: 30.5 | M37: 2 | N37: 1.6
A38: Veneer, plywood, and engineered wood product manufacturing | B38: 3212 | C38: 68.3 | D38: 82.1 | E38: 87 | F38: 13.8 | G38: 4.9 | H38: 1.9 | I38: 0.6 | J38: 17.6 | K38: 20.4 | L38: 23.8 | M38: 1.5 | N38: 1.6
A39: Other wood product manufacturing | B39: 3219 | C39: 208.7 | D39: 234.4 | E39: 210 | F39: 25.7 | G39: -24.4 | H39: 1.2 | I39: -1.1 | J39: 35.4 | K39: 47.9 | L39: 54.2 | M39: 3.1 | N39: 1.3
A40: Paper manufacturing | B40: 322 | C40: 407 | D40: 365.3 | E40: 340 | F40: -41.7 | G40: -25.3 | H40: -1.1 | I40: -0.7 | J40: 172.6 | K40: 176.6 | L40: 183 | M40: 0.2 | N40: 0.4 | O40: ISIC 17T18
A41: Pulp, paper, and paperboard mills | B41: 3221 | C41: 116.9 | D41: 96.4 | E41: 92.3 | F41: -20.5 | G41: -4.1 | H41: -1.9 | I41: -0.4 | J41: 79.4 | K41: 81.1 | L41: 84.4 | M41: 0.2 | N41: 0.4
...

Sheet AEO22 Table 23 Raw
A1: Table 23. Industrial Sector Macroeconomic Indicators
A2: https://www.eia.gov/outlooks/aeo/data/browser/#/?id=34-AEO2022&cases=lowmacro&sid=lowmacro-d011222a.10-114-AEO2022&sourcekey=0
A3: Thu Jul 14 2022 09:36:04 GMT-0400 (Eastern Daylight Time)
A4: Source: U.S. Energy Information Administration
B5: full name | C5: api key | D5: units | E5: 2020 | F5: 2021 | G5: 2022 | H5: 2023 | I5: 2024 | J5: 2025 | K5: 2026 | L5: 2027 | M5: 2028 | N5: 2029 | O5: 2030 | P5: 2031 | Q5: 2032 | R5: 2033 | S5: 2034 | T5: 2035 | U5: 2036 | V5: 2037 | W5: 2038 | X5: 2039 | Y5: 2040 | Z5: 2041 | AA5: 2042 | AB5: 2043 | AC5: 2044 | AD5: 2045 | AE5: 2046 | AF5: 2047 | AG5: 2048 | AH5: 2049 | AI5: 2050 | AJ5: Growth (2021-2050)
A6: Pinned Series
A7: Gross Domestic Product (billion 2012 dollars) | B7: Industrial Macroeconomic: Gross Domestic Product: Low economic growth | C7: 34-AEO2022.2.lowmacro-d011222a | D7: billion 2012 $ | F7: 19287.709 | G7: 19760.287 | H7: 20221.789 | I7: 20729.912 | J7: 21174.707 | K7: 21588.189 | L7: 21943.693 | M7: 22341.447 | N7: 22750.484 | O7: 23184.713 | P7: 23604.686 | Q7: 24072.311 | R7: 24531.643 | S7: 24923.117 | T7: 25304.564 | U7: 25681.664 | V7: 26080.943 | W7: 26491.984 | X7: 26940.375 | Y7: 27407.311 | Z7: 27842.832 | AA7: 28292.699 | AB7: 28753.758 | AC7: 29223.881 | AD7: 29725.133 | AE7: 30268.092 | AF7: 30800.547 | AG7: 31310.893 | AH7: 31858.811 | AI7: 32479.828 | AJ7: 0.018
A8: Nonfarm Employment (millions) | B8: Industrial Macroeconomic: Employment, Nonfarm: Low economic growth | C8: 34-AEO2022.4.lowmacro-d011222a | D8: millions | F8: 147.7354 | G8: 148.57752 | H8: 151.11475 | I8: 152.88181 | J8: 153.79976 | K8: 154.22972 | L8: 154.40425 | M8: 154.76437 | N8: 155.22359 | O8: 155.96846 | P8: 156.832 | Q8: 157.90752 | R8: 158.97392 | S8: 159.59203 | T8: 160.03293 | U8: 160.57657 | V8: 161.2149 | W8: 161.87415 | X8: 162.66341 | Y8: 163.58928 | Z8: 164.25658 | AA8: 164.99643 | AB8: 165.65443 | AC8: 166.30429 | AD8: 167.18918 | AE8: 168.24129 | AF8: 169.3114 | AG8: 170.22873 | AH8: 171.10382 | AI8: 172.19258 | AJ8: 0.005
A9: Value of Shipments (billion 2012 dollars) | C9: 34-AEO2022.6.
A10: Nonmanufacturing Sector | C10: 34-AEO2022.8.
A11: Agriculture/Forestry/Fishing/Hunting | B11: Industrial Macroeconomic: Nonmanufacturing: Agriculture/Forestry/Fishing/Hunting: Low economic growth | C11: 34-AEO2022.9.lowmacro-d011222a | D11: billion 2012 $ | F11: 545.77948 | G11: 551.13959 | H11: 558.31287 | I11: 562.69605 | J11: 566.57074 | K11: 570.89679 | L11: 574.01483 | M11: 575.9624 | N11: 577.76355 | O11: 580.1933 | P11: 582.15271 | Q11: 584.11523 | R11: 586.77783 | S11: 588.97095 | T11: 590.37793 | U11: 592.02594 | V11: 593.7182 | W11: 595.4386 | X11: 597.58563 | Y11: 599.5246 | Z11: 601.00348 | AA11: 602.93469 | AB11: 605.20435 | AC11: 606.87677 | AD11: 608.2262 | AE11: 609.61218 | AF11: 610.96179 | AG11: 613.48285 | AH11: 616.40076 | AI11: 619.95856 | AJ11: 0.004
A12: Mining | B12: Industrial Macroeconomic: Nonmanufacturing: Mining: Low economic growth | C12: 34-AEO2022.10.lowmacro-d011222a | D12: billion 2012 $ | F12: 688.52893 | G12: 684.08637 | H12: 694.49341 | I12: 699.258 | J12: 707.49762 | K12: 709.31628 | L12: 706.40289 | M12: 714.3717 | N12: 716.31879 | O12: 716.49072 | P12: 716.28943 | Q12: 717.49902 | R12: 719.57141 | S12: 714.41589 | T12: 711.59711 | U12: 710.25049 | V12: 708.04541 | W12: 708.72888 | X12: 711.70679 | Y12: 715.08569 | Z12: 715.07507 | AA12: 714.95477 | AB12: 716.31177 | AC12: 718.23499 | AD12: 723.43109 | AE12: 730.20544 | AF12: 733.34979 | AG12: 732.5788 | AH12: 733.87647 | AI12: 740.8158 | AJ12: 0.003
A13: Construction | B13: Industrial Macroeconomic: Nonmanufacturing: Construction: Low economic growth | C13: 34-AEO2022.14.lowmacro-d011222a | D13: billion 2012 $ | F13: 1448.7993 | G13: 1344.485 | H13: 1310.302 | I13: 1321.8097 | J13: 1327.167 | K13: 1326.1383 | L13: 1323.1837 | M13: 1333.3877 | N13: 1346.314 | O13: 1355.6226 | P13: 1366.4568 | Q13: 1408.8607 | R13: 1446.3237 | S13: 1453.333 | T13: 1458.3185 | U13: 1465.8523 | V13: 1487.8778 | W13: 1517.0828 | X13: 1549.0847 | Y13: 1575.9659 | Z13: 1597.8958 | AA13: 1619.077 | AB13: 1638.0723 | AC13: 1654.094 | AD13: 1668.0818 | AE13: 1686.9323 | AF13: 1705.474 | AG13: 1723.6689 | AH13: 1747.0677 | AI13: 1773.0322 | AJ13: 0.007
A14: Manufacturing Sector | C14: 34-AEO2022.16.
A15: Food Products | B15: Industrial Macroeconomic: Manufacturing: Food Products: Low economic growth | C15: 34-AEO2022.17.lowmacro-d011222a | D15: billion 2012 $ | F15: 951.64435 | G15: 968.1377 | H15: 969.99872 | I15: 974.52918 | J15: 980.4978 | K15: 986.57391 | L15: 993.19183 | M15: 999.98218 | N15: 1005.9415 | O15: 1011.705 | P15: 1017.6683 | Q15: 1023.1825 | R15: 1027.4513 | S15: 1031.0057 | T15: 1034.582 | U15: 1038.2365 | V15: 1041.2788 | W15: 1044.4017 | X15: 1048.0537 | Y15: 1051.4875 | Z15: 1054.3187 | AA15: 1057.787 | AB15: 1061.2743 | AC15: 1064.614 | AD15: 1067.8418 | AE15: 1070.3273 | AF15: 1072.7795 | AG15: 1076.1705 | AH15: 1080.1558 | AI15: 1085.246 | AJ15: 0.005
A16: Beverages and Tobacco Products | B16: Industrial Macroeconomic: Manufacturing: Beverages and Tobacco Products: Low economic growth | C16: 34-AEO2022.22.lowmacro-d011222a | D16: billion 2012 $ | F16: 150.72591 | G16: 146.54585 | H16: 143.67477 | I16: 141.76296 | J16: 140.0777 | K16: 138.97025 | L16: 138.3801 | M16: 138.23795 | N16: 138.09813 | O16: 138.0123 | P16: 137.9388 | Q16: 138.4285 | R16: 138.21021 | S16: 137.88588 | T16: 137.82194 | U16: 137.79297 | V16: 137.77362 | W16: 137.74858 | X16: 137.72784 | Y16: 137.70062 | Z16: 137.56975 | AA16: 137.47768 | AB16: 137.70128 | AC16: 138.13934 | AD16: 138.44804 | AE16: 138.82553 | AF16: 139.34398 | AG16: 140.1508 | AH16: 141.08917 | AI16: 142.09233 | AJ16: -0.002
A17: Textile Mills and Products | B17: Industrial Macroeconomic: Manufacturing: Textile Mills and Products: Low economic growth | C17: 34-AEO2022.23.lowmacro-d011222a | D17: billion 2012 $ | F17: 66.721695 | G17: 67.566856 | H17: 68.538239 | I17: 68.599648 | J17: 68.280685 | K17: 67.760956 | L17: 67.162628 | M17: 66.83532 | N17: 66.431587 | O17: 66.230736 | P17: 66.14399 | Q17: 65.868149 | R17: 65.687248 | S17: 65.428848 | T17: 65.043457 | U17: 64.738548 | V17: 64.548325 | W17: 64.244316 | X17: 64.002434 | Y17: 63.834743 | Z17: 63.52803 | AA17: 63.220856 | AB17: 63.055897 | AC17: 62.821331 | AD17: 62.599751 | AE17: 62.48616 | AF17: 62.27063 | AG17: 61.878735 | AH17: 61.477104 | AI17: 61.008438 | AJ17: -0.003
A18: Wood Products | B18: Industrial Macroeconomic: Manufacturing: Wood Products: Low economic growth | C18: 34-AEO2022.24.lowmacro-d011222a | D18: billion 2012 $ | F18: 109.86588 | G18: 103.38457 | H18: 97.434769 | I18: 97.533112 | J18: 98.415634 | K18: 94.94783 | L18: 90.944565 | M18: 87.395416 | N18: 85.54142 | O18: 85.198097 | P18: 83.265373 | Q18: 82.290382 | R18: 81.322891 | S18: 80.92173 | T18: 80.755692 | U18: 81.03405 | V18: 80.751335 | W18: 80.406364 | X18: 80.710457 | Y18: 81.227318 | Z18: 82.065094 | AA18: 83.27713 | AB18: 84.180367 | AC18: 83.959122 | AD18: 83.839531 | AE18: 84.499367 | AF18: 85.330498 | AG18: 86.038773 | AH18: 87.018608 | AI18: 89.788933 | AJ18: -0.007
A19: Furniture and Related Products | B19: Industrial Macroeconomic: Manufacturing: Furniture and Related Products: Low economic growth | C19: 34-AEO2022.25.lowmacro-d011222a | D19: billion 2012 $ | F19: 73.106606 | G19: 74.492615 | H19: 74.920853 | I19: 74.970245 | J19: 75.073692 | K19: 74.8134 | L19: 73.955078 | M19: 73.365143 | N19: 72.822044 | O19: 73.29007 | P19: 73.36235 | Q19: 73.803444 | R19: 74.245209 | S19: 74.740074 | T19: 75.565613 | U19: 76.517937 | V19: 77.588066 | W19: 78.300179 | X19: 79.465652 | Y19: 80.69249 | Z19: 81.847878 | AA19: 83.49836 | AB19: 85.137604 | AC19: 85.927277 | AD19: 86.475052 | AE19: 88.442543 | AF19: 90.415634 | AG19: 91.291969 | AH19: 92.91996 | AI19: 95.786667 | AJ19: 0.009
A20: Paper Products | B20: Industrial Macroeconomic: Manufacturing: Paper Products: Low economic growth | C20: 34-AEO2022.26.lowmacro-d011222a | D20: billion 2012 $ | F20: 172.22682 | G20: 173.27202 | H20: 172.6449 | I20: 171.37058 | J20: 169.47244 | K20: 167.81551 | L20: 166.21905 | M20: 164.84427 | N20: 163.43594 | O20: 161.91228 | P20: 160.28799 | Q20: 158.89955 | R20: 157.27025 | S20: 155.54358 | T20: 154.1387 | U20: 152.74083 | V20: 151.28488 | W20: 149.95772 | X20: 148.82761 | Y20: 147.4711 | Z20: 146.1517 | AA20: 145.10872 | AB20: 144.08342 | AC20: 142.386 | AD20: 141.10953 | AE20: 140.48241 | AF20: 139.86592 | AG20: 139.51621 | AH20: 137.74025 | AI20: 137.07678 | AJ20: -0.008
A21: Printing | B21: Industrial Macroeconomic: Manufacturing: Printing: Low economic growth | C21: 34-AEO2022.30.lowmacro-d011222a | D21: billion 2012 $ | F21: 82.234703 | G21: 81.187164 | H21: 79.630684 | I21: 77.586235 | J21: 75.565125 | K21: 73.57209 | L21: 71.851616 | M21: 70.612923 | N21: 69.551025 | O21: 68.676834 | P21: 67.632065 | Q21: 67.00843 | R21: 66.476471 | S21: 65.723656 | T21: 64.944397 | U21: 63.884346 | V21: 62.556236 | W21: 61.694462 | X21: 61.072052 | Y21: 61.092018 | Z21: 61.034531 | AA21: 60.722279 | AB21: 61.370449 | AC21: 60.406033 | AD21: 59.911457 | AE21: 58.687168 | AF21: 57.077961 | AG21: 55.920696 | AH21: 55.103806 | AI21: 53.869823 | AJ21: -0.014
A22: Chemical Manufacturing | B22: Industrial Macroeconomic: Manufacturing: Chemical Manufacturing: Low economic growth | C22: 34-AEO2022.31.lowmacro-d011222a | D22: billion 2012 $ | F22: 980.72162 | G22: 940.86902 | H22: 930.38812 | I22: 926.09253 | J22: 934.00262 | K22: 943.36395 | L22: 951.80042 | M22: 959.39624 | N22: 964.21442 | O22: 970.38867 | P22: 979.80133 | Q22: 994.3761 | R22: 1006.7592 | S22: 1016.3872 | T22: 1027.3154 | U22: 1039.3499 | V22: 1052.8604 | W22: 1066.6614 | X22: 1080.9395 | Y22: 1093.8854 | Z22: 1108.3926 | AA22: 1126.677 | AB22: 1146.8215 | AC22: 1162.175 | AD22: 1178.572 | AE22: 1203.0021 | AF22: 1224.2114 | AG22: 1238.2368 | AH22: 1257.2178 | AI22: 1282.0889 | AJ22: 0.009
A23: Bulk Chemicals | B23: Industrial Macroeconomic: Manufacturing: Chemicals: Bulk Chemicals: Low economic growth | C23: 34-AEO2022.32.lowmacro-d011222a | D23: billion 2012 $ | F23: 463.10675 | G23: 455.29825 | H23: 451.30203 | I23: 448.81549 | J23: 456.10266 | K23: 463.94165 | L23: 470.07739 | M23: 475.59738 | N23: 478.43301 | O23: 482.5159 | P23: 488.89401 | Q23: 499.06354 | R23: 506.06686 | S23: 510.52136 | T23: 515.73773 | U23: 521.2262 | V23: 527.0581 | W23: 532.28247 | X23: 537.46704 | Y23: 541.01819 | Z23: 545.26508 | AA23: 550.62842 | AB23: 556.98749 | AC23: 558.42749 | AD23: 560.82269 | AE23: 569.84582 | AF23: 574.25354 | AG23: 571.66547 | AH23: 573.69122 | AI23: 583.27954 | AJ23: 0.008
A24: Inorganic | B24: Industrial Macroeconomic: Manufacturing: Chemicals: Bulk Chemicals: Inorganic: Low economic growth | C24: 34-AEO2022.33.lowmacro-d011222a | D24: billion 2012 $ | F24: 53.850636 | G24: 51.550568 | H24: 49.438751 | I24: 48.350109 | J24: 47.734375 | K24: 47.503693 | L24: 47.458179 | M24: 47.77747 | N24: 47.768639 | O24: 47.684147 | P24: 47.559883 | Q24: 47.722786 | R24: 47.588608 | S24: 47.195621 | T24: 46.945366 | U24: 46.787834 | V24: 46.789524 | W24: 46.814411 | X24: 46.820007 | Y24: 46.556324 | Z24: 46.370941 | AA24: 46.241123 | AB24: 46.037731 | AC24: 45.256706 | AD24: 44.760391 | AE24: 44.776981 | AF24: 44.703194 | AG24: 43.526035 | AH24: 42.594841 | AI24: 42.479103 | AJ24: -0.008
A25: Organic | B25: Industrial Macroeconomic: Manufacturing: Chemicals: Bulk Chemicals: Organic: Low economic growth | C25: 34-AEO2022.34.lowmacro-d011222a | D25: billion 2012 $ | F25: 234.04575 | G25: 225.48904 | H25: 227.23129 | I25: 229.23759 | J25: 233.21202 | K25: 235.84613 | L25: 238.11675 | M25: 240.73488 | N25: 243.95473 | O25: 247.65332 | P25: 251.37535 | Q25: 256.15503 | R25: 259.93643 | S25: 264.31485 | T25: 268.79715 | U25: 273.12537 | V25: 277.17215 | W25: 280.96246 | X25: 284.30344 | Y25: 287.328 | Z25: 291.57227 | AA25: 296.06671 | AB25: 300.46002 | AC25: 301.39941 | AD25: 302.66382 | AE25: 308.00751 | AF25: 310.79541 | AG25: 309.99149 | AH25: 311.87802 | AI25: 317.72769 | AJ25: 0.011
A26: Resin | B26: Synthetic Rubber | C26: and Fibers | D26: Industrial Macroeconomic: Manufacturing: Chemicals: Bulk Chemicals: Resin, Synthetic Rubber, and Fibers: Low economic growth | E26: 34-AEO2022.36.lowmacro-d011222a | F26: 130.70677 | G26: 135.51041 | H26: 131.55824 | I26: 128.28755 | J26: 132.05852 | K26: 137.17943 | L26: 140.60777 | M26: 142.44058 | N26: 141.51822 | O26: 141.52049 | P26: 143.9295 | Q26: 148.53035 | R26: 151.4269 | S26: 151.70508 | T26: 152.396 | U26: 153.5166 | V26: 155.09947 | W26: 156.34813 | X26: 158.01975 | Y26: 158.76155 | Z26: 158.86943 | AA26: 159.73305 | AB26: 161.8185 | AC26: 163.12077 | AD26: 164.79562 | AE26: 168.07678 | AF26: 169.5834 | AG26: 169.12285 | AH26: 170.11667 | AI26: 173.62245 | AJ26: 0.01
A27: Agricultural Chemicals | B27: Industrial Macroeconomic: Manufacturing: Chemicals: Bulk Chemicals: Agricultural Chemicals: Low economic growth | C27: 34-AEO2022.37.lowmacro-d011222a | D27: billion 2012 $ | F27: 44.50359 | G27: 42.748219 | H27: 43.073761 | I27: 42.940258 | J27: 43.097713 | K27: 43.412411 | L27: 43.894714 | M27: 44.644444 | N27: 45.191433 | O27: 45.65794 | P27: 46.029278 | Q27: 46.65538 | R27: 47.114948 | S27: 47.305813 | T27: 47.59919 | U27: 47.796402 | V27: 47.996956 | W27: 48.157459 | X27: 48.323879 | Y27: 48.372288 | Z27: 48.45245 | AA27: 48.587543 | AB27: 48.671253 | AC27: 48.650597 | AD27: 48.602818 | AE27: 48.984562 | AF27: 49.171539 | AG27: 49.025089 | AH27: 49.101685 | AI27: 49.450348 | AJ27: 0.004
A28: Other Chemical Products | B28: Industrial Macroeconomic: Manufacturing: Chemicals: Other Chemical Products: Low economic growth | C28: 34-AEO2022.38.lowmacro-d011222a | D28: billion 2012 $ | F28: 517.61487 | G28: 485.57077 | H28: 479.08609 | I28: 477.27707 | J28: 477.89996 | K28: 479.4223 | L28: 481.72305 | M28: 483.79889 | N28: 485.7814 | O28: 487.87274 | P28: 490.90732 | Q28: 495.31259 | R28: 500.69232 | S28: 505.86581 | T28: 511.57764 | U28: 518.12372 | V28: 525.80219 | W28: 534.37884 | X28: 543.47247 | Y28: 552.86719 | Z28: 563.12744 | AA28: 576.04864 | AB28: 589.83411 | AC28: 603.74756 | AD28: 617.74927 | AE28: 633.15625 | AF28: 649.95789 | AG28: 666.57135 | AH28: 683.52649 | AI28: 698.80933 | AJ28: 0.01
A29: Petroleum and Coal Products | B29: Industrial Macroeconomic: Manufacturing: Petroleum and Coal Products: Low economic growth | C29: 34-AEO2022.43.lowmacro-d011222a | D29: billion 2012 $ | F29: 789.06366 | G29: 885.51178 | H29: 899.4964 | I29: 897.32391 | J29: 897.97327 | K29: 896.10211 | L29: 892.39954 | M29: 890.51331 | N29: 887.01245 | O29: 884.10364 | P29: 883.01489 | Q29: 884.73651 | R29: 884.38123 | S29: 882.0946 | T29: 879.74872 | U29: 878.12824 | V29: 877.94244 | W29: 877.26892 | X29: 878.56305 | Y29: 878.48267 | Z29: 879.24432 | AA29: 881.4317 | AB29: 883.83002 | AC29: 884.55798 | AD29: 886.77826 | AE29: 890.43878 | AF29: 892.92889 | AG29: 893.51227 | AH29: 896.77118 | AI29: 904.23969 | AJ29: 0.005
A30: Petroleum Refineries | B30: Industrial Macroeconomic: Manufacturing: Petroleum and Coal: Petroleum Refineries: Low economic growth | C30: 34-AEO2022.44.lowmacro-d011222a | D30: billion 2012 $ | F30: 746.87048 | G30: 840.716 | H30: 850.76227 | I30: 846.17731 | J30: 846.14966 | K30: 844.26404 | L30: 840.59943 | M30: 838.8761 | N30: 835.64575 | O30: 832.79443 | P30: 831.82013 | Q30: 833.64276 | R30: 833.2926 | S30: 831.01508 | T30: 828.73273 | U30: 827.11176 | V30: 826.83716 | W30: 826.18012 | X30: 827.33057 | Y30: 827.06683 | Z30: 827.62585 | AA30: 829.53912 | AB30: 831.72736 | AC30: 832.18103 | AD30: 834.06146 | AE30: 837.30823 | AF30: 839.42822 | AG30: 839.74255 | AH30: 842.51312 | AI30: 849.40979 | AJ30: 0.004
A31: Other Petroleum and Coal Products | B31: Industrial Macroeconomic: Manufacturing: Petroleum and Coal: Other Petroleum & Coal Products: Low economic growth | C31: 34-AEO2022.45.lowmacro-d011222a | D31: billion 2012 $ | F31: 42.193161 | G31: 44.795792 | H31: 48.734158 | I31: 51.146606 | J31: 51.823608 | K31: 51.838081 | L31: 51.800133 | M31: 51.637184 | N31: 51.366695 | O31: 51.309204 | P31: 51.194752 | Q31: 51.093731 | R31: 51.088634 | S31: 51.079502 | T31: 51.015999 | U31: 51.016506 | V31: 51.105297 | W31: 51.088779 | X31: 51.232498 | Y31: 51.415825 | Z31: 51.618454 | AA31: 51.89257 | AB31: 52.102638 | AC31: 52.376976 | AD31: 52.716824 | AE31: 53.130543 | AF31: 53.500679 | AG31: 53.769714 | AH31: 54.258045 | AI31: 54.829876 | AJ31: 0.009
A32: Plastics and Rubber Products | B32: Industrial Macroeconomic: Manufacturing: Plastics and Rubber Products: Low economic growth | C32: 34-AEO2022.46.lowmacro-d011222a | D32: billion 2012 $ | F32: 245.4554 | G32: 241.79295 | H32: 238.33037 | I32: 239.35245 | J32: 241.29742 | K32: 243.38844 | L32: 246.60761 | M32: 251.6187 | N32: 255.54027 | O32: 259.35934 | P32: 262.99316 | Q32: 267.15747 | R32: 270.87466 | S32: 273.07782 | T32: 276.69217 | U32: 280.75842 | V32: 285.36069 | W32: 289.78723 | X32: 294.53464 | Y32: 299.19794 | Z32: 303.74289 | AA32: 308.89786 | AB32: 315.15469 | AC32: 320.66641 | AD32: 326.10001 | AE32: 333.03391 | AF32: 339.61481 | AG32: 345.44083 | AH32: 351.487 | AI32: 359.67404 | AJ32: 0.013
A33: Stone | B33: Clay | C33: and Glass Products | D33: Industrial Macroeconomic: Manufacturing: Stone, Clay, and Glass Products: Low economic growth | E33: 34-AEO2022.47.lowmacro-d011222a | F33: 113.22774 | G33: 109.10921 | H33: 106.69244 | I33: 107.43405 | J33: 108.52844 | K33: 109.18559 | L33: 109.47917 | M33: 109.89218 | N33: 110.35785 | O33: 111.35317 | P33: 112.26262 | Q33: 113.35408 | R33: 114.38032 | S33: 114.70245 | T33: 115.58392 | U33: 116.3244 | V33: 117.12651 | W33: 117.76143 | X33: 118.411 | Y33: 119.15473 | Z33: 120.05633 | AA33: 120.6676 | AB33: 120.67708 | AC33: 121.01808 | AD33: 121.5524 | AE33: 122.32906 | AF33: 123.00944 | AG33: 122.92292 | AH33: 122.63182 | AI33: 122.74751 | AJ33: 0.003
A34: Glass and Glass Products | B34: Industrial Macroeconomic: Manufacturing: Stone, Clay, and Glass: Glass and Glass Products: Low economic growth | C34: 34-AEO2022.48.lowmacro-d011222a | D34: billion 2012 $ | F34: 23.465088 | G34: 21.78306 | H34: 21.384214 | I34: 20.878117 | J34: 20.782543 | K34: 20.692644 | L34: 20.512907 | M34: 20.323284 | N34: 20.166574 | O34: 20.228386 | P34: 20.307383 | Q34: 20.425203 | R34: 20.49914 | S34: 20.438978 | T34: 20.404791 | U34: 20.316797 | V34: 20.171747 | W34: 20.004017 | X34: 19.919577 | Y34: 19.699514 | Z34: 19.535419 | AA34: 19.386906 | AB34: 19.26335 | AC34: 19.142691 | AD34: 18.977442 | AE34: 18.848768 | AF34: 18.691172 | AG34: 18.550406 | AH34: 18.279713 | AI34: 18.123037 | AJ34: -0.009
A35: Cement and Lime | B35: Industrial Macroeconomic: Manufacturing: Stone, Clay, and Glass: Cement and Lime: Low economic growth | C35: 34-AEO2022.50.lowmacro-d011222a | D35: billion 2012 $ | F35: 13.972248 | G35: 14.70841 | H35: 14.789883 | I35: 15.090622 | J35: 15.311079 | K35: 15.412535 | L35: 15.460963 | M35: 15.52693 | N35: 15.640759 | O35: 15.860228 | P35: 16.10014 | Q35: 16.290489 | R35: 16.472929 | S35: 16.664034 | T35: 16.89053 | U35: 17.055897 | V35: 17.196074 | W35: 17.328506 | X35: 17.456821 | Y35: 17.659683 | Z35: 17.887959 | AA35: 18.065277 | AB35: 18.146942 | AC35: 18.263258 | AD35: 18.386185 | AE35: 18.506489 | AF35: 18.638 | AG35: 18.651054 | AH35: 18.658253 | AI35: 18.717762 | AJ35: 0.01
A36: Other Nonmetallic Mineral Products | B36: Industrial Macroeconomic: Manufacturing: Stone, Clay, and Glass: Other Nonmetallic Mineral Products: Low economic growth | C36: 34-AEO2022.53.lowmacro-d011222a | D36: billion 2012 $ | F36: 75.790398 | G36: 72.617737 | H36: 70.518349 | I36: 71.465309 | J36: 72.434814 | K36: 73.080406 | L36: 73.505302 | M36: 74.041969 | N36: 74.550514 | O36: 75.264557 | P36: 75.855095 | Q36: 76.63839 | R36: 77.408257 | S36: 77.599434 | T36: 78.288597 | U36: 78.951706 | V36: 79.75869 | W36: 80.428902 | X36: 81.034607 | Y36: 81.795532 | Z36: 82.63295 | AA36: 83.215416 | AB36: 83.266785 | AC36: 83.612137 | AD36: 84.188766 | AE36: 84.973801 | AF36: 85.680267 | AG36: 85.721458 | AH36: 85.693855 | AI36: 85.906715 | AJ36: 0.004
A37: Primary Metals Industry | B37: Industrial Macroeconomic: Manufacturing: Primary Metals Industry: Low economic growth | C37: 34-AEO2022.54.lowmacro-d011222a | D37: billion 2012 $ | F37: 240.15085 | G37: 248.90256 | H37: 250.07703 | I37: 249.02979 | J37: 250.30414 | K37: 250.60803 | L37: 250.12616 | M37: 250.00717 | N37: 249.85892 | O37: 249.90987 | P37: 249.19882 | Q37: 249.03748 | R37: 248.40512 | S37: 247.97603 | T37: 248.2272 | U37: 248.2901 | V37: 248.27737 | W37: 248.48131 | X37: 248.10503 | Y37: 247.7168 | Z37: 248.85091 | AA37: 250.90131 | AB37: 253.09219 | AC37: 253.60751 | AD37: 254.59634 | AE37: 257.39395 | AF37: 259.41773 | AG37: 258.65225 | AH37: 258.38315 | AI37: 260.98474 | AJ37: 0.003
A38: Iron and Steel Mills and Products | B38: Industrial Macroeconomic: Manufacturing: Primary Metals: Iron and Steel Mills and Products: Low economic growth | C38: 34-AEO2022.55.lowmacro-d011222a | D38: billion 2012 $ | F38: 125.35865 | G38: 127.9127 | H38: 128.28152 | I38: 127.14848 | J38: 128.20995 | K38: 127.60918 | L38: 126.0716 | M38: 124.35245 | N38: 123.02968 | O38: 122.10035 | P38: 120.69582 | Q38: 119.79025 | R38: 118.34252 | S38: 117.34465 | T38: 116.88985 | U38: 116.50053 | V38: 115.87187 | W38: 115.07552 | X38: 113.55775 | Y38: 112.11298 | Z38: 112.0481 | AA38: 112.7039 | AB38: 113.54688 | AC38: 112.8486 | AD38: 112.08395 | AE38: 112.8539 | AF38: 112.86078 | AG38: 110.48788 | AH38: 108.78362 | AI38: 109.414 | AJ38: -0.005
A39: Alumina and Aluminum Products | B39: Industrial Macroeconomic: Manufacturing: Primary Metals: Alumina and Aluminum Products: Low economic growth | C39: 34-AEO2022.56.lowmacro-d011222a | D39: billion 2012 $ | F39: 37.984837 | G39: 40.76638 | H39: 41.336983 | I39: 41.340252 | J39: 41.685944 | K39: 42.266392 | L39: 42.752811 | M39: 43.178772 | N39: 43.57325 | O39: 43.938221 | P39: 44.238689 | Q39: 44.402592 | R39: 44.571877 | S39: 44.748257 | T39: 44.868229 | U39: 44.736099 | V39: 44.609898 | W39: 44.769489 | X39: 44.712196 | Y39: 44.451584 | Z39: 44.670883 | AA39: 45.104656 | AB39: 45.442837 | AC39: 45.543003 | AD39: 45.942951 | AE39: 46.439526 | AF39: 46.926342 | AG39: 47.142418 | AH39: 47.268768 | AI39: 47.882832 | AJ39: 0.008
A40: Other Primary Metal Products | B40: Industrial Macroeconomic: Manufacturing: Primary Metals: Other Primary Metal Products: Low economic growth | C40: 34-AEO2022.57.lowmacro-d011222a | D40: billion 2012 $ | F40: 76.807365 | G40: 80.223488 | H40: 80.458534 | I40: 80.541054 | J40: 80.408257 | K40: 80.732468 | L40: 81.301743 | M40: 82.475945 | N40: 83.255989 | O40: 83.871292 | P40: 84.26432 | Q40: 84.844643 | R40: 85.49073 | S40: 85.883118 | T40: 86.469139 | U40: 87.053467 | V40: 87.795616 | W40: 88.636292 | X40: 89.835083 | Y40: 91.152229 | Z40: 92.131912 | AA40: 93.092735 | AB40: 94.102486 | AC40: 95.215919 | AD40: 96.569435 | AE40: 98.100525 | AF40: 99.630608 | AG40: 101.02195 | AH40: 102.33075 | AI40: 103.68793 | AJ40: 0.01
...

Sheet AEO22 Table 23
C1: ref2021.d113020a | D1: 2020 | E1: 2021 | F1: 2022 | G1: 2023 | H1: 2024 | I1: 2025 | J1: 2026 | K1: 2027 | L1: 2028 | M1: 2029 | N1: 2030 | O1: 2031 | P1: 2032 | Q1: 2033 | R1: 2034 | S1: 2035 | T1: 2036 | U1: 2037 | V1: 2038 | W1: 2039 | X1: 2040 | Y1: 2041 | Z1: 2042 | AA1: 2043 | AB1: 2044 | AC1: 2045 | AD1: 2046 | AE1: 2047 | AF1: 2048 | AG1: 2049 | AH1: 2050
D3: Report | E3: Annual Energy Outlook 2021
D4: Scenario | E4: ref2021 | H4: Reference case
D5: Datekey | E5: d113020a
D6: Release Date | F6: January 2021
A10: ISM000 | C10: 23. Industrial Sector Macroeconomic Indicators | AI10: Compound
AI11: Growth
AI12: 2020-2050
B13: Assigned ISIC Code | C13: Indicators | D13: 2020 | E13: 2021 | F13: 2022 | G13: 2023 | H13: 2024 | I13: 2025 | J13: 2026 | K13: 2027 | L13: 2028 | M13: 2029 | N13: 2030 | O13: 2031 | P13: 2032 | Q13: 2033 | R13: 2034 | S13: 2035 | T13: 2036 | U13: 2037 | V13: 2038 | W13: 2039 | X13: 2040 | Y13: 2041 | Z13: 2042 | AA13: 2043 | AB13: 2044 | AC13: 2045 | AD13: 2046 | AE13: 2047 | AF13: 2048 | AG13: 2049 | AH13: 2050 | AI13: (percent)
A15: ISM000:ba_GDP(billionm_ | C15: Gross Domestic Product (billion 2012 dollars) | D15: 18171.387 | E15: ='AEO22 Table 23 Raw'!F7 -> 19287.709 | F15: ='AEO22 Table 23 Raw'!G7 -> 19760.287 | G15: ='AEO22 Table 23 Raw'!H7 -> 20221.789 | H15: ='AEO22 Table 23 Raw'!I7 -> 20729.912 | I15: ='AEO22 Table 23 Raw'!J7 -> 21174.707 | J15: ='AEO22 Table 23 Raw'!K7 -> 21588.189 | K15: ='AEO22 Table 23 Raw'!L7 -> 21943.693 | L15: ='AEO22 Table 23 Raw'!M7 -> 22341.447 | ... AI15: ='AEO22 Table 23 Raw'!AJ7 -> 0.018
A17: ISM000:ca_NonfarmEmploy | C17: Nonfarm Employment (millions) | D17: 141.52545 | E17: ='AEO22 Table 23 Raw'!F8 -> 147.7354 | F17: ='AEO22 Table 23 Raw'!G8 -> 148.57752 | G17: ='AEO22 Table 23 Raw'!H8 -> 151.11475 | H17: ='AEO22 Table 23 Raw'!I8 -> 152.88181 | I17: ='AEO22 Table 23 Raw'!J8 -> 153.79976 | J17: ='AEO22 Table 23 Raw'!K8 -> 154.22972 | K17: ='AEO22 Table 23 Raw'!L8 -> 154.40425 | L17: ='AEO22 Table 23 Raw'!M8 -> 154.76437 | ... AI17: ='AEO22 Table 23 Raw'!AJ8 -> 0.005
C19: Value of Shipments (billion 2012 dollars)
C21: Nonmanufacturing Sector
A22: ISM000:ea_Agricultural | B22: ISIC 01T03 | C22: Agriculture/Forestry/Fishing/Hunting | D22: 498.04193 | E22: ='AEO22 Table 23 Raw'!F11 -> 545.77948 | F22: ='AEO22 Table 23 Raw'!G11 -> 551.13959 | G22: ='AEO22 Table 23 Raw'!H11 -> 558.31287 | H22: ='AEO22 Table 23 Raw'!I11 -> 562.69605 | I22: ='AEO22 Table 23 Raw'!J11 -> 566.57074 | J22: ='AEO22 Table 23 Raw'!K11 -> 570.89679 | K22: ='AEO22 Table 23 Raw'!L11 -> 574.01483 | L22: ='AEO22 Table 23 Raw'!M11 -> 575.9624 | ... AI22: ='AEO22 Table 23 Raw'!AJ11 -> 0.004
A23: ISM000:ea_Mining | B23: ISIC 05, ISIC 06, ISIC 07T08 | C23: Mining | D23: 717.90631 | E23: ='AEO22 Table 23 Raw'!F12 -> 688.52893 | F23: ='AEO22 Table 23 Raw'!G12 -> 684.08637 | G23: ='AEO22 Table 23 Raw'!H12 -> 694.49341 | H23: ='AEO22 Table 23 Raw'!I12 -> 699.258 | I23: ='AEO22 Table 23 Raw'!J12 -> 707.49762 | J23: ='AEO22 Table 23 Raw'!K12 -> 709.31628 | K23: ='AEO22 Table 23 Raw'!L12 -> 706.40289 | L23: ='AEO22 Table 23 Raw'!M12 -> 714.3717 | ... AI23: ='AEO22 Table 23 Raw'!AJ12 -> 0.003
A24: ISM000:ea_Construction | B24: ISIC 41T43 | C24: Construction | D24: 1319.283 | E24: ='AEO22 Table 23 Raw'!F13 -> 1448.7993 | F24: ='AEO22 Table 23 Raw'!G13 -> 1344.485 | G24: ='AEO22 Table 23 Raw'!H13 -> 1310.302 | H24: ='AEO22 Table 23 Raw'!I13 -> 1321.8097 | I24: ='AEO22 Table 23 Raw'!J13 -> 1327.167 | J24: ='AEO22 Table 23 Raw'!K13 -> 1326.1383 | K24: ='AEO22 Table 23 Raw'!L13 -> 1323.1837 | L24: ='AEO22 Table 23 Raw'!M13 -> 1333.3877 | ... AI24: ='AEO22 Table 23 Raw'!AJ13 -> 0.007
C26: Manufacturing Sector
A27: ISM000:fa_FoodandKindre | B27: ISIC 10T12 | C27: Food Products | D27: 892.20709 | E27: ='AEO22 Table 23 Raw'!F15 -> 951.64435 | F27: ='AEO22 Table 23 Raw'!G15 -> 968.1377 | G27: ='AEO22 Table 23 Raw'!H15 -> 969.99872 | H27: ='AEO22 Table 23 Raw'!I15 -> 974.52918 | I27: ='AEO22 Table 23 Raw'!J15 -> 980.4978 | J27: ='AEO22 Table 23 Raw'!K15 -> 986.57391 | K27: ='AEO22 Table 23 Raw'!L15 -> 993.19183 | L27: ='AEO22 Table 23 Raw'!M15 -> 999.98218 | ... AI27: ='AEO22 Table 23 Raw'!AJ15 -> 0.005
A28: ISM000:fa_BeveragesandT | B28: ISIC 10T12 | C28: Beverages and Tobacco Products | D28: 150.3951 | E28: ='AEO22 Table 23 Raw'!F16 -> 150.72591 | F28: ='AEO22 Table 23 Raw'!G16 -> 146.54585 | G28: ='AEO22 Table 23 Raw'!H16 -> 143.67477 | H28: ='AEO22 Table 23 Raw'!I16 -> 141.76296 | I28: ='AEO22 Table 23 Raw'!J16 -> 140.0777 | J28: ='AEO22 Table 23 Raw'!K16 -> 138.97025 | K28: ='AEO22 Table 23 Raw'!L16 -> 138.3801 | L28: ='AEO22 Table 23 Raw'!M16 -> 138.23795 | ... AI28: ='AEO22 Table 23 Raw'!AJ16 -> -0.002
A29: ISM000:fa_TextileMillPr | B29: ISIC 13T15 | C29: Textile Mills and Products | D29: 63.119968 | E29: ='AEO22 Table 23 Raw'!F17 -> 66.721695 | F29: ='AEO22 Table 23 Raw'!G17 -> 67.566856 | G29: ='AEO22 Table 23 Raw'!H17 -> 68.538239 | H29: ='AEO22 Table 23 Raw'!I17 -> 68.599648 | I29: ='AEO22 Table 23 Raw'!J17 -> 68.280685 | J29: ='AEO22 Table 23 Raw'!K17 -> 67.760956 | K29: ='AEO22 Table 23 Raw'!L17 -> 67.162628 | L29: ='AEO22 Table 23 Raw'!M17 -> 66.83532 | ... AI29: ='AEO22 Table 23 Raw'!AJ17 -> -0.003
A30: ISM000:fa_LumberandWood | B30: ISIC 16 | C30: Wood Products | D30: 91.311569 | E30: ='AEO22 Table 23 Raw'!F18 -> 109.86588 | F30: ='AEO22 Table 23 Raw'!G18 -> 103.38457 | G30: ='AEO22 Table 23 Raw'!H18 -> 97.434769 | H30: ='AEO22 Table 23 Raw'!I18 -> 97.533112 | I30: ='AEO22 Table 23 Raw'!J18 -> 98.415634 | J30: ='AEO22 Table 23 Raw'!K18 -> 94.94783 | K30: ='AEO22 Table 23 Raw'!L18 -> 90.944565 | L30: ='AEO22 Table 23 Raw'!M18 -> 87.395416 | ... AI30: ='AEO22 Table 23 Raw'!AJ18 -> -0.007
A31: ISM000:fa_FurnitureandF | B31: ISIC 31T33 | C31: Furniture and Related Products | D31: 63.518311 | E31: ='AEO22 Table 23 Raw'!F19 -> 73.106606 | F31: ='AEO22 Table 23 Raw'!G19 -> 74.492615 | G31: ='AEO22 Table 23 Raw'!H19 -> 74.920853 | H31: ='AEO22 Table 23 Raw'!I19 -> 74.970245 | I31: ='AEO22 Table 23 Raw'!J19 -> 75.073692 | J31: ='AEO22 Table 23 Raw'!K19 -> 74.8134 | K31: ='AEO22 Table 23 Raw'!L19 -> 73.955078 | L31: ='AEO22 Table 23 Raw'!M19 -> 73.365143 | ... AI31: ='AEO22 Table 23 Raw'!AJ19 -> 0.009
A32: ISM000:fa_PaperandAllie | B32: ISIC 17T18 | C32: Paper Products | D32: 168.2229 | E32: ='AEO22 Table 23 Raw'!F20 -> 172.22682 | F32: ='AEO22 Table 23 Raw'!G20 -> 173.27202 | G32: ='AEO22 Table 23 Raw'!H20 -> 172.6449 | H32: ='AEO22 Table 23 Raw'!I20 -> 171.37058 | I32: ='AEO22 Table 23 Raw'!J20 -> 169.47244 | J32: ='AEO22 Table 23 Raw'!K20 -> 167.81551 | K32: ='AEO22 Table 23 Raw'!L20 -> 166.21905 | L32: ='AEO22 Table 23 Raw'!M20 -> 164.84427 | ... AI32: ='AEO22 Table 23 Raw'!AJ20 -> -0.008
A33: ISM000:fa_PrintingandPu | B33: ISIC 17T18 | C33: Printing | D33: 62.247051 | E33: ='AEO22 Table 23 Raw'!F21 -> 82.234703 | F33: ='AEO22 Table 23 Raw'!G21 -> 81.187164 | G33: ='AEO22 Table 23 Raw'!H21 -> 79.630684 | H33: ='AEO22 Table 23 Raw'!I21 -> 77.586235 | I33: ='AEO22 Table 23 Raw'!J21 -> 75.565125 | J33: ='AEO22 Table 23 Raw'!K21 -> 73.57209 | K33: ='AEO22 Table 23 Raw'!L21 -> 71.851616 | L33: ='AEO22 Table 23 Raw'!M21 -> 70.612923 | ... AI33: ='AEO22 Table 23 Raw'!AJ21 -> -0.014
A34: ISM000:fa_ChemicalandAl | B34: ISIC 20 | C34: Chemical Manufacturing | D34: 801.99793 | E34: ='AEO22 Table 23 Raw'!F22 -> 980.72162 | F34: ='AEO22 Table 23 Raw'!G22 -> 940.86902 | G34: ='AEO22 Table 23 Raw'!H22 -> 930.38812 | H34: ='AEO22 Table 23 Raw'!I22 -> 926.09253 | I34: ='AEO22 Table 23 Raw'!J22 -> 934.00262 | J34: ='AEO22 Table 23 Raw'!K22 -> 943.36395 | K34: ='AEO22 Table 23 Raw'!L22 -> 951.80042 | L34: ='AEO22 Table 23 Raw'!M22 -> 959.39624 | ... AI34: ='AEO22 Table 23 Raw'!AJ22 -> 0.009
A35: ISM000:fa_BulkChemicals | C35: Bulk Chemicals | D35: 425.08127 | E35: ='AEO22 Table 23 Raw'!F23 -> 463.10675 | F35: ='AEO22 Table 23 Raw'!G23 -> 455.29825 | G35: ='AEO22 Table 23 Raw'!H23 -> 451.30203 | H35: ='AEO22 Table 23 Raw'!I23 -> 448.81549 | I35: ='AEO22 Table 23 Raw'!J23 -> 456.10266 | J35: ='AEO22 Table 23 Raw'!K23 -> 463.94165 | K35: ='AEO22 Table 23 Raw'!L23 -> 470.07739 | L35: ='AEO22 Table 23 Raw'!M23 -> 475.59738 | ... AI35: ='AEO22 Table 23 Raw'!AJ23 -> 0.008
A36: ISM000:fa_Inorganic | C36: Inorganic | D36: 41.68821 | E36: ='AEO22 Table 23 Raw'!F24 -> 53.850636 | F36: ='AEO22 Table 23 Raw'!G24 -> 51.550568 | G36: ='AEO22 Table 23 Raw'!H24 -> 49.438751 | H36: ='AEO22 Table 23 Raw'!I24 -> 48.350109 | I36: ='AEO22 Table 23 Raw'!J24 -> 47.734375 | J36: ='AEO22 Table 23 Raw'!K24 -> 47.503693 | K36: ='AEO22 Table 23 Raw'!L24 -> 47.458179 | L36: ='AEO22 Table 23 Raw'!M24 -> 47.77747 | ... AI36: ='AEO22 Table 23 Raw'!AJ24 -> -0.008
A37: ISM000:fa_Organic | C37: Organic | D37: 225.51531 | E37: ='AEO22 Table 23 Raw'!F25 -> 234.04575 | F37: ='AEO22 Table 23 Raw'!G25 -> 225.48904 | G37: ='AEO22 Table 23 Raw'!H25 -> 227.23129 | H37: ='AEO22 Table 23 Raw'!I25 -> 229.23759 | I37: ='AEO22 Table 23 Raw'!J25 -> 233.21202 | J37: ='AEO22 Table 23 Raw'!K25 -> 235.84613 | K37: ='AEO22 Table 23 Raw'!L25 -> 238.11675 | L37: ='AEO22 Table 23 Raw'!M25 -> 240.73488 | ... AI37: ='AEO22 Table 23 Raw'!AJ25 -> 0.011
A38: ISM000:fa_Resins | C38: Resin, Synthetic Rubber, and Fibers | D38: 105.9968 | E38: ='AEO22 Table 23 Raw'!F26 -> 130.70677 | F38: ='AEO22 Table 23 Raw'!G26 -> 135.51041 | G38: ='AEO22 Table 23 Raw'!H26 -> 131.55824 | H38: ='AEO22 Table 23 Raw'!I26 -> 128.28755 | I38: ='AEO22 Table 23 Raw'!J26 -> 132.05852 | J38: ='AEO22 Table 23 Raw'!K26 -> 137.17943 | K38: ='AEO22 Table 23 Raw'!L26 -> 140.60777 | L38: ='AEO22 Table 23 Raw'!M26 -> 142.44058 | ... AI38: ='AEO22 Table 23 Raw'!AJ26 -> 0.01
A39: ISM000:fa_AgriculturalC | C39: Agricultural Chemicals | D39: 51.880939 | E39: ='AEO22 Table 23 Raw'!F27 -> 44.50359 | F39: ='AEO22 Table 23 Raw'!G27 -> 42.748219 | G39: ='AEO22 Table 23 Raw'!H27 -> 43.073761 | H39: ='AEO22 Table 23 Raw'!I27 -> 42.940258 | I39: ='AEO22 Table 23 Raw'!J27 -> 43.097713 | J39: ='AEO22 Table 23 Raw'!K27 -> 43.412411 | K39: ='AEO22 Table 23 Raw'!L27 -> 43.894714 | L39: ='AEO22 Table 23 Raw'!M27 -> 44.644444 | ... AI39: ='AEO22 Table 23 Raw'!AJ27 -> 0.004
A40: ISM000:fa_OtherChemical | C40: Other Chemical Products | D40: 376.91669 | E40: ='AEO22 Table 23 Raw'!F28 -> 517.61487 | F40: ='AEO22 Table 23 Raw'!G28 -> 485.57077 | G40: ='AEO22 Table 23 Raw'!H28 -> 479.08609 | H40: ='AEO22 Table 23 Raw'!I28 -> 477.27707 | I40: ='AEO22 Table 23 Raw'!J28 -> 477.89996 | J40: ='AEO22 Table 23 Raw'!K28 -> 479.4223 | K40: ='AEO22 Table 23 Raw'!L28 -> 481.72305 | L40: ='AEO22 Table 23 Raw'!M28 -> 483.79889 | ... AI40: ='AEO22 Table 23 Raw'!AJ28 -> 0.01
A41: ISM000:fa_PetroleumandC | B41: ISIC 19 | C41: Petroleum and Coal Products | D41: 777.24219 | E41: ='AEO22 Table 23 Raw'!F29 -> 789.06366 | F41: ='AEO22 Table 23 Raw'!G29 -> 885.51178 | G41: ='AEO22 Table 23 Raw'!H29 -> 899.4964 | H41: ='AEO22 Table 23 Raw'!I29 -> 897.32391 | I41: ='AEO22 Table 23 Raw'!J29 -> 897.97327 | J41: ='AEO22 Table 23 Raw'!K29 -> 896.10211 | K41: ='AEO22 Table 23 Raw'!L29 -> 892.39954 | L41: ='AEO22 Table 23 Raw'!M29 -> 890.51331 | ... AI41: ='AEO22 Table 23 Raw'!AJ29 -> 0.005
A42: ISM000:fa_PetroleumRefi | C42: Petroleum Refineries | D42: 735.55859 | E42: ='AEO22 Table 23 Raw'!F30 -> 746.87048 | F42: ='AEO22 Table 23 Raw'!G30 -> 840.716 | G42: ='AEO22 Table 23 Raw'!H30 -> 850.76227 | H42: ='AEO22 Table 23 Raw'!I30 -> 846.17731 | I42: ='AEO22 Table 23 Raw'!J30 -> 846.14966 | J42: ='AEO22 Table 23 Raw'!K30 -> 844.26404 | K42: ='AEO22 Table 23 Raw'!L30 -> 840.59943 | L42: ='AEO22 Table 23 Raw'!M30 -> 838.8761 | ... AI42: ='AEO22 Table 23 Raw'!AJ30 -> 0.004
A43: ISM000:fa_OtherPetroleu | C43: Other Petroleum and Coal Products | D43: 41.68362 | E43: ='AEO22 Table 23 Raw'!F31 -> 42.193161 | F43: ='AEO22 Table 23 Raw'!G31 -> 44.795792 | G43: ='AEO22 Table 23 Raw'!H31 -> 48.734158 | H43: ='AEO22 Table 23 Raw'!I31 -> 51.146606 | I43: ='AEO22 Table 23 Raw'!J31 -> 51.823608 | J43: ='AEO22 Table 23 Raw'!K31 -> 51.838081 | K43: ='AEO22 Table 23 Raw'!L31 -> 51.800133 | L43: ='AEO22 Table 23 Raw'!M31 -> 51.637184 | ... AI43: ='AEO22 Table 23 Raw'!AJ31 -> 0.009
A44: ISM000:fa_RubberandMisc | B44: ISIC 22 | C44: Plastics and Rubber Products | D44: 204.0638 | E44: ='AEO22 Table 23 Raw'!F32 -> 245.4554 | F44: ='AEO22 Table 23 Raw'!G32 -> 241.79295 | G44: ='AEO22 Table 23 Raw'!H32 -> 238.33037 | H44: ='AEO22 Table 23 Raw'!I32 -> 239.35245 | I44: ='AEO22 Table 23 Raw'!J32 -> 241.29742 | J44: ='AEO22 Table 23 Raw'!K32 -> 243.38844 | K44: ='AEO22 Table 23 Raw'!L32 -> 246.60761 | L44: ='AEO22 Table 23 Raw'!M32 -> 251.6187 | ... AI44: ='AEO22 Table 23 Raw'!AJ32 -> 0.013
A45: ISM000:fa_Stone,Clay,an | C45: Stone, Clay, and Glass Products | D45: 109.90946 | E45: ='AEO22 Table 23 Raw'!F33 -> 113.22774 | F45: ='AEO22 Table 23 Raw'!G33 -> 109.10921 | G45: ='AEO22 Table 23 Raw'!H33 -> 106.69244 | H45: ='AEO22 Table 23 Raw'!I33 -> 107.43405 | I45: ='AEO22 Table 23 Raw'!J33 -> 108.52844 | J45: ='AEO22 Table 23 Raw'!K33 -> 109.18559 | K45: ='AEO22 Table 23 Raw'!L33 -> 109.47917 | L45: ='AEO22 Table 23 Raw'!M33 -> 109.89218 | ... AI45: ='AEO22 Table 23 Raw'!AJ33 -> 0.003
A46: ISM000:fa_GlassandGlass | B46: ISIC 231 | C46: Glass and Glass Products | D46: 21.00304 | E46: ='AEO22 Table 23 Raw'!F34 -> 23.465088 | F46: ='AEO22 Table 23 Raw'!G34 -> 21.78306 | G46: ='AEO22 Table 23 Raw'!H34 -> 21.384214 | H46: ='AEO22 Table 23 Raw'!I34 -> 20.878117 | I46: ='AEO22 Table 23 Raw'!J34 -> 20.782543 | J46: ='AEO22 Table 23 Raw'!K34 -> 20.692644 | K46: ='AEO22 Table 23 Raw'!L34 -> 20.512907 | L46: ='AEO22 Table 23 Raw'!M34 -> 20.323284 | ... AI46: ='AEO22 Table 23 Raw'!AJ34 -> -0.009
A47: ISM000:fa_CementandHydr | B47: ISIC 239 | C47: Cement and Lime | D47: 14.143185 | E47: ='AEO22 Table 23 Raw'!F35 -> 13.972248 | F47: ='AEO22 Table 23 Raw'!G35 -> 14.70841 | G47: ='AEO22 Table 23 Raw'!H35 -> 14.789883 | H47: ='AEO22 Table 23 Raw'!I35 -> 15.090622 | I47: ='AEO22 Table 23 Raw'!J35 -> 15.311079 | J47: ='AEO22 Table 23 Raw'!K35 -> 15.412535 | K47: ='AEO22 Table 23 Raw'!L35 -> 15.460963 | L47: ='AEO22 Table 23 Raw'!M35 -> 15.52693 | ... AI47: ='AEO22 Table 23 Raw'!AJ35 -> 0.01
A48: ISM000:fa_OtherStone,Cl | B48: ISIC 239 | C48: Other Nonmetallic Mineral Products | D48: 74.763237 | E48: ='AEO22 Table 23 Raw'!F36 -> 75.790398 | F48: ='AEO22 Table 23 Raw'!G36 -> 72.617737 | G48: ='AEO22 Table 23 Raw'!H36 -> 70.518349 | H48: ='AEO22 Table 23 Raw'!I36 -> 71.465309 | I48: ='AEO22 Table 23 Raw'!J36 -> 72.434814 | J48: ='AEO22 Table 23 Raw'!K36 -> 73.080406 | K48: ='AEO22 Table 23 Raw'!L36 -> 73.505302 | L48: ='AEO22 Table 23 Raw'!M36 -> 74.041969 | ... AI48: ='AEO22 Table 23 Raw'!AJ36 -> 0.004
A49: ISM000:ga_PrimaryMetals | C49: Primary Metals Industry | D49: 221.20732 | E49: ='AEO22 Table 23 Raw'!F37 -> 240.15085 | F49: ='AEO22 Table 23 Raw'!G37 -> 248.90256 | G49: ='AEO22 Table 23 Raw'!H37 -> 250.07703 | H49: ='AEO22 Table 23 Raw'!I37 -> 249.02979 | I49: ='AEO22 Table 23 Raw'!J37 -> 250.30414 | J49: ='AEO22 Table 23 Raw'!K37 -> 250.60803 | K49: ='AEO22 Table 23 Raw'!L37 -> 250.12616 | L49: ='AEO22 Table 23 Raw'!M37 -> 250.00717 | ... AI49: ='AEO22 Table 23 Raw'!AJ37 -> 0.003
...

Sheet Growth Rates
A1: BLS Data | F1: EIA AEO Data
B2: Compound Growth Rate (output-weighted average of components of each ISIC code)
B3: 2009-2019 | C3: 2019-2029 | G3: 2020-2050
A4: ISIC 01T03 | B4: {=SUMPRODUCT(--('BLS Table 2.7'!$O:$O=$A4),'BLS Table 2.7'!K:K,'BLS Table 2.7'!M:M)/SUMIFS('BLS Table 2.7'!K:K,'BLS Table 2.7'!$O:$O,$A4)/100} -> 0.022 | C4: {=SUMPRODUCT(--('BLS Table 2.7'!$O:$O=$A4),'BLS Table 2.7'!L:L,'BLS Table 2.7'!N:N)/SUMIFS('BLS Table 2.7'!L:L,'BLS Table 2.7'!$O:$O,$A4)/100} -> 0.018 | F4: ISIC 01T03 | G4: =IFERROR(INDEX('AEO22 Table 23'!$AI$22:$AI$58,MATCH($F4,'AEO22 Table 23'!$B$22:$B$58,0)),"") -> 0.004
A5: ISIC 05 | B5: {=SUMPRODUCT(--('BLS Table 2.7'!$O:$O=$A5),'BLS Table 2.7'!K:K,'BLS Table 2.7'!M:M)/SUMIFS('BLS Table 2.7'!K:K,'BLS Table 2.7'!$O:$O,$A5)/100} -> -0.013 | C5: {=SUMPRODUCT(--('BLS Table 2.7'!$O:$O=$A5),'BLS Table 2.7'!L:L,'BLS Table 2.7'!N:N)/SUMIFS('BLS Table 2.7'!L:L,'BLS Table 2.7'!$O:$O,$A5)/100} -> -0.002 | F5: ISIC 05 | G5: =IFERROR(INDEX('AEO22 Table 23'!$AI$22:$AI$58,MATCH($F5,'AEO22 Table 23'!$B$22:$B$58,0)),"")
A6: ISIC 06 | B6: {=SUMPRODUCT(--('BLS Table 2.7'!$O:$O=$A6),'BLS Table 2.7'!K:K,'BLS Table 2.7'!M:M)/SUMIFS('BLS Table 2.7'!K:K,'BLS Table 2.7'!$O:$O,$A6)/100} -> 0.055 | C6: {=SUMPRODUCT(--('BLS Table 2.7'!$O:$O=$A6),'BLS Table 2.7'!L:L,'BLS Table 2.7'!N:N)/SUMIFS('BLS Table 2.7'!L:L,'BLS Table 2.7'!$O:$O,$A6)/100} -> 0.034 | F6: ISIC 06 | G6: =IFERROR(INDEX('AEO22 Table 23'!$AI$22:$AI$58,MATCH($F6,'AEO22 Table 23'!$B$22:$B$58,0)),"")
A7: ISIC 07T08 | B7: {=SUMPRODUCT(--('BLS Table 2.7'!$O:$O=$A7),'BLS Table 2.7'!K:K,'BLS Table 2.7'!M:M)/SUMIFS('BLS Table 2.7'!K:K,'BLS Table 2.7'!$O:$O,$A7)/100} -> -0.01543937 | C7: {=SUMPRODUCT(--('BLS Table 2.7'!$O:$O=$A7),'BLS Table 2.7'!L:L,'BLS Table 2.7'!N:N)/SUMIFS('BLS Table 2.7'!L:L,'BLS Table 2.7'!$O:$O,$A7)/100} -> 0.010045584 | F7: ISIC 07T08 | G7: =IFERROR(INDEX('AEO22 Table 23'!$AI$22:$AI$58,MATCH($F7,'AEO22 Table 23'!$B$22:$B$58,0)),"")
A8: ISIC 09 | B8: {=SUMPRODUCT(--('BLS Table 2.7'!$O:$O=$A8),'BLS Table 2.7'!K:K,'BLS Table 2.7'!M:M)/SUMIFS('BLS Table 2.7'!K:K,'BLS Table 2.7'!$O:$O,$A8)/100} -> -0.001 | C8: {=SUMPRODUCT(--('BLS Table 2.7'!$O:$O=$A8),'BLS Table 2.7'!L:L,'BLS Table 2.7'!N:N)/SUMIFS('BLS Table 2.7'!L:L,'BLS Table 2.7'!$O:$O,$A8)/100} -> 0.029 | F8: ISIC 09 | G8: =IFERROR(INDEX('AEO22 Table 23'!$AI$22:$AI$58,MATCH($F8,'AEO22 Table 23'!$B$22:$B$58,0)),"")
A9: ISIC 10T12 | B9: {=SUMPRODUCT(--('BLS Table 2.7'!$O:$O=$A9),'BLS Table 2.7'!K:K,'BLS Table 2.7'!M:M)/SUMIFS('BLS Table 2.7'!K:K,'BLS Table 2.7'!$O:$O,$A9)/100} -> 0.0093064841 | C9: {=SUMPRODUCT(--('BLS Table 2.7'!$O:$O=$A9),'BLS Table 2.7'!L:L,'BLS Table 2.7'!N:N)/SUMIFS('BLS Table 2.7'!L:L,'BLS Table 2.7'!$O:$O,$A9)/100} -> 0.015585313 | F9: ISIC 10T12 | G9: =IFERROR(INDEX('AEO22 Table 23'!$AI$22:$AI$58,MATCH($F9,'AEO22 Table 23'!$B$22:$B$58,0)),"") -> 0.005
A10: ISIC 13T15 | B10: {=SUMPRODUCT(--('BLS Table 2.7'!$O:$O=$A10),'BLS Table 2.7'!K:K,'BLS Table 2.7'!M:M)/SUMIFS('BLS Table 2.7'!K:K,'BLS Table 2.7'!$O:$O,$A10)/100} -> -0.0052350487 | C10: {=SUMPRODUCT(--('BLS Table 2.7'!$O:$O=$A10),'BLS Table 2.7'!L:L,'BLS Table 2.7'!N:N)/SUMIFS('BLS Table 2.7'!L:L,'BLS Table 2.7'!$O:$O,$A10)/100} -> -0.0021448864 | F10: ISIC 13T15 | G10: =IFERROR(INDEX('AEO22 Table 23'!$AI$22:$AI$58,MATCH($F10,'AEO22 Table 23'!$B$22:$B$58,0)),"") -> -0.003
A11: ISIC 16 | B11: {=SUMPRODUCT(--('BLS Table 2.7'!$O:$O=$A11),'BLS Table 2.7'!K:K,'BLS Table 2.7'!M:M)/SUMIFS('BLS Table 2.7'!K:K,'BLS Table 2.7'!$O:$O,$A11)/100} -> 0.024 | C11: {=SUMPRODUCT(--('BLS Table 2.7'!$O:$O=$A11),'BLS Table 2.7'!L:L,'BLS Table 2.7'!N:N)/SUMIFS('BLS Table 2.7'!L:L,'BLS Table 2.7'!$O:$O,$A11)/100} -> 0.014 | F11: ISIC 16 | G11: =IFERROR(INDEX('AEO22 Table 23'!$AI$22:$AI$58,MATCH($F11,'AEO22 Table 23'!$B$22:$B$58,0)),"") -> -0.007
A12: ISIC 17T18 | B12: {=SUMPRODUCT(--('BLS Table 2.7'!$O:$O=$A12),'BLS Table 2.7'!K:K,'BLS Table 2.7'!M:M)/SUMIFS('BLS Table 2.7'!K:K,'BLS Table 2.7'!$O:$O,$A12)/100} -> 0.00039223972 | C12: {=SUMPRODUCT(--('BLS Table 2.7'!$O:$O=$A12),'BLS Table 2.7'!L:L,'BLS Table 2.7'!N:N)/SUMIFS('BLS Table 2.7'!L:L,'BLS Table 2.7'!$O:$O,$A12)/100} -> 0.0049882741 | F12: ISIC 17T18 | G12: =IFERROR(INDEX('AEO22 Table 23'!$AI$22:$AI$58,MATCH($F12,'AEO22 Table 23'!$B$22:$B$58,0)),"") -> -0.008
A13: ISIC 19 | B13: {=SUMPRODUCT(--('BLS Table 2.7'!$O:$O=$A13),'BLS Table 2.7'!K:K,'BLS Table 2.7'!M:M)/SUMIFS('BLS Table 2.7'!K:K,'BLS Table 2.7'!$O:$O,$A13)/100} -> 0.007 | C13: {=SUMPRODUCT(--('BLS Table 2.7'!$O:$O=$A13),'BLS Table 2.7'!L:L,'BLS Table 2.7'!N:N)/SUMIFS('BLS Table 2.7'!L:L,'BLS Table 2.7'!$O:$O,$A13)/100} -> 0.023 | F13: ISIC 19 | G13: =IFERROR(INDEX('AEO22 Table 23'!$AI$22:$AI$58,MATCH($F13,'AEO22 Table 23'!$B$22:$B$58,0)),"") -> 0.005
A14: ISIC 20 | B14: {=SUMPRODUCT(--('BLS Table 2.7'!$O:$O=$A14),'BLS Table 2.7'!K:K,'BLS Table 2.7'!M:M)/SUMIFS('BLS Table 2.7'!K:K,'BLS Table 2.7'!$O:$O,$A14)/100} -> 0.022260187 | C14: {=SUMPRODUCT(--('BLS Table 2.7'!$O:$O=$A14),'BLS Table 2.7'!L:L,'BLS Table 2.7'!N:N)/SUMIFS('BLS Table 2.7'!L:L,'BLS Table 2.7'!$O:$O,$A14)/100} -> 0.018352106 | F14: ISIC 20 | G14: =IFERROR(INDEX('AEO22 Table 23'!$AI$22:$AI$58,MATCH($F14,'AEO22 Table 23'!$B$22:$B$58,0)),"") -> 0.009
A15: ISIC 21 | B15: {=SUMPRODUCT(--('BLS Table 2.7'!$O:$O=$A15),'BLS Table 2.7'!K:K,'BLS Table 2.7'!M:M)/SUMIFS('BLS Table 2.7'!K:K,'BLS Table 2.7'!$O:$O,$A15)/100} -> -0.004 | C15: {=SUMPRODUCT(--('BLS Table 2.7'!$O:$O=$A15),'BLS Table 2.7'!L:L,'BLS Table 2.7'!N:N)/SUMIFS('BLS Table 2.7'!L:L,'BLS Table 2.7'!$O:$O,$A15)/100} -> 0.018 | F15: ISIC 21 | G15: =IFERROR(INDEX('AEO22 Table 23'!$AI$22:$AI$58,MATCH($F15,'AEO22 Table 23'!$B$22:$B$58,0)),"")
... A24: ISIC 28 | B24: {=SUMPRODUCT(--('BLS Table 2.7'!$O:$O=$A24),'BLS Table 2.7'!K:K,'BLS Table 2.7'!M:M)/SUMIFS('BLS Table 2.7'!K:K,'BLS Table 2.7'!$O:$O,$A24)/100} -> 0.025 | C24: {=SUMPRODUCT(--('BLS Table 2.7'!$O:$O=$A24),'BLS Table 2.7'!L:L,'BLS Table 2.7'!N:N)/SUMIFS('BLS Table 2.7'!L:L,'BLS Table 2.7'!$O:$O,$A24)/100} -> 0.015 | F24: ISIC 28 | G24: =IFERROR(INDEX('AEO22 Table 23'!$AI$22:$AI$58,MATCH($F24,'AEO22 Table 23'!$B$22:$B$58,0)),"") -> 0.013
A25: ISIC 29 | B25: {=SUMPRODUCT(--('BLS Table 2.7'!$O:$O=$A25),'BLS Table 2.7'!K:K,'BLS Table 2.7'!M:M)/SUMIFS('BLS Table 2.7'!K:K,'BLS Table 2.7'!$O:$O,$A25)/100} -> 0.073700262 | C25: {=SUMPRODUCT(--('BLS Table 2.7'!$O:$O=$A25),'BLS Table 2.7'!L:L,'BLS Table 2.7'!N:N)/SUMIFS('BLS Table 2.7'!L:L,'BLS Table 2.7'!$O:$O,$A25)/100} -> 0.018032437 | F25: ISIC 29 | G25: ='AEO22 Table 23'!$AI$56 -> 0.01
A26: ISIC 30 | B26: {=SUMPRODUCT(--('BLS Table 2.7'!$O:$O=$A26),'BLS Table 2.7'!K:K,'BLS Table 2.7'!M:M)/SUMIFS('BLS Table 2.7'!K:K,'BLS Table 2.7'!$O:$O,$A26)/100} -> 0.017897004 | C26: {=SUMPRODUCT(--('BLS Table 2.7'!$O:$O=$A26),'BLS Table 2.7'!L:L,'BLS Table 2.7'!N:N)/SUMIFS('BLS Table 2.7'!L:L,'BLS Table 2.7'!$O:$O,$A26)/100} -> 0.019602007 | F26: ISIC 30 | G26: ='AEO22 Table 23'!$AI$56 -> 0.01
A27: ISIC 31T33 | B27: {=SUMPRODUCT(--('BLS Table 2.7'!$O:$O=$A27),'BLS Table 2.7'!K:K,'BLS Table 2.7'!M:M)/SUMIFS('BLS Table 2.7'!K:K,'BLS Table 2.7'!$O:$O,$A27)/100} -> 0.0061778414 | C27: {=SUMPRODUCT(--('BLS Table 2.7'!$O:$O=$A27),'BLS Table 2.7'!L:L,'BLS Table 2.7'!N:N)/SUMIFS('BLS Table 2.7'!L:L,'BLS Table 2.7'!$O:$O,$A27)/100} -> 0.014107993 | F27: ISIC 31T33 | G27: =IFERROR(INDEX('AEO22 Table 23'!$AI$22:$AI$58,MATCH($F27,'AEO22 Table 23'!$B$22:$B$58,0)),"") -> 0.009
A28: ISIC 351 | B28: {=SUMPRODUCT(--('BLS Table 2.7'!$O:$O=$A28),'BLS Table 2.7'!K:K,'BLS Table 2.7'!M:M)/SUMIFS('BLS Table 2.7'!K:K,'BLS Table 2.7'!$O:$O,$A28)/100} -> 0.005 | C28: {=SUMPRODUCT(--('BLS Table 2.7'!$O:$O=$A28),'BLS Table 2.7'!L:L,'BLS Table 2.7'!N:N)/SUMIFS('BLS Table 2.7'!L:L,'BLS Table 2.7'!$O:$O,$A28)/100} -> 0.017 | F28: ISIC 351 | G28: =IFERROR(INDEX('AEO22 Table 23'!$AI$22:$AI$58,MATCH($F28,'AEO22 Table 23'!$B$22:$B$58,0)),"")
A29: ISIC 352T353 | B29: {=SUMPRODUCT(--('BLS Table 2.7'!$O:$O=$A29),'BLS Table 2.7'!K:K,'BLS Table 2.7'!M:M)/SUMIFS('BLS Table 2.7'!K:K,'BLS Table 2.7'!$O:$O,$A29)/100} -> 0.002 | C29: {=SUMPRODUCT(--('BLS Table 2.7'!$O:$O=$A29),'BLS Table 2.7'!L:L,'BLS Table 2.7'!N:N)/SUMIFS('BLS Table 2.7'!L:L,'BLS Table 2.7'!$O:$O,$A29)/100} -> 0.008 | F29: ISIC 352T353 | G29: =IFERROR(INDEX('AEO22 Table 23'!$AI$22:$AI$58,MATCH($F29,'AEO22 Table 23'!$B$22:$B$58,0)),"")
A30: ISIC 36T39 | B30: {=SUMPRODUCT(--('BLS Table 2.7'!$O:$O=$A30),'BLS Table 2.7'!K:K,'BLS Table 2.7'!M:M)/SUMIFS('BLS Table 2.7'!K:K,'BLS Table 2.7'!$O:$O,$A30)/100} -> 0.014653409 | C30: {=SUMPRODUCT(--('BLS Table 2.7'!$O:$O=$A30),'BLS Table 2.7'!L:L,'BLS Table 2.7'!N:N)/SUMIFS('BLS Table 2.7'!L:L,'BLS Table 2.7'!$O:$O,$A30)/100} -> 0.016380645 | F30: ISIC 36T39 | G30: =IFERROR(INDEX('AEO22 Table 23'!$AI$22:$AI$58,MATCH($F30,'AEO22 Table 23'!$B$22:$B$58,0)),"")
A31: ISIC 41T43 | B31: {=SUMPRODUCT(--('BLS Table 2.7'!$O:$O=$A31),'BLS Table 2.7'!K:K,'BLS Table 2.7'!M:M)/SUMIFS('BLS Table 2.7'!K:K,'BLS Table 2.7'!$O:$O,$A31)/100} -> 0.02 | C31: {=SUMPRODUCT(--('BLS Table 2.7'!$O:$O=$A31),'BLS Table 2.7'!L:L,'BLS Table 2.7'!N:N)/SUMIFS('BLS Table 2.7'!L:L,'BLS Table 2.7'!$O:$O,$A31)/100} -> 0.013 | F31: ISIC 41T43 | G31: =IFERROR(INDEX('AEO22 Table 23'!$AI$22:$AI$58,MATCH($F31,'AEO22 Table 23'!$B$22:$B$58,0)),"") -> 0.007
A32: ISIC 45T47 | B32: {=SUMPRODUCT(--('BLS Table 2.7'!$O:$O=$A32),'BLS Table 2.7'!K:K,'BLS Table 2.7'!M:M)/SUMIFS('BLS Table 2.7'!K:K,'BLS Table 2.7'!$O:$O,$A32)/100} -> 0.041035167 | C32: {=SUMPRODUCT(--('BLS Table 2.7'!$O:$O=$A32),'BLS Table 2.7'!L:L,'BLS Table 2.7'!N:N)/SUMIFS('BLS Table 2.7'!L:L,'BLS Table 2.7'!$O:$O,$A32)/100} -> 0.025021213 | F32: ISIC 45T47 | G32: =IFERROR(INDEX('AEO22 Table 23'!$AI$22:$AI$58,MATCH($F32,'AEO22 Table 23'!$B$22:$B$58,0)),"")
A33: ISIC 49T53 | B33: {=SUMPRODUCT(--('BLS Table 2.7'!$O:$O=$A33),'BLS Table 2.7'!K:K,'BLS Table 2.7'!M:M)/SUMIFS('BLS Table 2.7'!K:K,'BLS Table 2.7'!$O:$O,$A33)/100} -> 0.018 | C33: {=SUMPRODUCT(--('BLS Table 2.7'!$O:$O=$A33),'BLS Table 2.7'!L:L,'BLS Table 2.7'!N:N)/SUMIFS('BLS Table 2.7'!L:L,'BLS Table 2.7'!$O:$O,$A33)/100} -> 0.016 | F33: ISIC 49T53 | G33: =IFERROR(INDEX('AEO22 Table 23'!$AI$22:$AI$58,MATCH($F33,'AEO22 Table 23'!$B$22:$B$58,0)),"")
A34: ISIC 55T56 | B34: {=SUMPRODUCT(--('BLS Table 2.7'!$O:$O=$A34),'BLS Table 2.7'!K:K,'BLS Table 2.7'!M:M)/SUMIFS('BLS Table 2.7'!K:K,'BLS Table 2.7'!$O:$O,$A34)/100} -> 0.031 | C34: {=SUMPRODUCT(--('BLS Table 2.7'!$O:$O=$A34),'BLS Table 2.7'!L:L,'BLS Table 2.7'!N:N)/SUMIFS('BLS Table 2.7'!L:L,'BLS Table 2.7'!$O:$O,$A34)/100} -> 0.021 | F34: ISIC 55T56 | G34: =IFERROR(INDEX('AEO22 Table 23'!$AI$22:$AI$58,MATCH($F34,'AEO22 Table 23'!$B$22:$B$58,0)),"")
A35: ISIC 58T60 | B35: {=SUMPRODUCT(--('BLS Table 2.7'!$O:$O=$A35),'BLS Table 2.7'!K:K,'BLS Table 2.7'!M:M)/SUMIFS('BLS Table 2.7'!K:K,'BLS Table 2.7'!$O:$O,$A35)/100} -> 0.022434706 | C35: {=SUMPRODUCT(--('BLS Table 2.7'!$O:$O=$A35),'BLS Table 2.7'!L:L,'BLS Table 2.7'!N:N)/SUMIFS('BLS Table 2.7'!L:L,'BLS Table 2.7'!$O:$O,$A35)/100} -> 0.026399864 | F35: ISIC 58T60 | G35: =IFERROR(INDEX('AEO22 Table 23'!$AI$22:$AI$58,MATCH($F35,'AEO22 Table 23'!$B$22:$B$58,0)),"")
A36: ISIC 61 | B36: {=SUMPRODUCT(--('BLS Table 2.7'!$O:$O=$A36),'BLS Table 2.7'!K:K,'BLS Table 2.7'!M:M)/SUMIFS('BLS Table 2.7'!K:K,'BLS Table 2.7'!$O:$O,$A36)/100} -> 0.037 | C36: {=SUMPRODUCT(--('BLS Table 2.7'!$O:$O=$A36),'BLS Table 2.7'!L:L,'BLS Table 2.7'!N:N)/SUMIFS('BLS Table 2.7'!L:L,'BLS Table 2.7'!$O:$O,$A36)/100} -> 0.02 | F36: ISIC 61 | G36: =IFERROR(INDEX('AEO22 Table 23'!$AI$22:$AI$58,MATCH($F36,'AEO22 Table 23'!$B$22:$B$58,0)),"")
A37: ISIC 62T63 | B37: {=SUMPRODUCT(--('BLS Table 2.7'!$O:$O=$A37),'BLS Table 2.7'!K:K,'BLS Table 2.7'!M:M)/SUMIFS('BLS Table 2.7'!K:K,'BLS Table 2.7'!$O:$O,$A37)/100} -> 0.13241388 | C37: {=SUMPRODUCT(--('BLS Table 2.7'!$O:$O=$A37),'BLS Table 2.7'!L:L,'BLS Table 2.7'!N:N)/SUMIFS('BLS Table 2.7'!L:L,'BLS Table 2.7'!$O:$O,$A37)/100} -> 0.037309863 | F37: ISIC 62T63 | G37: =IFERROR(INDEX('AEO22 Table 23'!$AI$22:$AI$58,MATCH($F37,'AEO22 Table 23'!$B$22:$B$58,0)),"")
